Workbook

Sheet 总览
A1: ShellStorm2 游戏内容数据库 v0.1
A2: 设计、内容与实现状态的中央索引｜最后校对：2026-08-27｜正式入口：TowerDescent3D.tscn
A3: 绿色字体=已实装；蓝色字体=用户设计；橙色字体=Codex补充。条目存在不等于全部表现与数值已通过最终QA。
A5: 工作表 | B5: 当前条目 | C5: 已实装 | D5: 用户设计 | E5: Codex补充 | F5: 对应系统 | G5: 主要用途 | H5: 维护提示
A6: 武器 | B6: 24 | C6: 24 | D6: 0 | E6: 0 | F6: 系统2/5 | G6: 7远程枪身、3近战、8子弹、6配件、数值、价格和产出 | H6: WeaponInstance统一承载远近战；六公共枪械配件位置固定、兼容子集禁用、单拆/整枪随行；棒球棍为基地初级近战
A7: 命运卡 | B7: 78 | C7: 48 | D7: 30 | E7: 0 | F7: 系统2/6 | G7: 78张塔罗命运：22大+56小阿尔卡那；正/逆位功能、概率和翻牌UI设计 | H7: 目标分布36星星/21月亮/21太阳。48张现有卡已完成塔罗命名、正逆位效果快照和代码翻牌；30张新增卡执行器待施工
A8: 怪物与Boss | B8: =COUNTA('怪物与Boss'!$A$5:$A$204) | C8: =COUNTIF('怪物与Boss'!$L$5:$L$204,"[已实装]") | D8: =COUNTIF('怪物与Boss'!$L$5:$L$204,"[用户设计]") | E8: =COUNTIF('怪物与Boss'!$L$5:$L$204,"[Codex补充]") | F8: 系统3/4 | G8: 正式3D敌人基线、技能与刷新 | H8: 不要混入旧2D生命基线
A9: 精英怪 | B9: 12 | C9: 1 | D9: 11 | E9: 0 | F9: 系统4/7 | G9: 12只唯一精英定义；当前正式内容1/12 | H9: 首只背枪的裂口爬虫已投放98—96F并完成残血逃脱、击杀玩家归因、12级成长、副枪频率、夺械转译和悬赏兑现；其余11只design_only
A10: 掉落物品 | B10: 45 | C10: 38 | D10: 7 | E10: 0 | F10: 系统2/3/5/7 | G10: 物品、价格、稀有度和掉落池 | H10: 武器成品保留实例构筑；新增基地初级棒球棍；3种背包装备提供2/4/8扩展格；电池与贩卖机ID已对齐
A12: 七大系统与文档定位
A13: 编号 | B13: 核心系统 | C13: 主内容表 | D13: 设计状态 | E13: 实现状态 | F13: P0焦点 | G13: 主施工文档 | H13: 备注
A14: 1 | B14: 玩家状态机与操作 | C14: — | D14: 已冻结 | E14: 正式3D较完整 | F14: 交互仲裁/状态诊断 | G14: 03_技术施工_玩家与操作.md | H14: 视觉根与玩法根分离
A15: 2 | B15: 战斗/武器/子弹/命运卡 | C15: 武器/命运卡 | D15: 已冻结 | E15: 正式3D核心闭环已验收（含3近战/统一配件槽） | F15: 最终近战武器美术/配件专属模型/逐卡表现QA | G15: 04_技术施工_战斗与局内成长.md | H15: 构筑随具体武器实例；7远程+3近战；六公共配件位置固定，枪型开放兼容子集
A16: 3 | B16: 关卡生成与爬楼 | C16: 怪物/掉落 | D16: Boss路线新设定已冻结 | E16: 当前生成可用 | F16: 专钥匙/专门门/Boss后电梯 | G16: 05_技术施工_关卡生成与爬楼.md | H16: 整层一次冻结
A17: 4 | B17: 怪物/精英/Boss | C17: 怪物/精英怪 | D17: 12精英已冻结 | E17: 唯一系统完成；正式精英内容1/12 | F17: 剩余11只独立内容与投放 | G17: 06_技术施工_怪物精英与Boss.md | H17: 定义/档案/表现已解耦；未完成精英不进入随机池
A18: 5 | B18: 基地设施 | C18: 多表引用 | D18: 已冻结 | E18: 八设施可用 | F18: 精英档案/设施服务化 | G18: 07_技术施工_基地设施.md | H18: UI不直接写存档
A19: 6 | B19: 剧情触发 | C19: 后续剧情表 | D19: 系统边界已冻结 | E19: 基础NPC/事件 | F19: 独立触发服务 | G19: 08_技术施工_剧情触发.md | H19: 不擅自补写主线
A20: 7 | B20: 存档/结算/复活 | C20: 精英/掉落 | D20: 边界已冻结 | E20: 基地/结算与武器实例迁移可用 | F20: 结算幂等/复活策略 | G20: 09_技术施工_存档结算与复活.md | H20: 复活政策尚未冻结
A22: 发布前检查：稳定ID唯一｜78张卡名唯一｜22大+56小｜36/21/21作用域｜正/逆各50%｜逆位整卡倒置｜旧存档不重投｜实现状态真实

Sheet 武器
A1: ShellStorm2 游戏内容数据库｜武器
A2: 正式注册：7远程枪身、2大型近战武器、8子弹、6配件。独立WeaponInstance与普通武器8命运槽已实装；近战四态/三段/命中闭环已验收，逐条最终美术与专属音频继续QA。
A3: 字体颜色：绿色=已实装；蓝色=用户设计；橙色=Codex补充。实现状态需结合事实源判断。
A4: 内容ID | B4: 类别 | C4: 名称 | D4: 蓝图Tier | E4: 稀有度 | F4: 价格 | G4: 核心数值 | H4: 功能 | I4: 特殊效果/标签 | J4: 产出与掉落 | K4: 状态来源 | L4: 实现状态 | M4: 事实源 | N4: 备注 | O4: 基础命运槽 | P4: 实例/装配规则 | Q4: 新设计实现状态 | R4: 功能UI提示 | S4: 武器/战斗表现 | T4: 表现实现状态 | U4: 基地购买价 | V4: 基地出售价 | W4: 基地商店上架 | X4: 基地库存规则 | Y4: 基地货架顺序
A5: attach_big_mag | B5: 配件 | C5: 肉质弹匣 | D5: 1 | E5: uncommon | F5: 80 | G5: magazine_size=15 | H5: 装配后提供magazine_size=15；修饰方向：heal、capacity | I5: 标签：magazine、heal、capacity | J5: combat_floor_1×2.5；combat_floor_2×3；loot_abyss×2；loot_floor_3_4×2；loot_floor_5×2.5；scavenge_floor_3×2；scavenge_floor_4×2.5；scavenge_floor_5×2 | K5: [已实装] | L5: 正式注册；具体行为与表现仍需逐项QA | M5: src/base/BlueprintRegistry.gd；src/base/ItemRegistry.gd | P5: 可拆卸、可替换、可交易；不占命运槽；安装结果写入目标weapon_instance_id | Q5: [已实装] 可换装、不占命运槽，并随目标WeaponInstance完整保存/恢复 | R5: 弹匣槽显示容量/换弹差值与治疗触发说明；安装前后对比，注明可拆卸、不占命运槽 | S5: 更大弹匣实体与换弹动作同步；治疗触发时弹匣图标和绿色脉冲同时出现 | T5: [部分完成] 实例尾号、槽位、已装配件与命运刻印已可视；逐条专属VFX/音频仍待QA | U5: =IF(F5>0,F5,0) | V5: =IF(F5>0,ROUND(F5*0.5,0),0) | W5: FALSE | X5: not_listed | Y5: 0
A6: attach_copy_sticker | B6: 配件 | C6: 复制贴纸 | D6: 2 | E6: epic | F6: 200 | G6: copy_chance=0.25 | H6: 装配后提供copy_chance=0.25；修饰方向：copy、duplicate | I6: 标签：mutator、copy、duplicate | J6: boss_floor_1×3；boss_floor_2×4；combat_floor_3×1；combat_floor_4×1.5；combat_floor_5×2；loot_abyss×2；scavenge_floor_4×2；scavenge_floor_5×3 | K6: [已实装] | L6: 正式注册；具体行为与表现仍需逐项QA | M6: src/base/BlueprintRegistry.gd；src/base/ItemRegistry.gd | P6: 可拆卸、可替换、可交易；不占命运槽；安装结果写入目标weapon_instance_id | Q6: [已实装] 可换装、不占命运槽，并随目标WeaponInstance完整保存/恢复 | R6: 外接槽显示复制概率、可复制对象和触发条件；触发链显示来源与限制 | S6: 枪身出现实体贴纸；触发复制时产生对象残影、专属图标脉冲和短音效 | T6: [部分完成] 实例尾号、槽位、已装配件与命运刻印已可视；逐条专属VFX/音频仍待QA | U6: =IF(F6>0,F6,0) | V6: =IF(F6>0,ROUND(F6*0.5,0),0) | W6: FALSE | X6: not_listed | Y6: 0
A7: attach_fan | B7: 配件 | C7: 小风扇 | D7: 2 | E7: epic | F7: 150 | G7: pull_strength=0.5 | H7: 装配后提供pull_strength=0.5；修饰方向：pull、wind | I7: 标签：external、pull、wind | J7: boss_floor_1×3；combat_floor_3×1.5；combat_floor_4×2；combat_floor_5×2.5；loot_abyss×2.5；loot_floor_5×2；scavenge_floor_4×2；scavenge_floor_5×2.5 | K7: [已实装] | L7: 正式注册；具体行为与表现仍需逐项QA | M7: src/base/BlueprintRegistry.gd；src/base/ItemRegistry.gd | P7: 可拆卸、可替换、可交易；不占命运槽；安装结果写入目标weapon_instance_id | Q7: [已实装] 可换装、不占命运槽，并随目标WeaponInstance完整保存/恢复 | R7: 外接槽显示拉力强度、作用对象和范围；战斗HUD保留吸附行为图标 | S7: 小风扇叶片持续转动；受力对象显示朝向流线，触发点播放吸附短音 | T7: [部分完成] 实例尾号、槽位、已装配件与命运刻印已可视；逐条专属VFX/音频仍待QA | U7: =IF(F7>0,F7,0) | V7: =IF(F7>0,ROUND(F7*0.5,0),0) | W7: FALSE | X7: not_listed | Y7: 0
A8: attach_rubber_stock | B8: 配件 | C8: 橡皮枪托 | D8: 0 | E8: common | F8: 45 | G8: spread=-0.04 | H8: 装配后提供spread=-0.04；修饰方向：bounce | I8: 标签：stock、bounce | J8: combat_floor_1×2.5；combat_floor_2×2；loot_abyss×1.5；loot_floor_1_2×3；loot_floor_3_4×2.5；loot_floor_5×2；scavenge_floor_1×3；scavenge_floor_2×2.5；scavenge_floor_3×2；scavenge_floor_4×1.5；spawn_starter×3 | K8: [已实装] | L8: 正式注册；具体行为与表现仍需逐项QA | M8: src/base/BlueprintRegistry.gd；src/base/ItemRegistry.gd | P8: 可拆卸、可替换、可交易；不占命运槽；安装结果写入目标weapon_instance_id | Q8: [已实装] 可换装、不占命运槽，并随目标WeaponInstance完整保存/恢复 | R8: 枪托槽显示扩散变化和弹跳行为；提供准星散布前后对比 | S8: 橡胶枪托实体挂接；后坐/准星收束可见，弹跳命中显示方向折线 | T8: [部分完成] 实例尾号、槽位、已装配件与命运刻印已可视；逐条专属VFX/音频仍待QA | U8: =IF(F8>0,F8,0) | V8: =IF(F8>0,ROUND(F8*0.5,0),0) | W8: FALSE | X8: not_listed | Y8: 0
A9: attach_scope | B9: 配件 | C9: 放大镜瞄具 | D9: 1 | E9: rare | F9: 100 | G9: damage=5；spread=-0.05 | H9: 装配后提供damage=5；spread=-0.05；修饰方向：crit、accuracy | I9: 标签：scope、crit、accuracy | J9: combat_floor_2×1.5；combat_floor_3×2.5；loot_abyss×3；loot_floor_3_4×2；loot_floor_5×2.5；scavenge_floor_3×2；scavenge_floor_4×2.5；scavenge_floor_5×3 | K9: [已实装] | L9: 正式注册；具体行为与表现仍需逐项QA | M9: src/base/BlueprintRegistry.gd；src/base/ItemRegistry.gd | P9: 可拆卸、可替换、可交易；不占命运槽；安装结果写入目标weapon_instance_id | Q9: [已实装] 可换装、不占命运槽，并随目标WeaponInstance完整保存/恢复 | R9: 瞄具槽显示伤害、扩散/暴击来源和瞄准差值；注明兼容枪型 | S9: 实际瞄具模型、瞄准姿态与准星同步变化；暴击命中使用高亮反馈 | T9: [部分完成] 实例尾号、槽位、已装配件与命运刻印已可视；逐条专属VFX/音频仍待QA | U9: =IF(F9>0,F9,0) | V9: =IF(F9>0,ROUND(F9*0.5,0),0) | W9: FALSE | X9: not_listed | Y9: 0
A10: attach_triple_muzzle | B10: 配件 | C10: 三叉枪口 | D10: 0 | E10: uncommon | F10: 70 | G10: bullet_count=2；spread=0.08 | H10: 装配后提供bullet_count=2；spread=0.08；修饰方向：multi_shot | I10: 标签：muzzle、multi_shot | J10: combat_floor_1×2；combat_floor_2×1.5；loot_abyss×1；loot_floor_1_2×2.5；loot_floor_3_4×2；loot_floor_5×1.5；scavenge_floor_1×2.5；scavenge_floor_2×2；scavenge_floor_3×1.5；scavenge_floor_4×1；spawn_starter×2.5 | K10: [已实装] | L10: 正式注册；具体行为与表现仍需逐项QA | M10: src/base/BlueprintRegistry.gd；src/base/ItemRegistry.gd | P10: 可拆卸、可替换、可交易；不占命运槽；安装结果写入目标weapon_instance_id | Q10: [已实装] 可换装、不占命运槽，并随目标WeaponInstance完整保存/恢复 | R10: 枪口槽显示弹丸数与扩散差值，并预览弹道扇形 | S10: 三叉枪口实体；开火时多枪口火焰、多弹道和声层同步 | T10: [部分完成] 实例尾号、槽位、已装配件与命运刻印已可视；逐条专属VFX/音频仍待QA | U10: =IF(F10>0,F10,0) | V10: =IF(F10>0,ROUND(F10*0.5,0),0) | W10: FALSE | X10: not_listed | Y10: 0
A11: mod_bullet_balloon | B11: 子弹 | C11: 气球弹模块 | D11: 1 | E11: rare | F11: 90 | G11: bullet_damage=18；bullet_speed=0.5 | H11: 提供bullet_damage=18；bullet_speed=0.5；弹道/命中行为：balloon、slow、big | I11: 标签：bullet、balloon、slow、big | J11: combat_floor_3×1；combat_floor_4×1.5；loot_abyss×2；loot_floor_3_4×1.5；loot_floor_5×2；scavenge_floor_3×1.5；scavenge_floor_4×2；scavenge_floor_5×2 | K11: [已实装] | L11: 正式注册；具体行为与表现仍需逐项QA | M11: src/base/BlueprintRegistry.gd；src/base/ItemRegistry.gd | P11: 可更换子弹模块；不占命运槽；弹道配置写入目标weapon_instance_id | Q11: [已实装] 可换装、不占命运槽，并随目标WeaponInstance完整保存/恢复 | R11: 子弹页显示体积、伤害、速度差值和大型弹体标签 | S11: 膨胀弹体、较重尾迹与命中体积一致，不能只改伤害数值 | T11: [部分完成] 实例尾号、槽位、已装配件与命运刻印已可视；逐条专属VFX/音频仍待QA | U11: =IF(F11>0,F11,0) | V11: =IF(F11>0,ROUND(F11*0.5,0),0) | W11: FALSE | X11: not_listed | Y11: 0
A12: mod_bullet_blackhole | B12: 子弹 | C12: 黑洞弹模块 | D12: 2 | E12: epic | F12: 180 | G12: bullet_damage=12；bullet_speed=0.6 | H12: 提供bullet_damage=12；bullet_speed=0.6；弹道/命中行为：blackhole、pull | I12: 标签：bullet、blackhole、pull | J12: boss_floor_1×3；boss_floor_2×4；combat_floor_4×2；combat_floor_5×3；loot_abyss×2.5；scavenge_floor_4×2.5；scavenge_floor_5×4 | K12: [已实装] | L12: 正式注册；具体行为与表现仍需逐项QA | M12: src/base/BlueprintRegistry.gd；src/base/ItemRegistry.gd | P12: 可更换子弹模块；不占命运槽；弹道配置写入目标weapon_instance_id | Q12: [已实装] 可换装、不占命运槽，并随目标WeaponInstance完整保存/恢复 | R12: 显示伤害、速度、牵引范围/强度和受影响对象 | S12: 黑洞核心、吸入流线和范围边界清晰；命中/结束有收束反馈 | T12: [部分完成] 实例尾号、槽位、已装配件与命运刻印已可视；逐条专属VFX/音频仍待QA | U12: =IF(F12>0,F12,0) | V12: =IF(F12>0,ROUND(F12*0.5,0),0) | W12: FALSE | X12: not_listed | Y12: 0
A13: mod_bullet_bounce | B13: 子弹 | C13: 回旋镖弹模块 | D13: 0 | E13: uncommon | F13: 60 | G13: bullet_damage=7；bullet_speed=1.1 | H13: 提供bullet_damage=7；bullet_speed=1.1；弹道/命中行为：bounce、ricochet | I13: 标签：bullet、bounce、ricochet | J13: combat_floor_1×1.5；combat_floor_2×2；loot_abyss×2；loot_floor_1_2×1.5；loot_floor_3_4×2；loot_floor_5×2.5；scavenge_floor_1×1.5；scavenge_floor_2×2；spawn_starter×1.5 | K13: [已实装] | L13: 正式注册；具体行为与表现仍需逐项QA | M13: src/base/BlueprintRegistry.gd；src/base/ItemRegistry.gd | P13: 可更换子弹模块；不占命运槽；弹道配置写入目标weapon_instance_id | Q13: [已实装] 可换装、不占命运槽，并随目标WeaponInstance完整保存/恢复 | R13: 显示弹跳次数、可反弹表面和剩余次数 | S13: 反弹点有折线闪光与计数递减，飞行方向变化清楚可读 | T13: [部分完成] 实例尾号、槽位、已装配件与命运刻印已可视；逐条专属VFX/音频仍待QA | U13: =IF(F13>0,F13,0) | V13: =IF(F13>0,ROUND(F13*0.5,0),0) | W13: FALSE | X13: not_listed | Y13: 0
A14: mod_bullet_explosive | B14: 子弹 | C14: 爆炸弹模块 | D14: 1 | E14: rare | F14: 100 | G14: bullet_damage=28；bullet_speed=0.75 | H14: 提供bullet_damage=28；bullet_speed=0.75；弹道/命中行为：explosive、area | I14: 标签：bullet、explosive、area | J14: combat_floor_3×1；loot_abyss×2.5；loot_floor_3_4×1.5；loot_floor_5×2；scavenge_floor_3×1.5；scavenge_floor_4×2；scavenge_floor_5×2.5 | K14: [已实装] | L14: 正式注册；具体行为与表现仍需逐项QA | M14: src/base/BlueprintRegistry.gd；src/base/ItemRegistry.gd | P14: 可更换子弹模块；不占命运槽；弹道配置写入目标weapon_instance_id | Q14: [已实装] 可换装、不占命运槽，并随目标WeaponInstance完整保存/恢复 | R14: 显示爆炸伤害、半径和触发时机；地面预览危险圈 | S14: 弹体、尾迹、爆炸半径与伤害时点同步，低特效下保留轮廓圈 | T14: [部分完成] 实例尾号、槽位、已装配件与命运刻印已可视；逐条专属VFX/音频仍待QA | U14: =IF(F14>0,F14,0) | V14: =IF(F14>0,ROUND(F14*0.5,0),0) | W14: FALSE | X14: not_listed | Y14: 0
A15: mod_bullet_homing | B15: 子弹 | C15: 蜂卵弹模块 | D15: 2 | E15: epic | F15: 150 | G15: bullet_damage=10；bullet_speed=0.9 | H15: 提供bullet_damage=10；bullet_speed=0.9；弹道/命中行为：homing、summon | I15: 标签：bullet、homing、summon | J15: boss_floor_1×4；combat_floor_4×1.5；combat_floor_5×2.5；loot_abyss×3；loot_floor_5×2；scavenge_floor_4×2；scavenge_floor_5×3 | K15: [已实装] | L15: 正式注册；具体行为与表现仍需逐项QA | M15: src/base/BlueprintRegistry.gd；src/base/ItemRegistry.gd | P15: 可更换子弹模块；不占命运槽；弹道配置写入目标weapon_instance_id | Q15: [已实装] 可换装、不占命运槽，并随目标WeaponInstance完整保存/恢复 | R15: 显示追踪强度、锁定条件和当前目标标记 | S15: 锁定框、弯曲尾迹和转向动作一致；目标丢失有解除提示 | T15: [部分完成] 实例尾号、槽位、已装配件与命运刻印已可视；逐条专属VFX/音频仍待QA | U15: =IF(F15>0,F15,0) | V15: =IF(F15>0,ROUND(F15*0.5,0),0) | W15: FALSE | X15: not_listed | Y15: 0
A16: mod_bullet_piercing | B16: 子弹 | C16: 穿甲弹模块 | D16: 1 | E16: rare | F16: 80 | G16: bullet_damage=14；bullet_speed=1.4 | H16: 提供bullet_damage=14；bullet_speed=1.4；弹道/命中行为：piercing、armor | I16: 标签：bullet、piercing、armor | J16: combat_floor_3×1.5；loot_abyss×3；loot_floor_3_4×2；loot_floor_5×2.5；scavenge_floor_3×2；scavenge_floor_4×2.5；scavenge_floor_5×3 | K16: [已实装] | L16: 正式注册；具体行为与表现仍需逐项QA | M16: src/base/BlueprintRegistry.gd；src/base/ItemRegistry.gd | P16: 可更换子弹模块；不占命运槽；弹道配置写入目标weapon_instance_id | Q16: [已实装] 可换装、不占命运槽，并随目标WeaponInstance完整保存/恢复 | R16: 显示穿透等级、可穿对象和命中衰减规则 | S16: 穿透命中显示连续贯穿线与剩余层数，不在首个目标处假性消失 | T16: [部分完成] 实例尾号、槽位、已装配件与命运刻印已可视；逐条专属VFX/音频仍待QA | U16: =IF(F16>0,F16,0) | V16: =IF(F16>0,ROUND(F16*0.5,0),0) | W16: FALSE | X16: not_listed | Y16: 0
... A18: mod_bullet_sticky | B18: 子弹 | C18: 黏黏弹模块 | D18: 0 | E18: uncommon | F18: 50 | G18: bullet_damage=6；bullet_speed=0.8 | H18: 提供bullet_damage=6；bullet_speed=0.8；弹道/命中行为：sticky、dot | I18: 标签：bullet、sticky、dot | J18: combat_floor_1×2；combat_floor_2×2.5；loot_abyss×1.5；loot_floor_1_2×2；loot_floor_3_4×2.5；loot_floor_5×2；scavenge_floor_1×2；scavenge_floor_2×2.5；spawn_starter×2 | K18: [已实装] | L18: 正式注册；具体行为与表现仍需逐项QA | M18: src/base/BlueprintRegistry.gd；src/base/ItemRegistry.gd | P18: 可更换子弹模块；不占命运槽；弹道配置写入目标weapon_instance_id | Q18: [已实装] 可换装、不占命运槽，并随目标WeaponInstance完整保存/恢复 | R18: 显示黏附对象、持续/引爆条件与每秒效果 | S18: 命中后弹体留在表面并显示倒计时/状态，结束时反馈与结算同步 | T18: [部分完成] 实例尾号、槽位、已装配件与命运刻印已可视；逐条专属VFX/音频仍待QA | U18: =IF(F18>0,F18,0) | V18: =IF(F18>0,ROUND(F18*0.5,0),0) | W18: FALSE | X18: not_listed | Y18: 0
A19: bp_charge | B19: 枪身 | C19: 蓄力萝卜炮 | D19: 3 | E19: epic | F19: 350 | G19: bullet_count=1；charge_time=1.2；damage=30；fire_rate=1.5；magazine_size=4；reload_time=3；spread=0.05 | H19: 蓄力时间越长伤害越高，超蓄力后弹体变大并附带穿透。左键装备为当前主武器。 | I19: 标签：charge、蓄力、high_damage | J19: 成品：boss_floor_2×4；combat_floor_4×0.5；combat_floor_5×1；elite_floor_2×3；loot_abyss×2；loot_floor_5×0.8；scavenge_floor_4×0.4；scavenge_floor_5×1 蓝图：boss_floor_2×4；combat_floor_4×0.5；combat_floor_5×1；loot_abyss×2；scavenge_floor_5×0.5 | K19: [已实装] | L19: 正式注册；具体行为与表现仍需逐项QA | M19: src/base/BlueprintRegistry.gd；src/base/ItemRegistry.gd | N19: 装配ID=bp_charge；成品物品ID=weapon_charge；蓝图物品ID=bp_charge | O19: 8 | P19: 成品生成永久weapon_instance_id；命运槽、子弹模块与配件随实例在装备/背包/地面/商店/保险/存档间移动 | Q19: [已实装] 唯一实例ID、8槽基线、完整构筑/弹药/命运记录随枪转移与存档 | R19: HUD和详情显示蓄力阶段、当前倍率、超蓄力风险、弹量和换弹 | S19: 枪身能量逐级充盈、音高与震动递增；释放弹体大小和穿透随阶段变化 | T19: [部分完成] 实例尾号、槽位、已装配件与命运刻印已可视；逐条专属VFX/音频仍待QA | U19: =IF(F19>0,F19,0) | V19: =IF(F19>0,ROUND(F19*0.5,0),0) | W19: FALSE | X19: not_listed | Y19: 0
A20: bp_launcher | B20: 枪身 | C20: 反胃榴弹筒 | D20: 2 | E20: rare | F20: 250 | G20: bullet_count=1；damage=38；fire_rate=0.8；magazine_size=3；reload_time=4；spread=0.1 | H20: 发射爆炸弹，抛物线弹道，大范围AOE。左键装备为当前主武器。 | I20: 标签：launcher、explosive、slow | J20: 成品：boss_floor_1×2.5；boss_floor_2×4；combat_floor_3×0.8；combat_floor_4×0.5；combat_floor_5×1；elite_floor_2×3；loot_abyss×2.5；loot_floor_3_4×1；loot_floor_5×1.5；scavenge_floor_3×0.5；scavenge_floor_4×1；scavenge_floor_5×2 蓝图：boss_floor_1×3；boss_floor_2×4；combat_floor_3×0.5；combat_floor_4×0.3；loot_abyss×2.5；scavenge_floor_5×1 | K20: [已实装] | L20: 正式注册；具体行为与表现仍需逐项QA | M20: src/base/BlueprintRegistry.gd；src/base/ItemRegistry.gd | N20: 装配ID=bp_launcher；成品物品ID=weapon_launcher；蓝图物品ID=bp_launcher | O20: 8 | P20: 成品生成永久weapon_instance_id；命运槽、子弹模块与配件随实例在装备/背包/地面/商店/保险/存档间移动 | Q20: [已实装] 唯一实例ID、8槽基线、完整构筑/弹药/命运记录随枪转移与存档 | R20: 显示抛物线、爆炸半径、弹量与安全距离；瞄准时给落点预览 | S20: 发射器抬升动作、弧线弹道、落点圈和爆炸反馈一致 | T20: [部分完成] 实例尾号、槽位、已装配件与命运刻印已可视；逐条专属VFX/音频仍待QA | U20: =IF(F20>0,F20,0) | V20: =IF(F20>0,ROUND(F20*0.5,0),0) | W20: FALSE | X20: not_listed | Y20: 0
A21: bp_machinegun | B21: 枪身 | C21: 蜂窝机枪 | D21: 1 | E21: uncommon | F21: 180 | G21: bullet_count=1；damage=15；fire_rate=12；magazine_size=60；reload_time=2.8；spread=0.15 | H21: 高射速压制武器，适合清群怪。左键装备为当前主武器。 | I21: 标签：auto、high_rate、spray | J21: 成品：combat_floor_1×0.8；combat_floor_2×1.2；combat_floor_3×1.5；elite_floor_1×1.5；elite_floor_2×2.5；loot_abyss×2.5；loot_floor_1_2×1；loot_floor_3_4×1.5；loot_floor_5×2；scavenge_floor_1×0.5；scavenge_floor_2×1；scavenge_floor_3×1.2；scavenge_floor_4×1.5；scavenge_floor_5×2.5 蓝图：combat_floor_1×0.8；combat_floor_2×0.5；loot_abyss×2.5；loot_floor_3_4×1.5；loot_floor_5×2；scavenge_floor_3×1.5；scavenge_floor_4×2；scavenge_floor_5×2.5 | K21: [已实装] | L21: 正式注册；具体行为与表现仍需逐项QA | M21: src/base/BlueprintRegistry.gd；src/base/ItemRegistry.gd | N21: 装配ID=bp_machinegun；成品物品ID=weapon_machinegun；蓝图物品ID=bp_machinegun | O21: 8 | P21: 成品生成永久weapon_instance_id；命运槽、子弹模块与配件随实例在装备/背包/地面/商店/保险/存档间移动 | Q21: [已实装] 唯一实例ID、8槽基线、完整构筑/弹药/命运记录随枪转移与存档 | R21: 显示高射速、弹量、扩散与持续射击节奏；低弹药警告明显 | S21: 连续枪口焰、机械循环和后坐累积可读，不能用单发动画冒充连射 | T21: [部分完成] 实例尾号、槽位、已装配件与命运刻印已可视；逐条专属VFX/音频仍待QA | U21: =IF(F21>0,F21,0) | V21: =IF(F21>0,ROUND(F21*0.5,0),0) | W21: FALSE | X21: not_listed | Y21: 0
A22: bp_pistol | B22: 枪身 | C22: 豌豆手枪 | D22: 0 | E22: common | F22: 70 | G22: bullet_count=1；damage=18；fire_rate=3.5；magazine_size=12；reload_time=1.5；spread=0.03 | H22: 可靠的基础半自动武器。左键装备为当前主武器。 | I22: 标签：pistol、semi_auto、sidearm | J22: 成品：combat_floor_1×0.5；combat_floor_2×0.8；loot_floor_1_2×0.8；scavenge_floor_1×0.8；scavenge_floor_2×1.4 蓝图：combat_floor_1×1.5；combat_floor_2×1；loot_abyss×1.5；loot_common×1；loot_floor_1_2×3；loot_floor_3_4×2.5；loot_floor_5×2；scavenge_floor_1×2.5；scavenge_floor_2×1.8；spawn_starter×4 | K22: [已实装] | L22: 正式注册；具体行为与表现仍需逐项QA | M22: src/base/BlueprintRegistry.gd；src/base/ItemRegistry.gd | N22: 装配ID=bp_pistol；成品物品ID=weapon_pistol；蓝图物品ID=bp_pistol | O22: 8 | P22: 生成永久weapon_instance_id；六个公共配件位置固定，枪型仅开放兼容子集；单拆配件，整枪移动时完整装配树随实例转移 | Q22: [已实装并验收] WeaponInstance schema v2、主副武器独立配件、兼容禁用、替换回滚与旧快照迁移 | R22: 显示半自动节奏、伤害、弹量与精准度，作为轻型基准枪比较 | S22: 每次点击有清晰单发后坐、枪口焰与复位，轮廓轻巧 | T22: [部分完成] 实例尾号、槽位、已装配件与命运刻印已可视；逐条专属VFX/音频仍待QA | U22: =IF(F22>0,F22,0) | V22: =IF(F22>0,ROUND(F22*0.5,0),0) | W22: TRUE | X22: unlimited | Y22: 2
A23: bp_rifle | B23: 枪身 | C23: 步枪 | D23: 1 | E23: rare | F23: 150 | G23: bullet_count=1；damage=22；fire_rate=6；magazine_size=30；reload_time=2.2；spread=0.07 | H23: 稳定连发的中距离武器。左键装备为当前主武器。 | I23: 标签：rifle、automatic、assault | J23: 成品：boss_floor_1×2；boss_floor_2×3；combat_floor_1×0.5；combat_floor_2×1；combat_floor_3×1.5；elite_floor_1×1.5；elite_floor_2×2；loot_abyss×2.5；loot_floor_1_2×0.3；loot_floor_3_4×1.5；loot_floor_5×2；scavenge_floor_3×1；scavenge_floor_4×1.5；scavenge_floor_5×2 蓝图：boss_floor_1×3；combat_floor_1×1.5；combat_floor_2×1；combat_floor_3×0.8；loot_abyss×3；loot_common×1；loot_floor_3_4×2；loot_floor_5×2.5；scavenge_floor_3×1.5；scavenge_floor_4×2；spawn_starter×2 | K23: [已实装] | L23: 正式注册；具体行为与表现仍需逐项QA | M23: src/base/BlueprintRegistry.gd；src/base/ItemRegistry.gd | N23: 装配ID=bp_rifle；成品物品ID=weapon_rifle；蓝图物品ID=bp_rifle | O23: 8 | P23: 生成永久weapon_instance_id；六个公共配件位置固定，枪型仅开放兼容子集；单拆配件，整枪移动时完整装配树随实例转移 | Q23: [已实装并验收] WeaponInstance schema v2、主副武器独立配件、兼容禁用、替换回滚与旧快照迁移 | R23: 显示中距离连发、伤害、射速、弹量和扩散的平衡定位 | S23: 连发节奏、枪身动作和中等后坐一致，弹道辨识稳定 | T23: [部分完成] 实例尾号、槽位、已装配件与命运刻印已可视；逐条专属VFX/音频仍待QA | U23: =IF(F23>0,F23,0) | V23: =IF(F23>0,ROUND(F23*0.5,0),0) | W23: TRUE | X23: unlimited | Y23: 4
A24: bp_shotgun | B24: 枪身 | C24: 散射喷壶 | D24: 0 | E24: uncommon | F24: 110 | G24: bullet_count=5；damage=12；fire_rate=1.2；magazine_size=6；reload_time=3；spread=0.35 | H24: 近距离多弹丸散射武器。左键装备为当前主武器。 | I24: 标签：shotgun、close_range、burst | J24: 成品：combat_floor_1×0.8；combat_floor_2×1.2；loot_floor_1_2×1；scavenge_floor_1×1.4；scavenge_floor_2×2；spawn_starter×3 蓝图：combat_floor_1×1；combat_floor_2×0.5；loot_abyss×1；loot_common×1；loot_floor_1_2×2.5；loot_floor_3_4×2；loot_floor_5×1.5；scavenge_floor_1×2；scavenge_floor_2×1.5；spawn_starter×3.5 | K24: [已实装] | L24: 正式注册；具体行为与表现仍需逐项QA | M24: src/base/BlueprintRegistry.gd；src/base/ItemRegistry.gd | N24: 装配ID=bp_shotgun；成品物品ID=weapon_shotgun；蓝图物品ID=bp_shotgun | O24: 8 | P24: 生成永久weapon_instance_id；六个公共配件位置固定，枪型仅开放兼容子集；单拆配件，整枪移动时完整装配树随实例转移 | Q24: [已实装并验收] WeaponInstance schema v2、主副武器独立配件、兼容禁用、替换回滚与旧快照迁移 | R24: 显示每发弹丸数、散布锥、近距收益、弹量与换弹 | S24: 多弹丸扇形、强后坐和近距命中层次同步；命中数量可读 | T24: [部分完成] 实例尾号、槽位、已装配件与命运刻印已可视；逐条专属VFX/音频仍待QA | U24: =IF(F24>0,F24,0) | V24: =IF(F24>0,ROUND(F24*0.5,0),0) | W24: TRUE | X24: unlimited | Y24: 3
A25: bp_sniper | B25: 枪身 | C25: 弹弓狙击 | D25: 2 | E25: rare | F25: 220 | G25: bullet_count=1；damage=55；fire_rate=1；magazine_size=5；reload_time=3.5；spread=0.01 | H25: 低射速高伤害，穿透力强，适合精准打击。左键装备为当前主武器。 | I25: 标签：sniper、precision、high_damage | J25: 成品：boss_floor_1×2；boss_floor_2×4；combat_floor_2×0.3；combat_floor_3×0.8；elite_floor_1×1.5；elite_floor_2×2；loot_abyss×2.5；loot_floor_3_4×0.5；loot_floor_5×1.5；scavenge_floor_3×0.5；scavenge_floor_4×1；scavenge_floor_5×2 蓝图：boss_floor_1×4；boss_floor_2×5；combat_floor_3×1.5；combat_floor_4×2；combat_floor_5×2.5；loot_abyss×3；loot_common×0.5；loot_floor_5×2；scavenge_floor_5×1.5；spawn_starter×1 | K25: [已实装] | L25: 正式注册；具体行为与表现仍需逐项QA | M25: src/base/BlueprintRegistry.gd；src/base/ItemRegistry.gd | N25: 装配ID=bp_sniper；成品物品ID=weapon_sniper；蓝图物品ID=bp_sniper | O25: 8 | P25: 成品生成永久weapon_instance_id；命运槽、子弹模块与配件随实例在装备/背包/地面/商店/保险/存档间移动 | Q25: [已实装] 唯一实例ID、8槽基线、完整构筑/弹药/命运记录随枪转移与存档 | R25: 显示高伤害、低射速、精准/穿透与瞄准状态；提供远距比较 | S25: 长枪轮廓、瞄准准星、强单发反馈和贯穿线一致，射击时点明确 | T25: [部分完成] 实例尾号、槽位、已装配件与命运刻印已可视；逐条专属VFX/音频仍待QA | U25: =IF(F25>0,F25,0) | V25: =IF(F25>0,ROUND(F25*0.5,0),0) | W25: FALSE | X25: not_listed | Y25: 0
A26: bp_greatblade | B26: 近战武器 | C26: 巨型工业断刃 | D26: 0 | E26: uncommon | F26: 165 | G26: damage=34；reach=2.65m；arc=115°；knockback=5.4；combo=3 | H26: 左横斩→右回斩→过顶重劈；每段前摇/命中/后摇；无弹药与换弹 | I26: 标签：melee、heavy_melee、greatblade、wide_arc；第三段1.48×伤害/1.55×击退 | J26: 成品：spawn_starter×1.2；loot_floor_1_2×0.75；loot_floor_3_4×1.2；scavenge_floor_1×0.65；scavenge_floor_2×1.1；combat_floor_1×0.5；combat_floor_2×0.9 | K26: [已实装] | L26: 正式注册；近战专项验收通过 | M26: src/base/BlueprintRegistry.gd；src/base/ItemRegistry.gd；src/player3d/melee/PlayerMeleeCombat3D.gd | N26: 装配ID=bp_greatblade；成品物品ID=weapon_greatblade；程序原型总长2.42m | O26: 8 | P26: 生成永久weapon_instance_id；无子弹槽；命运/主副槽/背负/地面/背包/保险/存档随实例移动 | Q26: [已实装并验收] 四态动作机、三段缓存、扇区/墙体/去重、伤害/击退/中断与反馈闭环 | R26: HUD显示近战·三段；动作快照显示阶段、进度、攻击ID；挥空有弧光/切风声，命中有爆点/冲击声 | S26: 双手重型持握；青色能量断刃；三段弧光方向可辨，第三段尺寸与冲击最强 | T26: [核心已验收] 程序模型/三段动作/参数化VFX/专属音频完成；最终模型与低特效模式待替换/复验 | W26: 0 | X26: not_listed | Y26: 0
A27: bp_waraxe | B27: 近战武器 | C27: 攻城裂甲斧 | D27: 1 | E27: rare | F27: 240 | G27: damage=46；reach=2.85m；arc=100°；knockback=7.2；combo=3 | H27: 上挑斩→交叉斩→砸地裂斩；高伤高击退；无弹药与换弹 | I27: 标签：melee、heavy_melee、waraxe、high_knockback；第三段1.62×伤害/1.70×击退 | J27: 成品：loot_floor_1_2×0.18；loot_floor_3_4×0.95；loot_floor_5×1.45；loot_abyss×1.8；scavenge_floor_3×0.8；combat_floor_3×0.72；elite_floor_1×1.2；elite_floor_2×1.8 | K27: [已实装] | L27: 正式注册；近战专项验收通过 | M27: src/base/BlueprintRegistry.gd；src/base/ItemRegistry.gd；src/player3d/melee/PlayerMeleeCombat3D.gd | N27: 装配ID=bp_waraxe；成品物品ID=weapon_waraxe；程序原型总长2.62m | O27: 8 | P27: 生成永久weapon_instance_id；无子弹槽；命运/主副槽/背负/地面/背包/保险/存档随实例移动 | Q27: [已实装并验收] 四态动作机、三段缓存、扇区/墙体/去重、伤害/击退/中断与反馈闭环 | R27: HUD显示近战·三段；动作快照显示阶段、进度、攻击ID；挥空有弧光/切风声，命中有爆点/冲击声 | S27: 双手长柄持握；橙色冲击核心；第三段最大过顶弧光，音高更低、冲击更重 | T27: [核心已验收] 程序模型/三段动作/参数化VFX/专属音频完成；最终模型与低特效模式待替换/复验 | W27: 0 | X27: not_listed | Y27: 0
A28: bp_baseball_bat | B28: 近战武器 | C28: 废土棒球棍 | D28: 0 | E28: common | F28: 45 | G28: damage=20；reach=2.05m；arc=105°；knockback=3.2；combo=3 | H28: 左横扫→右回扫→蓄力重挥；初级快速近战；无弹药与换弹 | I28: 标签：melee、light_melee、baseball_bat、starter_melee；第三段1.28×伤害/1.35×击退 | J28: 成品：spawn_starter×2.2；loot_floor_1_2×1.6；scavenge_floor_1×1.8；scavenge_floor_2×1.2；combat_floor_1×1.0；基地贩卖机无限库存 | K28: [已实装] | L28: 正式注册；基地贩卖、近战专项与配件系统专项验收通过 | M28: src/base/BlueprintRegistry.gd；src/base/ItemRegistry.gd；src/player3d/melee/PlayerMeleeCombat3D.gd；tests/verification/verify_weapon_attachment_inventory_flow.gd | N28: 装配ID=bp_baseball_bat；成品物品ID=weapon_baseball_bat；程序原型总长1.48m | O28: 8 | P28: 生成永久weapon_instance_id；无子弹/普通枪械配件槽；命运/主副槽/背负/地面/背包/保险/存档随实例移动 | Q28: [已实装并验收] 复用ready/windup/active/recovery四态、三段缓存、扇区/遮挡/去重、伤害/击退/中断与反馈闭环 | R28: HUD显示近战·三段；第三段反馈增强；基地货架明确初级定位 | S28: 双手挥击；木质粗大轮廓、金属加固环；沿local -Z延伸，背负/手持轮廓清晰 | T28: [核心已验收] 程序模型/三段动作/VFX/音频完成；最终模型待替换 | U28: 45 | V28: 23 | W28: 1 | X28: unlimited | Y28: 1

Sheet 命运卡
A1: ShellStorm2 游戏内容数据库｜命运塔罗
A2: 78张完整牌组：48张现有卡已接入塔罗名称、正/逆位效果快照、50%/50%方位与代码翻牌；新增30张须完成独立玩法执行器后再进入正式池。
A3: 每张卡先抽身份，再以50%/50%独立抽正位或逆位；同名、同稳定ID、同收藏条目。逆位只倒置图案/框体，名称、说明、数值和目标文字始终正向。
A4: 稳定卡ID | B4: 塔罗名称 | C4: 类型 | D4: 品质 | E4: 正位短说明 | F4: 正位完整功能 | G4: 背景介绍 | H4: 背景来源 | I4: 目标规则 | J4: 当前/正位效果参数 | K4: 获得方式 | L4: 状态来源 | M4: 实现状态 | N4: 事实源 | O4: 备注 | P4: 作用域 | Q4: 槽位/所有者规则 | R4: 塔罗实现状态 | S4: 选择/槽位UI提示 | T4: 触发/战斗/世界表现 | U4: 表现实现状态 | V4: 旧名/迁移别名 | W4: 塔罗编号 | X4: 阿尔卡那 | Y4: 花色 | Z4: 正位概率 | AA4: 逆位概率 | AB4: 正位功能说明 | AC4: 正位效果参数 | AD4: 逆位功能说明 | AE4: 逆位效果参数 | AF4: 翻转/UI表现 | AG4: 塔罗设计状态
A5: fate_mark_enemy | B5: 愚者 | C5: 规则 | D5: 传说 | E5: 击杀第10个敌人获得随机命卡 | F5: 每击杀 10 个敌人，有 50% 概率获得一张随机命运卡片 | G5: 第十个倒下者会留下短暂印记，偶尔把一张新的规则卡交给胜者。 | H5: [Codex补充] | J5: action=GRANT_RANDOM_CARD；grant_probability=0.5；kill_threshold=10 | K5: 玩家卡池；也可由地图阈值事件触发 | L5: [已实装] | M5: [部分实装] 塔罗名称、正/逆位效果快照与通用执行已接入；复杂逆位专属行为继续逐卡QA | N5: src/weapons/FateCard.gd；src/weapons/FateCardPresets.gd；src/weapons/FateCardEngine.gd；src/game/FateCardGameBridge.gd；docs/v0.1/14_技术施工_命运塔罗牌组.md；src/weapons/TarotFateCatalog.gd；tests/verification/verify_tarot_fate_runtime.gd | O5: 迁移前名称：命运标记；稳定ID不变，旧存档迁移为正位，不重投方位 | P5: CHARACTER | Q5: 不占武器槽；写入角色局内规则状态 | R5: [已实装] 塔罗名称、50/50方位、正逆位同ID、代码翻牌、整卡倒置、逆位描述替换与方位持久化已接入 | S5: ☾ 月亮命运｜愚者｜翻牌后显示正位/逆位、目标、槽位与对应功能 | T5: 卡背绕Y轴翻面；逆位整张正面卡牌（含边框、图案、文字与布局）收束180°，并显示逆位效果描述；目标头顶出现可读标记；达成条件时角色HUD进度完成，枪械外观不变 | U5: [部分实装] 通用卡背/翻牌/逆位倒置已验收；逐卡逆位专属VFX与音效继续QA | V5: 命运标记 | W5: 0 | X5: MAJOR | Y5: MAJOR | Z5: 0.5 | AA5: 0.5 | AB5: 每击杀 10 个敌人，有 50% 概率获得一张随机命运卡片 | AC5: action=GRANT_RANDOM_CARD；grant_probability=0.5；kill_threshold=10 | AD5: 每10击杀必得随机命运，但失去30魂 | AE5: action=GRANT_RANDOM_CARD; kill_threshold=10; grant_probability=1; currency_cost=30 | AF5: 0.00s卡背→0.24s薄边换面→0.42s收束；逆位图案/框体180°，卡名、天体、方位标签和说明文字0°；0.62s后可点 | AG5: [设计完成/数据已入表/运行时待施工]
A6: fate_gun_on_gun | B6: 魔术师 | C6: 组合 | D6: 传说 | E6: 副枪跟随主枪一起开火 | F6: 选择一个枪身，将其挂到当前枪身上，副枪跟随射击 | G6: 当一个扳机不够时，就让第二把枪把第一把枪的节奏当成命令。 | H6: [Codex补充] | J6: action=ATTACH_GUN_TO_GUN；damage_scale=0.5；fire_rate_scale=0.6；follow_probability=1 | K6: 门后命运/三选一/工作台共用卡池 | L6: [已实装] | M6: [部分实装] 塔罗名称、正/逆位效果快照与通用执行已接入；复杂逆位专属行为继续逐卡QA | N6: src/weapons/FateCard.gd；src/weapons/FateCardPresets.gd；src/weapons/FateCardEngine.gd；src/game/FateCardGameBridge.gd；docs/v0.1/14_技术施工_命运塔罗牌组.md；src/weapons/TarotFateCatalog.gd；tests/verification/verify_tarot_fate_runtime.gd | O6: 迁移前名称：枪上加枪；稳定ID不变，旧存档迁移为正位，不重投方位 | P6: WEAPON | Q6: 占目标枪械下一个永久命运槽；按序追加、不可拆卸/替换/回退 | R6: [已实装] 塔罗名称、50/50方位、正逆位同ID、代码翻牌、整卡倒置、逆位描述替换与方位持久化已接入 | S6: ★ 星星命运｜魔术师｜翻牌后显示正位/逆位、目标、槽位与对应功能 | T6: 卡背绕Y轴翻面；逆位整张正面卡牌（含边框、图案、文字与布局）收束180°，并显示逆位效果描述；主枪上出现副枪实体/能量轮廓；同步或派生开火用不同声层区分 | U6: [部分实装] 通用卡背/翻牌/逆位倒置已验收；逐卡逆位专属VFX与音效继续QA | V6: 枪上加枪 | W6: I | X6: MAJOR | Y6: MAJOR | Z6: 0.5 | AA6: 0.5 | AB6: 选择一个枪身，将其挂到当前枪身上，副枪跟随射击 | AC6: action=ATTACH_GUN_TO_GUN；damage_scale=0.5；fire_rate_scale=0.6；follow_probability=1 | AD6: 主副枪交替开火，单发更强但主枪变慢 | AE6: action=ATTACH_GUN_TO_GUN; alternate_fire=true; damage_scale=0.85; main_fire_rate_scale=0.85 | AF6: 0.00s卡背→0.24s薄边换面→0.42s收束；逆位图案/框体180°，卡名、天体、方位标签和说明文字0°；0.62s后可点 | AG6: [设计完成/数据已入表/运行时待施工]
A7: fate_moon_vitality | B7: 女祭司 | C7: 强化 | D7: 稀有 | E7: 生命上限+20 | F7: 最大生命提升20，并立刻恢复20生命 | G7: 月光让受损躯体重新生长，把本局的生存空间向上推高。 | H7: [用户设计] | J7: action=APPLY_SCOPED_MODIFIER；modifier=max_hp；amount=20 | K7: 门后命运/三选一/工作台共用正式卡池 | L7: [已实装] | M7: [部分实装] 塔罗名称、正/逆位效果快照与通用执行已接入；复杂逆位专属行为继续逐卡QA | N7: src/weapons/FateCard.gd；src/weapons/FateCardPresets.gd；src/weapons/FateCardEngine.gd；src/game/FateCardGameBridge.gd；src/player3d/Player3D.gd；src/world3d/Dungeon3D.gd；docs/v0.1/14_技术施工_命运塔罗牌组.md；src/weapons/TarotFateCatalog.gd；tests/verification/verify_tarot_fate_runtime.gd | O7: 迁移前名称：月相增生；稳定ID不变，旧存档迁移为正位，不重投方位 | P7: CHARACTER | Q7: 不占武器槽；写入角色局内规则状态 | R7: [已实装] 塔罗名称、50/50方位、正逆位同ID、代码翻牌、整卡倒置、逆位描述替换与方位持久化已接入 | S7: ☾ 月亮命运｜女祭司｜翻牌后显示正位/逆位、目标、槽位与对应功能 | T7: 卡背绕Y轴翻面；逆位整张正面卡牌（含边框、图案、文字与布局）收束180°，并显示逆位效果描述；角色生命上限与当前生命同步增加，红色生命条立即扩容 | U7: [部分实装] 通用卡背/翻牌/逆位倒置已验收；逐卡逆位专属VFX与音效继续QA | V7: 月相增生 | W7: II | X7: MAJOR | Y7: MAJOR | Z7: 0.5 | AA7: 0.5 | AB7: 最大生命提升20，并立刻恢复20生命 | AC7: action=APPLY_SCOPED_MODIFIER；modifier=max_hp；amount=20 | AD7: 生命上限-10，立即恢复50生命 | AE7: action=APPLY_SCOPED_MODIFIER; modifier=max_hp_trade; max_hp_delta=-10; heal=50 | AF7: 0.00s卡背→0.24s薄边换面→0.42s收束；逆位图案/框体180°，卡名、天体、方位标签和说明文字0°；0.62s后可点 | AG7: [设计完成/数据已入表/运行时待施工]
A8: fate_sun_extra_loot | B8: 皇后 | C8: 规则 | D8: 史诗 | E8: 下箱追加2抽，保留最佳 | F8: 下一个容器追加2次候选抽取并保留最高品质结果，地面仍只掉落1件 | G8: 太阳延长了这一日的收成，但只让猎人带走其中最值得的一件。 | H8: [用户设计] | J8: action=APPLY_SCOPED_MODIFIER；modifier=next_chest_extra；count=2 | K8: 门后命运/三选一/工作台共用正式卡池 | L8: [已实装] | M8: [部分实装] 塔罗名称、正/逆位效果快照与通用执行已接入；复杂逆位专属行为继续逐卡QA | N8: src/weapons/FateCard.gd；src/weapons/FateCardPresets.gd；src/weapons/FateCardEngine.gd；src/game/FateCardGameBridge.gd；src/player3d/Player3D.gd；src/world3d/Dungeon3D.gd；docs/v0.1/14_技术施工_命运塔罗牌组.md；src/weapons/TarotFateCatalog.gd；tests/verification/verify_tarot_fate_runtime.gd | O8: 迁移前名称：丰收日；稳定ID不变，旧存档迁移为正位，不重投方位 | P8: WORLD | Q8: 不占武器槽；写入行动/房间/掉落/撤离规则状态 | R8: [已实装] 塔罗名称、50/50方位、正逆位同ID、代码翻牌、整卡倒置、逆位描述替换与方位持久化已接入 | S8: ☀ 太阳命运｜皇后｜翻牌后显示正位/逆位、目标、槽位与对应功能 | T8: 开箱时追加2次候选扫描，界面闪过候选后只生成1个最高品质地面实体并清空计数 | U8: [部分实装] 通用卡背/翻牌/逆位倒置已验收；逐卡逆位专属VFX与音效继续QA | V8: 丰收日 | W8: III | X8: MAJOR | Y8: MAJOR | Z8: 0.5 | AA8: 0.5 | AB8: 下一个容器追加2次候选抽取并保留最高品质结果，地面仍只掉落1件 | AC8: action=APPLY_SCOPED_MODIFIER；modifier=next_chest_extra；count=2 | AD8: 下一容器追加4次候选抽取并保留最佳，品质上限为稀有，地面仍只掉落1件 | AE8: action=APPLY_SCOPED_MODIFIER; modifier=next_chest_extra_capped; count=4; rarity_cap=RARE | AF8: 0.00s卡背→0.24s薄边换面→0.42s收束；逆位图案/框体180°，卡名、天体、方位标签和说明文字0°；0.62s后可点 | AG8: [设计完成/数据已入表/运行时待施工]
A9: fate_sun_reinforce | B9: 皇帝 | C9: 规则 | D9: 史诗 | E9: 下房敌人+3 | F9: 下一个敌对房间额外出现3名敌人 | G9: 日冕暴露了行动路线，下一间敌对区域会提前集结增援。 | H9: [用户设计] | J9: action=APPLY_SCOPED_MODIFIER；modifier=next_room_enemy_count；count=3 | K9: 门后命运/三选一/工作台共用正式卡池 | L9: [已实装] | M9: [部分实装] 塔罗名称、正/逆位效果快照与通用执行已接入；复杂逆位专属行为继续逐卡QA | N9: src/weapons/FateCard.gd；src/weapons/FateCardPresets.gd；src/weapons/FateCardEngine.gd；src/game/FateCardGameBridge.gd；src/player3d/Player3D.gd；src/world3d/Dungeon3D.gd；docs/v0.1/14_技术施工_命运塔罗牌组.md；src/weapons/TarotFateCatalog.gd；tests/verification/verify_tarot_fate_runtime.gd | O9: 迁移前名称：日冕增援；稳定ID不变，旧存档迁移为正位，不重投方位 | P9: WORLD | Q9: 不占武器槽；写入行动/房间/掉落/撤离规则状态 | R9: [已实装] 塔罗名称、50/50方位、正逆位同ID、代码翻牌、整卡倒置、逆位描述替换与方位持久化已接入 | S9: ☀ 太阳命运｜皇帝｜翻牌后显示正位/逆位、目标、槽位与对应功能 | T9: 卡背绕Y轴翻面；逆位整张正面卡牌（含边框、图案、文字与布局）收束180°，并显示逆位效果描述；下一敌对房间生成表追加3名敌人后消费状态 | U9: [部分实装] 通用卡背/翻牌/逆位倒置已验收；逐卡逆位专属VFX与音效继续QA | V9: 日冕增援 | W9: IV | X9: MAJOR | Y9: MAJOR | Z9: 0.5 | AA9: 0.5 | AB9: 下一个敌对房间额外出现3名敌人 | AC9: action=APPLY_SCOPED_MODIFIER；modifier=next_room_enemy_count；count=3 | AD9: 下一敌对房增加1精英，清理后+50魂 | AE9: action=APPLY_SCOPED_MODIFIER; modifier=next_room_elite_reward; elite_count=1; currency_reward=50 | AF9: 0.00s卡背→0.24s薄边换面→0.42s收束；逆位图案/框体180°，卡名、天体、方位标签和说明文字0°；0.62s后可点 | AG9: [设计完成/数据已入表/运行时待施工]
A10: fate_sun_key | B10: 教皇 | C10: 强化 | D10: 稀有 | E10: 获得房间钥匙 | F10: 立即获得1把普通房间钥匙 | G10: 灼热印记在掌心凝成一把只属于本次行动的房间钥匙。 | H10: [用户设计] | J10: action=APPLY_SCOPED_MODIFIER；modifier=grant_room_key；count=1 | K10: 门后命运/三选一/工作台共用正式卡池 | L10: [已实装] | M10: [部分实装] 塔罗名称、正/逆位效果快照与通用执行已接入；复杂逆位专属行为继续逐卡QA | N10: src/weapons/FateCard.gd；src/weapons/FateCardPresets.gd；src/weapons/FateCardEngine.gd；src/game/FateCardGameBridge.gd；src/player3d/Player3D.gd；src/world3d/Dungeon3D.gd；docs/v0.1/14_技术施工_命运塔罗牌组.md；src/weapons/TarotFateCatalog.gd；tests/verification/verify_tarot_fate_runtime.gd | O10: 迁移前名称：太阳钥印；稳定ID不变，旧存档迁移为正位，不重投方位 | P10: WORLD | Q10: 不占武器槽；写入行动/房间/掉落/撤离规则状态 | R10: [已实装] 塔罗名称、50/50方位、正逆位同ID、代码翻牌、整卡倒置、逆位描述替换与方位持久化已接入 | S10: ☀ 太阳命运｜教皇｜翻牌后显示正位/逆位、目标、槽位与对应功能 | T10: 卡背绕Y轴翻面；逆位整张正面卡牌（含边框、图案、文字与布局）收束180°，并显示逆位效果描述；普通房间钥匙计数立即+1，HUD同步刷新 | U10: [部分实装] 通用卡背/翻牌/逆位倒置已验收；逐卡逆位专属VFX与音效继续QA | V10: 太阳钥印 | W10: V | X10: MAJOR | Y10: MAJOR | Z10: 0.5 | AA10: 0.5 | AB10: 立即获得1把普通房间钥匙 | AC10: action=APPLY_SCOPED_MODIFIER；modifier=grant_room_key；count=1 | AD10: 获得2把临时钥匙，离开当层失效 | AE10: action=APPLY_SCOPED_MODIFIER; modifier=grant_temporary_keys; count=2; expires=FLOOR_EXIT | AF10: 0.00s卡背→0.24s薄边换面→0.42s收束；逆位图案/框体180°，卡名、天体、方位标签和说明文字0°；0.62s后可点 | AG10: [设计完成/数据已入表/运行时待施工]
A11: fate_moon_power | B11: 恋人 | C11: 强化 | D11: 史诗 | E11: 枪伤+12% | F11: 本局角色造成的枪械伤害提升12% | G11: 月刃不改写枪械本体，却让持有者的每次射击更有力量。 | H11: [用户设计] | J11: action=APPLY_SCOPED_MODIFIER；modifier=weapon_damage；multiplier=1.12 | K11: 门后命运/三选一/工作台共用正式卡池 | L11: [已实装] | M11: [部分实装] 塔罗名称、正/逆位效果快照与通用执行已接入；复杂逆位专属行为继续逐卡QA | N11: src/weapons/FateCard.gd；src/weapons/FateCardPresets.gd；src/weapons/FateCardEngine.gd；src/game/FateCardGameBridge.gd；src/player3d/Player3D.gd；src/world3d/Dungeon3D.gd；docs/v0.1/14_技术施工_命运塔罗牌组.md；src/weapons/TarotFateCatalog.gd；tests/verification/verify_tarot_fate_runtime.gd | O11: 迁移前名称：月刃共鸣；稳定ID不变，旧存档迁移为正位，不重投方位 | P11: CHARACTER | Q11: 不占武器槽；写入角色局内规则状态 | R11: [已实装] 塔罗名称、50/50方位、正逆位同ID、代码翻牌、整卡倒置、逆位描述替换与方位持久化已接入 | S11: ☾ 月亮命运｜恋人｜翻牌后显示正位/逆位、目标、槽位与对应功能 | T11: 卡背绕Y轴翻面；逆位整张正面卡牌（含边框、图案、文字与布局）收束180°，并显示逆位效果描述；角色伤害乘区生效；换枪后加成仍随角色，不随枪转移 | U11: [部分实装] 通用卡背/翻牌/逆位倒置已验收；逐卡逆位专属VFX与音效继续QA | V11: 月刃共鸣 | W11: VI | X11: MAJOR | Y11: MAJOR | Z11: 0.5 | AA11: 0.5 | AB11: 本局角色造成的枪械伤害提升12% | AC11: action=APPLY_SCOPED_MODIFIER；modifier=weapon_damage；multiplier=1.12 | AD11: 枪伤-8%，暴击率+15% | AE11: action=APPLY_SCOPED_MODIFIER; modifier=weapon_damage_crit_trade; damage_multiplier=0.92; crit_chance_add=0.15 | AF11: 0.00s卡背→0.24s薄边换面→0.42s收束；逆位图案/框体180°，卡名、天体、方位标签和说明文字0°；0.62s后可点 | AG11: [设计完成/数据已入表/运行时待施工]
A12: fate_bullet_carry_gun | B12: 战车 | C12: 组合 | D12: 史诗 | E12: 子弹飞出去时自动开枪 | F12: 选择一个子弹和一个枪身，该子弹将携带枪身并自动射击 | G12: 有人把整把枪绑在弹头上，荒唐的结构在命运规则下反而可以边飞边射。 | H12: [Codex补充] | J12: action=ATTACH_GUN_TO_BULLET；damage_scale=0.45；fire_rate_scale=0.6；max_attached_gun=1 | K12: 门后命运/三选一/工作台共用卡池 | L12: [已实装] | M12: [部分实装] 塔罗名称、正/逆位效果快照与通用执行已接入；复杂逆位专属行为继续逐卡QA | N12: src/weapons/FateCard.gd；src/weapons/FateCardPresets.gd；src/weapons/FateCardEngine.gd；src/game/FateCardGameBridge.gd；docs/v0.1/14_技术施工_命运塔罗牌组.md；src/weapons/TarotFateCatalog.gd；tests/verification/verify_tarot_fate_runtime.gd | O12: 迁移前名称：子弹背枪；稳定ID不变，旧存档迁移为正位，不重投方位 | P12: WEAPON | Q12: 占目标枪械下一个永久命运槽；按序追加、不可拆卸/替换/回退 | R12: [已实装] 塔罗名称、50/50方位、正逆位同ID、代码翻牌、整卡倒置、逆位描述替换与方位持久化已接入 | S12: ★ 星星命运｜战车｜翻牌后显示正位/逆位、目标、槽位与对应功能 | T12: 卡背绕Y轴翻面；逆位整张正面卡牌（含边框、图案、文字与布局）收束180°，并显示逆位效果描述；投射物上可见微型枪械或等价轮廓；派生开火有独立枪口焰且来源可追溯 | U12: [部分实装] 通用卡背/翻牌/逆位倒置已验收；逐卡逆位专属VFX与音效继续QA | V12: 子弹背枪 | W12: VII | X12: MAJOR | Y12: MAJOR | Z12: 0.5 | AA12: 0.5 | AB12: 选择一个子弹和一个枪身，该子弹将携带枪身并自动射击 | AC12: action=ATTACH_GUN_TO_BULLET；damage_scale=0.45；fire_rate_scale=0.6；max_attached_gun=1 | AD12: 携枪子弹只在命中时开一次高伤射击 | AE12: action=ATTACH_GUN_TO_BULLET; trigger=ON_HIT; shots=1; damage_scale=0.75 | AF12: 0.00s卡背→0.24s薄边换面→0.42s收束；逆位图案/框体180°，卡名、天体、方位标签和说明文字0°；0.62s后可点 | AG12: [设计完成/数据已入表/运行时待施工]
A13: fate_armor_pierce | B13: 力量 | C13: 强化 | D13: 稀有 | E13: 伤害提升 50%，无视护盾 | F13: 选择一个节点，伤害提升 50%，无视护盾减伤效果 | G13: 废弃军械库留下的硬芯工艺，专门教子弹绕过壳甲最自信的角度。 | H13: [Codex补充] | J13: action=ADD_DAMAGE；damage_scale=1.5；pierce_shield=true | K13: 门后命运/三选一/工作台共用卡池 | L13: [已实装] | M13: [部分实装] 塔罗名称、正/逆位效果快照与通用执行已接入；复杂逆位专属行为继续逐卡QA | N13: src/weapons/FateCard.gd；src/weapons/FateCardPresets.gd；src/weapons/FateCardEngine.gd；src/game/FateCardGameBridge.gd；docs/v0.1/14_技术施工_命运塔罗牌组.md；src/weapons/TarotFateCatalog.gd；tests/verification/verify_tarot_fate_runtime.gd | O13: 迁移前名称：穿甲强化；稳定ID不变，旧存档迁移为正位，不重投方位 | P13: WEAPON | Q13: 占目标枪械下一个永久命运槽；按序追加、不可拆卸/替换/回退 | R13: [已实装] 塔罗名称、50/50方位、正逆位同ID、代码翻牌、整卡倒置、逆位描述替换与方位持久化已接入 | S13: ★ 星星命运｜力量｜翻牌后显示正位/逆位、目标、槽位与对应功能 | T13: 卡背绕Y轴翻面；逆位整张正面卡牌（含边框、图案、文字与布局）收束180°，并显示逆位效果描述；弹体使用贯穿线；护甲命中出现破盾裂纹与剩余穿透提示 | U13: [部分实装] 通用卡背/翻牌/逆位倒置已验收；逐卡逆位专属VFX与音效继续QA | V13: 穿甲强化 | W13: VIII | X13: MAJOR | Y13: MAJOR | Z13: 0.5 | AA13: 0.5 | AB13: 选择一个节点，伤害提升 50%，无视护盾减伤效果 | AC13: action=ADD_DAMAGE；damage_scale=1.5；pierce_shield=true | AD13: 伤害+15%，不穿盾但对护盾×2 | AE13: action=ADD_DAMAGE; damage_scale=1.15; pierce_shield=false; shield_damage_scale=2 | AF13: 0.00s卡背→0.24s薄边换面→0.42s收束；逆位图案/框体180°，卡名、天体、方位标签和说明文字0°；0.62s后可点 | AG13: [设计完成/数据已入表/运行时待施工]
A14: fate_moon_stride | B14: 隐者 | C14: 强化 | D14: 稀有 | E14: 移速+12% | F14: 本局角色移动速度提升12% | G14: 月影贴着脚步移动，让角色更快穿过火力空隙。 | H14: [用户设计] | J14: action=APPLY_SCOPED_MODIFIER；modifier=move_speed；multiplier=1.12 | K14: 门后命运/三选一/工作台共用正式卡池 | L14: [已实装] | M14: [部分实装] 塔罗名称、正/逆位效果快照与通用执行已接入；复杂逆位专属行为继续逐卡QA | N14: src/weapons/FateCard.gd；src/weapons/FateCardPresets.gd；src/weapons/FateCardEngine.gd；src/game/FateCardGameBridge.gd；src/player3d/Player3D.gd；src/world3d/Dungeon3D.gd；docs/v0.1/14_技术施工_命运塔罗牌组.md；src/weapons/TarotFateCatalog.gd；tests/verification/verify_tarot_fate_runtime.gd | O14: 迁移前名称：月影疾行；稳定ID不变，旧存档迁移为正位，不重投方位 | P14: CHARACTER | Q14: 不占武器槽；写入角色局内规则状态 | R14: [已实装] 塔罗名称、50/50方位、正逆位同ID、代码翻牌、整卡倒置、逆位描述替换与方位持久化已接入 | S14: ☾ 月亮命运｜隐者｜翻牌后显示正位/逆位、目标、槽位与对应功能 | T14: 卡背绕Y轴翻面；逆位整张正面卡牌（含边框、图案、文字与布局）收束180°，并显示逆位效果描述；角色实际移动速度提高，月亮命运常驻栏可追溯 | U14: [部分实装] 通用卡背/翻牌/逆位倒置已验收；逐卡逆位专属VFX与音效继续QA | V14: 月影疾行 | W14: IX | X14: MAJOR | Y14: MAJOR | Z14: 0.5 | AA14: 0.5 | AB14: 本局角色移动速度提升12% | AC14: action=APPLY_SCOPED_MODIFIER；modifier=move_speed；multiplier=1.12 | AD14: 移速-8%，冲刺无敌+0.12秒 | AE14: action=APPLY_SCOPED_MODIFIER; modifier=stride_invulnerability_trade; move_multiplier=0.92; invulnerability_add=0.12 | AF14: 0.00s卡背→0.24s薄边换面→0.42s收束；逆位图案/框体180°，卡名、天体、方位标签和说明文字0°；0.62s后可点 | AG14: [设计完成/数据已入表/运行时待施工]
A15: fate_every_seventh | B15: 命运之轮 | C15: 规则 | D15: 稀有 | E15: 第7发子弹触发额外效果 | F15: 选择一个枪身，第 7 发子弹伤害翻倍并引发小爆炸 | G15: 塔内旧式计数器只承认第七次脉冲，并把那一发标记为异常。 | H15: [Codex补充] | I15: select=GUNBODY | J15: action=EVERY_NTH_FIRE；bonus_effect=small_explosion；damage_multiplier=2；nth=7 | K15: 门后命运/三选一/工作台共用卡池 | L15: [已实装] | M15: [部分实装] 塔罗名称、正/逆位效果快照与通用执行已接入；复杂逆位专属行为继续逐卡QA | N15: src/weapons/FateCard.gd；src/weapons/FateCardPresets.gd；src/weapons/FateCardEngine.gd；src/game/FateCardGameBridge.gd；docs/v0.1/14_技术施工_命运塔罗牌组.md；src/weapons/TarotFateCatalog.gd；tests/verification/verify_tarot_fate_runtime.gd | O15: 迁移前名称：每第七发；稳定ID不变，旧存档迁移为正位，不重投方位 | P15: WEAPON | Q15: 占目标枪械下一个永久命运槽；按序追加、不可拆卸/替换/回退 | R15: [已实装] 塔罗名称、50/50方位、正逆位同ID、代码翻牌、整卡倒置、逆位描述替换与方位持久化已接入 | S15: ★ 星星命运｜命运之轮｜翻牌后显示正位/逆位、目标、槽位与对应功能 | T15: 卡背绕Y轴翻面；逆位整张正面卡牌（含边框、图案、文字与布局）收束180°，并显示逆位效果描述；第7发枪身、弹体和枪口焰同时高亮，命中使用专属反馈 | U15: [部分实装] 通用卡背/翻牌/逆位倒置已验收；逐卡逆位专属VFX与音效继续QA | V15: 每第七发 | W15: X | X15: MAJOR | Y15: MAJOR | Z15: 0.5 | AA15: 0.5 | AB15: 选择一个枪身，第 7 发子弹伤害翻倍并引发小爆炸 | AC15: action=EVERY_NTH_FIRE；bonus_effect=small_explosion；damage_multiplier=2；nth=7 | AD15: 每次换弹后第1发×2.5，弹匣-20% | AE15: action=EVERY_RELOAD_FIRST; damage_multiplier=2.5; magazine_multiplier=0.8 | AF15: 0.00s卡背→0.24s薄边换面→0.42s收束；逆位图案/框体180°，卡名、天体、方位标签和说明文字0°；0.62s后可点 | AG15: [设计完成/数据已入表/运行时待施工]
A16: fate_sun_trial | B16: 正义 | C16: 诅咒 | D16: 传说 | E16: 强敌双倍魂 | F16: 下一个敌对房间敌人伤害+25%，其魂掉落×2 | G16: 烈日要求用更危险的一战证明资格，并用双倍魂回报胜者。 | H16: [用户设计] | J16: action=APPLY_SCOPED_MODIFIER；modifier=next_room_trial；damage_multiplier=1.25；currency_multiplier=2 | K16: 门后命运/三选一/工作台共用正式卡池 | L16: [已实装] | M16: [部分实装] 塔罗名称、正/逆位效果快照与通用执行已接入；复杂逆位专属行为继续逐卡QA | N16: src/weapons/FateCard.gd；src/weapons/FateCardPresets.gd；src/weapons/FateCardEngine.gd；src/game/FateCardGameBridge.gd；src/player3d/Player3D.gd；src/world3d/Dungeon3D.gd；docs/v0.1/14_技术施工_命运塔罗牌组.md；src/weapons/TarotFateCatalog.gd；tests/verification/verify_tarot_fate_runtime.gd | O16: 迁移前名称：烈日试炼；稳定ID不变，旧存档迁移为正位，不重投方位 | P16: WORLD | Q16: 不占武器槽；写入行动/房间/掉落/撤离规则状态 | R16: [已实装] 塔罗名称、50/50方位、正逆位同ID、代码翻牌、整卡倒置、逆位描述替换与方位持久化已接入 | S16: ☀ 太阳命运｜正义｜翻牌后显示正位/逆位、目标、槽位与对应功能 | T16: 卡背绕Y轴翻面；逆位整张正面卡牌（含边框、图案、文字与布局）收束180°，并显示逆位效果描述；下一敌对房敌伤乘1.25、魂乘2；风险与收益同时消费 | U16: [部分实装] 通用卡背/翻牌/逆位倒置已验收；逐卡逆位专属VFX与音效继续QA | V16: 烈日试炼 | W16: XI | X16: MAJOR | Y16: MAJOR | Z16: 0.5 | AA16: 0.5 | AB16: 下一个敌对房间敌人伤害+25%，其魂掉落×2 | AC16: action=APPLY_SCOPED_MODIFIER；modifier=next_room_trial；damage_multiplier=1.25；currency_multiplier=2 | AD16: 下房敌伤-20%、魂×0.5 | AE16: action=APPLY_SCOPED_MODIFIER; modifier=next_room_safe_trial; damage_multiplier=0.8; currency_multiplier=0.5 | AF16: 0.00s卡背→0.24s薄边换面→0.42s收束；逆位图案/框体180°，卡名、天体、方位标签和说明文字0°；0.62s后可点 | AG16: [设计完成/数据已入表/运行时待施工]
A17: fate_moon_guard | B17: 倒吊人 | C17: 强化 | D17: 史诗 | E17: 受伤-12% | F17: 本局角色受到的伤害降低12% | G17: 银色月壳在冲击抵达前分走一部分力量。 | H17: [用户设计] | J17: action=APPLY_SCOPED_MODIFIER；modifier=damage_taken；multiplier=0.88 | K17: 门后命运/三选一/工作台共用正式卡池 | L17: [已实装] | M17: [部分实装] 塔罗名称、正/逆位效果快照与通用执行已接入；复杂逆位专属行为继续逐卡QA | N17: src/weapons/FateCard.gd；src/weapons/FateCardPresets.gd；src/weapons/FateCardEngine.gd；src/game/FateCardGameBridge.gd；src/player3d/Player3D.gd；src/world3d/Dungeon3D.gd；docs/v0.1/14_技术施工_命运塔罗牌组.md；src/weapons/TarotFateCatalog.gd；tests/verification/verify_tarot_fate_runtime.gd | O17: 迁移前名称：银月护体；稳定ID不变，旧存档迁移为正位，不重投方位 | P17: CHARACTER | Q17: 不占武器槽；写入角色局内规则状态 | R17: [已实装] 塔罗名称、50/50方位、正逆位同ID、代码翻牌、整卡倒置、逆位描述替换与方位持久化已接入 | S17: ☾ 月亮命运｜倒吊人｜翻牌后显示正位/逆位、目标、槽位与对应功能 | T17: 卡背绕Y轴翻面；逆位整张正面卡牌（含边框、图案、文字与布局）收束180°，并显示逆位效果描述；受击结算乘以0.88，角色状态常驻可见 | U17: [部分实装] 通用卡背/翻牌/逆位倒置已验收；逐卡逆位专属VFX与音效继续QA | V17: 银月护体 | W17: XII | X17: MAJOR | Y17: MAJOR | Z17: 0.5 | AA17: 0.5 | AB17: 本局角色受到的伤害降低12% | AC17: action=APPLY_SCOPED_MODIFIER；modifier=damage_taken；multiplier=0.88 | AD17: 受伤+8%，反射15%实际伤害 | AE17: action=APPLY_SCOPED_MODIFIER; modifier=damage_reflect_trade; damage_taken_multiplier=1.08; reflect_ratio=0.15 | AF17: 0.00s卡背→0.24s薄边换面→0.42s收束；逆位图案/框体180°，卡名、天体、方位标签和说明文字0°；0.62s后可点 | AG17: [设计完成/数据已入表/运行时待施工]
A18: fate_gluttony | B18: 死神 | C18: 诅咒 | D18: 禁忌 | E18: 每次命中子弹变大，伤害变高 | F18: 选择一个子弹，每次命中敌人后子弹伤害和体积增加 15%，最大可叠加 5 次 | G18: 每次命中都让弹体吞下一部分猎物，直到体积与力量达到极限。 | H18: [Codex补充] | I18: select=BULLET | J18: action=SIZE_GROWTH；damage_per_hit=0.15；max_stacks=5；scale_per_hit=0.12 | K18: 门后命运/三选一/工作台共用卡池 | L18: [已实装] | M18: [部分实装] 塔罗名称、正/逆位效果快照与通用执行已接入；复杂逆位专属行为继续逐卡QA | N18: src/weapons/FateCard.gd；src/weapons/FateCardPresets.gd；src/weapons/FateCardEngine.gd；src/game/FateCardGameBridge.gd；docs/v0.1/14_技术施工_命运塔罗牌组.md；src/weapons/TarotFateCatalog.gd；tests/verification/verify_tarot_fate_runtime.gd | O18: 迁移前名称：火力暴食；稳定ID不变，旧存档迁移为正位，不重投方位 | P18: WEAPON | Q18: 占目标枪械下一个永久命运槽；按序追加、不可拆卸/替换/回退 | R18: [已实装] 塔罗名称、50/50方位、正逆位同ID、代码翻牌、整卡倒置、逆位描述替换与方位持久化已接入 | S18: ★ 星星命运｜死神｜翻牌后显示正位/逆位、目标、槽位与对应功能 | T18: 卡背绕Y轴翻面；逆位整张正面卡牌（含边框、图案、文字与布局）收束180°，并显示逆位效果描述；弹体或节点随层数渐进增大；HUD层数与尺寸变化同步，满层明显收束 | U18: [部分实装] 通用卡背/翻牌/逆位倒置已验收；逐卡逆位专属VFX与音效继续QA | V18: 火力暴食 | W18: XIII | X18: MAJOR | Y18: MAJOR | Z18: 0.5 | AA18: 0.5 | AB18: 选择一个子弹，每次命中敌人后子弹伤害和体积增加 15%，最大可叠加 5 次 | AC18: action=SIZE_GROWTH；damage_per_hit=0.15；max_stacks=5；scale_per_hit=0.12 | AD18: 未命中时成长，下次命中消耗全部层数 | AE18: action=SIZE_GROWTH_ON_MISS; damage_per_stack=0.15; scale_per_stack=0.12; max_stacks=5; consume_on_hit=true | AF18: 0.00s卡背→0.24s薄边换面→0.42s收束；逆位图案/框体180°，卡名、天体、方位标签和说明文字0°；0.62s后可点 | AG18: [设计完成/数据已入表/运行时待施工]
A19: fate_sun_scorch | B19: 节制 | C19: 规则 | D19: 史诗 | E19: 下房敌血-20% | F19: 下一个敌对房间的敌人最大生命降低20% | G19: 天火先扫过下一战区，让尚未现身的敌群带着灼伤入场。 | H19: [用户设计] | J19: action=APPLY_SCOPED_MODIFIER；modifier=next_room_enemy_hp；multiplier=0.8 | K19: 门后命运/三选一/工作台共用正式卡池 | L19: [已实装] | M19: [部分实装] 塔罗名称、正/逆位效果快照与通用执行已接入；复杂逆位专属行为继续逐卡QA | N19: src/weapons/FateCard.gd；src/weapons/FateCardPresets.gd；src/weapons/FateCardEngine.gd；src/game/FateCardGameBridge.gd；src/player3d/Player3D.gd；src/world3d/Dungeon3D.gd；docs/v0.1/14_技术施工_命运塔罗牌组.md；src/weapons/TarotFateCatalog.gd；tests/verification/verify_tarot_fate_runtime.gd | O19: 迁移前名称：天火灼地；稳定ID不变，旧存档迁移为正位，不重投方位 | P19: WORLD | Q19: 不占武器槽；写入行动/房间/掉落/撤离规则状态 | R19: [已实装] 塔罗名称、50/50方位、正逆位同ID、代码翻牌、整卡倒置、逆位描述替换与方位持久化已接入 | S19: ☀ 太阳命运｜节制｜翻牌后显示正位/逆位、目标、槽位与对应功能 | T19: 卡背绕Y轴翻面；逆位整张正面卡牌（含边框、图案、文字与布局）收束180°，并显示逆位效果描述；下一敌对房所有波次按0.8最大生命生成，随后清除待用状态 | U19: [部分实装] 通用卡背/翻牌/逆位倒置已验收；逐卡逆位专属VFX与音效继续QA | V19: 天火灼地 | W19: XIV | X19: MAJOR | Y19: MAJOR | Z19: 0.5 | AA19: 0.5 | AB19: 下一个敌对房间的敌人最大生命降低20% | AC19: action=APPLY_SCOPED_MODIFIER；modifier=next_room_enemy_hp；multiplier=0.8 | AD19: 下房敌血+20%，敌伤-20% | AE19: action=APPLY_SCOPED_MODIFIER; modifier=next_room_endurance; hp_multiplier=1.2; damage_multiplier=0.8 | AF19: 0.00s卡背→0.24s薄边换面→0.42s收束；逆位图案/框体180°，卡名、天体、方位标签和说明文字0°；0.62s后可点 | AG19: [设计完成/数据已入表/运行时待施工]
A20: fate_out_of_control | B20: 恶魔 | C20: 诅咒 | D20: 禁忌 | E20: 子弹上的枪随机乱射 | F20: 选择一个子弹，携带的枪会随机乱射，射击方向完全随机，伤害提升 30% | G20: 失控的附属枪不再等待瞄准，用更高伤害换取完全不可预测的方向。 | H20: [Codex补充] | I20: require_gun=true；select=BULLET | J20: action=OUT_OF_CONTROL；damage_scale=1.3；fire_rate_scale=2；spread_angle=360 | K20: 门后命运/三选一/工作台共用卡池 | L20: [已实装] | M20: [部分实装] 塔罗名称、正/逆位效果快照与通用执行已接入；复杂逆位专属行为继续逐卡QA | N20: src/weapons/FateCard.gd；src/weapons/FateCardPresets.gd；src/weapons/FateCardEngine.gd；src/game/FateCardGameBridge.gd；docs/v0.1/14_技术施工_命运塔罗牌组.md；src/weapons/TarotFateCatalog.gd；tests/verification/verify_tarot_fate_runtime.gd | O20: 迁移前名称：管不住了；稳定ID不变，旧存档迁移为正位，不重投方位 | P20: WEAPON | Q20: 占目标枪械下一个永久命运槽；按序追加、不可拆卸/替换/回退 | R20: [已实装] 塔罗名称、50/50方位、正逆位同ID、代码翻牌、整卡倒置、逆位描述替换与方位持久化已接入 | S20: ★ 星星命运｜恶魔｜翻牌后显示正位/逆位、目标、槽位与对应功能 | T20: 卡背绕Y轴翻面；逆位整张正面卡牌（含边框、图案、文字与布局）收束180°，并显示逆位效果描述；枪身警示脉冲、异常后坐/弹道与危险音色对应真实失控规则 | U20: [部分实装] 通用卡背/翻牌/逆位倒置已验收；逐卡逆位专属VFX与音效继续QA | V20: 管不住了 | W20: XV | X20: MAJOR | Y20: MAJOR | Z20: 0.5 | AA20: 0.5 | AB20: 选择一个子弹，携带的枪会随机乱射，射击方向完全随机，伤害提升 30% | AC20: action=OUT_OF_CONTROL；damage_scale=1.3；fire_rate_scale=2；spread_angle=360 | AD20: 乱射收束为90°锥形，射速更高但后坐增大 | AE20: action=OUT_OF_CONTROL; spread_angle=90; fire_rate_scale=2.5; damage_scale=1.15; recoil_scale=1.5 | AF20: 0.00s卡背→0.24s薄边换面→0.42s收束；逆位图案/框体180°，卡名、天体、方位标签和说明文字0°；0.62s后可点 | AG20: [设计完成/数据已入表/运行时待施工]
A21: fate_explode_reload | B21: 高塔 | C21: 诅咒 | D21: 禁忌 | E21: 换弹时对周围造成爆炸伤害 | F21: 选择一个枪身，换弹时对周围 150 范围内的敌人造成 80% 伤害的爆炸，但换弹时间增加 0.5 秒 | G21: 被排出的热量在换弹瞬间释放，保护了空窗，也延长了空窗。 | H21: [Codex补充] | I21: select=GUNBODY | J21: action=EXPLODE_ON_RELOAD；explosion_damage=0.8；explosion_radius=150；reload_penalty=0.5 | K21: 门后命运/三选一/工作台共用卡池 | L21: [已实装] | M21: [部分实装] 塔罗名称、正/逆位效果快照与通用执行已接入；复杂逆位专属行为继续逐卡QA | N21: src/weapons/FateCard.gd；src/weapons/FateCardPresets.gd；src/weapons/FateCardEngine.gd；src/game/FateCardGameBridge.gd；docs/v0.1/14_技术施工_命运塔罗牌组.md；src/weapons/TarotFateCatalog.gd；tests/verification/verify_tarot_fate_runtime.gd | O21: 迁移前名称：换弹爆炸；稳定ID不变，旧存档迁移为正位，不重投方位 | P21: WEAPON | Q21: 占目标枪械下一个永久命运槽；按序追加、不可拆卸/替换/回退 | R21: [已实装] 塔罗名称、50/50方位、正逆位同ID、代码翻牌、整卡倒置、逆位描述替换与方位持久化已接入 | S21: ★ 星星命运｜高塔｜翻牌后显示正位/逆位、目标、槽位与对应功能 | T21: 卡背绕Y轴翻面；逆位整张正面卡牌（含边框、图案、文字与布局）收束180°，并显示逆位效果描述；换弹开始显示范围圈与充能，结算时爆炸VFX/音效和伤害时点一致 | U21: [部分实装] 通用卡背/翻牌/逆位倒置已验收；逐卡逆位专属VFX与音效继续QA | V21: 换弹爆炸 | W21: XVI | X21: MAJOR | Y21: MAJOR | Z21: 0.5 | AA21: 0.5 | AB21: 选择一个枪身，换弹时对周围 150 范围内的敌人造成 80% 伤害的爆炸，但换弹时间增加 0.5 秒 | AC21: action=EXPLODE_ON_RELOAD；explosion_damage=0.8；explosion_radius=150；reload_penalty=0.5 | AD21: 换弹产生低伤吸引爆炸，换弹+0.2秒 | AE21: action=IMPLODE_ON_RELOAD; explosion_damage=0.5; radius=180; pull_strength=1; reload_penalty=0.2 | AF21: 0.00s卡背→0.24s薄边换面→0.42s收束；逆位图案/框体180°，卡名、天体、方位标签和说明文字0°；0.62s后可点 | AG21: [设计完成/数据已入表/运行时待施工]
A22: fate_living_bullet | B22: 星星 | C22: 变种 | D22: 稀有 | E22: 子弹会追踪最近的敌人 | F22: 选择一个子弹，使其变成追踪弹，自动飞向最近的敌人 | G22: 弹体长出了辨认敌意的本能，它不再服从直线，只服从最近的猎物。 | H22: [Codex补充] | I22: select=BULLET | J22: action=MUTATE_TO_HOMING；homing_strength=0.6；turn_rate=3 | K22: 门后命运/三选一/工作台共用卡池 | L22: [已实装] | M22: [部分实装] 塔罗名称、正/逆位效果快照与通用执行已接入；复杂逆位专属行为继续逐卡QA | N22: src/weapons/FateCard.gd；src/weapons/FateCardPresets.gd；src/weapons/FateCardEngine.gd；src/game/FateCardGameBridge.gd；docs/v0.1/14_技术施工_命运塔罗牌组.md；src/weapons/TarotFateCatalog.gd；tests/verification/verify_tarot_fate_runtime.gd | O22: 迁移前名称：活过来；稳定ID不变，旧存档迁移为正位，不重投方位 | P22: WEAPON | Q22: 占目标枪械下一个永久命运槽；按序追加、不可拆卸/替换/回退 | R22: [已实装] 塔罗名称、50/50方位、正逆位同ID、代码翻牌、整卡倒置、逆位描述替换与方位持久化已接入 | S22: ★ 星星命运｜星星｜翻牌后显示正位/逆位、目标、槽位与对应功能 | T22: 卡背绕Y轴翻面；逆位整张正面卡牌（含边框、图案、文字与布局）收束180°，并显示逆位效果描述；弹体获得生命化轮廓与转向动作，尾迹表现主动寻敌而非普通追踪 | U22: [部分实装] 通用卡背/翻牌/逆位倒置已验收；逐卡逆位专属VFX与音效继续QA | V22: 活过来 | W22: XVII | X22: MAJOR | Y22: MAJOR | Z22: 0.5 | AA22: 0.5 | AB22: 选择一个子弹，使其变成追踪弹，自动飞向最近的敌人 | AC22: action=MUTATE_TO_HOMING；homing_strength=0.6；turn_rate=3 | AD22: 子弹追踪最远可见敌人，伤害+25% | AE22: action=MUTATE_TO_HOMING; target_policy=FARTHEST_VISIBLE; homing_strength=0.35; damage_scale=1.25 | AF22: 0.00s卡背→0.24s薄边换面→0.42s收束；逆位图案/框体180°，卡名、天体、方位标签和说明文字0°；0.62s后可点 | AG22: [设计完成/数据已入表/运行时待施工]
A23: fate_moon_first_hit | B23: 月亮 | C23: 规则 | D23: 传说 | E23: 首次受伤减半 | F23: 每个房间第一次受到的伤害降低50% | G23: 静夜只替进入者挡下第一记冲击，随后屏障沉寂。 | H23: [用户设计] | J23: action=APPLY_SCOPED_MODIFIER；modifier=first_hit_guard；multiplier=0.5 | K23: 门后命运/三选一/工作台共用正式卡池 | L23: [已实装] | M23: [部分实装] 塔罗名称、正/逆位效果快照与通用执行已接入；复杂逆位专属行为继续逐卡QA | N23: src/weapons/FateCard.gd；src/weapons/FateCardPresets.gd；src/weapons/FateCardEngine.gd；src/game/FateCardGameBridge.gd；src/player3d/Player3D.gd；src/world3d/Dungeon3D.gd；docs/v0.1/14_技术施工_命运塔罗牌组.md；src/weapons/TarotFateCatalog.gd；tests/verification/verify_tarot_fate_runtime.gd | O23: 迁移前名称：静夜屏障；稳定ID不变，旧存档迁移为正位，不重投方位 | P23: CHARACTER | Q23: 不占武器槽；写入角色局内规则状态 | R23: [已实装] 塔罗名称、50/50方位、正逆位同ID、代码翻牌、整卡倒置、逆位描述替换与方位持久化已接入 | S23: ☾ 月亮命运｜月亮｜翻牌后显示正位/逆位、目标、槽位与对应功能 | T23: 卡背绕Y轴翻面；逆位整张正面卡牌（含边框、图案、文字与布局）收束180°，并显示逆位效果描述；首次进入房间重置屏障；第一次受伤后立即消耗 | U23: [部分实装] 通用卡背/翻牌/逆位倒置已验收；逐卡逆位专属VFX与音效继续QA | V23: 静夜屏障 | W23: XVIII | X23: MAJOR | Y23: MAJOR | Z23: 0.5 | AA23: 0.5 | AB23: 每个房间第一次受到的伤害降低50% | AC23: action=APPLY_SCOPED_MODIFIER；modifier=first_hit_guard；multiplier=0.5 | AD23: 首次受伤不减免，随后3次受伤-20% | AE23: action=APPLY_SCOPED_MODIFIER; modifier=delayed_guard; first_hit_multiplier=1; next_hits=3; next_hit_multiplier=0.8 | AF23: 0.00s卡背→0.24s薄边换面→0.42s收束；逆位图案/框体180°，卡名、天体、方位标签和说明文字0°；0.62s后可点 | AG23: [设计完成/数据已入表/运行时待施工]
A24: fate_sun_currency | B24: 太阳 | C24: 强化 | D24: 史诗 | E24: 魂获取+30% | F24: 本局之后获得的魂数量提升30% | G24: 太阳把敌人遗留的魂染成金色，让之后的收获更丰厚。 | H24: [用户设计] | J24: action=APPLY_SCOPED_MODIFIER；modifier=currency_gain；multiplier=1.3 | K24: 门后命运/三选一/工作台共用正式卡池 | L24: [已实装] | M24: [部分实装] 塔罗名称、正/逆位效果快照与通用执行已接入；复杂逆位专属行为继续逐卡QA | N24: src/weapons/FateCard.gd；src/weapons/FateCardPresets.gd；src/weapons/FateCardEngine.gd；src/game/FateCardGameBridge.gd；src/player3d/Player3D.gd；src/world3d/Dungeon3D.gd；docs/v0.1/14_技术施工_命运塔罗牌组.md；src/weapons/TarotFateCatalog.gd；tests/verification/verify_tarot_fate_runtime.gd | O24: 迁移前名称：黄金潮汐；稳定ID不变，旧存档迁移为正位，不重投方位 | P24: WORLD | Q24: 不占武器槽；写入行动/房间/掉落/撤离规则状态 | R24: [已实装] 塔罗名称、50/50方位、正逆位同ID、代码翻牌、整卡倒置、逆位描述替换与方位持久化已接入 | S24: ☀ 太阳命运｜太阳｜翻牌后显示正位/逆位、目标、槽位与对应功能 | T24: 卡背绕Y轴翻面；逆位整张正面卡牌（含边框、图案、文字与布局）收束180°，并显示逆位效果描述；之后敌人魂掉落乘以1.3；太阳命运常驻栏显示来源 | U24: [部分实装] 通用卡背/翻牌/逆位倒置已验收；逐卡逆位专属VFX与音效继续QA | V24: 黄金潮汐 | W24: XIX | X24: MAJOR | Y24: MAJOR | Z24: 0.5 | AA24: 0.5 | AB24: 本局之后获得的魂数量提升30% | AC24: action=APPLY_SCOPED_MODIFIER；modifier=currency_gain；multiplier=1.3 | AD24: 魂获取-15%，每第3件掉落品质+1 | AE24: action=APPLY_SCOPED_MODIFIER; modifier=currency_quality_trade; currency_multiplier=0.85; every_nth_drop=3; rarity_tiers=1 | AF24: 0.00s卡背→0.24s薄边换面→0.42s收束；逆位图案/框体180°，卡名、天体、方位标签和说明文字0°；0.62s后可点 | AG24: [设计完成/数据已入表/运行时待施工]
A25: fate_moon_last_stand | B25: 审判 | C25: 规则 | D25: 传说 | E25: 致命伤保留1血 | F25: 致命伤改为保留1生命；每张牌提供1次 | G25: 残月不会阻止伤害，只在生命归零前留下最后一道弧光。 | H25: [用户设计] | J25: action=APPLY_SCOPED_MODIFIER；modifier=last_stand；charges=1 | K25: 门后命运/三选一/工作台共用正式卡池 | L25: [已实装] | M25: [部分实装] 塔罗名称、正/逆位效果快照与通用执行已接入；复杂逆位专属行为继续逐卡QA | N25: src/weapons/FateCard.gd；src/weapons/FateCardPresets.gd；src/weapons/FateCardEngine.gd；src/game/FateCardGameBridge.gd；src/player3d/Player3D.gd；src/world3d/Dungeon3D.gd；docs/v0.1/14_技术施工_命运塔罗牌组.md；src/weapons/TarotFateCatalog.gd；tests/verification/verify_tarot_fate_runtime.gd | O25: 迁移前名称：残月不灭；稳定ID不变，旧存档迁移为正位，不重投方位 | P25: CHARACTER | Q25: 不占武器槽；写入角色局内规则状态 | R25: [已实装] 塔罗名称、50/50方位、正逆位同ID、代码翻牌、整卡倒置、逆位描述替换与方位持久化已接入 | S25: ☾ 月亮命运｜审判｜翻牌后显示正位/逆位、目标、槽位与对应功能 | T25: 卡背绕Y轴翻面；逆位整张正面卡牌（含边框、图案、文字与布局）收束180°，并显示逆位效果描述；致命伤结算保留1血并消费1次；剩余次数保存在角色状态 | U25: [部分实装] 通用卡背/翻牌/逆位倒置已验收；逐卡逆位专属VFX与音效继续QA | V25: 残月不灭 | W25: XX | X25: MAJOR | Y25: MAJOR | Z25: 0.5 | AA25: 0.5 | AB25: 致命伤改为保留1生命；每张牌提供1次 | AC25: action=APPLY_SCOPED_MODIFIER；modifier=last_stand；charges=1 | AD25: 致命时消耗50魂并恢复25%生命，每张1次 | AE25: action=APPLY_SCOPED_MODIFIER; modifier=paid_last_stand; currency_cost=50; restore_ratio=0.25; charges=1 | AF25: 0.00s卡背→0.24s薄边换面→0.42s收束；逆位图案/框体180°，卡名、天体、方位标签和说明文字0°；0.62s后可点 | AG25: [设计完成/数据已入表/运行时待施工]
A26: fate_sun_extraction | B26: 世界 | C26: 规则 | D26: 传说 | E26: 撤离时间-20% | F26: 本局所有撤离同步时间缩短20% | G26: 日落前留下的短暂通道压缩了所有撤离信标的同步过程。 | H26: [用户设计] | J26: action=APPLY_SCOPED_MODIFIER；modifier=extraction_time；multiplier=0.8 | K26: 门后命运/三选一/工作台共用正式卡池 | L26: [已实装] | M26: [部分实装] 塔罗名称、正/逆位效果快照与通用执行已接入；复杂逆位专属行为继续逐卡QA | N26: src/weapons/FateCard.gd；src/weapons/FateCardPresets.gd；src/weapons/FateCardEngine.gd；src/game/FateCardGameBridge.gd；src/player3d/Player3D.gd；src/world3d/Dungeon3D.gd；docs/v0.1/14_技术施工_命运塔罗牌组.md；src/weapons/TarotFateCatalog.gd；tests/verification/verify_tarot_fate_runtime.gd | O26: 迁移前名称：日落捷径；稳定ID不变，旧存档迁移为正位，不重投方位 | P26: WORLD | Q26: 不占武器槽；写入行动/房间/掉落/撤离规则状态 | R26: [已实装] 塔罗名称、50/50方位、正逆位同ID、代码翻牌、整卡倒置、逆位描述替换与方位持久化已接入 | S26: ☀ 太阳命运｜世界｜翻牌后显示正位/逆位、目标、槽位与对应功能 | T26: 卡背绕Y轴翻面；逆位整张正面卡牌（含边框、图案、文字与布局）收束180°，并显示逆位效果描述；现有与后续撤离信标时长乘0.8，撤离HUD使用新时长 | U26: [部分实装] 通用卡背/翻牌/逆位倒置已验收；逐卡逆位专属VFX与音效继续QA | V26: 日落捷径 | W26: XXI | X26: MAJOR | Y26: MAJOR | Z26: 0.5 | AA26: 0.5 | AB26: 本局所有撤离同步时间缩短20% | AC26: action=APPLY_SCOPED_MODIFIER；modifier=extraction_time；multiplier=0.8 | AD26: 撤离时间+30%，同步区内敌人移速-50% | AE26: action=APPLY_SCOPED_MODIFIER; modifier=slow_extraction; time_multiplier=1.3; enemy_speed_multiplier=0.5 | AF26: 0.00s卡背→0.24s薄边换面→0.42s收束；逆位图案/框体180°，卡名、天体、方位标签和说明文字0°；0.62s后可点 | AG26: [设计完成/数据已入表/运行时待施工]
A27: fate_scale_node | B27: 权杖·王牌 | C27: 强化 | D27: 普通 | E27: 体型与碰撞范围增加 | F27: 选择一个节点，体型与碰撞范围增加，伤害提升 30%，速度降低 20% | G27: 塔内的尺度并不可信；一枚被命运放大的零件，会用迟缓交换压倒性的体积。 | H27: [Codex补充] | J27: action=SCALE_NODE；damage_scale=1.3；scale=1.4；speed_scale=0.8 | K27: 门后命运/三选一/工作台共用卡池 | L27: [已实装] | M27: [部分实装] 塔罗名称、正/逆位效果快照与通用执行已接入；复杂逆位专属行为继续逐卡QA | N27: src/weapons/FateCard.gd；src/weapons/FateCardPresets.gd；src/weapons/FateCardEngine.gd；src/game/FateCardGameBridge.gd；docs/v0.1/14_技术施工_命运塔罗牌组.md；src/weapons/TarotFateCatalog.gd；tests/verification/verify_tarot_fate_runtime.gd | O27: 迁移前名称：变大了；稳定ID不变，旧存档迁移为正位，不重投方位 | P27: WEAPON | Q27: 占目标枪械下一个永久命运槽；按序追加、不可拆卸/替换/回退 | R27: [已实装] 塔罗名称、50/50方位、正逆位同ID、代码翻牌、整卡倒置、逆位描述替换与方位持久化已接入 | S27: ★ 星星命运｜权杖·王牌｜翻牌后显示正位/逆位、目标、槽位与对应功能 | T27: 卡背绕Y轴翻面；逆位整张正面卡牌（含边框、图案、文字与布局）收束180°，并显示逆位效果描述；被放大的枪体/挂件/弹体同步改变轮廓、动作重量和尾迹，命中体积与规则一致 | U27: [部分实装] 通用卡背/翻牌/逆位倒置已验收；逐卡逆位专属VFX与音效继续QA | V27: 变大了 | W27: ACE | X27: MINOR | Y27: WANDS | Z27: 0.5 | AA27: 0.5 | AB27: 选择一个节点，体型与碰撞范围增加，伤害提升 30%，速度降低 20% | AC27: action=SCALE_NODE；damage_scale=1.3；scale=1.4；speed_scale=0.8 | AD27: 体积×0.75、伤害-20%、速度+25% | AE27: action=SCALE_NODE; scale=0.75; damage_scale=0.8; speed_scale=1.25 | AF27: 0.00s卡背→0.24s薄边换面→0.42s收束；逆位图案/框体180°，卡名、天体、方位标签和说明文字0°；0.62s后可点 | AG27: [设计完成/数据已入表/运行时待施工]
A28: fate_overclock | B28: 权杖·二 | C28: 强化 | D28: 稀有 | E28: 射速提升 80% | F28: 选择一个枪身，射速提升 80%，但每次射击后累计受击伤害倍率（overheat_penalty=1.5：射击越多，受伤越痛） | G28: 把供能旋钮拧过红线的人通常只记得火力，却忘了过热会把每次受击放大。 | H28: [Codex补充] | J28: action=MULTIPLY_FIRE_RATE；fire_rate_scale=1.8；overheat_penalty=1.5 | K28: 门后命运/三选一/工作台共用卡池 | L28: [已实装] | M28: [部分实装] 塔罗名称、正/逆位效果快照与通用执行已接入；复杂逆位专属行为继续逐卡QA | N28: src/weapons/FateCard.gd；src/weapons/FateCardPresets.gd；src/weapons/FateCardEngine.gd；src/game/FateCardGameBridge.gd；docs/v0.1/14_技术施工_命运塔罗牌组.md；src/weapons/TarotFateCatalog.gd；tests/verification/verify_tarot_fate_runtime.gd | O28: 迁移前名称：超频；稳定ID不变，旧存档迁移为正位，不重投方位 | P28: WEAPON | Q28: 占目标枪械下一个永久命运槽；按序追加、不可拆卸/替换/回退 | R28: [已实装] 塔罗名称、50/50方位、正逆位同ID、代码翻牌、整卡倒置、逆位描述替换与方位持久化已接入 | S28: ★ 星星命运｜权杖·二｜翻牌后显示正位/逆位、目标、槽位与对应功能 | T28: 卡背绕Y轴翻面；逆位整张正面卡牌（含边框、图案、文字与布局）收束180°，并显示逆位效果描述；枪管热色、机械循环、枪口节奏和过热反馈同步，不能只让数值变快 | U28: [部分实装] 通用卡背/翻牌/逆位倒置已验收；逐卡逆位专属VFX与音效继续QA | V28: 超频 | W28: 2 | X28: MINOR | Y28: WANDS | Z28: 0.5 | AA28: 0.5 | AB28: 选择一个枪身，射速提升 80%，但每次射击后累计受击伤害倍率（overheat_penalty=1.5：射击越多，受伤越痛） | AC28: action=MULTIPLY_FIRE_RATE；fire_rate_scale=1.8；overheat_penalty=1.5 | AD28: 射速-25%，单发伤害+55% | AE28: action=MULTIPLY_FIRE_RATE; fire_rate_scale=0.75; damage_scale=1.55 | AF28: 0.00s卡背→0.24s薄边换面→0.42s收束；逆位图案/框体180°，卡名、天体、方位标签和说明文字0°；0.62s后可点 | AG28: [设计完成/数据已入表/运行时待施工]
A29: fate_attachment_parasite | B29: 权杖·三 | C29: 组合 | D29: 史诗 | E29: 配件附在子弹上，命中时触发效果 | F29: 选择一个配件使其寄生到子弹上，命中时触发配件效果 | G29: 活化配件会抓住弹体，把原本静止的功能带到每一次命中现场。 | H29: [Codex补充] | I29: select=BULLET | J29: action=ATTACH_TO_MOUNT；target_slot=MUZZLE；trigger_on_hit=true | K29: 门后命运/三选一/工作台共用卡池 | L29: [已实装] | M29: [部分实装] 塔罗名称、正/逆位效果快照与通用执行已接入；复杂逆位专属行为继续逐卡QA | N29: src/weapons/FateCard.gd；src/weapons/FateCardPresets.gd；src/weapons/FateCardEngine.gd；src/game/FateCardGameBridge.gd；docs/v0.1/14_技术施工_命运塔罗牌组.md；src/weapons/TarotFateCatalog.gd；tests/verification/verify_tarot_fate_runtime.gd | O29: 迁移前名称：配件寄生；稳定ID不变，旧存档迁移为正位，不重投方位 | P29: WEAPON | Q29: 占目标枪械下一个永久命运槽；按序追加、不可拆卸/替换/回退 | R29: [已实装] 塔罗名称、50/50方位、正逆位同ID、代码翻牌、整卡倒置、逆位描述替换与方位持久化已接入 | S29: ★ 星星命运｜权杖·三｜翻牌后显示正位/逆位、目标、槽位与对应功能 | T29: 卡背绕Y轴翻面；逆位整张正面卡牌（含边框、图案、文字与布局）收束180°，并显示逆位效果描述；寄生部位有有机脉冲；命中触发时局部亮起并在目标处播放专属反馈 | U29: [部分实装] 通用卡背/翻牌/逆位倒置已验收；逐卡逆位专属VFX与音效继续QA | V29: 配件寄生 | W29: 3 | X29: MINOR | Y29: WANDS | Z29: 0.5 | AA29: 0.5 | AB29: 选择一个配件使其寄生到子弹上，命中时触发配件效果 | AC29: action=ATTACH_TO_MOUNT；target_slot=MUZZLE；trigger_on_hit=true | AD29: 配件效果改在换弹完成时触发，3秒冷却 | AE29: action=ATTACH_TO_MOUNT; trigger=RELOAD_COMPLETE; cooldown=3 | AF29: 0.00s卡背→0.24s薄边换面→0.42s收束；逆位图案/框体180°，卡名、天体、方位标签和说明文字0°；0.62s后可点 | AG29: [设计完成/数据已入表/运行时待施工]
A30: fate_turret_on_land | B30: 权杖·四 | C30: 变种 | D30: 史诗 | E30: 子弹落地后自动炮击 | F30: 选择一个子弹，子弹落地后生成一座自动炮台，持续射击附近的敌人 | G30: 未命中的子弹拒绝浪费自己，它在落地点扎根并继续履行射击职责。 | H30: [Codex补充] | I30: select=BULLET | J30: action=MUTATE_TO_TURRET_ON_LAND；turret_damage=0.3；turret_duration=8；turret_fire_rate=2 | K30: 门后命运/三选一/工作台共用卡池 | L30: [已实装] | M30: [部分实装] 塔罗名称、正/逆位效果快照与通用执行已接入；复杂逆位专属行为继续逐卡QA | N30: src/weapons/FateCard.gd；src/weapons/FateCardPresets.gd；src/weapons/FateCardEngine.gd；src/game/FateCardGameBridge.gd；docs/v0.1/14_技术施工_命运塔罗牌组.md；src/weapons/TarotFateCatalog.gd；tests/verification/verify_tarot_fate_runtime.gd | O30: 迁移前名称：落地炮台；稳定ID不变，旧存档迁移为正位，不重投方位 | P30: WEAPON | Q30: 占目标枪械下一个永久命运槽；按序追加、不可拆卸/替换/回退 | R30: [已实装] 塔罗名称、50/50方位、正逆位同ID、代码翻牌、整卡倒置、逆位描述替换与方位持久化已接入 | S30: ★ 星星命运｜权杖·四｜翻牌后显示正位/逆位、目标、槽位与对应功能 | T30: 卡背绕Y轴翻面；逆位整张正面卡牌（含边框、图案、文字与布局）收束180°，并显示逆位效果描述；弹体落地变为可辨炮塔，生成、攻击、结束三阶段均有反馈 | U30: [部分实装] 通用卡背/翻牌/逆位倒置已验收；逐卡逆位专属VFX与音效继续QA | V30: 落地炮台 | W30: 4 | X30: MINOR | Y30: WANDS | Z30: 0.5 | AA30: 0.5 | AB30: 选择一个子弹，子弹落地后生成一座自动炮台，持续射击附近的敌人 | AC30: action=MUTATE_TO_TURRET_ON_LAND；turret_damage=0.3；turret_duration=8；turret_fire_rate=2 | AD30: 落地生成4秒追随玩家的移动炮台 | AE30: action=MUTATE_TO_FOLLOW_TURRET; duration=4; turret_damage=0.3; follow_player=true | AF30: 0.00s卡背→0.24s薄边换面→0.42s收束；逆位图案/框体180°，卡名、天体、方位标签和说明文字0°；0.62s后可点 | AG30: [设计完成/数据已入表/运行时待施工]
A31: fate_home_on_land | B31: 权杖·五 | C31: 变种 | D31: 稀有 | E31: 子弹飞出去后返回玩家 | F31: 选择一个子弹，子弹飞出后返回玩家方向，返回途中继续造成 60% 伤害，持续 5 秒 | G31: 被塔拒绝的弹体沿旧轨迹回返，在归途上仍然记得谁是敌人。 | H31: [Codex补充] | I31: select=BULLET | J31: action=MUTATE_TO_HOME_ON_LAND；home_lifetime=5；return_damage_multiplier=0.6 | K31: 门后命运/三选一/工作台共用卡池 | L31: [已实装] | M31: [部分实装] 塔罗名称、正/逆位效果快照与通用执行已接入；复杂逆位专属行为继续逐卡QA | N31: src/weapons/FateCard.gd；src/weapons/FateCardPresets.gd；src/weapons/FateCardEngine.gd；src/game/FateCardGameBridge.gd；docs/v0.1/14_技术施工_命运塔罗牌组.md；src/weapons/TarotFateCatalog.gd；tests/verification/verify_tarot_fate_runtime.gd | O31: 迁移前名称：回家看看；稳定ID不变，旧存档迁移为正位，不重投方位 | P31: WEAPON | Q31: 占目标枪械下一个永久命运槽；按序追加、不可拆卸/替换/回退 | R31: [已实装] 塔罗名称、50/50方位、正逆位同ID、代码翻牌、整卡倒置、逆位描述替换与方位持久化已接入 | S31: ★ 星星命运｜权杖·五｜翻牌后显示正位/逆位、目标、槽位与对应功能 | T31: 卡背绕Y轴翻面；逆位整张正面卡牌（含边框、图案、文字与布局）收束180°，并显示逆位效果描述；落地时生成返航弧线与目标标记，回收/消失时给出明确收束 | U31: [部分实装] 通用卡背/翻牌/逆位倒置已验收；逐卡逆位专属VFX与音效继续QA | V31: 回家看看 | W31: 5 | X31: MINOR | Y31: WANDS | Z31: 0.5 | AA31: 0.5 | AB31: 选择一个子弹，子弹飞出后返回玩家方向，返回途中继续造成 60% 伤害，持续 5 秒 | AC31: action=MUTATE_TO_HOME_ON_LAND；home_lifetime=5；return_damage_multiplier=0.6 | AD31: 去程伤害-30%，回程伤害+120% | AE31: action=MUTATE_TO_HOME_ON_LAND; outbound_damage_scale=0.7; return_damage_multiplier=2.2; lifetime=4 | AF31: 0.00s卡背→0.24s薄边换面→0.42s收束；逆位图案/框体180°，卡名、天体、方位标签和说明文字0°；0.62s后可点 | AG31: [设计完成/数据已入表/运行时待施工]
