Workbook

Sheet 总览
A1: SHELLSTORM 2 · 表现资源美术账本 v0.1
A3: 归属域=表现资源｜覆盖大类=UI / 音频｜AssetID 前缀=UI / AUD｜主账本（总目录）=assets/registry/ShellStorm2_美术资产台账_v001.xlsx；本账本可独立并行编辑，跨域契约见主账本
A5: 资产总数 | C5: 已完成/已接入 | E5: 待制作/程序占位 | G5: 重复警报 | I5: 域内专表 / 3D Prefab 分页
A6: =COUNTA('资产主表'!$A$6:$A$79) | C6: =COUNTIF('资产主表'!$K$6:$K$79,"已完成")+COUNTIF('资产主表'!$K$6:$K$79,"原型已接入")+COUNTIF('资产主表'!$K$6:$K$79,"正式美术已接入")+COUNTIF('资产主表'!$K$6:$K$79,"已优化并正式接入")+COUNTIF('资产主表'!$K$6:$K$79,"Blender源已完成")+COUNTIF('资产主表'!$K$6:$K$79,"已导入；优化完成") | E6: =COUNTIF('资产主表'!$K$6:$K$79,"待制作")+COUNTIF('资产主表'!$K$6:$K$79,"程序占位") | G6: =COUNTIF('资产主表'!$S$6:$S$79,"重复") | I6: 域内专表：无 | 3D Prefab 分页：无
A9: 大类 | B9: 资产数 | C9: 完成/接入 | E9: 本账本只登记上列大类；跨域搬运资产须同步主账本《分类与编码》并重跑门禁
A10: UI | B10: =COUNTIF('资产主表'!$C$6:$C$79,A10) | C10: =SUMPRODUCT(('资产主表'!$C$6:$C$79=A10)*(('资产主表'!$K$6:$K$79="已完成")+('资产主表'!$K$6:$K$79="原型已接入")+('资产主表'!$K$6:$K$79="正式美术已接入")+('资产主表'!$K$6:$K$79="已优化并正式接入")+('资产主表'!$K$6:$K$79="Blender源已完成")+('资产主表'!$K$6:$K$79="已导入；优化完成")))
A11: 音频 | B11: =COUNTIF('资产主表'!$C$6:$C$79,A11) | C11: =SUMPRODUCT(('资产主表'!$C$6:$C$79=A11)*(('资产主表'!$K$6:$K$79="已完成")+('资产主表'!$K$6:$K$79="原型已接入")+('资产主表'!$K$6:$K$79="正式美术已接入")+('资产主表'!$K$6:$K$79="已优化并正式接入")+('资产主表'!$K$6:$K$79="Blender源已完成")+('资产主表'!$K$6:$K$79="已导入；优化完成")))
A12: 合计 | B12: =SUM(B10:B11) | C12: =SUM(C10:C11)

Sheet 账本说明
A1: 本账本说明 · 表现资源
A3: 本表是分账本自描述；机器可读真源为 assets/registry/ledger_index.json，二者不一致时以 JSON 为准
A5: 项 | B5: 值
A6: 账本归属域 | B6: 表现资源
A7: 分账本文件 | B7: assets/registry/ledgers/ShellStorm2_表现资源账本_v001.xlsx
A8: 覆盖大类 | B8: UI / 音频
A9: AssetID 前缀 | B9: UI / AUD
A10: 域内专表 | B10: 无
A11: 3D Prefab 分页 | B11: 无
A12: 动画登记表 | B12: 无
A13: 主账本（总目录） | B13: assets/registry/ShellStorm2_美术资产台账_v001.xlsx
A14: 跨域契约 | B14: 分类与编码 / 命名与查重 / 版本记录 / Skill 清单 / 3D Prefab 总控 —— 全部只在主账本维护
A15: 首选制作 Skill | B15: godot-model-asset-import-standard
A16: 协作 Skill | B16: 无
... A23: 快照日期 | B23: 2026-09-18

Sheet 资产主表
A1: 资产主表 · 唯一登记源
A3: 查重键由公式生成；S 列出现“重复”时禁止制作，先合并或建立变体父子关系
A5: AssetID | B5: 中文名 | C5: 大类 | D5: 子类 | E5: 逻辑ID/源键 | F5: 组件槽 | G5: 变体父ID | H5: 视角 | I5: 状态/动画 | J5: 复用范围 | K5: 制作状态 | L5: 优先级 | M5: 版本 | N5: 规格(px) | O5: 文件路径 | P5: 源码/策划依据 | Q5: 关键词/别名 | R5: 查重键 | S5: 查重结果 | T5: SHA-256 | U5: 负责人 | V5: 更新时间 | W5: 来源/许可 | X5: 源编号（Blender collection） | Y5: 备注
A6: UI-SCREEN-HUD | B6: 战斗 HUD | C6: UI | D6: screen | E6: hud | F6: root | H6: 屏幕空间 | I6: default | J6: 跨分辨率 | K6: 原型已接入 | L6: P0 | M6: v002 | N6: 1280×720 基准；九宫格/矢量优先 | O6: scenes/Dungeon3D.tscn | P6: src/ui/GameUIManager.gd | R6: =LOWER(TRIM(C6)&"|"&TRIM(D6)&"|"&TRIM(E6)&"|"&TRIM(F6)&"|"&TRIM(H6)&"|"&TRIM(I6)) | S6: =IF(COUNTIF($R$6:$R$79,R6)>1,"重复","唯一") | T6: 86fa546a86758f57eb7b5c8fae0aeadb30e62b29e08c1b40d7fb685ac36a4b53 | U6: 待分配 | V6: 46264 | W6: 原创/待确认 | X6: — | Y6: v0.1：主游戏HUD升级为深色半透明青色全息面板，危险/撤离信息使用琥珀与绿色分层；小地图以20Hz实时更新当前楼层，显示玩家位置与朝向、扫描扇区、脉冲环、透视网格、已发现房间/连线和楼层纵向索引。 2026-08-30 AST-02：登记路径规范化 <空> → scenes/Dungeon3D.tscn；多实现/源码依据保留在P列。 2026-08-30 AST-02：补齐单一生产路径SHA；验收：verify_hud_presenter_3d；verify_3d_performance_budget；SHA 4e61089a3bcd。
A7: UI-SCREEN-INVENTORY | B7: 背包 | C7: UI | D7: screen | E7: inventory | F7: root | H7: 屏幕空间 | I7: default | J7: 跨分辨率 | K7: 原型已接入 | L7: P0 | M7: v001 | N7: 1280×720 基准；九宫格/矢量优先 | O7: src/ui/InventoryUI.gd | P7: src/ui/InventoryUI.gd | R7: =LOWER(TRIM(C7)&"|"&TRIM(D7)&"|"&TRIM(E7)&"|"&TRIM(F7)&"|"&TRIM(H7)&"|"&TRIM(I7)) | S7: =IF(COUNTIF($R$6:$R$79,R7)>1,"重复","唯一") | T7: 7237a181430578fa95598dc6501fe3a37def471fa180f7771ebc816f28ffdce2 | U7: 待分配 | V7: 46264 | W7: 原创/待确认 | X7: — | Y7: 背包共享逻辑根；3D表现登记为 UI-SCREEN-INVENTORY-3D；12+2槽与保险契约不变 2026-08-30 AST-02：登记路径规范化 <空> → src/ui/InventoryUI.gd；多实现/源码依据保留在P列。 2026-08-30 AST-02：补齐单一生产路径SHA；验收：verify_3d_inventory_weapon_flow；SHA e2c3f432a561。
A8: UI-SCREEN-MERCHANT | B8: 商人 | C8: UI | D8: screen | E8: merchant | F8: root | H8: 屏幕空间 | I8: default | J8: 跨分辨率 | K8: 程序占位 | L8: P2 | M8: v001 | N8: 1280×720 基准；九宫格/矢量优先 | P8: src/ui/MerchantUI.gd | R8: =LOWER(TRIM(C8)&"|"&TRIM(D8)&"|"&TRIM(E8)&"|"&TRIM(F8)&"|"&TRIM(H8)&"|"&TRIM(I8)) | S8: =IF(COUNTIF($R$6:$R$79,R8)>1,"重复","唯一") | U8: 待分配 | V8: 46224 | W8: 原创/待确认 | X8: — | Y8: 先建组件库，再做页面，避免每页重复画按钮/面板
A9: UI-SCREEN-WORKSHOP | B9: 枪械工坊 | C9: UI | D9: screen | E9: workshop | F9: root | H9: 屏幕空间 | I9: default | J9: 跨分辨率 | K9: 程序占位 | L9: P2 | M9: v001 | N9: 1280×720 基准；九宫格/矢量优先 | P9: src/ui/WorkshopMenu.gd | R9: =LOWER(TRIM(C9)&"|"&TRIM(D9)&"|"&TRIM(E9)&"|"&TRIM(F9)&"|"&TRIM(H9)&"|"&TRIM(I9)) | S9: =IF(COUNTIF($R$6:$R$79,R9)>1,"重复","唯一") | U9: 待分配 | V9: 46224 | W9: 原创/待确认 | X9: — | Y9: 先建组件库，再做页面，避免每页重复画按钮/面板
A10: UI-SCREEN-WORKBENCH | B10: 工作台 | C10: UI | D10: screen | E10: workbench | F10: root | H10: 屏幕空间 | I10: default | J10: 跨分辨率 | K10: 程序占位 | L10: P2 | M10: v001 | N10: 1280×720 基准；九宫格/矢量优先 | P10: src/ui/WorkbenchPanel.gd | R10: =LOWER(TRIM(C10)&"|"&TRIM(D10)&"|"&TRIM(E10)&"|"&TRIM(F10)&"|"&TRIM(H10)&"|"&TRIM(I10)) | S10: =IF(COUNTIF($R$6:$R$79,R10)>1,"重复","唯一") | U10: 待分配 | V10: 46224 | W10: 原创/待确认 | X10: — | Y10: 先建组件库，再做页面，避免每页重复画按钮/面板
A11: UI-SCREEN-WEAPON-TREE | B11: 武器装配树 | C11: UI | D11: screen | E11: weapon_tree | F11: root | H11: 屏幕空间 | I11: default | J11: 跨分辨率 | K11: 程序占位 | L11: P2 | M11: v001 | N11: 1280×720 基准；九宫格/矢量优先 | P11: src/ui/WeaponAssemblyTreePanel.gd | R11: =LOWER(TRIM(C11)&"|"&TRIM(D11)&"|"&TRIM(E11)&"|"&TRIM(F11)&"|"&TRIM(H11)&"|"&TRIM(I11)) | S11: =IF(COUNTIF($R$6:$R$79,R11)>1,"重复","唯一") | U11: 待分配 | V11: 46224 | W11: 原创/待确认 | X11: — | Y11: 先建组件库，再做页面，避免每页重复画按钮/面板
A12: UI-SCREEN-FATE-SELECT | B12: 命运卡选择 | C12: UI | D12: screen | E12: fate_select | F12: root | H12: 屏幕空间 | I12: default | J12: 跨分辨率 | K12: 程序占位 | L12: P2 | M12: v001 | N12: 1280×720 基准；九宫格/矢量优先 | P12: src/ui/FateCardUIController.gd | R12: =LOWER(TRIM(C12)&"|"&TRIM(D12)&"|"&TRIM(E12)&"|"&TRIM(F12)&"|"&TRIM(H12)&"|"&TRIM(I12)) | S12: =IF(COUNTIF($R$6:$R$79,R12)>1,"重复","唯一") | U12: 待分配 | V12: 46224 | W12: 原创/待确认 | X12: — | Y12: 先建组件库，再做页面，避免每页重复画按钮/面板
A13: UI-SCREEN-FATE-COLLECTION | B13: 命运卡收藏 | C13: UI | D13: screen | E13: fate_collection | F13: root | H13: 屏幕空间 | I13: default | J13: 跨分辨率 | K13: 程序占位 | L13: P2 | M13: v001 | N13: 1280×720 基准；九宫格/矢量优先 | P13: src/ui/FateCardCollectionMenu.gd | R13: =LOWER(TRIM(C13)&"|"&TRIM(D13)&"|"&TRIM(E13)&"|"&TRIM(F13)&"|"&TRIM(H13)&"|"&TRIM(I13)) | S13: =IF(COUNTIF($R$6:$R$79,R13)>1,"重复","唯一") | U13: 待分配 | V13: 46224 | W13: 原创/待确认 | X13: — | Y13: 先建组件库，再做页面，避免每页重复画按钮/面板
A14: UI-SCREEN-LEVEL-SELECT | B14: 关卡选择 | C14: UI | D14: screen | E14: level_select | F14: root | H14: 屏幕空间 | I14: default | J14: 跨分辨率 | K14: 程序占位 | L14: P2 | M14: v001 | N14: 1280×720 基准；九宫格/矢量优先 | P14: src/ui/LevelSelectMenu.gd | R14: =LOWER(TRIM(C14)&"|"&TRIM(D14)&"|"&TRIM(E14)&"|"&TRIM(F14)&"|"&TRIM(H14)&"|"&TRIM(I14)) | S14: =IF(COUNTIF($R$6:$R$79,R14)>1,"重复","唯一") | U14: 待分配 | V14: 46224 | W14: 原创/待确认 | X14: — | Y14: 先建组件库，再做页面，避免每页重复画按钮/面板
A15: UI-SCREEN-VAULT | B15: 保险柜 | C15: UI | D15: screen | E15: vault | F15: root | H15: 屏幕空间 | I15: default | J15: 跨分辨率 | K15: 程序占位 | L15: P2 | M15: v001 | N15: 1280×720 基准；九宫格/矢量优先 | P15: src/ui/VaultMenu.gd | R15: =LOWER(TRIM(C15)&"|"&TRIM(D15)&"|"&TRIM(E15)&"|"&TRIM(F15)&"|"&TRIM(H15)&"|"&TRIM(I15)) | S15: =IF(COUNTIF($R$6:$R$79,R15)>1,"重复","唯一") | U15: 待分配 | V15: 46224 | W15: 原创/待确认 | X15: — | Y15: 先建组件库，再做页面，避免每页重复画按钮/面板
A16: UI-SCREEN-MONSTER-ARCHIVE | B16: 怪物档案 | C16: UI | D16: screen | E16: monster_archive | F16: root | H16: 屏幕空间 | I16: default | J16: 跨分辨率 | K16: 程序占位 | L16: P2 | M16: v001 | N16: 1280×720 基准；九宫格/矢量优先 | P16: src/ui/MonsterArchiveMenu.gd | R16: =LOWER(TRIM(C16)&"|"&TRIM(D16)&"|"&TRIM(E16)&"|"&TRIM(F16)&"|"&TRIM(H16)&"|"&TRIM(I16)) | S16: =IF(COUNTIF($R$6:$R$79,R16)>1,"重复","唯一") | U16: 待分配 | V16: 46224 | W16: 原创/待确认 | X16: — | Y16: 先建组件库，再做页面，避免每页重复画按钮/面板
A17: UI-SCREEN-BASE-MENU | B17: 基地菜单 | C17: UI | D17: screen | E17: base_menu | F17: root | H17: 屏幕空间 | I17: default | J17: 跨分辨率 | K17: 程序占位 | L17: P2 | M17: v001 | N17: 1280×720 基准；九宫格/矢量优先 | P17: src/ui/BaseMenu.gd | R17: =LOWER(TRIM(C17)&"|"&TRIM(D17)&"|"&TRIM(E17)&"|"&TRIM(F17)&"|"&TRIM(H17)&"|"&TRIM(I17)) | S17: =IF(COUNTIF($R$6:$R$79,R17)>1,"重复","唯一") | U17: 待分配 | V17: 46224 | W17: 原创/待确认 | X17: — | Y17: 先建组件库，再做页面，避免每页重复画按钮/面板
A18: UI-SCREEN-MOBILE-CONTROLS | B18: 移动端控制 | C18: UI | D18: screen | E18: mobile_controls | F18: root | H18: 屏幕空间 | I18: default | J18: 跨分辨率 | K18: 程序占位 | L18: P2 | M18: v001 | N18: 1280×720 基准；九宫格/矢量优先 | P18: src/ui/MobileControls.gd | R18: =LOWER(TRIM(C18)&"|"&TRIM(D18)&"|"&TRIM(E18)&"|"&TRIM(F18)&"|"&TRIM(H18)&"|"&TRIM(I18)) | S18: =IF(COUNTIF($R$6:$R$79,R18)>1,"重复","唯一") | U18: 待分配 | V18: 46224 | W18: 原创/待确认 | X18: — | Y18: 先建组件库，再做页面，避免每页重复画按钮/面板
A19: AUD-BGM-WASTELAND | B19: 末日荒野 BGM | C19: 音频 | D19: bgm | E19: bgm_wasteland | F19: root | H19: 不适用 | I19: default | J19: 按事件复用 | K19: 待制作 | L19: P2 | M19: v001 | N19: 循环 WAV/OGG | P19: bgm_wasteland.wav | R19: =LOWER(TRIM(C19)&"|"&TRIM(D19)&"|"&TRIM(E19)&"|"&TRIM(F19)&"|"&TRIM(H19)&"|"&TRIM(I19)) | S19: =IF(COUNTIF($R$6:$R$79,R19)>1,"重复","唯一") | U19: 待分配 | V19: 46224 | W19: 项目现有/待核对 | X19: — | Y19: 2026-08-30 AST-02：仓库未找到 bgm_wasteland.wav/.ogg，原“已完成”状态无文件证据，降级为待制作；不伪造路径或SHA。
A20: AUD-PISTOL-FIRE | B20: 手枪射击 | C20: 音频 | D20: sfx | E20: pistol_fire | F20: root | H20: 不适用 | I20: default | J20: 按事件复用 | K20: 待制作 | L20: P2 | M20: v001 | N20: 0.1–2.0s WAV/OGG | P20: src/core/AudioManager.gd | R20: =LOWER(TRIM(C20)&"|"&TRIM(D20)&"|"&TRIM(E20)&"|"&TRIM(F20)&"|"&TRIM(H20)&"|"&TRIM(I20)) | S20: =IF(COUNTIF($R$6:$R$79,R20)>1,"重复","唯一") | U20: 待分配 | V20: 46224 | W20: 原创/待确认 | X20: —
A21: AUD-RIFLE-FIRE | B21: 步枪射击 | C21: 音频 | D21: sfx | E21: rifle_fire | F21: root | H21: 不适用 | I21: default | J21: 按事件复用 | K21: 待制作 | L21: P2 | M21: v001 | N21: 0.1–2.0s WAV/OGG | P21: src/core/AudioManager.gd | R21: =LOWER(TRIM(C21)&"|"&TRIM(D21)&"|"&TRIM(E21)&"|"&TRIM(F21)&"|"&TRIM(H21)&"|"&TRIM(I21)) | S21: =IF(COUNTIF($R$6:$R$79,R21)>1,"重复","唯一") | U21: 待分配 | V21: 46224 | W21: 原创/待确认 | X21: —
A22: AUD-SHOTGUN-FIRE | B22: 霰弹枪射击 | C22: 音频 | D22: sfx | E22: shotgun_fire | F22: root | H22: 不适用 | I22: default | J22: 按事件复用 | K22: 待制作 | L22: P2 | M22: v001 | N22: 0.1–2.0s WAV/OGG | P22: src/core/AudioManager.gd | R22: =LOWER(TRIM(C22)&"|"&TRIM(D22)&"|"&TRIM(E22)&"|"&TRIM(F22)&"|"&TRIM(H22)&"|"&TRIM(I22)) | S22: =IF(COUNTIF($R$6:$R$79,R22)>1,"重复","唯一") | U22: 待分配 | V22: 46224 | W22: 原创/待确认 | X22: —
A23: AUD-SMG-FIRE | B23: 机枪射击 | C23: 音频 | D23: sfx | E23: smg_fire | F23: root | H23: 不适用 | I23: default | J23: 按事件复用 | K23: 待制作 | L23: P2 | M23: v001 | N23: 0.1–2.0s WAV/OGG | P23: src/core/AudioManager.gd | R23: =LOWER(TRIM(C23)&"|"&TRIM(D23)&"|"&TRIM(E23)&"|"&TRIM(F23)&"|"&TRIM(H23)&"|"&TRIM(I23)) | S23: =IF(COUNTIF($R$6:$R$79,R23)>1,"重复","唯一") | U23: 待分配 | V23: 46224 | W23: 原创/待确认 | X23: —
A24: AUD-SNIPER-FIRE | B24: 狙击射击 | C24: 音频 | D24: sfx | E24: sniper_fire | F24: root | H24: 不适用 | I24: default | J24: 按事件复用 | K24: 待制作 | L24: P2 | M24: v001 | N24: 0.1–2.0s WAV/OGG | P24: src/core/AudioManager.gd | R24: =LOWER(TRIM(C24)&"|"&TRIM(D24)&"|"&TRIM(E24)&"|"&TRIM(F24)&"|"&TRIM(H24)&"|"&TRIM(I24)) | S24: =IF(COUNTIF($R$6:$R$79,R24)>1,"重复","唯一") | U24: 待分配 | V24: 46224 | W24: 原创/待确认 | X24: —
A25: AUD-PLAYER-HIT | B25: 玩家受击 | C25: 音频 | D25: sfx | E25: player_hit | F25: root | H25: 不适用 | I25: default | J25: 按事件复用 | K25: 待制作 | L25: P2 | M25: v001 | N25: 0.1–2.0s WAV/OGG | P25: src/core/AudioManager.gd | R25: =LOWER(TRIM(C25)&"|"&TRIM(D25)&"|"&TRIM(E25)&"|"&TRIM(F25)&"|"&TRIM(H25)&"|"&TRIM(I25)) | S25: =IF(COUNTIF($R$6:$R$79,R25)>1,"重复","唯一") | U25: 待分配 | V25: 46224 | W25: 原创/待确认 | X25: —
A26: AUD-PLAYER-DASH | B26: 玩家冲刺 | C26: 音频 | D26: sfx | E26: player_dash | F26: root | H26: 不适用 | I26: default | J26: 按事件复用 | K26: 待制作 | L26: P2 | M26: v001 | N26: 0.1–2.0s WAV/OGG | P26: src/core/AudioManager.gd | R26: =LOWER(TRIM(C26)&"|"&TRIM(D26)&"|"&TRIM(E26)&"|"&TRIM(F26)&"|"&TRIM(H26)&"|"&TRIM(I26)) | S26: =IF(COUNTIF($R$6:$R$79,R26)>1,"重复","唯一") | U26: 待分配 | V26: 46224 | W26: 原创/待确认 | X26: —
A27: AUD-ENEMY-HIT | B27: 敌人受击 | C27: 音频 | D27: sfx | E27: enemy_hit | F27: root | H27: 不适用 | I27: default | J27: 按事件复用 | K27: 待制作 | L27: P2 | M27: v001 | N27: 0.1–2.0s WAV/OGG | P27: src/core/AudioManager.gd | R27: =LOWER(TRIM(C27)&"|"&TRIM(D27)&"|"&TRIM(E27)&"|"&TRIM(F27)&"|"&TRIM(H27)&"|"&TRIM(I27)) | S27: =IF(COUNTIF($R$6:$R$79,R27)>1,"重复","唯一") | U27: 待分配 | V27: 46224 | W27: 原创/待确认 | X27: —
A28: AUD-ENEMY-DIE | B28: 敌人死亡 | C28: 音频 | D28: sfx | E28: enemy_die | F28: root | H28: 不适用 | I28: default | J28: 按事件复用 | K28: 待制作 | L28: P2 | M28: v001 | N28: 0.1–2.0s WAV/OGG | P28: src/core/AudioManager.gd | R28: =LOWER(TRIM(C28)&"|"&TRIM(D28)&"|"&TRIM(E28)&"|"&TRIM(F28)&"|"&TRIM(H28)&"|"&TRIM(I28)) | S28: =IF(COUNTIF($R$6:$R$79,R28)>1,"重复","唯一") | U28: 待分配 | V28: 46224 | W28: 原创/待确认 | X28: —
A29: AUD-RELOAD | B29: 换弹 | C29: 音频 | D29: sfx | E29: reload | F29: root | H29: 不适用 | I29: default | J29: 按事件复用 | K29: 待制作 | L29: P2 | M29: v001 | N29: 0.1–2.0s WAV/OGG | P29: src/core/AudioManager.gd | R29: =LOWER(TRIM(C29)&"|"&TRIM(D29)&"|"&TRIM(E29)&"|"&TRIM(F29)&"|"&TRIM(H29)&"|"&TRIM(I29)) | S29: =IF(COUNTIF($R$6:$R$79,R29)>1,"重复","唯一") | U29: 待分配 | V29: 46224 | W29: 原创/待确认 | X29: —
A30: AUD-EXTRACTION-START | B30: 撤离启动 | C30: 音频 | D30: sfx | E30: extraction_start | F30: root | H30: 不适用 | I30: default | J30: 按事件复用 | K30: 待制作 | L30: P2 | M30: v001 | N30: 0.1–2.0s WAV/OGG | P30: src/core/AudioManager.gd | R30: =LOWER(TRIM(C30)&"|"&TRIM(D30)&"|"&TRIM(E30)&"|"&TRIM(F30)&"|"&TRIM(H30)&"|"&TRIM(I30)) | S30: =IF(COUNTIF($R$6:$R$79,R30)>1,"重复","唯一") | U30: 待分配 | V30: 46224 | W30: 原创/待确认 | X30: —
A31: AUD-EXTRACTION-DONE | B31: 撤离完成 | C31: 音频 | D31: sfx | E31: extraction_done | F31: root | H31: 不适用 | I31: default | J31: 按事件复用 | K31: 待制作 | L31: P2 | M31: v001 | N31: 0.1–2.0s WAV/OGG | P31: src/core/AudioManager.gd | R31: =LOWER(TRIM(C31)&"|"&TRIM(D31)&"|"&TRIM(E31)&"|"&TRIM(F31)&"|"&TRIM(H31)&"|"&TRIM(I31)) | S31: =IF(COUNTIF($R$6:$R$79,R31)>1,"重复","唯一") | U31: 待分配 | V31: 46224 | W31: 原创/待确认 | X31: —
A32: UI-SCREEN-INVENTORY-3D | B32: 3D背包与保险界面 | C32: UI | D32: screen | E32: inventory | F32: root_3d | G32: UI-SCREEN-INVENTORY | H32: 屏幕空间 | I32: default | J32: 3D行动区 | K32: 原型已接入 | L32: P0 | M32: v002 | N32: 全屏Control/12+2槽/96×96投影 | O32: src/ui/InventoryUI.gd | P32: scenes/Dungeon3D.tscn | Q32: 背包;保险;I键;Tab;模态输入锁;3D道具投影;实际点击装备 | R32: =LOWER(TRIM(C32)&"|"&TRIM(D32)&"|"&TRIM(E32)&"|"&TRIM(F32)&"|"&TRIM(H32)&"|"&TRIM(I32)) | S32: =IF(COUNTIF($R$6:$R$79,R32)>1,"重复","唯一") | T32: 7237a181430578fa95598dc6501fe3a37def471fa180f7771ebc816f28ffdce2 | U32: Codex | V32: 46264 | W32: 原创程序UI | X32: — | Y32: 复用背包根身份的3D子变体；I/Tab；打开时锁输入；道具共用 ItemModelFactory3D；实际 ItemSlot 信号完成换枪 ｜ 2026-08-07：左角色装备/右包裹网格；主副武器、背包装备、快捷物、物品与保险格统一正方形图标；深蓝黑+霓虹青+生命红语言。 2026-08-30 AST-02：合法内容更新；文件为Git已跟踪且修改时间不早于原台账日期；验收：verify_3d_inventory_weapon_flow；SHA ccd8f7d7f3c9→e2c3f432a561。
A33: UI-SCREEN-PAUSE-3D | B33: 3D共用暂停界面 | C33: UI | D33: screen | E33: pause | F33: root_3d | H33: 屏幕空间 | I33: default | J33: 地下城/基地/靶场 | K33: 已完成 | L33: P0 | M33: v001 | N33: PackedScene/全屏Control | O33: assets/art/ui/pause_3d/ui_pause_overlay_screen.tscn | P33: src/ui/PauseMenu3D.gd | Q33: 暂停;Esc;继续;全局模态;3D HUD | R33: =LOWER(TRIM(C33)&"|"&TRIM(D33)&"|"&TRIM(E33)&"|"&TRIM(F33)&"|"&TRIM(H33)&"|"&TRIM(I33)) | S33: =IF(COUNTIF($R$6:$R$79,R33)>1,"重复","唯一") | T33: 0ed9c0963e35156a1116af3eb6878b084a498bac87af50a9e9a4071d5f6b49b8 | U33: Codex | V33: 46264 | W33: 原创程序UI | X33: — | Y33: 三张3D地图共用；Esc先关闭最上层模态，再进入真实暂停 2026-08-30 AST-02：合法内容更新；文件为Git已跟踪且修改时间不早于原台账日期；验收：verify_pause_game_save_reset_flow；SHA 8fed542ebf6b→47f097938d22。
A34: UI-ICON-ITEM-MODEL-3D | B34: 背包道具3D模型投影组件 | C34: UI | D34: icon | E34: item_model_icon | F34: root_3d | G34: UI-SCREEN-INVENTORY-3D | H34: 屏幕空间/3D投影 | I34: default | J34: 背包/保险格/道具预览 | K34: 原型已接入 | L34: P0 | M34: v001 | N34: 96×96 SubViewport/UPDATE_ONCE | O34: assets/art/ui/inventory_3d/ui_item_model_icon_root.tscn | P34: src/ui/ItemModelIcon3D.gd | Q34: 3D道具图标;模型投影;背包图标;共享世界模型;单次渲染 | R34: =LOWER(TRIM(C34)&"|"&TRIM(D34)&"|"&TRIM(E34)&"|"&TRIM(F34)&"|"&TRIM(H34)&"|"&TRIM(I34)) | S34: =IF(COUNTIF($R$6:$R$79,R34)>1,"重复","唯一") | T34: 7d3deb95a52bbebca119606ce4189e501a812ed496b7c2f8f1e389ebeeb38d3c | U34: Codex | V34: 46225 | W34: 原创程序UI | X34: — | Y34: 与地面拾取共用 ItemModelFactory3D；96×96 内部视口缩放至56px槽位；只渲染一次；验收图：assets/art/ui/inventory_3d/ui_inventory_item_model_preview_v001.png
A35: UI-SCREEN-BASE-VENDING | B35: 基地自动贩卖机商店界面 | C35: UI | D35: base_facility | E35: base_vending_shop | F35: screen | G35: UI-SCREEN-MERCHANT | H35: Screen | I35: default | J35: 基地自动贩卖机 | K35: 原型已接入 | L35: P0 | M35: v002 | N35: 1280×720自适应 | O35: scenes/BaseVendingMenu.tscn | P35: 用户设计+docs/v0.1/07_技术施工_基地设施.md | Q35: 基地商店; 购买; 出售; 3D物品图标 | R35: =LOWER(TRIM(C35)&"|"&TRIM(D35)&"|"&TRIM(E35)&"|"&TRIM(F35)&"|"&TRIM(H35)&"|"&TRIM(I35)) | S35: =IF(COUNTIF($R$6:$R$79,R35)>1,"重复","唯一") | T35: 119e03cab16d9fc3780315b3df088e710f6bf2f2d9e4e84c95c79b6abb540bd3 | U35: Codex | V35: 46264 | W35: 程序控件/原创 | X35: — | Y35: 左右买卖双栏；复用ItemModelIcon3D；资源与容量常驻；Esc退出 ｜ 2026-08-07：购买/出售改为3列商品卡网格，正方形ItemModelIcon3D，与I键背包同源；统一主HUD配色和按钮状态。 2026-08-30 AST-02：登记路径规范化 scenes/BaseVendingMenu.tscn; src/ui/BaseVendingMenu.gd → scenes/BaseVendingMenu.tscn；多实现/源码依据保留在P列。 2026-08-30 AST-02：补齐单一生产路径SHA；验收：verify_base_shop_save_flow；SHA 064d8c1f92cf。
A36: AUD-SFX-AMMO-EMPTY | B36: 空仓扳机音效 | C36: 音频 | D36: sfx | E36: ammo_empty | F36: runtime | H36: 全局/非空间 | I36: default | J36: 桌面与Android正式运行 | K36: 已完成 | L36: P0 | M36: v001 | N36: 44.1kHz / OGG Vorbis / stereo | O36: src/assets/audio/sfx/ammo_empty_v001.ogg | P36: src/assets/audio/sfx/ammo_empty.wav; src/音效接入说明.md | Q36: ammo_empty; 音效; OGG; Android; 移动端 | R36: =LOWER(TRIM(C36)&"|"&TRIM(D36)&"|"&TRIM(E36)&"|"&TRIM(F36)&"|"&TRIM(H36)&"|"&TRIM(I36)) | S36: =IF(COUNTIF($R$6:$R$79,R36)>1,"重复","唯一") | T36: f5d0339c3c7fce8227970163bd773a11f15faffa57a878ec41111308657a000c | U36: Codex | V36: 46241 | W36: 项目WAV母版转码 | X36: — | Y36: 正式运行OGG；WAV仅作母版；AudioManager事件=ammo_empty；Android/桌面统一版本化路径，禁止旧音效回退。
A37: AUD-SFX-BOSS-DEFEAT | B37: Boss击败音效 | C37: 音频 | D37: sfx | E37: boss_defeat | F37: runtime | H37: 全局/非空间 | I37: default | J37: 桌面与Android正式运行 | K37: 已完成 | L37: P0 | M37: v001 | N37: 44.1kHz / OGG Vorbis / stereo | O37: src/assets/audio/sfx/boss_defeat_v001.ogg | P37: src/assets/audio/sfx/boss_defeat.wav; src/音效接入说明.md | Q37: boss_defeat; 音效; OGG; Android; 移动端 | R37: =LOWER(TRIM(C37)&"|"&TRIM(D37)&"|"&TRIM(E37)&"|"&TRIM(F37)&"|"&TRIM(H37)&"|"&TRIM(I37)) | S37: =IF(COUNTIF($R$6:$R$79,R37)>1,"重复","唯一") | T37: 245b27a482a9166c6bc09cdabae3094f4a2bb1e67956f8a8f54b767eb15fefba | U37: Codex | V37: 46241 | W37: 项目WAV母版转码 | X37: — | Y37: 正式运行OGG；WAV仅作母版；AudioManager事件=boss_defeat；Android/桌面统一版本化路径，禁止旧音效回退。
A38: AUD-SFX-BOSS-INTRO | B38: Boss入场音效 | C38: 音频 | D38: sfx | E38: boss_intro | F38: runtime | H38: 全局/非空间 | I38: default | J38: 桌面与Android正式运行 | K38: 已完成 | L38: P0 | M38: v001 | N38: 44.1kHz / OGG Vorbis / stereo | O38: src/assets/audio/sfx/boss_intro_v001.ogg | P38: src/assets/audio/sfx/boss_intro.wav; src/音效接入说明.md | Q38: boss_intro; 音效; OGG; Android; 移动端 | R38: =LOWER(TRIM(C38)&"|"&TRIM(D38)&"|"&TRIM(E38)&"|"&TRIM(F38)&"|"&TRIM(H38)&"|"&TRIM(I38)) | S38: =IF(COUNTIF($R$6:$R$79,R38)>1,"重复","唯一") | T38: 4e18a3afe9c7b804e6fb6905fbf05b62cba70d9b15a324c650a04d04a981d5ff | U38: Codex | V38: 46241 | W38: 项目WAV母版转码 | X38: — | Y38: 正式运行OGG；WAV仅作母版；AudioManager事件=boss_intro；Android/桌面统一版本化路径，禁止旧音效回退。
A39: AUD-SFX-BOSS-PHASE | B39: Boss阶段切换音效 | C39: 音频 | D39: sfx | E39: boss_phase | F39: runtime | H39: 全局/非空间 | I39: default | J39: 桌面与Android正式运行 | K39: 已完成 | L39: P0 | M39: v001 | N39: 44.1kHz / OGG Vorbis / stereo | O39: src/assets/audio/sfx/boss_phase_v001.ogg | P39: src/assets/audio/sfx/boss_phase.wav; src/音效接入说明.md | Q39: boss_phase; 音效; OGG; Android; 移动端 | R39: =LOWER(TRIM(C39)&"|"&TRIM(D39)&"|"&TRIM(E39)&"|"&TRIM(F39)&"|"&TRIM(H39)&"|"&TRIM(I39)) | S39: =IF(COUNTIF($R$6:$R$79,R39)>1,"重复","唯一") | T39: 804457fc13cb83e18bdc1e7e84d1b9a27414be72128f82811e016c17fc331ad3 | U39: Codex | V39: 46241 | W39: 项目WAV母版转码 | X39: — | Y39: 正式运行OGG；WAV仅作母版；AudioManager事件=boss_phase；Android/桌面统一版本化路径，禁止旧音效回退。
A40: AUD-SFX-CONTAINER-OPEN | B40: 搜索容器开启音效 | C40: 音频 | D40: sfx | E40: container_open | F40: runtime | H40: 全局/非空间 | I40: default | J40: 桌面与Android正式运行 | K40: 已完成 | L40: P0 | M40: v001 | N40: 44.1kHz / OGG Vorbis / stereo | O40: src/assets/audio/sfx/container_open_v001.ogg | P40: src/assets/audio/sfx/container_open.wav; src/音效接入说明.md | Q40: container_open; 音效; OGG; Android; 移动端 | R40: =LOWER(TRIM(C40)&"|"&TRIM(D40)&"|"&TRIM(E40)&"|"&TRIM(F40)&"|"&TRIM(H40)&"|"&TRIM(I40)) | S40: =IF(COUNTIF($R$6:$R$79,R40)>1,"重复","唯一") | T40: 8e9d9e0a773ab0daf850734913302212a2f279dc7afb0f457a193300325840d0 | U40: Codex | V40: 46241 | W40: 项目WAV母版转码 | X40: — | Y40: 正式运行OGG；WAV仅作母版；AudioManager事件=container_open；Android/桌面统一版本化路径，禁止旧音效回退。
A41: AUD-SFX-CRIT-HIT | B41: 暴击命中音效 | C41: 音频 | D41: sfx | E41: crit_hit | F41: runtime | H41: 全局/非空间 | I41: default | J41: 桌面与Android正式运行 | K41: 已完成 | L41: P0 | M41: v001 | N41: 44.1kHz / OGG Vorbis / stereo | O41: src/assets/audio/sfx/crit_hit_v001.ogg | P41: src/assets/audio/sfx/crit_hit.wav; src/音效接入说明.md | Q41: crit_hit; 音效; OGG; Android; 移动端 | R41: =LOWER(TRIM(C41)&"|"&TRIM(D41)&"|"&TRIM(E41)&"|"&TRIM(F41)&"|"&TRIM(H41)&"|"&TRIM(I41)) | S41: =IF(COUNTIF($R$6:$R$79,R41)>1,"重复","唯一") | T41: 9228e4544dc5472afe0dfaa53df5be2ec8c95bd253ea7ffd9b6136c6dd19069f | U41: Codex | V41: 46241 | W41: 项目WAV母版转码 | X41: — | Y41: 正式运行OGG；WAV仅作母版；AudioManager事件=crit_hit；Android/桌面统一版本化路径，禁止旧音效回退。
A42: AUD-SFX-DOOR-LOCKED | B42: 门锁定音效 | C42: 音频 | D42: sfx | E42: door_locked | F42: runtime | H42: 全局/非空间 | I42: default | J42: 桌面与Android正式运行 | K42: 已完成 | L42: P0 | M42: v001 | N42: 44.1kHz / OGG Vorbis / stereo | O42: src/assets/audio/sfx/door_locked_v001.ogg | P42: src/assets/audio/sfx/door_locked.wav; src/音效接入说明.md | Q42: door_locked; 音效; OGG; Android; 移动端 | R42: =LOWER(TRIM(C42)&"|"&TRIM(D42)&"|"&TRIM(E42)&"|"&TRIM(F42)&"|"&TRIM(H42)&"|"&TRIM(I42)) | S42: =IF(COUNTIF($R$6:$R$79,R42)>1,"重复","唯一") | T42: db9ece4cf6a904b8c23319b0d3bc83bce2d48ea69d7ebd246dd2bb30f2587e74 | U42: Codex | V42: 46241 | W42: 项目WAV母版转码 | X42: — | Y42: 正式运行OGG；WAV仅作母版；AudioManager事件=door_locked；Android/桌面统一版本化路径，禁止旧音效回退。
...

Sheet 域变更日志
A1: 表现资源账本变更日志
A3: 只记录本账本的域内变更；跨域与全局变更记录在主账本《版本记录》
A5: 台账版本 | B5: 日期 | C5: 变更类型 | D5: 范围 | E5: 说明 | F5: 兼容性 | G5: 负责人
A6: v0.1.0 | B6: 2026-09-18 | C6: 分账本建立 | D6: 表现资源 | E6: 由单体账本《ShellStorm2_美术资产台账_v001.xlsx》按大类拆分而来；本账本接管大类=UI / 音频，条目内容逐格不变，仅登记位置变化。 | F6: 资产条目、AssetID、路径与哈希全部不变；只换文件。旧引用可用 scripts/ledger_registry.py 解析。 | G6: 摩斯拉
