Workbook

Sheet 总览
A1: SHELLSTORM 2 · 武器美术账本 v0.1
A3: 归属域=武器｜覆盖大类=武器｜AssetID 前缀=WPN｜主账本（总目录）=assets/registry/ShellStorm2_美术资产台账_v001.xlsx；本账本可独立并行编辑，跨域契约见主账本
A5: 资产总数 | C5: 已完成/已接入 | E5: 待制作/程序占位 | G5: 重复警报 | I5: 域内专表 / 3D Prefab 分页
A6: =COUNTA('资产主表'!$A$6:$A$41) | C6: =COUNTIF('资产主表'!$K$6:$K$41,"已完成")+COUNTIF('资产主表'!$K$6:$K$41,"原型已接入")+COUNTIF('资产主表'!$K$6:$K$41,"正式美术已接入")+COUNTIF('资产主表'!$K$6:$K$41,"已优化并正式接入")+COUNTIF('资产主表'!$K$6:$K$41,"Blender源已完成")+COUNTIF('资产主表'!$K$6:$K$41,"已导入；优化完成")+COUNTIF('资产主表'!$K$6:$K$41,"白模源已完成；QA PASS") | E6: =COUNTIF('资产主表'!$K$6:$K$41,"待制作")+COUNTIF('资产主表'!$K$6:$K$41,"程序占位") | G6: =COUNTIF('资产主表'!$S$6:$S$41,"重复") | I6: 域内专表：3D-武器 | 3D Prefab 分页：3D-武器
A9: 大类 | B9: 资产数 | C9: 完成/接入 | E9: 本账本只登记上列大类；跨域搬运资产须同步主账本《分类与编码》并重跑门禁
A10: 武器 | B10: =COUNTIF('资产主表'!$C$6:$C$41,A10) | C10: =SUMPRODUCT(('资产主表'!$C$6:$C$41=A10)*(('资产主表'!$K$6:$K$41="已完成")+('资产主表'!$K$6:$K$41="原型已接入")+('资产主表'!$K$6:$K$41="正式美术已接入")+('资产主表'!$K$6:$K$41="已优化并正式接入")+('资产主表'!$K$6:$K$41="Blender源已完成")+('资产主表'!$K$6:$K$41="已导入；优化完成")+('资产主表'!$K$6:$K$41="白模源已完成；QA PASS")))
A11: 合计 | B11: =COUNTIF('资产主表'!$C$6:$C$41,A11) | C11: =SUMPRODUCT(('资产主表'!$C$6:$C$41=A11)*(('资产主表'!$K$6:$K$41="已完成")+('资产主表'!$K$6:$K$41="原型已接入")+('资产主表'!$K$6:$K$41="正式美术已接入")+('资产主表'!$K$6:$K$41="已优化并正式接入")+('资产主表'!$K$6:$K$41="Blender源已完成")+('资产主表'!$K$6:$K$41="已导入；优化完成")+('资产主表'!$K$6:$K$41="白模源已完成；QA PASS")))
A13: 域内 3D Prefab 分页统计（快照口径与本账本分页一致；权威清单在各分页表）
A14: 分页 | B14: Prefab 数 | C14: 直接引用 GLB | D14: 有功能脚本 | E14: 碰撞开启 | F14: 说明
A15: 3D-武器 | B15: =COUNTA('3D-武器'!$A$5:$A$204) | C15: =COUNTIF('3D-武器'!$D$5:$D$204,"<>") | D15: =COUNTIF('3D-武器'!$G$5:$G$204,"<>") | E15: =COUNTIF('3D-武器'!$H$5:$H$204,"开") | F15: 一行 = 一个实际存在的 Godot PackedScene
A16: 合计 | B16: =SUM(B15) | C16: =SUM(C15) | D16: =SUM(D15) | E16: =SUM(E15)

Sheet 账本说明
A1: 本账本说明 · 武器
A3: 本表是分账本自描述；机器可读真源为 assets/registry/ledger_index.json，二者不一致时以 JSON 为准
A5: 项 | B5: 值
A6: 账本归属域 | B6: 武器
A7: 分账本文件 | B7: assets/registry/ledgers/ShellStorm2_武器账本_v001.xlsx
A8: 覆盖大类 | B8: 武器
A9: AssetID 前缀 | B9: WPN
A10: 域内专表 | B10: 3D-武器
A11: 3D Prefab 分页 | B11: 3D-武器
A12: 动画登记表 | B12: 无
A13: 主账本（总目录） | B13: assets/registry/ShellStorm2_美术资产台账_v001.xlsx
A14: 跨域契约 | B14: 分类与编码 / 命名与查重 / 版本记录 / Skill 清单 / 3D Prefab 总控 —— 全部只在主账本维护
A15: 首选制作 Skill | B15: game-weapon-model-pipeline
A16: 协作 Skill | B16: 无
... A23: 快照日期 | B23: 2026-09-18

Sheet 资产主表
A1: 资产主表 · 唯一登记源
A3: 查重键由公式生成；S 列出现“重复”时禁止制作，先合并或建立变体父子关系
A5: AssetID | B5: 中文名 | C5: 大类 | D5: 子类 | E5: 逻辑ID/源键 | F5: 组件槽 | G5: 变体父ID | H5: 视角 | I5: 状态/动画 | J5: 复用范围 | K5: 制作状态 | L5: 优先级 | M5: 版本 | N5: 规格(px) | O5: 文件路径 | P5: 源码/策划依据 | Q5: 关键词/别名 | R5: 查重键 | S5: 查重结果 | T5: SHA-256 | U5: 负责人 | V5: 更新时间 | W5: 来源/许可 | X5: 源编号（Blender collection） | Y5: 备注
A6: WPN-GUN-BP-PISTOL | B6: 豌豆手枪 / 吹风机造型 | C6: 武器 | D6: gunbody | E6: bp_pistol | F6: root | H6: 俯视3D / local -Z 枪口 | I6: default / 标准握把与8类挂点 | J6: 手持/背负/地面/UI 共用独立PackedScene | K6: 已完成 | L6: P0 | M6: v001 | N6: 握把原点；local -Z枪口；3材质；独立GLB/PackedScene | O6: assets/art/weapons/weapon_3d/runtime/hair_dryer/wpn_hair_dryer_root_top3d_v001.tscn | P6: art_source/weapons/weapon_3d/source/hair_dryer/wpn_hair_dryer_source_v003.blend; src/combat3d/WeaponModel3D.gd | Q6: bp_pistol; 吹风机; 握把原点; -Z枪口; 通用挂点; 多巴胺配色 | R6: =LOWER(TRIM(C6)&"|"&TRIM(D6)&"|"&TRIM(E6)&"|"&TRIM(F6)&"|"&TRIM(H6)&"|"&TRIM(I6)) | S6: =IF(COUNTIF($R$6:$R$41,R6)>1,"重复","唯一") | T6: ec5be48b60ec8724759108b9d8f0530473e324e0df25f392622474909f52f05e | U6: Codex | V6: 46264 | W6: 用户自制Blender资产 | X6: — | Y6: 由18枪合集拆成独立资产；根节点即握把原点，枪口统一local -Z；无需玩家侧逐枪旋转补丁。 2026-08-21：复用WPN-GUN-BP-PISTOL与v003 GLB；Godot包装层保持GripSocket=根原点，将可见握把中心及全部非Grip语义挂点统一校正(0,-0.122838,-0.168785)。待机与开火时枪模local -Z锁定真实aim_direction，后坐只沿枪轴平移，不改变弹道、伤害、碰撞或装配。 2026-08-30 AST-01规范化（原制作状态：正式美术已接入；原大类：枪械） 2026-08-30 AST-02：合法内容更新；文件为Git已跟踪且修改时间不早于原台账日期；验收：verify_weapon_instance_contract_matrix；SHA c8e52bda1186→ec5be48b60ec。
A7: WPN-GUN-BP-SHOTGUN | B7: 散射喷壶 / 双管炮造型 | C7: 武器 | D7: gunbody | E7: bp_shotgun | F7: root | H7: 俯视3D / local -Z 枪口 | I7: default / 标准握把与8类挂点 | J7: 手持/背负/地面/UI 共用独立PackedScene | K7: 已完成 | L7: P0 | M7: v001 | N7: 握把原点；local -Z枪口；3材质；独立GLB/PackedScene | O7: assets/art/weapons/weapon_3d/runtime/double_barrel_cannon/wpn_double_barrel_cannon_root_top3d_v001.tscn | P7: ../ShellStorm2-backup/2026-10-11_slimming/original_tree/art_source/weapons/weapon_3d/source/double_barrel_cannon/wpn_double_barrel_cannon_source_v001.blend; src/combat3d/WeaponModel3D.gd | Q7: bp_shotgun; 双管炮; 握把原点; -Z枪口; 通用挂点; 多巴胺配色 | R7: =LOWER(TRIM(C7)&"|"&TRIM(D7)&"|"&TRIM(E7)&"|"&TRIM(F7)&"|"&TRIM(H7)&"|"&TRIM(I7)) | S7: =IF(COUNTIF($R$6:$R$41,R7)>1,"重复","唯一") | T7: 67aa2883793ca21ce27b41732c48b1f4b250182c505dfab8267fcd45eb74831b | U7: Codex | V7: 46264 | W7: 用户自制Blender资产 | X7: — | Y7: 由18枪合集拆成独立资产；根节点即握把原点，枪口统一local -Z；无需玩家侧逐枪旋转补丁。 2026-08-30 AST-01规范化（原制作状态：正式美术已接入；原大类：枪械） 2026-08-30 AST-02：合法内容更新；文件为Git已跟踪且修改时间不早于原台账日期；验收：verify_weapon_instance_contract_matrix；SHA 8e026c49d788→67aa2883793c。
A8: WPN-GUN-BP-RIFLE | B8: 步枪 / 扫帚步枪造型 | C8: 武器 | D8: gunbody | E8: bp_rifle | F8: root | H8: 俯视3D / local -Z 枪口 | I8: default / 标准握把与8类挂点 | J8: 手持/背负/地面/UI 共用独立PackedScene | K8: 已完成 | L8: P0 | M8: v001 | N8: 握把原点；local -Z枪口；3材质；独立GLB/PackedScene | O8: assets/art/weapons/weapon_3d/runtime/broom_rifle/wpn_broom_rifle_root_top3d_v001.tscn | P8: ../ShellStorm2-backup/2026-10-11_slimming/original_tree/art_source/weapons/weapon_3d/source/broom_rifle/wpn_broom_rifle_source_v001.blend; src/combat3d/WeaponModel3D.gd | Q8: bp_rifle; 扫帚步枪; 握把原点; -Z枪口; 通用挂点; 多巴胺配色 | R8: =LOWER(TRIM(C8)&"|"&TRIM(D8)&"|"&TRIM(E8)&"|"&TRIM(F8)&"|"&TRIM(H8)&"|"&TRIM(I8)) | S8: =IF(COUNTIF($R$6:$R$41,R8)>1,"重复","唯一") | T8: ce12927b14a1cb3be4f8403dfca41347f21a038faab502b3779245ef9f211cd8 | U8: Codex | V8: 46264 | W8: 用户自制Blender资产 | X8: — | Y8: 由18枪合集拆成独立资产；根节点即握把原点，枪口统一local -Z；无需玩家侧逐枪旋转补丁。 2026-08-30 AST-01规范化（原制作状态：正式美术已接入；原大类：枪械） 2026-08-30 AST-02：合法内容更新；文件为Git已跟踪且修改时间不早于原台账日期；验收：verify_weapon_instance_contract_matrix；SHA 67a1515e3659→ce12927b14a1。
A9: WPN-GUN-BP-MACHINEGUN | B9: 蜂窝机枪 / 水箱爆能枪造型 | C9: 武器 | D9: gunbody | E9: bp_machinegun | F9: root | H9: 俯视3D / local -Z 枪口 | I9: default / 标准握把与8类挂点 | J9: 手持/背负/地面/UI 共用独立PackedScene | K9: 已完成 | L9: P1 | M9: v001 | N9: 握把原点；local -Z枪口；3材质；独立GLB/PackedScene | O9: assets/art/weapons/weapon_3d/runtime/water_tank_blaster/wpn_water_tank_blaster_root_top3d.tscn | P9: ../ShellStorm2-backup/2026-10-11_slimming/original_tree/art_source/weapons/weapon_3d/source/water_tank_blaster/wpn_water_tank_blaster_source_v001.blend; src/combat3d/WeaponModel3D.gd | Q9: bp_machinegun; 水箱爆能枪; 握把原点; -Z枪口; 通用挂点; 多巴胺配色 | R9: =LOWER(TRIM(C9)&"|"&TRIM(D9)&"|"&TRIM(E9)&"|"&TRIM(F9)&"|"&TRIM(H9)&"|"&TRIM(I9)) | S9: =IF(COUNTIF($R$6:$R$41,R9)>1,"重复","唯一") | T9: 037a040062930e47d813d7b1ffd5f6cff96b826750d4a9b2e38f42a78b5f5f98 | U9: Codex | V9: 46264 | W9: 用户自制Blender资产 | X9: — | Y9: 由18枪合集拆成独立资产；根节点即握把原点，枪口统一local -Z；无需玩家侧逐枪旋转补丁。 2026-08-30 AST-01规范化（原制作状态：正式美术已接入；原大类：枪械） 2026-08-30 AST-02：合法内容更新；文件为Git已跟踪且修改时间不早于原台账日期；验收：verify_weapon_instance_contract_matrix；SHA 24608d0d872a→037a04006293。
A10: WPN-GUN-BP-SNIPER | B10: 弹弓狙击 / 糖果狙击枪造型 | C10: 武器 | D10: gunbody | E10: bp_sniper | F10: root | H10: 俯视3D / local -Z 枪口 | I10: default / 标准握把与8类挂点 | J10: 手持/背负/地面/UI 共用独立PackedScene | K10: 已完成 | L10: P1 | M10: v001 | N10: 握把原点；local -Z枪口；3材质；独立GLB/PackedScene | O10: assets/art/weapons/weapon_3d/runtime/candy_sniper/wpn_candy_sniper_root_top3d_v001.tscn | P10: ../ShellStorm2-backup/2026-10-11_slimming/original_tree/art_source/weapons/weapon_3d/source/candy_sniper/wpn_candy_sniper_source_v001.blend; src/combat3d/WeaponModel3D.gd | Q10: bp_sniper; 糖果狙击枪; 握把原点; -Z枪口; 通用挂点; 多巴胺配色 | R10: =LOWER(TRIM(C10)&"|"&TRIM(D10)&"|"&TRIM(E10)&"|"&TRIM(F10)&"|"&TRIM(H10)&"|"&TRIM(I10)) | S10: =IF(COUNTIF($R$6:$R$41,R10)>1,"重复","唯一") | T10: a9c319e031c0f30b7404a435de8b5aaf2f5d5e470bd591e7dfbcf2e6ed8f2753 | U10: Codex | V10: 46264 | W10: 用户自制Blender资产 | X10: — | Y10: 由18枪合集拆成独立资产；根节点即握把原点，枪口统一local -Z；无需玩家侧逐枪旋转补丁。 2026-08-30 AST-01规范化（原制作状态：正式美术已接入；原大类：枪械） 2026-08-30 AST-02：合法内容更新；文件为Git已跟踪且修改时间不早于原台账日期；验收：verify_weapon_instance_contract_matrix；SHA 3900da0b2425→a9c319e031c0。
A11: WPN-GUN-BP-LAUNCHER | B11: 反胃榴弹筒 / 烤面包机造型 | C11: 武器 | D11: gunbody | E11: bp_launcher | F11: root | H11: 俯视3D / local -Z 枪口 | I11: default / 标准握把与8类挂点 | J11: 手持/背负/地面/UI 共用独立PackedScene | K11: 已完成 | L11: P1 | M11: v001 | N11: 握把原点；local -Z枪口；3材质；独立GLB/PackedScene | O11: assets/art/weapons/weapon_3d/runtime/toaster_launcher/wpn_toaster_launcher_root_top3d_v001.tscn | P11: ../ShellStorm2-backup/2026-10-11_slimming/original_tree/art_source/weapons/weapon_3d/source/toaster_launcher/wpn_toaster_launcher_source_v001.blend; src/combat3d/WeaponModel3D.gd | Q11: bp_launcher; 烤面包机发射器; 握把原点; -Z枪口; 通用挂点; 多巴胺配色 | R11: =LOWER(TRIM(C11)&"|"&TRIM(D11)&"|"&TRIM(E11)&"|"&TRIM(F11)&"|"&TRIM(H11)&"|"&TRIM(I11)) | S11: =IF(COUNTIF($R$6:$R$41,R11)>1,"重复","唯一") | T11: 97d05fc29d0ed170225489c8d7282c0065757d557c9bfaa31bd31761f8f67a41 | U11: Codex | V11: 46264 | W11: 用户自制Blender资产 | X11: — | Y11: 由18枪合集拆成独立资产；根节点即握把原点，枪口统一local -Z；无需玩家侧逐枪旋转补丁。 2026-08-30 AST-01规范化（原制作状态：正式美术已接入；原大类：枪械） 2026-08-30 AST-02：合法内容更新；文件为Git已跟踪且修改时间不早于原台账日期；验收：verify_weapon_instance_contract_matrix；SHA 461e79fd5256→97d05fc29d0e。
A12: WPN-GUN-BP-CHARGE | B12: 蓄力萝卜炮 / 口香糖机造型 | C12: 武器 | D12: gunbody | E12: bp_charge | F12: root | H12: 俯视3D / local -Z 枪口 | I12: default / 标准握把与8类挂点 | J12: 手持/背负/地面/UI 共用独立PackedScene | K12: 已完成 | L12: P2 | M12: v001 | N12: 握把原点；local -Z枪口；3材质；独立GLB/PackedScene | O12: assets/art/weapons/weapon_3d/runtime/gumball_cannon/wpn_gumball_cannon_root_top3d_v001.tscn | P12: ../ShellStorm2-backup/2026-10-11_slimming/original_tree/art_source/weapons/weapon_3d/source/gumball_cannon/wpn_gumball_cannon_source_v001.blend; src/combat3d/WeaponModel3D.gd | Q12: bp_charge; 口香糖机加农炮; 握把原点; -Z枪口; 通用挂点; 多巴胺配色 | R12: =LOWER(TRIM(C12)&"|"&TRIM(D12)&"|"&TRIM(E12)&"|"&TRIM(F12)&"|"&TRIM(H12)&"|"&TRIM(I12)) | S12: =IF(COUNTIF($R$6:$R$41,R12)>1,"重复","唯一") | T12: 1c494d0811ef503c74e8dc61277b307e35db210241b46083a6da7b2121b54cee | U12: Codex | V12: 46264 | W12: 用户自制Blender资产 | X12: — | Y12: 由18枪合集拆成独立资产；根节点即握把原点，枪口统一local -Z；无需玩家侧逐枪旋转补丁。 2026-08-30 AST-01规范化（原制作状态：正式美术已接入；原大类：枪械） 2026-08-30 AST-02：合法内容更新；文件为Git已跟踪且修改时间不早于原台账日期；验收：verify_weapon_instance_contract_matrix；SHA 94576279e46f→1c494d0811ef。
A13: WPN-BUL-MOD-BULLET-STANDARD | B13: 标准子弹模块 | C13: 武器 | D13: bullet_module | E13: mod_bullet_standard | F13: root | H13: 底面中心原点；Blender +Z向上，正面-Y；Godot +Y向上、正面+Z | I13: tier_0_static | J13: 独立物品/配件原始源；后续拾取、库存与武器装配复用 | K13: Blender源已完成 | L13: P1 | M13: v001 | N13: 0.3760×0.3760×0.9400m；单位米；根缩放1；场景四材质/公共色盘/PaletteUV；实测快照见asset_contract.json；preview高模；ground 176三角面（100–200预算） | O13: art_source/items_weapons/weapons/bullet_standard/source/wpn_bullet_standard_source_v001.blend; art_source/items_weapons/weapons/bullet_standard/source/wpn_bullet_standard_ground_source_v001.blend | P13: src/world3d/ItemModelFactory3D.gd; src/world3d/GroundLootPickup3D.gd; src/combat3d/WeaponModel3D.gd; art_source/items_weapons/weapons/bullet_standard/asset_contract.json | Q13: mod_bullet_standard;标准子弹模块 | R13: =LOWER(TRIM(C13)&"|"&TRIM(D13)&"|"&TRIM(E13)&"|"&TRIM(F13)&"|"&TRIM(H13)&"|"&TRIM(I13)) | S13: =IF(COUNTIF($R$6:$R$41,R13)>1,"重复","唯一") | T13: 9c1f7ffa3a57dc6b2bfedbb10ccb1d023df98c7761ea42f9eb00aa729958bb5e | U13: Codex | V13: 46309 | W13: 用户提供参考图重建；项目公共色盘 | X13: WPN_标准子弹模块_中文资产管理 | Y13: 2026-10-14 用户参考图制作；Godot物品工厂/拾取实体/配件挂点实测后冻结主轴尺寸，其余轴按图等比。仅Blender原始源；未导出GLB、未导入Godot；运行时仍用现有占位。 双模型源：preview=3368三角；ground=176三角；地面源SHA256=183bdba5012c84457782d224b2cc6e871af09e3d126187f665497d98a8ca89cd；高模哈希保持；未接入运行时。
A14: WPN-BUL-MOD-BULLET-STICKY | B14: 黏黏弹 | C14: 武器 | D14: bullet_module | E14: mod_bullet_sticky | F14: root | H14: 顶视/方向无关 | I14: default | J14: 弹体/VFX/UI 图标 | K14: 程序占位 | L14: P1 | M14: v001 | N14: 建议 12×12 px | P14: src/base/BlueprintRegistry.gd | R14: =LOWER(TRIM(C14)&"|"&TRIM(D14)&"|"&TRIM(E14)&"|"&TRIM(F14)&"|"&TRIM(H14)&"|"&TRIM(I14)) | S14: =IF(COUNTIF($R$6:$R$41,R14)>1,"重复","唯一") | U14: 待分配 | V14: 46224 | W14: 原创/待确认 | X14: — | Y14: 优先复用颜色和弹道特效，不为每把枪重复制作 2026-08-30 AST-01规范化（原大类：枪械）
A15: WPN-BUL-MOD-BULLET-BOUNCE | B15: 回旋镖弹 | C15: 武器 | D15: bullet_module | E15: mod_bullet_bounce | F15: root | H15: 顶视/方向无关 | I15: default | J15: 弹体/VFX/UI 图标 | K15: 程序占位 | L15: P1 | M15: v001 | N15: 建议 12×12 px | P15: src/base/BlueprintRegistry.gd | R15: =LOWER(TRIM(C15)&"|"&TRIM(D15)&"|"&TRIM(E15)&"|"&TRIM(F15)&"|"&TRIM(H15)&"|"&TRIM(I15)) | S15: =IF(COUNTIF($R$6:$R$41,R15)>1,"重复","唯一") | U15: 待分配 | V15: 46224 | W15: 原创/待确认 | X15: — | Y15: 优先复用颜色和弹道特效，不为每把枪重复制作 2026-08-30 AST-01规范化（原大类：枪械）
A16: WPN-BUL-MOD-BULLET-PIERCING | B16: 穿甲弹 | C16: 武器 | D16: bullet_module | E16: mod_bullet_piercing | F16: root | H16: 顶视/方向无关 | I16: default | J16: 弹体/VFX/UI 图标 | K16: 程序占位 | L16: P1 | M16: v001 | N16: 建议 12×12 px | P16: src/base/BlueprintRegistry.gd | R16: =LOWER(TRIM(C16)&"|"&TRIM(D16)&"|"&TRIM(E16)&"|"&TRIM(F16)&"|"&TRIM(H16)&"|"&TRIM(I16)) | S16: =IF(COUNTIF($R$6:$R$41,R16)>1,"重复","唯一") | U16: 待分配 | V16: 46224 | W16: 原创/待确认 | X16: — | Y16: 优先复用颜色和弹道特效，不为每把枪重复制作 2026-08-30 AST-01规范化（原大类：枪械）
A17: WPN-BUL-MOD-BULLET-EXPLOSIVE | B17: 爆炸弹 | C17: 武器 | D17: bullet_module | E17: mod_bullet_explosive | F17: root | H17: 顶视/方向无关 | I17: default | J17: 弹体/VFX/UI 图标 | K17: 程序占位 | L17: P1 | M17: v001 | N17: 建议 12×12 px | P17: src/base/BlueprintRegistry.gd | R17: =LOWER(TRIM(C17)&"|"&TRIM(D17)&"|"&TRIM(E17)&"|"&TRIM(F17)&"|"&TRIM(H17)&"|"&TRIM(I17)) | S17: =IF(COUNTIF($R$6:$R$41,R17)>1,"重复","唯一") | U17: 待分配 | V17: 46224 | W17: 原创/待确认 | X17: — | Y17: 优先复用颜色和弹道特效，不为每把枪重复制作 2026-08-30 AST-01规范化（原大类：枪械）
A18: WPN-BUL-MOD-BULLET-HOMING | B18: 蜂卵弹 | C18: 武器 | D18: bullet_module | E18: mod_bullet_homing | F18: root | H18: 顶视/方向无关 | I18: default | J18: 弹体/VFX/UI 图标 | K18: 程序占位 | L18: P1 | M18: v001 | N18: 建议 12×12 px | P18: src/base/BlueprintRegistry.gd | R18: =LOWER(TRIM(C18)&"|"&TRIM(D18)&"|"&TRIM(E18)&"|"&TRIM(F18)&"|"&TRIM(H18)&"|"&TRIM(I18)) | S18: =IF(COUNTIF($R$6:$R$41,R18)>1,"重复","唯一") | U18: 待分配 | V18: 46224 | W18: 原创/待确认 | X18: — | Y18: 优先复用颜色和弹道特效，不为每把枪重复制作 2026-08-30 AST-01规范化（原大类：枪械）
A19: WPN-BUL-MOD-BULLET-BLACKHOLE | B19: 黑洞弹 | C19: 武器 | D19: bullet_module | E19: mod_bullet_blackhole | F19: root | H19: 顶视/方向无关 | I19: default | J19: 弹体/VFX/UI 图标 | K19: 程序占位 | L19: P1 | M19: v001 | N19: 建议 12×12 px | P19: src/base/BlueprintRegistry.gd | R19: =LOWER(TRIM(C19)&"|"&TRIM(D19)&"|"&TRIM(E19)&"|"&TRIM(F19)&"|"&TRIM(H19)&"|"&TRIM(I19)) | S19: =IF(COUNTIF($R$6:$R$41,R19)>1,"重复","唯一") | U19: 待分配 | V19: 46224 | W19: 原创/待确认 | X19: — | Y19: 优先复用颜色和弹道特效，不为每把枪重复制作 2026-08-30 AST-01规范化（原大类：枪械）
A20: WPN-BUL-MOD-BULLET-BALLOON | B20: 气球弹 | C20: 武器 | D20: bullet_module | E20: mod_bullet_balloon | F20: root | H20: 顶视/方向无关 | I20: default | J20: 弹体/VFX/UI 图标 | K20: 程序占位 | L20: P1 | M20: v001 | N20: 建议 12×12 px | P20: src/base/BlueprintRegistry.gd | R20: =LOWER(TRIM(C20)&"|"&TRIM(D20)&"|"&TRIM(E20)&"|"&TRIM(F20)&"|"&TRIM(H20)&"|"&TRIM(I20)) | S20: =IF(COUNTIF($R$6:$R$41,R20)>1,"重复","唯一") | U20: 待分配 | V20: 46224 | W20: 原创/待确认 | X20: — | Y20: 优先复用颜色和弹道特效，不为每把枪重复制作 2026-08-30 AST-01规范化（原大类：枪械）
A21: WPN-ATT-ATTACH-TRIPLE-MUZZLE | B21: 三叉枪口 | C21: 武器 | D21: attachment | E21: attach_triple_muzzle | F21: root | H21: 挂点中心原点；Blender +Y 对应 Godot -Z 枪口，+Z向上 | I21: tier_0_static | J21: 独立物品/配件原始源；后续拾取、库存与武器装配复用 | K21: Blender源已完成 | L21: P2 | M21: v001 | N21: 0.1404×0.1600×0.1460m；单位米；根缩放1；场景四材质/公共色盘/PaletteUV；实测快照见asset_contract.json；preview高模；ground 198三角面（100–200预算） | O21: art_source/items_weapons/weapons/triple_muzzle/source/wpn_triple_muzzle_source_v001.blend; art_source/items_weapons/weapons/triple_muzzle/source/wpn_triple_muzzle_ground_source_v001.blend | P21: src/world3d/ItemModelFactory3D.gd; src/world3d/GroundLootPickup3D.gd; src/combat3d/WeaponModel3D.gd; art_source/items_weapons/weapons/triple_muzzle/asset_contract.json | Q21: attach_triple_muzzle;三叉枪口 | R21: =LOWER(TRIM(C21)&"|"&TRIM(D21)&"|"&TRIM(E21)&"|"&TRIM(F21)&"|"&TRIM(H21)&"|"&TRIM(I21)) | S21: =IF(COUNTIF($R$6:$R$41,R21)>1,"重复","唯一") | T21: 53871c61c511ac2ac41685bcc65e765b591b5cbcd7880d3685cacf545cdd94c5 | U21: Codex | V21: 46309 | W21: 用户提供参考图重建；项目公共色盘 | X21: WPN_三叉枪口_中文资产管理 | Y21: 2026-10-14 用户参考图制作；Godot物品工厂/拾取实体/配件挂点实测后冻结主轴尺寸，其余轴按图等比。仅Blender原始源；未导出GLB、未导入Godot；运行时仍用现有占位。 双模型源：preview=7820三角；ground=198三角；地面源SHA256=3fba4ba572c107b080cb05289d21f8d5f6ae778776f7587ffa998222bdf7c293；高模哈希保持；未接入运行时。
A22: WPN-ATT-ATTACH-RUBBER-STOCK | B22: 橡皮枪托 | C22: 武器 | D22: attachment | E22: attach_rubber_stock | F22: root | H22: 挂点中心原点；Blender +Y 对应 Godot -Z 枪口，+Z向上 | I22: tier_0_static | J22: 独立物品/配件原始源；后续拾取、库存与武器装配复用 | K22: Blender源已完成 | L22: P2 | M22: v001 | N22: 0.1246×0.3200×0.2222m；单位米；根缩放1；场景四材质/公共色盘/PaletteUV；实测快照见asset_contract.json；preview高模；ground 145三角面（100–200预算） | O22: art_source/items_weapons/weapons/rubber_stock/source/wpn_rubber_stock_source_v001.blend; art_source/items_weapons/weapons/rubber_stock/source/wpn_rubber_stock_ground_source_v001.blend | P22: src/world3d/ItemModelFactory3D.gd; src/world3d/GroundLootPickup3D.gd; src/combat3d/WeaponModel3D.gd; art_source/items_weapons/weapons/rubber_stock/asset_contract.json | Q22: attach_rubber_stock;橡皮枪托 | R22: =LOWER(TRIM(C22)&"|"&TRIM(D22)&"|"&TRIM(E22)&"|"&TRIM(F22)&"|"&TRIM(H22)&"|"&TRIM(I22)) | S22: =IF(COUNTIF($R$6:$R$41,R22)>1,"重复","唯一") | T22: f1cf82e20b7c1a481dfe979503bc3f98fd9566cac09ede315ba238ab9a6c90bb | U22: Codex | V22: 46309 | W22: 用户提供参考图重建；项目公共色盘 | X22: WPN_橡皮枪托_中文资产管理 | Y22: 2026-10-14 用户参考图制作；Godot物品工厂/拾取实体/配件挂点实测后冻结主轴尺寸，其余轴按图等比。仅Blender原始源；未导出GLB、未导入Godot；运行时仍用现有占位。 双模型源：preview=20732三角；ground=145三角；地面源SHA256=4e4a906492d9eb1f79bfd5e756991584422fd30664dd502a25cfe542436791d7；高模哈希保持；未接入运行时。
A23: WPN-ATT-ATTACH-SCOPE | B23: 放大镜瞄具 | C23: 武器 | D23: attachment | E23: attach_scope | F23: root | H23: 挂点中心原点；Blender +Y 对应 Godot -Z 枪口，+Z向上 | I23: tier_0_static | J23: 独立物品/配件原始源；后续拾取、库存与武器装配复用 | K23: Blender源已完成 | L23: P2 | M23: v001 | N23: 0.1346×0.2800×0.1806m；单位米；根缩放1；场景四材质/公共色盘/PaletteUV；实测快照见asset_contract.json；preview高模；ground 198三角面（100–200预算） | O23: art_source/items_weapons/weapons/scope/source/wpn_scope_source_v001.blend; art_source/items_weapons/weapons/scope/source/wpn_scope_ground_source_v001.blend | P23: src/world3d/ItemModelFactory3D.gd; src/world3d/GroundLootPickup3D.gd; src/combat3d/WeaponModel3D.gd; art_source/items_weapons/weapons/scope/asset_contract.json | Q23: attach_scope;放大镜瞄具 | R23: =LOWER(TRIM(C23)&"|"&TRIM(D23)&"|"&TRIM(E23)&"|"&TRIM(F23)&"|"&TRIM(H23)&"|"&TRIM(I23)) | S23: =IF(COUNTIF($R$6:$R$41,R23)>1,"重复","唯一") | T23: 6c4244348bb117f35a862187503ab5577be801b5f1dd00e72bcb17c095274b95 | U23: Codex | V23: 46309 | W23: 用户提供参考图重建；项目公共色盘 | X23: WPN_放大镜瞄具_中文资产管理 | Y23: 2026-10-14 用户参考图制作；Godot物品工厂/拾取实体/配件挂点实测后冻结主轴尺寸，其余轴按图等比。仅Blender原始源；未导出GLB、未导入Godot；运行时仍用现有占位。 双模型源：preview=9044三角；ground=198三角；地面源SHA256=a6ebf1f74d67fb2ee77f1be0bc5442fe1d74d1058826c6cf4d0a43d3f9b9e138；高模哈希保持；未接入运行时。
A24: WPN-ATT-ATTACH-BIG-MAG | B24: 肉质弹匣 | C24: 武器 | D24: attachment | E24: attach_big_mag | F24: root | H24: 挂点中心原点；Blender +Y 对应 Godot -Z 枪口，+Z向上 | I24: tier_0_static | J24: 独立物品/配件原始源；后续拾取、库存与武器装配复用 | K24: Blender源已完成 | L24: P2 | M24: v001 | N24: 0.1101×0.0705×0.2400m；单位米；根缩放1；场景四材质/公共色盘/PaletteUV；实测快照见asset_contract.json；preview高模；ground 192三角面（100–200预算） | O24: art_source/items_weapons/weapons/big_mag/source/wpn_big_mag_source_v001.blend; art_source/items_weapons/weapons/big_mag/source/wpn_big_mag_ground_source_v001.blend | P24: src/world3d/ItemModelFactory3D.gd; src/world3d/GroundLootPickup3D.gd; src/combat3d/WeaponModel3D.gd; art_source/items_weapons/weapons/big_mag/asset_contract.json | Q24: attach_big_mag;肉质弹匣 | R24: =LOWER(TRIM(C24)&"|"&TRIM(D24)&"|"&TRIM(E24)&"|"&TRIM(F24)&"|"&TRIM(H24)&"|"&TRIM(I24)) | S24: =IF(COUNTIF($R$6:$R$41,R24)>1,"重复","唯一") | T24: 8513e3320fad3a4af8ee4562b5149b9a45f0e95d72df06accb96b0b7befe72f5 | U24: Codex | V24: 46309 | W24: 用户提供参考图重建；项目公共色盘 | X24: WPN_肉质弹匣_中文资产管理 | Y24: 2026-10-14 用户参考图制作；Godot物品工厂/拾取实体/配件挂点实测后冻结主轴尺寸，其余轴按图等比。仅Blender原始源；未导出GLB、未导入Godot；运行时仍用现有占位。 双模型源：preview=5856三角；ground=192三角；地面源SHA256=a67664acb24910e970b61d43ed1cf2e3395a876a6896a67853cd5648a19cafff；高模哈希保持；未接入运行时。
A25: WPN-ATT-ATTACH-FAN | B25: 小风扇 | C25: 武器 | D25: attachment | E25: attach_fan | F25: root | H25: 侧面朝右 | I25: default | J25: 装配树/枪身/UI 图标 | K25: 程序占位 | L25: P2 | M25: v001 | N25: 建议 12–24 px | P25: src/base/BlueprintRegistry.gd | R25: =LOWER(TRIM(C25)&"|"&TRIM(D25)&"|"&TRIM(E25)&"|"&TRIM(F25)&"|"&TRIM(H25)&"|"&TRIM(I25)) | S25: =IF(COUNTIF($R$6:$R$41,R25)>1,"重复","唯一") | U25: 待分配 | V25: 46224 | W25: 原创/待确认 | X25: — | Y25: 以挂点部件制作，不烘焙进整枪 2026-08-30 AST-01规范化（原大类：枪械）
A26: WPN-ATT-ATTACH-COPY-STICKER | B26: 复制贴纸 | C26: 武器 | D26: attachment | E26: attach_copy_sticker | F26: root | H26: 侧面朝右 | I26: default | J26: 装配树/枪身/UI 图标 | K26: 程序占位 | L26: P2 | M26: v001 | N26: 建议 12–24 px | P26: src/base/BlueprintRegistry.gd | R26: =LOWER(TRIM(C26)&"|"&TRIM(D26)&"|"&TRIM(E26)&"|"&TRIM(F26)&"|"&TRIM(H26)&"|"&TRIM(I26)) | S26: =IF(COUNTIF($R$6:$R$41,R26)>1,"重复","唯一") | U26: 待分配 | V26: 46224 | W26: 原创/待确认 | X26: — | Y26: 以挂点部件制作，不烘焙进整枪 2026-08-30 AST-01规范化（原大类：枪械）
A27: WPN-GUN-KIT-3D | B27: 枪械3D通用模型套件 | C27: 武器 | D27: gunbody | E27: blueprint_gun_catalog | F27: root_3d | H27: 俯视3D | I27: default | J27: 玩家/靶场/全部副本 | K27: 原型已接入 | L27: P0 | M27: v001 | N27: PackedScene/7枪配置模型 | O27: assets/art/weapons/weapon_3d/wpn_gun_kit_root_top3d_v001.tscn | P27: src/combat3d/WeaponModel3D.gd | Q27: 枪械;7枪身;8弹药;后坐力;枪口 | R27: =LOWER(TRIM(C27)&"|"&TRIM(D27)&"|"&TRIM(E27)&"|"&TRIM(F27)&"|"&TRIM(H27)&"|"&TRIM(I27)) | S27: =IF(COUNTIF($R$6:$R$41,R27)>1,"重复","唯一") | T27: e13801540404433f6fc5f00faa0f523b804d18ec7fa30c0f6c15fab48f1ec4c9 | U27: Codex | V27: 46225 | W27: 原创程序几何 | X27: — | Y27: 真实GPU窗口检查暗室、家具、角色、怪物和战斗；开灯状态复用同一身份，验收图：assets/art/environments/dungeon_3d/env_dungeon_runtime_light_on_preview_top3d_v001.png；WeaponModel3D为换弹唯一计时源；开始/连续进度/完成或取消信号驱动六态覆盖动画与头顶条；56组合共用 2026-08-30 AST-01规范化（原大类：枪械）
A28: WPN-MELEE-BP-GREATBLADE | B28: 巨型工业断刃程序原型 | C28: 武器 | D28: melee | E28: bp_greatblade | F28: root | H28: 俯视3D | I28: default / three_step_combo | J28: 手持/背负/地面/背包图标/表现页 | K28: 程序占位 | L28: P0 | M28: v001 | N28: 程序Mesh；0.82×0.30×2.42m；无碰撞 | O28: assets/art/weapons/melee_3d/wpn_melee_greatblade_root_top3d_v001.tscn | P28: src/combat3d/MeleeWeaponVisual3D.gd; src/player3d/melee/PlayerMeleeCombat3D.gd | Q28: 近战;大型武器;工业断刃;三段连击;greatblade;melee | R28: =LOWER(TRIM(C28)&"|"&TRIM(D28)&"|"&TRIM(E28)&"|"&TRIM(F28)&"|"&TRIM(H28)&"|"&TRIM(I28)) | S28: =IF(COUNTIF($R$6:$R$41,R28)>1,"重复","唯一") | U28: Codex | V28: 46244 | W28: 原创程序原型 | X28: — | Y28: 总长2.42m；双手重型持握；四态动作子状态机；三段池化弧光/命中爆点与专属挥砍/冲击音频已接入；最终美术替换保留握柄原点/local -Z与稳定ID。
A29: WPN-MELEE-BP-WARAXE | B29: 攻城裂甲斧程序原型 | C29: 武器 | D29: melee | E29: bp_waraxe | F29: root | H29: 俯视3D | I29: default / three_step_combo | J29: 手持/背负/地面/背包图标/表现页 | K29: 程序占位 | L29: P0 | M29: v001 | N29: 程序Mesh；1.18×0.34×2.62m；无碰撞 | O29: assets/art/weapons/melee_3d/wpn_melee_waraxe_root_top3d_v001.tscn | P29: src/combat3d/MeleeWeaponVisual3D.gd; src/player3d/melee/PlayerMeleeCombat3D.gd | Q29: 近战;大型武器;攻城斧;三段连击;waraxe;melee | R29: =LOWER(TRIM(C29)&"|"&TRIM(D29)&"|"&TRIM(E29)&"|"&TRIM(F29)&"|"&TRIM(H29)&"|"&TRIM(I29)) | S29: =IF(COUNTIF($R$6:$R$41,R29)>1,"重复","唯一") | U29: Codex | V29: 46244 | W29: 原创程序原型 | X29: — | Y29: 总长2.62m；高伤高击退；四态动作子状态机；第三段最大弧光并降低音高/提高冲击响度；最终美术替换保留握柄原点/local -Z与稳定ID。
A30: WPN-MELEE-BP-BASEBALL-BAT | B30: 废土棒球棍程序原型 | C30: 武器 | D30: melee | E30: bp_baseball_bat | F30: root | H30: 俯视3D | I30: default / three_step_combo | J30: 手持/背负/地面/背包图标/表现页/基地贩卖机 | K30: 程序占位 | L30: P0 | M30: v001 | N30: 程序Mesh；0.28×0.28×1.48m；无碰撞 | O30: assets/art/weapons/melee_3d/wpn_melee_baseball_bat_root_top3d_v001.tscn | P30: src/combat3d/MeleeWeaponVisual3D.gd; src/player3d/melee/PlayerMeleeCombat3D.gd; tests/verification/verify_weapon_attachment_inventory_flow.gd | Q30: 近战;初级武器;棒球棍;三段连击;baseball_bat;melee;基地贩卖机 | R30: =LOWER(TRIM(C30)&"|"&TRIM(D30)&"|"&TRIM(E30)&"|"&TRIM(F30)&"|"&TRIM(H30)&"|"&TRIM(I30)) | S30: =IF(COUNTIF($R$6:$R$41,R30)>1,"重复","唯一") | T30: 700ecf26ca26d653967db40dbe48f8572387ae63b43a1428aa54721c25ca7b0a | U30: Codex | V30: 46244 | W30: 原创程序原型 | X30: — | Y30: 基地45魂初级近战；三段快速挥击、第三段强化击退；复用近战四态、弧光/命中VFX和版本化音频。最终美术替换须保留握柄原点/local -Z与稳定ID。
A31: WPN-GUN-FUTURE-MEGAPHONE-CANNON-3D | B31: 扩音器加农炮 | C31: 武器 | D31: gunbody | E31: future_megaphone_cannon | F31: root | H31: 俯视3D / local -Z 枪口 | I31: default / 标准握把与8类挂点 | J31: 未来枪械池/独立资产 | K31: 已完成 | L31: P2 | M31: v001 | N31: 握把原点；local -Z枪口；3材质；独立GLB/PackedScene | O31: assets/art/weapons/weapon_3d/runtime/megaphone_cannon/wpn_megaphone_cannon_root_top3d_v001.tscn | P31: ../ShellStorm2-backup/2026-10-11_slimming/original_tree/art_source/weapons/weapon_3d/source/megaphone_cannon/wpn_megaphone_cannon_source_v001.blend | Q31: megaphone_cannon; 扩音器加农炮; 未来枪械; 通用挂点; 多巴胺配色 | R31: =LOWER(TRIM(C31)&"|"&TRIM(D31)&"|"&TRIM(E31)&"|"&TRIM(F31)&"|"&TRIM(H31)&"|"&TRIM(I31)) | S31: =IF(COUNTIF($R$6:$R$41,R31)>1,"重复","唯一") | T31: 5af8a086bf2988755cc0e385bb5b6d527e9dbde0d11123c809741d306b38e45f | U31: Codex | V31: 46264 | W31: 用户自制Blender资产 | X31: — | Y31: 暂不绑定现有蓝图ID；已独立导入并统一Grip/Muzzle/Scope/Magazine/Stock/Tactical等节点。 2026-08-30 AST-01规范化（原制作状态：正式美术已入库/待玩法映射） 2026-08-30 AST-02：合法内容更新；文件为Git已跟踪且修改时间不早于原台账日期；验收：verify_weapon_instance_contract_matrix；SHA 6b8f58fe196a→5af8a086bf29。
A32: WPN-GUN-FUTURE-GUITAR-BLASTER-3D | B32: 吉他爆能枪 | C32: 武器 | D32: gunbody | E32: future_guitar_blaster | F32: root | H32: 俯视3D / local -Z 枪口 | I32: default / 标准握把与8类挂点 | J32: 未来枪械池/独立资产 | K32: 已完成 | L32: P2 | M32: v001 | N32: 握把原点；local -Z枪口；3材质；独立GLB/PackedScene | O32: assets/art/weapons/weapon_3d/runtime/guitar_blaster/wpn_guitar_blaster_root_top3d_v001.tscn | P32: ../ShellStorm2-backup/2026-10-11_slimming/original_tree/art_source/weapons/weapon_3d/source/guitar_blaster/wpn_guitar_blaster_source_v001.blend | Q32: guitar_blaster; 吉他爆能枪; 未来枪械; 通用挂点; 多巴胺配色 | R32: =LOWER(TRIM(C32)&"|"&TRIM(D32)&"|"&TRIM(E32)&"|"&TRIM(F32)&"|"&TRIM(H32)&"|"&TRIM(I32)) | S32: =IF(COUNTIF($R$6:$R$41,R32)>1,"重复","唯一") | T32: 7611a99cf53a4a0fd80404be89c450351994bafd161824a0b92d05a729ec05f3 | U32: Codex | V32: 46264 | W32: 用户自制Blender资产 | X32: — | Y32: 暂不绑定现有蓝图ID；已独立导入并统一Grip/Muzzle/Scope/Magazine/Stock/Tactical等节点。 2026-08-30 AST-01规范化（原制作状态：正式美术已入库/待玩法映射） 2026-08-30 AST-02：合法内容更新；文件为Git已跟踪且修改时间不早于原台账日期；验收：verify_weapon_instance_contract_matrix；SHA b82adc9dde68→7611a99cf53a。
A33: WPN-GUN-FUTURE-SPATULA-RIFLE-3D | B33: 锅铲步枪 | C33: 武器 | D33: gunbody | E33: future_spatula_rifle | F33: root | H33: 俯视3D / local -Z 枪口 | I33: default / 标准握把与8类挂点 | J33: 未来枪械池/独立资产 | K33: 已完成 | L33: P2 | M33: v001 | N33: 握把原点；local -Z枪口；3材质；独立GLB/PackedScene | O33: assets/art/weapons/weapon_3d/runtime/spatula_rifle/wpn_spatula_rifle_root_top3d_v001.tscn | P33: ../ShellStorm2-backup/2026-10-11_slimming/original_tree/art_source/weapons/weapon_3d/source/spatula_rifle/wpn_spatula_rifle_source_v001.blend | Q33: spatula_rifle; 锅铲步枪; 未来枪械; 通用挂点; 多巴胺配色 | R33: =LOWER(TRIM(C33)&"|"&TRIM(D33)&"|"&TRIM(E33)&"|"&TRIM(F33)&"|"&TRIM(H33)&"|"&TRIM(I33)) | S33: =IF(COUNTIF($R$6:$R$41,R33)>1,"重复","唯一") | T33: 04a9659dcef16faed7af37c04dbe4f2bd7322b87992d9f269f503d87ea2f9cca | U33: Codex | V33: 46264 | W33: 用户自制Blender资产 | X33: — | Y33: 暂不绑定现有蓝图ID；已独立导入并统一Grip/Muzzle/Scope/Magazine/Stock/Tactical等节点。 2026-08-30 AST-01规范化（原制作状态：正式美术已入库/待玩法映射） 2026-08-30 AST-02：合法内容更新；文件为Git已跟踪且修改时间不早于原台账日期；验收：verify_weapon_instance_contract_matrix；SHA 8af70da0fa51→04a9659dcef1。
A34: WPN-GUN-FUTURE-FRYING-PAN-CANNON-3D | B34: 平底锅加农炮 | C34: 武器 | D34: gunbody | E34: future_frying_pan_cannon | F34: root | H34: 俯视3D / local -Z 枪口 | I34: default / 标准握把与8类挂点 | J34: 未来枪械池/独立资产 | K34: 已完成 | L34: P2 | M34: v001 | N34: 握把原点；local -Z枪口；3材质；独立GLB/PackedScene | O34: assets/art/weapons/weapon_3d/runtime/frying_pan_cannon/wpn_frying_pan_cannon_root_top3d_v001.tscn | P34: ../ShellStorm2-backup/2026-10-11_slimming/original_tree/art_source/weapons/weapon_3d/source/frying_pan_cannon/wpn_frying_pan_cannon_source_v001.blend | Q34: frying_pan_cannon; 平底锅加农炮; 未来枪械; 通用挂点; 多巴胺配色 | R34: =LOWER(TRIM(C34)&"|"&TRIM(D34)&"|"&TRIM(E34)&"|"&TRIM(F34)&"|"&TRIM(H34)&"|"&TRIM(I34)) | S34: =IF(COUNTIF($R$6:$R$41,R34)>1,"重复","唯一") | T34: f73360d92e0188808efdd39aa652067dec9a7fd5fd1fef243879b6e28b61c465 | U34: Codex | V34: 46264 | W34: 用户自制Blender资产 | X34: — | Y34: 暂不绑定现有蓝图ID；已独立导入并统一Grip/Muzzle/Scope/Magazine/Stock/Tactical等节点。 2026-08-30 AST-01规范化（原制作状态：正式美术已入库/待玩法映射） 2026-08-30 AST-02：合法内容更新；文件为Git已跟踪且修改时间不早于原台账日期；验收：verify_weapon_instance_contract_matrix；SHA 074036c4f15d→f73360d92e01。
A35: WPN-GUN-FUTURE-SCOPE-CANNON-3D | B35: 瞄准镜加农炮 | C35: 武器 | D35: gunbody | E35: future_scope_cannon | F35: root | H35: 俯视3D / local -Z 枪口 | I35: default / 标准握把与8类挂点 | J35: 未来枪械池/独立资产 | K35: 已完成 | L35: P2 | M35: v001 | N35: 握把原点；local -Z枪口；3材质；独立GLB/PackedScene | O35: assets/art/weapons/weapon_3d/runtime/scope_cannon/wpn_scope_cannon_root_top3d_v001.tscn | P35: ../ShellStorm2-backup/2026-10-11_slimming/original_tree/art_source/weapons/weapon_3d/source/scope_cannon/wpn_scope_cannon_source_v001.blend | Q35: scope_cannon; 瞄准镜加农炮; 未来枪械; 通用挂点; 多巴胺配色 | R35: =LOWER(TRIM(C35)&"|"&TRIM(D35)&"|"&TRIM(E35)&"|"&TRIM(F35)&"|"&TRIM(H35)&"|"&TRIM(I35)) | S35: =IF(COUNTIF($R$6:$R$41,R35)>1,"重复","唯一") | T35: ad9e3e21a430c104cc44345297a05b7a4ea61a02bb1d605ef79c4b8d1c49de35 | U35: Codex | V35: 46264 | W35: 用户自制Blender资产 | X35: — | Y35: 暂不绑定现有蓝图ID；已独立导入并统一Grip/Muzzle/Scope/Magazine/Stock/Tactical等节点。 2026-08-30 AST-01规范化（原制作状态：正式美术已入库/待玩法映射） 2026-08-30 AST-02：合法内容更新；文件为Git已跟踪且修改时间不早于原台账日期；验收：verify_weapon_instance_contract_matrix；SHA ba54d1e1126c→ad9e3e21a430。
A36: WPN-GUN-FUTURE-POPCORN-BLASTER-3D | B36: 爆米花爆能枪 | C36: 武器 | D36: gunbody | E36: future_popcorn_blaster | F36: root | H36: 俯视3D / local -Z 枪口 | I36: default / 标准握把与8类挂点 | J36: 未来枪械池/独立资产 | K36: 已完成 | L36: P2 | M36: v001 | N36: 握把原点；local -Z枪口；3材质；独立GLB/PackedScene | O36: assets/art/weapons/weapon_3d/runtime/popcorn_blaster/wpn_popcorn_blaster_root_top3d_v001.tscn | P36: ../ShellStorm2-backup/2026-10-11_slimming/original_tree/art_source/weapons/weapon_3d/source/popcorn_blaster/wpn_popcorn_blaster_source_v001.blend | Q36: popcorn_blaster; 爆米花爆能枪; 未来枪械; 通用挂点; 多巴胺配色 | R36: =LOWER(TRIM(C36)&"|"&TRIM(D36)&"|"&TRIM(E36)&"|"&TRIM(F36)&"|"&TRIM(H36)&"|"&TRIM(I36)) | S36: =IF(COUNTIF($R$6:$R$41,R36)>1,"重复","唯一") | T36: 01c3204ae0d66aa0e0bf28bf2643c327a7550ff1c024f36114f45fb9010de7a8 | U36: Codex | V36: 46264 | W36: 用户自制Blender资产 | X36: — | Y36: 暂不绑定现有蓝图ID；已独立导入并统一Grip/Muzzle/Scope/Magazine/Stock/Tactical等节点。 2026-08-30 AST-01规范化（原制作状态：正式美术已入库/待玩法映射） 2026-08-30 AST-02：合法内容更新；文件为Git已跟踪且修改时间不早于原台账日期；验收：verify_weapon_instance_contract_matrix；SHA c77c70255421→01c3204ae0d6。
A37: WPN-GUN-FUTURE-SODA-STRAW-BLASTER-3D | B37: 饮料管爆能枪 | C37: 武器 | D37: gunbody | E37: future_soda_straw_blaster | F37: root | H37: 俯视3D / local -Z 枪口 | I37: default / 标准握把与8类挂点 | J37: 未来枪械池/独立资产 | K37: 已完成 | L37: P2 | M37: v001 | N37: 握把原点；local -Z枪口；3材质；独立GLB/PackedScene | O37: assets/art/weapons/weapon_3d/runtime/soda_straw_blaster/wpn_soda_straw_blaster_root_top3d_v001.tscn | P37: ../ShellStorm2-backup/2026-10-11_slimming/original_tree/art_source/weapons/weapon_3d/source/soda_straw_blaster/wpn_soda_straw_blaster_source_v001.blend | Q37: soda_straw_blaster; 饮料管爆能枪; 未来枪械; 通用挂点; 多巴胺配色 | R37: =LOWER(TRIM(C37)&"|"&TRIM(D37)&"|"&TRIM(E37)&"|"&TRIM(F37)&"|"&TRIM(H37)&"|"&TRIM(I37)) | S37: =IF(COUNTIF($R$6:$R$41,R37)>1,"重复","唯一") | T37: bc0fa22a6e7c32ed741079af21a73152e3404b7f4fd236cdb38e2a3ab0e477fa | U37: Codex | V37: 46264 | W37: 用户自制Blender资产 | X37: — | Y37: 暂不绑定现有蓝图ID；已独立导入并统一Grip/Muzzle/Scope/Magazine/Stock/Tactical等节点。 2026-08-30 AST-01规范化（原制作状态：正式美术已入库/待玩法映射） 2026-08-30 AST-02：合法内容更新；文件为Git已跟踪且修改时间不早于原台账日期；验收：verify_weapon_instance_contract_matrix；SHA 2eb1414de901→bc0fa22a6e7c。
A38: WPN-GUN-FUTURE-CROCODILE-CANNON-3D | B38: 鳄鱼加农炮 | C38: 武器 | D38: gunbody | E38: future_crocodile_cannon | F38: root | H38: 俯视3D / local -Z 枪口 | I38: default / 标准握把与8类挂点 | J38: 未来枪械池/独立资产 | K38: 已完成 | L38: P2 | M38: v001 | N38: 握把原点；local -Z枪口；3材质；独立GLB/PackedScene | O38: assets/art/weapons/weapon_3d/runtime/crocodile_cannon/wpn_crocodile_cannon_root_top3d_v001.tscn | P38: ../ShellStorm2-backup/2026-10-11_slimming/original_tree/art_source/weapons/weapon_3d/source/crocodile_cannon/wpn_crocodile_cannon_source_v001.blend | Q38: crocodile_cannon; 鳄鱼加农炮; 未来枪械; 通用挂点; 多巴胺配色 | R38: =LOWER(TRIM(C38)&"|"&TRIM(D38)&"|"&TRIM(E38)&"|"&TRIM(F38)&"|"&TRIM(H38)&"|"&TRIM(I38)) | S38: =IF(COUNTIF($R$6:$R$41,R38)>1,"重复","唯一") | T38: 01d4ecf005d76562942e584db25fa586a9bfb9fa2533ea7290fbfdd65bc1f749 | U38: Codex | V38: 46264 | W38: 用户自制Blender资产 | X38: — | Y38: 暂不绑定现有蓝图ID；已独立导入并统一Grip/Muzzle/Scope/Magazine/Stock/Tactical等节点。 2026-08-30 AST-01规范化（原制作状态：正式美术已入库/待玩法映射） 2026-08-30 AST-02：合法内容更新；文件为Git已跟踪且修改时间不早于原台账日期；验收：verify_weapon_instance_contract_matrix；SHA 3e46907368f7→01d4ecf005d7。
A39: WPN-GUN-FUTURE-CAMERA-BLASTER-3D | B39: 相机爆能枪 | C39: 武器 | D39: gunbody | E39: future_camera_blaster | F39: root | H39: 俯视3D / local -Z 枪口 | I39: default / 标准握把与8类挂点 | J39: 未来枪械池/独立资产 | K39: 已完成 | L39: P2 | M39: v001 | N39: 握把原点；local -Z枪口；3材质；独立GLB/PackedScene | O39: assets/art/weapons/weapon_3d/runtime/camera_blaster/wpn_camera_blaster_root_top3d_v001.tscn | P39: ../ShellStorm2-backup/2026-10-11_slimming/original_tree/art_source/weapons/weapon_3d/source/camera_blaster/wpn_camera_blaster_source_v001.blend | Q39: camera_blaster; 相机爆能枪; 未来枪械; 通用挂点; 多巴胺配色 | R39: =LOWER(TRIM(C39)&"|"&TRIM(D39)&"|"&TRIM(E39)&"|"&TRIM(F39)&"|"&TRIM(H39)&"|"&TRIM(I39)) | S39: =IF(COUNTIF($R$6:$R$41,R39)>1,"重复","唯一") | T39: 07ec25c941bb19732944bafdaae85db88ea93b4a870606b3202669bee8313932 | U39: Codex | V39: 46264 | W39: 用户自制Blender资产 | X39: — | Y39: 暂不绑定现有蓝图ID；已独立导入并统一Grip/Muzzle/Scope/Magazine/Stock/Tactical等节点。 2026-08-30 AST-01规范化（原制作状态：正式美术已入库/待玩法映射） 2026-08-30 AST-02：合法内容更新；文件为Git已跟踪且修改时间不早于原台账日期；验收：verify_weapon_instance_contract_matrix；SHA 3d49c92df382→07ec25c941bb。
A40: WPN-GUN-FUTURE-TISSUE-BOX-CANNON-3D | B40: 纸巾盒加农炮 | C40: 武器 | D40: gunbody | E40: future_tissue_box_cannon | F40: root | H40: 俯视3D / local -Z 枪口 | I40: default / 标准握把与8类挂点 | J40: 未来枪械池/独立资产 | K40: 已完成 | L40: P2 | M40: v001 | N40: 握把原点；local -Z枪口；3材质；独立GLB/PackedScene | O40: assets/art/weapons/weapon_3d/runtime/tissue_box_cannon/wpn_tissue_box_cannon_root_top3d_v001.tscn | P40: ../ShellStorm2-backup/2026-10-11_slimming/original_tree/art_source/weapons/weapon_3d/source/tissue_box_cannon/wpn_tissue_box_cannon_source_v001.blend | Q40: tissue_box_cannon; 纸巾盒加农炮; 未来枪械; 通用挂点; 多巴胺配色 | R40: =LOWER(TRIM(C40)&"|"&TRIM(D40)&"|"&TRIM(E40)&"|"&TRIM(F40)&"|"&TRIM(H40)&"|"&TRIM(I40)) | S40: =IF(COUNTIF($R$6:$R$41,R40)>1,"重复","唯一") | T40: 6c277b10c52f4dde4790e91c760a6f981fa38af9b19bf67fdf584785659a618e | U40: Codex | V40: 46264 | W40: 用户自制Blender资产 | X40: — | Y40: 暂不绑定现有蓝图ID；已独立导入并统一Grip/Muzzle/Scope/Magazine/Stock/Tactical等节点。 2026-08-30 AST-01规范化（原制作状态：正式美术已入库/待玩法映射） 2026-08-30 AST-02：合法内容更新；文件为Git已跟踪且修改时间不早于原台账日期；验收：verify_weapon_instance_contract_matrix；SHA a67bef331339→6c277b10c52f。
A41: WPN-GUN-FUTURE-FAN-BLASTER-3D | B41: 风扇爆能枪 | C41: 武器 | D41: gunbody | E41: future_fan_blaster | F41: root | H41: 俯视3D / local -Z 枪口 | I41: default / 标准握把与8类挂点 | J41: 未来枪械池/独立资产 | K41: 已完成 | L41: P2 | M41: v001 | N41: 握把原点；local -Z枪口；3材质；独立GLB/PackedScene | O41: assets/art/weapons/weapon_3d/runtime/fan_blaster/wpn_fan_blaster_root_top3d_v001.tscn | P41: ../ShellStorm2-backup/2026-10-11_slimming/original_tree/art_source/weapons/weapon_3d/source/fan_blaster/wpn_fan_blaster_source_v001.blend | Q41: fan_blaster; 风扇爆能枪; 未来枪械; 通用挂点; 多巴胺配色 | R41: =LOWER(TRIM(C41)&"|"&TRIM(D41)&"|"&TRIM(E41)&"|"&TRIM(F41)&"|"&TRIM(H41)&"|"&TRIM(I41)) | S41: =IF(COUNTIF($R$6:$R$41,R41)>1,"重复","唯一") | T41: 5b740e26cc2b5e2b4cbdd1334b371224cba40165048a6747fad4e5962e53c8c7 | U41: Codex | V41: 46264 | W41: 用户自制Blender资产 | X41: — | Y41: 暂不绑定现有蓝图ID；已独立导入并统一Grip/Muzzle/Scope/Magazine/Stock/Tactical等节点。 2026-08-30 AST-01规范化（原制作状态：正式美术已入库/待玩法映射） 2026-08-30 AST-02：合法内容更新；文件为Git已跟踪且修改时间不早于原台账日期；验收：verify_weapon_instance_contract_matrix；SHA bde9a97ec8a3→5b740e26cc2b。

Sheet 3D-武器
A1: ShellStorm2 · 武器 3D Prefab
A2: 枪械、近战武器与武器装配根；本次扫描 22 个独立Prefab。
A4: AssetID | B4: 中文名 | C4: Prefab路径 | D4: GLB模型路径 | E4: Blender源文件 | F4: 功能说明 | G4: 功能脚本路径 | H4: 碰撞开关 | I4: 碰撞归属 | J4: 碰撞方式 | K4: 标准尺寸 | L4: 原点与朝向 | M4: 使用位置 | N4: 制作状态 | O4: 版本 | P4: 备注
A5: WPN-MELEE-BP-BASEBALL-BAT | B5: 废土棒球棍程序原型 | C5: assets/art/weapons/melee_3d/wpn_melee_baseball_bat_root_top3d_v001.tscn | F5: 武器3D表现Prefab；由武器系统装配 | G5: src/combat3d/MeleeWeaponVisual3D.gd | H5: 无 | I5: 无 | J5: 无 | K5: 程序Mesh；0.28×0.28×1.48m；无碰撞 | L5: 未声明 | M5: 手持/背负/地面/背包图标/表现页/基地贩卖机 | N5: 程序占位 | O5: v001 | P5: 根节点=BaseballBatRootTop3D(Node3D)
A6: WPN-MELEE-BP-GREATBLADE | B6: 巨型工业断刃程序原型 | C6: assets/art/weapons/melee_3d/wpn_melee_greatblade_root_top3d_v001.tscn | F6: 武器3D表现Prefab；由武器系统装配 | G6: src/combat3d/MeleeWeaponVisual3D.gd | H6: 无 | I6: 无 | J6: 无 | K6: 程序Mesh；0.82×0.30×2.42m；无碰撞 | L6: 未声明 | M6: 手持/背负/地面/背包图标/表现页 | N6: 程序占位 | O6: v001 | P6: 根节点=GreatbladeVisual3D(Node3D)
A7: WPN-MELEE-BP-WARAXE | B7: 攻城裂甲斧程序原型 | C7: assets/art/weapons/melee_3d/wpn_melee_waraxe_root_top3d_v001.tscn | F7: 武器3D表现Prefab；由武器系统装配 | G7: src/combat3d/MeleeWeaponVisual3D.gd | H7: 无 | I7: 无 | J7: 无 | K7: 程序Mesh；1.18×0.34×2.62m；无碰撞 | L7: 未声明 | M7: 手持/背负/地面/背包图标/表现页 | N7: 程序占位 | O7: v001 | P7: 根节点=WaraxeVisual3D(Node3D)
A8: WPN-GUN-BP-RIFLE | B8: 步枪 / 扫帚步枪造型 | C8: assets/art/weapons/weapon_3d/runtime/broom_rifle/wpn_broom_rifle_root_top3d_v001.tscn | D8: assets/art/weapons/weapon_3d/components/broom_rifle/wpn_broom_rifle_visual_top3d_v003.glb | E8: art_source/weapons/weapon_3d/source/broom_rifle/wpn_broom_rifle_source_v003.blend | F8: 武器3D表现Prefab；由武器系统装配 | G8: src/player3d/WeaponModel3D.gd | H8: 无 | I8: 无 | J8: 无 | K8: 握把原点；local -Z枪口；3材质；独立GLB/PackedScene | L8: -Z | M8: 手持/背负/地面/UI 共用独立PackedScene | N8: 正式美术已接入 | O8: v001 | P8: 根节点=扫帚步枪(Node3D)
A9: WPN-GUN-FUTURE-CAMERA-BLASTER-3D | B9: 相机爆能枪 | C9: assets/art/weapons/weapon_3d/runtime/camera_blaster/wpn_camera_blaster_root_top3d_v001.tscn | D9: assets/art/weapons/weapon_3d/components/camera_blaster/wpn_camera_blaster_visual_top3d_v003.glb | E9: art_source/weapons/weapon_3d/source/camera_blaster/wpn_camera_blaster_source_v003.blend | F9: 武器3D表现Prefab；由武器系统装配 | G9: src/player3d/WeaponModel3D.gd | H9: 无 | I9: 无 | J9: 无 | K9: 握把原点；local -Z枪口；3材质；独立GLB/PackedScene | L9: -Z | M9: 未来枪械池/独立资产 | N9: 正式美术已入库/待玩法映射 | O9: v001 | P9: 根节点=相机爆能枪(Node3D)
A10: WPN-GUN-BP-SNIPER | B10: 弹弓狙击 / 糖果狙击枪造型 | C10: assets/art/weapons/weapon_3d/runtime/candy_sniper/wpn_candy_sniper_root_top3d_v001.tscn | D10: assets/art/weapons/weapon_3d/components/candy_sniper/wpn_candy_sniper_visual_top3d_v003.glb | E10: art_source/weapons/weapon_3d/source/candy_sniper/wpn_candy_sniper_source_v003.blend | F10: 武器3D表现Prefab；由武器系统装配 | G10: src/player3d/WeaponModel3D.gd | H10: 无 | I10: 无 | J10: 无 | K10: 握把原点；local -Z枪口；3材质；独立GLB/PackedScene | L10: -Z | M10: 手持/背负/地面/UI 共用独立PackedScene | N10: 正式美术已接入 | O10: v001 | P10: 根节点=糖果狙击枪(Node3D)
A11: WPN-GUN-FUTURE-CROCODILE-CANNON-3D | B11: 鳄鱼加农炮 | C11: assets/art/weapons/weapon_3d/runtime/crocodile_cannon/wpn_crocodile_cannon_root_top3d_v001.tscn | D11: assets/art/weapons/weapon_3d/components/crocodile_cannon/wpn_crocodile_cannon_visual_top3d_v003.glb | E11: art_source/weapons/weapon_3d/source/crocodile_cannon/wpn_crocodile_cannon_source_v003.blend | F11: 武器3D表现Prefab；由武器系统装配 | G11: src/player3d/WeaponModel3D.gd | H11: 无 | I11: 无 | J11: 无 | K11: 握把原点；local -Z枪口；3材质；独立GLB/PackedScene | L11: -Z | M11: 未来枪械池/独立资产 | N11: 正式美术已入库/待玩法映射 | O11: v001 | P11: 根节点=鳄鱼加农炮(Node3D)
A12: WPN-GUN-BP-SHOTGUN | B12: 散射喷壶 / 双管炮造型 | C12: assets/art/weapons/weapon_3d/runtime/double_barrel_cannon/wpn_double_barrel_cannon_root_top3d_v001.tscn | D12: assets/art/weapons/weapon_3d/components/double_barrel_cannon/wpn_double_barrel_cannon_visual_top3d_v003.glb | E12: art_source/weapons/weapon_3d/source/double_barrel_cannon/wpn_double_barrel_cannon_source_v003.blend | F12: 武器3D表现Prefab；由武器系统装配 | G12: src/player3d/WeaponModel3D.gd | H12: 无 | I12: 无 | J12: 无 | K12: 握把原点；local -Z枪口；3材质；独立GLB/PackedScene | L12: -Z | M12: 手持/背负/地面/UI 共用独立PackedScene | N12: 正式美术已接入 | O12: v001 | P12: 根节点=双管炮(Node3D)
A13: WPN-GUN-FUTURE-FAN-BLASTER-3D | B13: 风扇爆能枪 | C13: assets/art/weapons/weapon_3d/runtime/fan_blaster/wpn_fan_blaster_root_top3d_v001.tscn | D13: assets/art/weapons/weapon_3d/components/fan_blaster/wpn_fan_blaster_visual_top3d_v003.glb | E13: art_source/weapons/weapon_3d/source/fan_blaster/wpn_fan_blaster_source_v003.blend | F13: 武器3D表现Prefab；由武器系统装配 | G13: src/player3d/WeaponModel3D.gd | H13: 无 | I13: 无 | J13: 无 | K13: 握把原点；local -Z枪口；3材质；独立GLB/PackedScene | L13: -Z | M13: 未来枪械池/独立资产 | N13: 正式美术已入库/待玩法映射 | O13: v001 | P13: 根节点=风扇爆能枪(Node3D)
A14: WPN-GUN-FUTURE-FRYING-PAN-CANNON-3D | B14: 平底锅加农炮 | C14: assets/art/weapons/weapon_3d/runtime/frying_pan_cannon/wpn_frying_pan_cannon_root_top3d_v001.tscn | D14: assets/art/weapons/weapon_3d/components/frying_pan_cannon/wpn_frying_pan_cannon_visual_top3d_v003.glb | E14: art_source/weapons/weapon_3d/source/frying_pan_cannon/wpn_frying_pan_cannon_source_v003.blend | F14: 武器3D表现Prefab；由武器系统装配 | G14: src/player3d/WeaponModel3D.gd | H14: 无 | I14: 无 | J14: 无 | K14: 握把原点；local -Z枪口；3材质；独立GLB/PackedScene | L14: -Z | M14: 未来枪械池/独立资产 | N14: 正式美术已入库/待玩法映射 | O14: v001 | P14: 根节点=平底锅加农炮(Node3D)
A15: WPN-GUN-FUTURE-GUITAR-BLASTER-3D | B15: 吉他爆能枪 | C15: assets/art/weapons/weapon_3d/runtime/guitar_blaster/wpn_guitar_blaster_root_top3d_v001.tscn | D15: assets/art/weapons/weapon_3d/components/guitar_blaster/wpn_guitar_blaster_visual_top3d_v003.glb | E15: art_source/weapons/weapon_3d/source/guitar_blaster/wpn_guitar_blaster_source_v003.blend | F15: 武器3D表现Prefab；由武器系统装配 | G15: src/player3d/WeaponModel3D.gd | H15: 无 | I15: 无 | J15: 无 | K15: 握把原点；local -Z枪口；3材质；独立GLB/PackedScene | L15: -Z | M15: 未来枪械池/独立资产 | N15: 正式美术已入库/待玩法映射 | O15: v001 | P15: 根节点=吉他爆能枪(Node3D)
A16: WPN-GUN-BP-CHARGE | B16: 蓄力萝卜炮 / 口香糖机造型 | C16: assets/art/weapons/weapon_3d/runtime/gumball_cannon/wpn_gumball_cannon_root_top3d_v001.tscn | D16: assets/art/weapons/weapon_3d/components/gumball_cannon/wpn_gumball_cannon_visual_top3d_v003.glb | E16: art_source/weapons/weapon_3d/source/gumball_cannon/wpn_gumball_cannon_source_v003.blend | F16: 武器3D表现Prefab；由武器系统装配 | G16: src/player3d/WeaponModel3D.gd | H16: 无 | I16: 无 | J16: 无 | K16: 握把原点；local -Z枪口；3材质；独立GLB/PackedScene | L16: -Z | M16: 手持/背负/地面/UI 共用独立PackedScene | N16: 正式美术已接入 | O16: v001 | P16: 根节点=口香糖机加农炮(Node3D)
A17: WPN-GUN-BP-PISTOL | B17: 豌豆手枪 / 吹风机造型 | C17: assets/art/weapons/weapon_3d/runtime/hair_dryer/wpn_hair_dryer_root_top3d_v001.tscn | D17: assets/art/weapons/weapon_3d/components/hair_dryer/wpn_hair_dryer_visual_top3d_v003.glb | E17: art_source/weapons/weapon_3d/source/hair_dryer/wpn_hair_dryer_source_v003.blend | F17: 武器3D表现Prefab；由武器系统装配 | G17: src/combat3d/WeaponModel3D.gd | H17: 无 | I17: 无 | J17: 无 | K17: GripSocket根原点；可见握把中心校正到根；local -Z枪口；3材质；独立GLB/PackedScene | L17: -Z | M17: 手持/背负/地面/UI 共用独立PackedScene | N17: 正式美术已接入 | O17: v001 | P17: 根节点=吹风机(Node3D)；VisualRoot/全部非Grip挂点统一偏移(0,-0.122838,-0.168785)；GripSocket=手掌球中心；待机/开火枪口轴与真实弹道0度差
A18: WPN-GUN-FUTURE-MEGAPHONE-CANNON-3D | B18: 扩音器加农炮 | C18: assets/art/weapons/weapon_3d/runtime/megaphone_cannon/wpn_megaphone_cannon_root_top3d_v001.tscn | D18: assets/art/weapons/weapon_3d/components/megaphone_cannon/wpn_megaphone_cannon_visual_top3d_v003.glb | E18: art_source/weapons/weapon_3d/source/megaphone_cannon/wpn_megaphone_cannon_source_v003.blend | F18: 武器3D表现Prefab；由武器系统装配 | G18: src/player3d/WeaponModel3D.gd | H18: 无 | I18: 无 | J18: 无 | K18: 握把原点；local -Z枪口；3材质；独立GLB/PackedScene | L18: -Z | M18: 未来枪械池/独立资产 | N18: 正式美术已入库/待玩法映射 | O18: v001 | P18: 根节点=扩音器加农炮(Node3D)
A19: WPN-GUN-FUTURE-POPCORN-BLASTER-3D | B19: 爆米花爆能枪 | C19: assets/art/weapons/weapon_3d/runtime/popcorn_blaster/wpn_popcorn_blaster_root_top3d_v001.tscn | D19: assets/art/weapons/weapon_3d/components/popcorn_blaster/wpn_popcorn_blaster_visual_top3d_v003.glb | E19: art_source/weapons/weapon_3d/source/popcorn_blaster/wpn_popcorn_blaster_source_v003.blend | F19: 武器3D表现Prefab；由武器系统装配 | G19: src/player3d/WeaponModel3D.gd | H19: 无 | I19: 无 | J19: 无 | K19: 握把原点；local -Z枪口；3材质；独立GLB/PackedScene | L19: -Z | M19: 未来枪械池/独立资产 | N19: 正式美术已入库/待玩法映射 | O19: v001 | P19: 根节点=爆米花爆能枪(Node3D)
... A25: WPN-GUN-BP-MACHINEGUN | B25: 蜂窝机枪 / 水箱爆能枪造型 | C25: assets/art/weapons/weapon_3d/runtime/water_tank_blaster/wpn_water_tank_blaster_root_top3d.tscn | D25: assets/art/weapons/weapon_3d/components/water_tank_blaster/wpn_water_tank_blaster_visual_top3d_v003.glb | E25: art_source/weapons/weapon_3d/source/water_tank_blaster/wpn_water_tank_blaster_source_v003.blend | F25: 武器3D表现Prefab；由武器系统装配 | G25: src/player3d/WeaponModel3D.gd | H25: 无 | I25: 无 | J25: 无 | K25: 握把原点；local -Z枪口；3材质；独立GLB/PackedScene | L25: -Z | M25: 手持/背负/地面/UI 共用独立PackedScene | N25: 正式美术已接入 | O25: v001 | P25: 根节点=水箱爆能枪(Node3D)
A26: WPN-GUN-KIT-3D | B26: 枪械3D通用模型套件 | C26: assets/art/weapons/weapon_3d/wpn_gun_kit_root_top3d_v001.tscn | F26: 武器3D表现Prefab；由武器系统装配 | G26: src/combat3d/WeaponModel3D.gd | H26: 无 | I26: 无 | J26: 无 | K26: PackedScene/7枪配置模型 | L26: 未声明 | M26: 玩家/靶场/全部副本 | N26: 原型已接入 | O26: v001 | P26: 根节点=WeaponModel3D(Node3D)

Sheet 域变更日志
A1: 武器账本变更日志
A3: 只记录本账本的域内变更；跨域与全局变更记录在主账本《版本记录》
A5: 台账版本 | B5: 日期 | C5: 变更类型 | D5: 范围 | E5: 说明 | F5: 兼容性 | G5: 负责人
A6: v0.1.0 | B6: 2026-09-18 | C6: 分账本建立 | D6: 武器 | E6: 由单体账本《ShellStorm2_美术资产台账_v001.xlsx》按大类拆分而来；本账本接管大类=武器，条目内容逐格不变，仅登记位置变化。 | F6: 资产条目、AssetID、路径与哈希全部不变；只换文件。旧引用可用 scripts/ledger_registry.py 解析。 | G6: 摩斯拉
A7: v0.1.1 | B7: 2026-10-14 | C7: 参考图8件道具：Blender原始源 | D7: 道具与武器原始源 | E7: WPN-ATT-ATTACH-BIG-MAG,WPN-BUL-MOD-BULLET-STANDARD,WPN-ATT-ATTACH-RUBBER-STOCK,WPN-ATT-ATTACH-SCOPE,WPN-ATT-ATTACH-TRIPLE-MUZZLE | F7: 实测尺寸/场景四材质/源已完成；未运行时接入 | G7: Codex
A8: v0.1.100 | B8: 2026-10-14 | C8: 物品道具双模型源 | D8: preview / ground | E8: 现有高模保留；地面100–200三角面 | F8: 源已完成；运行时用途选择未接入 | G8: Codex

Sheet 背包物品调用索引
A1: 武器账本 · 背包物品调用索引
A2: 成品武器、子弹模块、通用弹药、枪械配件唯一归属本账本；内容ID导航页，不新增资产主表行。
A4: 内容ID | B4: 名称 | C4: 种类 | D4: 子类 | E4: 唯一登记账本 | F4: 内容定义入口 | G4: 内容数据库定位 | H4: 怪物掉落来源 | I4: 池声明入口 | J4: 背包接收入口 | K4: 使用/装配入口 | L4: 模型调用入口 | M4: 当前模型表现 | N4: 关联AssetID（引用） | O4: 资产登记定位（引用） | P4: 功能模块 | Q4: 审查备注
A5: weapon_pistol | B5: 豌豆手枪 | C5: weapon | D5: gun_body | E5: assets/registry/ledgers/ShellStorm2_武器账本_v001.xlsx | F5: src/base/ItemRegistry.gd#L205 | G5: docs/v0.1/data/ShellStorm2_游戏内容数据库_v010.xlsx#掉落物品!A33 | H5: docs/v0.1/data/怪物掉落表_地图x怪物.csv#CSV行2 / melee_chaser | I5: src/base/ItemRegistry.gd#L205 / loot_floor_1_2, scavenge_floor_1, scavenge_floor_2, combat_floor_1, combat_floor_2 | J5: src/game/InventoryModule.gd#add_item | K5: src/world3d/Dungeon3D.gd#_equip_weapon_from_inventory | L5: src/world3d/ItemModelFactory3D.gd#create_model / get_model_kind | M5: weapon；真实武器快照重建 | N5: WPN-GUN-BP-PISTOL | O5: assets/registry/ledgers/ShellStorm2_武器账本_v001.xlsx#资产主表!A6 | P5: WORLD-LOOT / REWARD-SERVICE / INVENTORY-SLOTS / WEAPON-OWNERSHIP | Q5: 已注册；本表只导航，堆叠/数值/掉落概率由原定义拥有
A6: weapon_shotgun | B6: 散射喷壶 | C6: weapon | D6: gun_body | E6: assets/registry/ledgers/ShellStorm2_武器账本_v001.xlsx | F6: src/base/ItemRegistry.gd#L224 | G6: docs/v0.1/data/ShellStorm2_游戏内容数据库_v010.xlsx#掉落物品!A35 | H6: 未在当前CSV列出；池来源见下一列 | I6: src/base/ItemRegistry.gd#L224 / spawn_starter, loot_floor_1_2, scavenge_floor_1, scavenge_floor_2, combat_floor_1, combat_floor_2 | J6: src/game/InventoryModule.gd#add_item | K6: src/world3d/Dungeon3D.gd#_equip_weapon_from_inventory | L6: src/world3d/ItemModelFactory3D.gd#create_model / get_model_kind | M6: weapon；真实武器快照重建 | N6: WPN-GUN-BP-SHOTGUN | O6: assets/registry/ledgers/ShellStorm2_武器账本_v001.xlsx#资产主表!A7 | P6: WORLD-LOOT / REWARD-SERVICE / INVENTORY-SLOTS / WEAPON-OWNERSHIP | Q6: 已注册；本表只导航，堆叠/数值/掉落概率由原定义拥有；远征01作者掉落表未列此项（不可视为无其他产出）
A7: weapon_rifle | B7: 步枪 | C7: weapon | D7: gun_body | E7: assets/registry/ledgers/ShellStorm2_武器账本_v001.xlsx | F7: src/base/ItemRegistry.gd#L244 | G7: docs/v0.1/data/ShellStorm2_游戏内容数据库_v010.xlsx#掉落物品!A34 | H7: 未在当前CSV列出；池来源见下一列 | I7: src/base/ItemRegistry.gd#L244 / loot_floor_1_2, loot_floor_3_4, loot_floor_5, loot_abyss, boss_floor_1, boss_floor_2, scavenge_floor_3, scavenge_floor_4, scavenge_floor_5, combat_floor_1, combat_floor_2, combat_floor_3, elite_floor_1, elite_floor_2 | J7: src/game/InventoryModule.gd#add_item | K7: src/world3d/Dungeon3D.gd#_equip_weapon_from_inventory | L7: src/world3d/ItemModelFactory3D.gd#create_model / get_model_kind | M7: weapon；真实武器快照重建 | N7: WPN-GUN-BP-RIFLE | O7: assets/registry/ledgers/ShellStorm2_武器账本_v001.xlsx#资产主表!A8 | P7: WORLD-LOOT / REWARD-SERVICE / INVENTORY-SLOTS / WEAPON-OWNERSHIP | Q7: 已注册；本表只导航，堆叠/数值/掉落概率由原定义拥有；远征01作者掉落表未列此项（不可视为无其他产出）
A8: weapon_machinegun | B8: 蜂窝机枪 | C8: weapon | D8: gun_body | E8: assets/registry/ledgers/ShellStorm2_武器账本_v001.xlsx | F8: src/base/ItemRegistry.gd#L273 | G8: docs/v0.1/data/ShellStorm2_游戏内容数据库_v010.xlsx#掉落物品!A32 | H8: 未在当前CSV列出；池来源见下一列 | I8: src/base/ItemRegistry.gd#L273 / loot_floor_1_2, loot_floor_3_4, loot_floor_5, loot_abyss, scavenge_floor_1, scavenge_floor_2, scavenge_floor_3, scavenge_floor_4, scavenge_floor_5, combat_floor_1, combat_floor_2, combat_floor_3, elite_floor_1, elite_floor_2 | J8: src/game/InventoryModule.gd#add_item | K8: src/world3d/Dungeon3D.gd#_equip_weapon_from_inventory | L8: src/world3d/ItemModelFactory3D.gd#create_model / get_model_kind | M8: weapon；真实武器快照重建 | N8: WPN-GUN-BP-MACHINEGUN | O8: assets/registry/ledgers/ShellStorm2_武器账本_v001.xlsx#资产主表!A9 | P8: WORLD-LOOT / REWARD-SERVICE / INVENTORY-SLOTS / WEAPON-OWNERSHIP | Q8: 已注册；本表只导航，堆叠/数值/掉落概率由原定义拥有；远征01作者掉落表未列此项（不可视为无其他产出）
A9: weapon_sprinkler | B9: 花洒机枪 | C9: weapon | D9: gun_body | E9: assets/registry/ledgers/ShellStorm2_武器账本_v001.xlsx | F9: src/base/ItemRegistry.gd#L302 | G9: 缺行 | H9: 未在当前CSV列出；池来源见下一列 | I9: src/base/ItemRegistry.gd#L302 / loot_floor_1_2, loot_floor_3_4, loot_floor_5, loot_abyss, scavenge_floor_1, scavenge_floor_2, scavenge_floor_3, scavenge_floor_4, scavenge_floor_5, combat_floor_1, combat_floor_2, combat_floor_3, elite_floor_1, elite_floor_2 | J9: src/game/InventoryModule.gd#add_item | K9: src/world3d/Dungeon3D.gd#_equip_weapon_from_inventory | L9: src/world3d/ItemModelFactory3D.gd#create_model / get_model_kind | M9: weapon；真实武器快照重建 | N9: 未登记 | O9: 未登记 | P9: WORLD-LOOT / REWARD-SERVICE / INVENTORY-SLOTS / WEAPON-OWNERSHIP | Q9: 已注册；本表只导航，堆叠/数值/掉落概率由原定义拥有；远征01作者掉落表未列此项（不可视为无其他产出）；内容数据库缺行，运行注册表有此ID；无对应资产主表登记，不新增AssetID
A10: weapon_sniper | B10: 弹弓狙击 | C10: weapon | D10: gun_body | E10: assets/registry/ledgers/ShellStorm2_武器账本_v001.xlsx | F10: src/base/ItemRegistry.gd#L333 | G10: docs/v0.1/data/ShellStorm2_游戏内容数据库_v010.xlsx#掉落物品!A36 | H10: 未在当前CSV列出；池来源见下一列 | I10: src/base/ItemRegistry.gd#L333 / loot_floor_3_4, loot_floor_5, loot_abyss, boss_floor_1, boss_floor_2, scavenge_floor_3, scavenge_floor_4, scavenge_floor_5, combat_floor_2, combat_floor_3, elite_floor_1, elite_floor_2 | J10: src/game/InventoryModule.gd#add_item | K10: src/world3d/Dungeon3D.gd#_equip_weapon_from_inventory | L10: src/world3d/ItemModelFactory3D.gd#create_model / get_model_kind | M10: weapon；真实武器快照重建 | N10: WPN-GUN-BP-SNIPER | O10: assets/registry/ledgers/ShellStorm2_武器账本_v001.xlsx#资产主表!A10 | P10: WORLD-LOOT / REWARD-SERVICE / INVENTORY-SLOTS / WEAPON-OWNERSHIP | Q10: 已注册；本表只导航，堆叠/数值/掉落概率由原定义拥有；远征01作者掉落表未列此项（不可视为无其他产出）
A11: weapon_launcher | B11: 反胃榴弹筒 | C11: weapon | D11: gun_body | E11: assets/registry/ledgers/ShellStorm2_武器账本_v001.xlsx | F11: src/base/ItemRegistry.gd#L360 | G11: docs/v0.1/data/ShellStorm2_游戏内容数据库_v010.xlsx#掉落物品!A31 | H11: docs/v0.1/data/怪物掉落表_地图x怪物.csv#CSV行15 / exploder | I11: src/base/ItemRegistry.gd#L360 / loot_floor_3_4, loot_floor_5, loot_abyss, boss_floor_1, boss_floor_2, scavenge_floor_3, scavenge_floor_4, scavenge_floor_5, combat_floor_3, combat_floor_4, combat_floor_5, elite_floor_2 | J11: src/game/InventoryModule.gd#add_item | K11: src/world3d/Dungeon3D.gd#_equip_weapon_from_inventory | L11: src/world3d/ItemModelFactory3D.gd#create_model / get_model_kind | M11: weapon；真实武器快照重建 | N11: WPN-GUN-BP-LAUNCHER | O11: assets/registry/ledgers/ShellStorm2_武器账本_v001.xlsx#资产主表!A11 | P11: WORLD-LOOT / REWARD-SERVICE / INVENTORY-SLOTS / WEAPON-OWNERSHIP | Q11: 已注册；本表只导航，堆叠/数值/掉落概率由原定义拥有
A12: weapon_charge | B12: 蓄力萝卜炮 | C12: weapon | D12: gun_body | E12: assets/registry/ledgers/ShellStorm2_武器账本_v001.xlsx | F12: src/base/ItemRegistry.gd#L387 | G12: docs/v0.1/data/ShellStorm2_游戏内容数据库_v010.xlsx#掉落物品!A30 | H12: 未在当前CSV列出；池来源见下一列 | I12: src/base/ItemRegistry.gd#L387 / loot_floor_5, loot_abyss, boss_floor_2, scavenge_floor_4, scavenge_floor_5, combat_floor_4, combat_floor_5, elite_floor_2 | J12: src/game/InventoryModule.gd#add_item | K12: src/world3d/Dungeon3D.gd#_equip_weapon_from_inventory | L12: src/world3d/ItemModelFactory3D.gd#create_model / get_model_kind | M12: weapon；真实武器快照重建 | N12: WPN-GUN-BP-CHARGE | O12: assets/registry/ledgers/ShellStorm2_武器账本_v001.xlsx#资产主表!A12 | P12: WORLD-LOOT / REWARD-SERVICE / INVENTORY-SLOTS / WEAPON-OWNERSHIP | Q12: 已注册；本表只导航，堆叠/数值/掉落概率由原定义拥有；远征01作者掉落表未列此项（不可视为无其他产出）
A13: weapon_baseball_bat | B13: 废土棒球棍 | C13: weapon | D13: melee_weapon | E13: assets/registry/ledgers/ShellStorm2_武器账本_v001.xlsx | F13: src/base/ItemRegistry.gd#L410 | G13: docs/v0.1/data/ShellStorm2_游戏内容数据库_v010.xlsx#掉落物品!A49 | H13: docs/v0.1/data/怪物掉落表_地图x怪物.csv#CSV行3 / melee_chaser | I13: src/base/ItemRegistry.gd#L410 / spawn_starter, loot_floor_1_2, scavenge_floor_1, scavenge_floor_2, combat_floor_1 | J13: src/game/InventoryModule.gd#add_item | K13: src/world3d/Dungeon3D.gd#_equip_weapon_from_inventory | L13: src/world3d/ItemModelFactory3D.gd#create_model / get_model_kind | M13: weapon；真实武器快照重建 | N13: WPN-MELEE-BP-BASEBALL-BAT | O13: assets/registry/ledgers/ShellStorm2_武器账本_v001.xlsx#资产主表!A30 | P13: WORLD-LOOT / REWARD-SERVICE / INVENTORY-SLOTS / WEAPON-OWNERSHIP | Q13: 已注册；本表只导航，堆叠/数值/掉落概率由原定义拥有
A14: weapon_greatblade | B14: 巨型工业断刃 | C14: weapon | D14: melee_weapon | E14: assets/registry/ledgers/ShellStorm2_武器账本_v001.xlsx | F14: src/base/ItemRegistry.gd#L430 | G14: docs/v0.1/data/ShellStorm2_游戏内容数据库_v010.xlsx#掉落物品!A47 | H14: 未在当前CSV列出；池来源见下一列 | I14: src/base/ItemRegistry.gd#L430 / spawn_starter, loot_floor_1_2, loot_floor_3_4, scavenge_floor_1, scavenge_floor_2, combat_floor_1, combat_floor_2 | J14: src/game/InventoryModule.gd#add_item | K14: src/world3d/Dungeon3D.gd#_equip_weapon_from_inventory | L14: src/world3d/ItemModelFactory3D.gd#create_model / get_model_kind | M14: weapon；真实武器快照重建 | N14: WPN-MELEE-BP-GREATBLADE | O14: assets/registry/ledgers/ShellStorm2_武器账本_v001.xlsx#资产主表!A28 | P14: WORLD-LOOT / REWARD-SERVICE / INVENTORY-SLOTS / WEAPON-OWNERSHIP | Q14: 已注册；本表只导航，堆叠/数值/掉落概率由原定义拥有；远征01作者掉落表未列此项（不可视为无其他产出）
A15: weapon_waraxe | B15: 攻城裂甲斧 | C15: weapon | D15: melee_weapon | E15: assets/registry/ledgers/ShellStorm2_武器账本_v001.xlsx | F15: src/base/ItemRegistry.gd#L452 | G15: docs/v0.1/data/ShellStorm2_游戏内容数据库_v010.xlsx#掉落物品!A48 | H15: 未在当前CSV列出；池来源见下一列 | I15: src/base/ItemRegistry.gd#L452 / loot_floor_1_2, loot_floor_3_4, loot_floor_5, loot_abyss, scavenge_floor_3, combat_floor_3, elite_floor_1, elite_floor_2 | J15: src/game/InventoryModule.gd#add_item | K15: src/world3d/Dungeon3D.gd#_equip_weapon_from_inventory | L15: src/world3d/ItemModelFactory3D.gd#create_model / get_model_kind | M15: weapon；真实武器快照重建 | N15: WPN-MELEE-BP-WARAXE | O15: assets/registry/ledgers/ShellStorm2_武器账本_v001.xlsx#资产主表!A29 | P15: WORLD-LOOT / REWARD-SERVICE / INVENTORY-SLOTS / WEAPON-OWNERSHIP | Q15: 已注册；本表只导航，堆叠/数值/掉落概率由原定义拥有；远征01作者掉落表未列此项（不可视为无其他产出）
A16: item_ammo_pack | B16: 通用弹药 | C16: consumable | E16: assets/registry/ledgers/ShellStorm2_武器账本_v001.xlsx | F16: src/base/ItemRegistry.gd#L739 | G16: docs/v0.1/data/ShellStorm2_游戏内容数据库_v010.xlsx#掉落物品!A18 | H16: docs/v0.1/data/怪物掉落表_地图x怪物.csv#CSV行5 / melee_chaser docs/v0.1/data/怪物掉落表_地图x怪物.csv#CSV行10 / ranged_caster docs/v0.1/data/怪物掉落表_地图x怪物.csv#CSV行16 / exploder | I16: src/base/ItemRegistry.gd#L739 / loot_common, loot_floor_1_2, spawn_starter, combat_floor_1, combat_floor_2, combat_floor_3, combat_floor_4, combat_floor_5 | J16: src/game/InventoryModule.gd#add_item | K16: src/world3d/Dungeon3D.gd#_on_inventory_item_clicked | L16: src/world3d/ItemModelFactory3D.gd#create_model / get_model_kind | M16: ammo；程序罐体 | N16: 未登记 | O16: 未登记 | P16: WORLD-LOOT / REWARD-SERVICE / INVENTORY-SLOTS / WEAPON-OWNERSHIP | Q16: 已注册；本表只导航，堆叠/数值/掉落概率由原定义拥有；无对应资产主表登记，不新增AssetID
A17: mod_bullet_standard | B17: 标准子弹模块 | C17: module | D17: bullet | E17: assets/registry/ledgers/ShellStorm2_武器账本_v001.xlsx | F17: src/base/ItemRegistry.gd#L886 | G17: docs/v0.1/data/ShellStorm2_游戏内容数据库_v010.xlsx#掉落物品!A28 | H17: docs/v0.1/data/怪物掉落表_地图x怪物.csv#CSV行4 / melee_chaser | I17: src/base/ItemRegistry.gd#L886 / loot_floor_1_2, loot_floor_3_4, loot_floor_5, loot_abyss, spawn_starter, scavenge_floor_1, scavenge_floor_2, combat_floor_1, combat_floor_2 | J17: src/game/InventoryModule.gd#add_item | K17: src/world3d/Dungeon3D.gd#_install_weapon_module_from_item | L17: src/world3d/ItemModelFactory3D.gd#create_model / get_model_kind | M17: bullet | N17: WPN-BUL-MOD-BULLET-STANDARD | O17: assets/registry/ledgers/ShellStorm2_武器账本_v001.xlsx#资产主表!A13 | P17: WORLD-LOOT / REWARD-SERVICE / INVENTORY-SLOTS / WEAPON-OWNERSHIP | Q17: 已注册；本表只导航，堆叠/数值/掉落概率由原定义拥有；2026-10-14 Blender源已完成（未导入运行时）：art_source/items_weapons/weapons/bullet_standard/source/wpn_bullet_standard_source_v001.blend；preview/ground双模型源已完成，ground100–200三角，运行时用途分流待接入。
A18: mod_bullet_sticky | B18: 黏黏弹模块 | C18: module | D18: bullet | E18: assets/registry/ledgers/ShellStorm2_武器账本_v001.xlsx | F18: src/base/ItemRegistry.gd#L909 | G18: docs/v0.1/data/ShellStorm2_游戏内容数据库_v010.xlsx#掉落物品!A29 | H18: 未在当前CSV列出；池来源见下一列 | I18: src/base/ItemRegistry.gd#L909 / loot_floor_1_2, loot_floor_3_4, loot_floor_5, loot_abyss, spawn_starter, scavenge_floor_1, scavenge_floor_2, combat_floor_1, combat_floor_2 | J18: src/game/InventoryModule.gd#add_item | K18: src/world3d/Dungeon3D.gd#_install_weapon_module_from_item | L18: src/world3d/ItemModelFactory3D.gd#create_model / get_model_kind | M18: bullet | N18: WPN-BUL-MOD-BULLET-STICKY VFX-BULLET-STICKY-3D | O18: assets/registry/ledgers/ShellStorm2_武器账本_v001.xlsx#资产主表!A14 assets/registry/ledgers/ShellStorm2_特效账本_v001.xlsx#资产主表!A28 | P18: WORLD-LOOT / REWARD-SERVICE / INVENTORY-SLOTS / WEAPON-OWNERSHIP | Q18: 已注册；本表只导航，堆叠/数值/掉落概率由原定义拥有；远征01作者掉落表未列此项（不可视为无其他产出）
A19: mod_bullet_bounce | B19: 回旋镖弹模块 | C19: module | D19: bullet | E19: assets/registry/ledgers/ShellStorm2_武器账本_v001.xlsx | F19: src/base/ItemRegistry.gd#L932 | G19: docs/v0.1/data/ShellStorm2_游戏内容数据库_v010.xlsx#掉落物品!A24 | H19: docs/v0.1/data/怪物掉落表_地图x怪物.csv#CSV行8 / ranged_caster | I19: src/base/ItemRegistry.gd#L932 / loot_floor_1_2, loot_floor_3_4, loot_floor_5, loot_abyss, spawn_starter, scavenge_floor_1, scavenge_floor_2, combat_floor_1, combat_floor_2 | J19: src/game/InventoryModule.gd#add_item | K19: src/world3d/Dungeon3D.gd#_install_weapon_module_from_item | L19: src/world3d/ItemModelFactory3D.gd#create_model / get_model_kind | M19: bullet | N19: WPN-BUL-MOD-BULLET-BOUNCE VFX-BULLET-BOUNCE-3D | O19: assets/registry/ledgers/ShellStorm2_武器账本_v001.xlsx#资产主表!A15 assets/registry/ledgers/ShellStorm2_特效账本_v001.xlsx#资产主表!A29 | P19: WORLD-LOOT / REWARD-SERVICE / INVENTORY-SLOTS / WEAPON-OWNERSHIP | Q19: 已注册；本表只导航，堆叠/数值/掉落概率由原定义拥有
