Workbook

Sheet 总览
A1: SHELLSTORM 2 · 角色美术账本 v0.1
A3: 归属域=角色｜覆盖大类=角色｜AssetID 前缀=CHR / SKEL / BONE｜主账本（总目录）=assets/registry/ShellStorm2_美术资产台账_v001.xlsx；本账本可独立并行编辑，跨域契约见主账本
A5: 资产总数 | C5: 已完成/已接入 | E5: 待制作/程序占位 | G5: 重复警报 | I5: 域内专表 / 3D Prefab 分页
A6: =COUNTA('资产主表'!$A$6:$A$30) | C6: =COUNTIF('资产主表'!$K$6:$K$30,"已完成")+COUNTIF('资产主表'!$K$6:$K$30,"原型已接入")+COUNTIF('资产主表'!$K$6:$K$30,"正式美术已接入")+COUNTIF('资产主表'!$K$6:$K$30,"已优化并正式接入")+COUNTIF('资产主表'!$K$6:$K$30,"Blender源已完成")+COUNTIF('资产主表'!$K$6:$K$30,"已导入；优化完成")+COUNTIF('资产主表'!$K$6:$K$30,"白模源已完成；QA PASS") | E6: =COUNTIF('资产主表'!$K$6:$K$30,"待制作")+COUNTIF('资产主表'!$K$6:$K$30,"程序占位") | G6: =COUNTIF('资产主表'!$S$6:$S$30,"重复") | I6: 域内专表：角色组件 / 动画与状态 / 原型角色 / 角色中转记录 / 3D-角色 | 3D Prefab 分页：3D-角色
A9: 大类 | B9: 资产数 | C9: 完成/接入 | E9: 本账本只登记上列大类；跨域搬运资产须同步主账本《分类与编码》并重跑门禁
A10: 角色 | B10: =COUNTIF('资产主表'!$C$6:$C$30,A10) | C10: =SUMPRODUCT(('资产主表'!$C$6:$C$30=A10)*(('资产主表'!$K$6:$K$30="已完成")+('资产主表'!$K$6:$K$30="原型已接入")+('资产主表'!$K$6:$K$30="正式美术已接入")+('资产主表'!$K$6:$K$30="已优化并正式接入")+('资产主表'!$K$6:$K$30="Blender源已完成")+('资产主表'!$K$6:$K$30="已导入；优化完成")+('资产主表'!$K$6:$K$30="白模源已完成；QA PASS")))
A11: 合计 | B11: =COUNTIF('资产主表'!$C$6:$C$30,A11) | C11: =SUMPRODUCT(('资产主表'!$C$6:$C$30=A11)*(('资产主表'!$K$6:$K$30="已完成")+('资产主表'!$K$6:$K$30="原型已接入")+('资产主表'!$K$6:$K$30="正式美术已接入")+('资产主表'!$K$6:$K$30="已优化并正式接入")+('资产主表'!$K$6:$K$30="Blender源已完成")+('资产主表'!$K$6:$K$30="已导入；优化完成")+('资产主表'!$K$6:$K$30="白模源已完成；QA PASS")))
A13: 域内 3D Prefab 分页统计（快照口径与本账本分页一致；权威清单在各分页表）
A14: 分页 | B14: Prefab 数 | C14: 直接引用 GLB | D14: 有功能脚本 | E14: 碰撞开启 | F14: 说明
A15: 3D-角色 | B15: =COUNTA('3D-角色'!$A$5:$A$204) | C15: =COUNTIF('3D-角色'!$D$5:$D$204,"<>") | D15: =COUNTIF('3D-角色'!$G$5:$G$204,"<>") | E15: =COUNTIF('3D-角色'!$H$5:$H$204,"开") | F15: 一行 = 一个实际存在的 Godot PackedScene
A16: 合计 | B16: =SUM(B15) | C16: =SUM(C15) | D16: =SUM(D15) | E16: =SUM(E15)

Sheet 账本说明
A1: 本账本说明 · 角色
A3: 本表是分账本自描述；机器可读真源为 assets/registry/ledger_index.json，二者不一致时以 JSON 为准
A5: 项 | B5: 值
A6: 账本归属域 | B6: 角色
A7: 分账本文件 | B7: assets/registry/ledgers/ShellStorm2_角色账本_v001.xlsx
A8: 覆盖大类 | B8: 角色
A9: AssetID 前缀 | B9: CHR / SKEL / BONE
A10: 域内专表 | B10: 角色组件 / 动画与状态 / 原型角色 / 角色中转记录 / 3D-角色
A11: 3D Prefab 分页 | B11: 3D-角色
A12: 动画登记表 | B12: 动画与状态 / 角色中转记录
A13: 主账本（总目录） | B13: assets/registry/ShellStorm2_美术资产台账_v001.xlsx
A14: 跨域契约 | B14: 分类与编码 / 命名与查重 / 版本记录 / Skill 清单 / 3D Prefab 总控 —— 全部只在主账本维护
A15: 首选制作 Skill | B15: game-character-model-pipeline
A16: 协作 Skill | B16: player-avatar-asset-standard
... A23: 快照日期 | B23: 2026-09-18

Sheet 资产主表
A1: 资产主表 · 唯一登记源
A3: 查重键由公式生成；S 列出现“重复”时禁止制作，先合并或建立变体父子关系
A5: AssetID | B5: 中文名 | C5: 大类 | D5: 子类 | E5: 逻辑ID/源键 | F5: 组件槽 | G5: 变体父ID | H5: 视角 | I5: 状态/动画 | J5: 复用范围 | K5: 制作状态 | L5: 优先级 | M5: 版本 | N5: 规格(px) | O5: 文件路径 | P5: 源码/策划依据 | Q5: 关键词/别名 | R5: 查重键 | S5: 查重结果 | T5: SHA-256 | U5: 负责人 | V5: 更新时间 | W5: 来源/许可 | X5: 源编号（Blender collection） | Y5: 备注
A6: CHR-PLY-CAPSULE01 | B6: 胶囊防护体玩家 | C6: 角色 | D6: player | E6: player_capsule01 | F6: root | H6: 俯视3D | I6: default / seated | J6: 正式3D玩家 | K6: 原型已接入 | L6: P0 | M6: v021 | N6: 可见边界0.724×1.050×0.452m（含耳）；Player3D 碰撞胶囊高1.5m、半径0.34m | O6: assets/art/characters/player/chr_player_capsule01_3d/chr_player_capsule01_root_top3d_v001.tscn | P6: art_source/characters/player/chr_player_capsule01_3d/variants/bunny01/production/v021/source/model/chr_bunny01_model_v021.blend; ../ShellStorm2-backup/2026-10-11_slimming/original_tree/art_source/characters/player/chr_player_capsule01_3d/variants/bunny01/production/v021/source/animation/chr_bunny01_animation_v021.blend; assets/art/characters/player/chr_player_capsule01_3d/variants/bunny01/production/v021/character_transfer_ledger_v021.json; art_source/characters/player/chr_player_capsule01_3d/variants/bunny01/production/v023/source/animation/chr_bunny01_animation_v022.blend; assets/art/characters/player/chr_player_capsule01_3d/variants/bunny01/production/v023/character_transfer_ledger_v022.json | Q6: 玩家; 胶囊体; 防护服; 主角 | R6: =LOWER(TRIM(C6)&"|"&TRIM(D6)&"|"&TRIM(E6)&"|"&TRIM(F6)&"|"&TRIM(H6)&"|"&TRIM(I6)) | S6: =IF(COUNTIF($R$6:$R$30,R6)>1,"重复","唯一") | T6: d962a133c9f966e97e0471adf110eaddda7ade65c2ef3ec47b56dbf2f1c93af0 | U6: 待分配 | V6: 46294 | W6: 稳定玩法根 AssetID | X6: — | Y6: 2026-08-09：旧2D胶囊表现已退役并删除；正式表现使用 CHR-PLY-CAPSULE01-3D-BUNNY01 v008。 2026-08-30 AST-02：补齐单一生产路径SHA；验收：verify_player3d_avatar_bounds；SHA cbd405cbac3e。 2026-08-30 AST-04：运行时消费者已使用 Bunny v008；稳定 AssetID 不变；路径 assets/art/characters/player/chr_player_capsule01_3d/variants/bunny01/chr_player_capsule01_bunny01_root_top3d_v006.tscn → assets/art/characters/player/chr_player_capsule01_3d/variants/bunny01/chr_player_capsule01_bunny01_root_top3d_v008.tscn；Blender v008 源审计通过（METRIC、root scale 1、节点驱动挂点保持）；验收角色尺寸/动画/持握/下身挂点/头部配件专项。 2026-09-09：双Blend共享骨架 v009；新导出分件骨局部原点，八态Blender动作库接入；玩法层级/碰撞不变。 2026-09-09：v010 腰胸/上下臂/指链/大小腿新骨架，模型未改；待机、移动、持枪待机、持枪移动重新制作并接入。用户要求跳过验收，未验证；其他状态沿用v009。 2026-09-10：v011 +Y到Godot -Z统一朝向；原位直链绑定、腰胸归位、四基础动作无骨链拉伸。验收结果见中转JSON。 2026-09-10：v021 完整12动作库接入；八个玩法基础状态与慢走/单手持枪变体均来自新版Blender，body读取chest，右手使用掌心握点。仅替换表现层，碰撞与功能层级不变。 2026-09-29：v021 模型及原12动作保持不变；新增 v022 Blender 坐姿滑行循环 seated，Player3D 九态状态机与 99F 两把可驾驶椅接入；verify_pushable_base_chairs 通过。 2026-09-29：v023 Blender 坐姿源将双脚向座面前方伸出；角色乘坐时可正常射击，相机补偿座面抬升，离座恢复世界碰撞。
A7: CHR-PLY-CAPSULE01-HEAD-SIDE | B7: 胶囊头壳 | C7: 角色 | D7: player_component | E7: player_capsule01 | F7: head | G7: CHR-PLY-CAPSULE01 | H7: 侧面朝右（可水平翻转） | I7: deprecated | J7: 单资产 | K7: 弃用 | L7: P0 | M7: v001 | N7: 28×24 px | Q7: 头; 头盔; 传感器 | R7: =LOWER(TRIM(C7)&"|"&TRIM(D7)&"|"&TRIM(E7)&"|"&TRIM(F7)&"|"&TRIM(H7)&"|"&TRIM(I7)) | S7: =IF(COUNTIF($R$6:$R$30,R7)>1,"重复","唯一") | T7: 6035db0c8d1824ee0d0f12c0bcf7d5ebced8e37666541b7c31000ff7bad2f905 | U7: 待分配 | V7: 46243 | W7: 原创/待确认 | X7: — | Y7: 2026-08-09：旧2D玩家像素表现文件已从仓库删除；仅保留AssetID/哈希作为历史记录，替代项为 CHR-PLY-CAPSULE01-3D-BUNNY01。
A8: CHR-PLY-CAPSULE01-BODY-SIDE | B8: 胶囊防护服躯干 | C8: 角色 | D8: player_component | E8: player_capsule01 | F8: body | G8: CHR-PLY-CAPSULE01 | H8: 侧面朝右（可水平翻转） | I8: deprecated | J8: 单资产 | K8: 弃用 | L8: P0 | M8: v001 | N8: 32×35 px | Q8: 身子; 躯干; 防护服 | R8: =LOWER(TRIM(C8)&"|"&TRIM(D8)&"|"&TRIM(E8)&"|"&TRIM(F8)&"|"&TRIM(H8)&"|"&TRIM(I8)) | S8: =IF(COUNTIF($R$6:$R$30,R8)>1,"重复","唯一") | T8: 653190cbcd99aaa10735842e4ee694c61e3c04b2d6aee7acfc3b03e0c7a65d6e | U8: 待分配 | V8: 46243 | W8: 原创/待确认 | X8: — | Y8: 2026-08-09：旧2D玩家像素表现文件已从仓库删除；仅保留AssetID/哈希作为历史记录，替代项为 CHR-PLY-CAPSULE01-3D-BUNNY01。
A9: CHR-PLY-CAPSULE01-HAND-L-SIDE | B9: 左悬浮手（停用） | C9: 角色 | D9: player_component | E9: player_capsule01 | F9: hand_l_source | G9: CHR-PLY-CAPSULE01 | H9: 侧面朝右（可水平翻转） | I9: deprecated | J9: 单资产 | K9: 弃用 | L9: P0 | M9: v001 | N9: 22×21 px | Q9: 左手; 辅助手 | R9: =LOWER(TRIM(C9)&"|"&TRIM(D9)&"|"&TRIM(E9)&"|"&TRIM(F9)&"|"&TRIM(H9)&"|"&TRIM(I9)) | S9: =IF(COUNTIF($R$6:$R$30,R9)>1,"重复","唯一") | T9: 6270855f57a22aa2c1bc156b4fb85c98d8cc1b3978cd19082a0874e3d901c7c9 | U9: 待分配 | V9: 46243 | W9: 原创/待确认 | X9: — | Y9: 2026-08-09：旧2D玩家像素表现文件已从仓库删除；仅保留AssetID/哈希作为历史记录，替代项为 CHR-PLY-CAPSULE01-3D-BUNNY01。
A10: CHR-PLY-CAPSULE01-HAND-R-SIDE | B10: 唯一镜像握持手 | C10: 角色 | D10: player_component | E10: player_capsule01 | F10: hand | G10: CHR-PLY-CAPSULE01 | H10: 侧面朝右（可水平翻转） | I10: deprecated | J10: 单资产 | K10: 弃用 | L10: P0 | M10: v001 | N10: 22×17 px | Q10: 右手; 主手; 枪手; 镜像握持 | R10: =LOWER(TRIM(C10)&"|"&TRIM(D10)&"|"&TRIM(E10)&"|"&TRIM(F10)&"|"&TRIM(H10)&"|"&TRIM(I10)) | S10: =IF(COUNTIF($R$6:$R$30,R10)>1,"重复","唯一") | T10: 69c2529cbd277ed337ce3b0a02a1994a2b470c99e545fad297e314a60485cfdf | U10: 待分配 | V10: 46243 | W10: 原创/待确认 | X10: — | Y10: 2026-08-09：旧2D玩家像素表现文件已从仓库删除；仅保留AssetID/哈希作为历史记录，替代项为 CHR-PLY-CAPSULE01-3D-BUNNY01。
A11: CHR-PLY-CAPSULE01-SCARF-SIDE | B11: 红色安全围巾 | C11: 角色 | D11: player_accessory | E11: player_capsule01 | F11: scarf | G11: CHR-PLY-CAPSULE01 | H11: 侧面朝右（可水平翻转） | I11: deprecated | J11: 单资产 | K11: 弃用 | L11: P0 | M11: v001 | N11: 26×14 px | Q11: 红围巾; 牛仔围巾; 识别色 | R11: =LOWER(TRIM(C11)&"|"&TRIM(D11)&"|"&TRIM(E11)&"|"&TRIM(F11)&"|"&TRIM(H11)&"|"&TRIM(I11)) | S11: =IF(COUNTIF($R$6:$R$30,R11)>1,"重复","唯一") | T11: d3a7b1bb5e2ac0ef0c2129854ce59e91d7503a88e478326e1bd3b918a74fc079 | U11: 待分配 | V11: 46243 | W11: 原创/待确认 | X11: — | Y11: 2026-08-09：旧2D玩家像素表现文件已从仓库删除；仅保留AssetID/哈希作为历史记录，替代项为 CHR-PLY-CAPSULE01-3D-BUNNY01。
A12: CHR-PLY-CAPSULE01-PREVIEW-STATES | B12: 玩家六态验收预览 | C12: 角色 | D12: review_board | E12: player_capsule01 | F12: preview | G12: CHR-PLY-CAPSULE01 | H12: 侧面朝右（可水平翻转） | I12: deprecated | J12: 评审/回归 | K12: 弃用 | L12: P0 | M12: v001 | N12: 1280×720 px | Q12: 六态; 验收板 | R12: =LOWER(TRIM(C12)&"|"&TRIM(D12)&"|"&TRIM(E12)&"|"&TRIM(F12)&"|"&TRIM(H12)&"|"&TRIM(I12)) | S12: =IF(COUNTIF($R$6:$R$30,R12)>1,"重复","唯一") | U12: 待分配 | V12: 46243 | W12: 原创/待确认 | X12: — | Y12: 2026-08-09：旧2D玩家像素表现文件已从仓库删除；仅保留AssetID/哈希作为历史记录，替代项为 CHR-PLY-CAPSULE01-3D-BUNNY01。
A13: CHR-PLY-CAPSULE01-3D-BUNNY01 | B13: 兔子主角3D根变体 | C13: 角色 | D13: player_variant | E13: player_capsule01 | F13: root_3d_bunny01 | G13: CHR-PLY-CAPSULE01-3D | H13: 俯视3D | I13: 128 clips / 37 distinct melee actions / six melee phases | J13: 3D玩家场景 | K13: active | L13: P0 | M13: v042 | N13: 创作高1.5m；默认运行倍率0.8/静止高1.2m；碰撞仍由Player3D拥有。 | O13: assets/art/characters/player/chr_player_capsule01_3d/variants/bunny01/production/v021/runtime/chr_bunny01_root_v021.tscn | P13: art_source/characters/player/chr_player_capsule01_3d/variants/bunny01/production/v021/source/model/chr_bunny01_model_v021.blend; ../ShellStorm2-backup/2026-10-11_slimming/original_tree/art_source/characters/player/chr_player_capsule01_3d/variants/bunny01/production/v021/source/animation/chr_bunny01_animation_v021.blend; assets/art/characters/player/chr_player_capsule01_3d/variants/bunny01/production/v021/character_transfer_ledger_v021.json; art_source/characters/player/chr_player_capsule01_3d/variants/bunny01/production/v023/source/animation/chr_bunny01_animation_v022.blend; assets/art/characters/player/chr_player_capsule01_3d/variants/bunny01/production/v023/character_transfer_ledger_v022.json; ../ShellStorm2-backup/2026-10-11_slimming/original_tree/assets/art/characters/player/chr_player_capsule01_3d/variants/bunny01/production/v024/source/animation/chr_bunny01_animation_v024.blend; assets/art/characters/player/chr_player_capsule01_3d/variants/bunny01/production/v024/character_transfer_ledger_v024.json; ../ShellStorm2-backup/2026-10-11_slimming/original_tree/art_source/characters/player/chr_player_capsule01_3d/variants/bunny01/source/animation/chr_bunny01_animation_v025.blend; art_source/characters/player/chr_player_capsule01_3d/variants/bunny01/source/animation/chr_bunny01_weapon_idles_v025.json; ../ShellStorm2-backup/2026-10-11_slimming/original_tree/art_source/characters/player/chr_player_capsule01_3d/variants/bunny01/source/animation/chr_bunny01_animation_v026.blend; art_source/characters/player/chr_player_capsule01_3d/variants/bunny01/source/animation/chr_bunny01_weapon_idles_v026.json; ../ShellStorm2-backup/2026-10-11_slimming/original_tree/art_source/characters/player/chr_player_capsule01_3d/variants/bunny01/source/animation/chr_bunny01_animation_v027.blend; art_source/characters/player/chr_player_capsule01_3d/variants/bunny01/source/animation/chr_bunny01_directional_v027.json; ../ShellStorm2-backup/2026-10-11_slimming/original_tree/art_source/characters/player/chr_player_capsule01_3d/variants/bunny01/source/animation/chr_bunny01_animation_v028.blend; art_source/characters/player/chr_player_capsule01_3d/variants/bunny01/source/animation/chr_bunny01_directional_v028.json; ../ShellStorm2-backup/2026-10-11_slimming/original_tree/art_source/characters/player/chr_player_capsule01_3d/variants/bunny01/source/animation/chr_bunny01_animation_v029.blend; assets/art/characters/player/chr_player_capsule01_3d/variants/bunny01/character_transfer_ledger.json; assets/art/characters/player/chr_player_capsule01_3d/variants/bunny01/components/chr_bunny01_motion/asset_manifest.json; ../ShellStorm2-backup/2026-10-11_slimming/original_tree/art_source/characters/player/chr_player_capsule01_3d/variants/bunny01/source/animation/chr_bunny01_animation_v030.blend; assets/art/characters/player/chr_player_capsule01_3d/variants/bunny01/character_transfer_ledger.json; assets/art/characters/player/chr_player_capsule01_3d/variants/bunny01/components/chr_bunny01_motion/asset_manifest.json; ../ShellStorm2-backup/2026-10-11_slimming/original_tree/art_source/characters/player/chr_player_capsule01_3d/variants/bunny01/source/animation/chr_bunny01_animation_v031.blend; assets/art/characters/player/chr_player_capsule01_3d/variants/bunny01/character_transfer_ledger.json; assets/art/characters/player/chr_player_capsule01_3d/variants/bunny01/components/chr_bunny01_motion/asset_manifest.json; ../ShellStorm2-backup/2026-10-11_slimming/original_tree/art_source/characters/player/chr_player_capsule01_3d/variants/bunny01/source/animation/chr_bunny01_animation_v032.blend; assets/art/characters/player/chr_player_capsule01_3d/variants/bunny01/character_transfer_ledger.json; assets/art/characters/player/chr_player_capsule01_3d/variants/bunny01/components/chr_bunny01_motion/asset_manifest.json; ../ShellStorm2-backup/2026-10-11_slimming/original_tree/art_source/characters/player/chr_player_capsule01_3d/variants/bunny01/source/animation/chr_bunny01_animation_v033.blend; assets/art/characters/player/chr_player_capsule01_3d/variants/bunny01/character_transfer_ledger.json; assets/art/characters/player/chr_player_capsule01_3d/variants/bunny01/components/chr_bunny01_motion/asset_manifest.json; ../ShellStorm2-backup/2026-10-11_slimming/original_tree/art_source/characters/player/chr_player_capsule01_3d/variants/bunny01/source/animation/chr_bunny01_animation_v034.blend; assets/art/characters/player/chr_player_capsule01_3d/variants/bunny01/character_transfer_ledger.json; assets/art/characters/player/chr_player_capsule01_3d/variants/bunny01/components/chr_bunny01_motion/asset_manifest.json; ../ShellStorm2-backup/2026-10-11_slimming/original_tree/art_source/characters/player/chr_player_capsule01_3d/variants/bunny01/source/animation/chr_bunny01_animation_v035.blend; assets/art/characters/player/chr_player_capsule01_3d/variants/bunny01/character_transfer_ledger.json; assets/art/characters/player/chr_player_capsule01_3d/variants/bunny01/components/chr_bunny01_motion/asset_manifest.json; ../ShellStorm2-backup/2026-10-11_slimming/original_tree/art_source/characters/player/chr_player_capsule01_3d/variants/bunny01/source/animation/chr_bunny01_animation_v036.blend; assets/art/characters/player/chr_player_capsule01_3d/variants/bunny01/character_transfer_ledger.json; assets/art/characters/player/chr_player_capsule01_3d/variants/bunny01/components/chr_bunny01_motion/asset_manifest.json; art_source/characters/player/chr_player_capsule01_3d/variants/bunny01/source/animation/chr_bunny01_animation_v037.blend; assets/art/characters/player/chr_player_capsule01_3d/variants/bunny01/character_transfer_ledger.json; assets/art/characters/player/chr_player_capsule01_3d/variants/bunny01/components/chr_bunny01_motion/asset_manifest.json; art_source/characters/player/chr_player_capsule01_3d/variants/bunny01/source/animation/chr_bunny01_animation_v039.blend; assets/art/characters/player/chr_player_capsule01_3d/variants/bunny01/character_transfer_ledger.json; art_source/characters/player/chr_player_capsule01_3d/variants/bunny01/source/animation/chr_bunny01_animation_v041.blend; art_source/characters/player/chr_player_capsule01_3d/variants/bunny01/source/animation/chr_bunny01_animation_v042.blend | Q13: 兔子;主角;兔耳;3D;Blender;bunny01 | R13: =LOWER(TRIM(C13)&"|"&TRIM(D13)&"|"&TRIM(E13)&"|"&TRIM(F13)&"|"&TRIM(H13)&"|"&TRIM(I13)) | S13: =IF(COUNTIF($R$6:$R$30,R13)>1,"重复","唯一") | T13: 50861d4bc1ff5fc16ac2851288a4e4cbbb0018078aee848e63e570b0066c8306 | U13: Codex | V13: 46312 | W13: 原创 Blender/Godot 组合 | X13: — | Y13: v0.1 v006：正式BunnyRig保持双手武器姿势；新增BodyJoint/LowerBodySocket；DIY body/head/hand/feet直接映射可见GLB材质；状态画廊覆盖层读数兼容结构化flashlight快照。角色网格保持layer2与现有外部灯光投影契约。 2026-08-21：复用bunny01 v006与现有武器GLB/AssetID，sidearm_hold改为右前下方低位警戒；仅程序姿势修订，不改玩法碰撞、射击或装配。 2026-08-21：右手掌球中心、HandJointR与枪械GripSocket改为同一挂点事实；沿用bunny01 v006与现有AssetID，不改玩法。 2026-08-21：手枪待机取消整枪俯仰/偏航/侧滚，开火角度后坐不再作用于枪身；枪口local -Z与真实aim_direction保持0度差。 2026-08-30 AST-02：合法内容更新；文件为Git已跟踪且修改时间不早于原台账日期；验收：verify_player3d_avatar_bounds；verify_player3d_weapon_pose_collision_flow；SHA b894e9fe05f8→cbd405cbac3e。 2026-08-30 AST-04：运行时消费者已使用 Bunny v008；稳定 AssetID 不变；路径 assets/art/characters/player/chr_player_capsule01_3d/variants/bunny01/chr_player_capsule01_bunny01_root_top3d_v006.tscn → assets/art/characters/player/chr_player_capsule01_3d/variants/bunny01/chr_player_capsule01_bunny01_root_top3d_v008.tscn；Blender v008 源审计通过（METRIC、root scale 1、节点驱动挂点保持）；验收角色尺寸/动画/持握/下身挂点/头部配件专项。 2026-09-09：双Blend共享骨架 v009；新导出分件骨局部原点，八态Blender动作库接入；玩法层级/碰撞不变。 2026-09-09：v010 腰胸/上下臂/指链/大小腿新骨架，模型未改；待机、移动、持枪待机、持枪移动重新制作并接入。用户要求跳过验收，未验证；其他状态沿用v009。 2026-09-10：v011 +Y到Godot -Z统一朝向；原位直链绑定、腰胸归位、四基础动作无骨链拉伸。验收结果见中转JSON。 2026-09-10：v021 完整12动作库接入；八个玩法基础状态与慢走/单手持枪变体均来自新版Blender，body读取chest，右手使用掌心握点。仅替换表现层，碰撞与功能层级不变。 2026-09-29：v021 模型及原12动作保持不变；新增 v022 Blender 坐姿滑行循环 seated，Player3D 九态状态机与 99F 两把可驾驶椅接入；verify_pushable_base_chairs 通过。 2026-09-29：v023 Blender 坐姿源将双脚向座面前方伸出；角色乘坐时可正常射击，相机补偿座面抬升，离座恢复世界碰撞。 2026-09-29：v024原角色动画母版新增climbing交替手脚攀爬循环，映射到Player3D climbing状态。；2026-10-07新增v025站立持枪待机sidearm_idle/longgun_idle/machinegun_idle，源级authored，待导出接线；保留原14条动作、模型与骨架，四方向移动另待制作。运行路径/版本/状态保持，不代表新动作已启用。；v026按用户正侧参考调整短枪前上倾、三枪前移，握点同步；源级待导入，v025保留。；v027按v026持枪姿态新增三枪型×慢走/正常移动×左移/右移/后退18循环，源级authored，待导入；前进另待制作。；v028为v027的18移动循环补耳朵反方向拖曳/回弹，其余曲线保持，源级authored待导入。；v029正式接入35新剪辑并保留14旧剪辑，机枪独立族、四方向/两速度、耳朵跟随、掌心与枪朝向采样。专项通过，命名/文档全局既有红项保留；其他长枪支撑差异和世界滑步、专用战斗动作待完善。见2026-10-07_player_motion_runtime_v029.md。；v030正式接入27举枪射击剪辑并保留49旧剪辑，机枪独立族、四方向/两速度、耳朵跟随、掌心与枪朝向采样。专项通过，命名/文档全局既有红项保留；其他长枪支撑差异和世界滑步、换弹蓄力近战待完善。见2026-10-07_player_motion_firing_v030.md。；v031正式接入18条长枪机枪斜持修订并保留58条其他剪辑，长枪机枪小幅斜持、机枪收近3.5cm创作尺寸；身体脚步耳朵、短枪和射击不变。专项通过，命名/文档全局既有红项保留；其他长枪支撑差异和世界滑步、换弹蓄力近战待完善。见2026-10-07_player_motion_carry_v031.md。；v032修订4条无枪前后摆臂，新增12条三枪型双背槽收取枪；其余72条保持。1/2重复当前槽收枪、双枪背负，切换先收后取；弹药与实例保留。专项通过，命名/文档全局既有红项保留；其他长枪支撑差异和世界滑步、换弹蓄力近战待完善。见2026-10-08_player_motion_switch_v032.md。；v033新增三类独立换弹，按WeaponModel3D真实progress同步播放；保留88条原剪辑。0.4/1.5/4秒、移动/取消/换槽打断专项174检查通过；无新增弹匣物件。专项通过，命名/文档全局既有红项保留；其他长枪支撑差异和世界滑步、蓄力近战待完善。见2026-10-08_player_motion_reload_v033.md。；v034增强长枪机枪换弹枪体抬起、倾斜、沉降回弹与压紧回位；短枪及其余89条剪辑逐值保持，实际progress同步不变。0.4/1.5/4秒、移动/取消/换槽打断专项178检查通过；无新增弹匣物件。专项通过，命名/文档全局既有红项保留；其他长枪支撑差异和世界滑步、蓄力近战待完善。见2026-10-08_player_motion_reload_v034.md。；v035机枪枪口转向前下方并抬高枪尾换弹操作位；短枪、长枪及其余90条剪辑逐值保持，实际progress同步不变。0.4/1.5/4秒、移动/取消/换槽打断专项184检查通过；无新增弹匣物件。专项通过，命名/文档全局既有红项保留；其他长枪支撑差异和世界滑步、蓄力近战待完善。见2026-10-08_player_motion_reload_v035.md。；v036机枪枪口向前下方约45度，握点不前伸，近身抬高枪尾换弹；短枪、长枪及其余90条剪辑逐值保持，实际progress同步不变。0.4/1.5/4秒、移动/取消/换槽打断专项225检查通过；无新增弹匣物件。专项通过，命名/文档全局既有红项保留；其他长枪支撑差异和世界滑步、蓄力近战待完善。见2026-10-08_player_motion_reload_v036.md。；v037机枪顶视斜向左前45度、枪口上抬；握点近身不前伸；短枪、长枪及其余90条剪辑逐值保持，实际progress同步不变。0.4/1.5/4秒、移动/取消/换槽打断专项225检查通过；无新增弹匣物件。专项通过，命名/文档全局既有红项保留；其他长枪支撑差异和世界滑步、蓄力近战待完善。见2026-10-08_player_motion_reload_v037.md。；2026-10-15 v039：63条四方向慢走/跑步/移动射击及7待机增强头部起伏与躯干扭转；双手随动、射击稳枪。28条非目标剪辑保持，下肢/根差异<0.000001；源63条及15项导入/运行/真实渲染检查通过。完整项目与移动端未验，历史头像哈希/命名债务另列。；v041：棍普通挥击、斧慢速下劈与蓄力击退、剑交替横扫与持续旋风。37段Blender近战动作、91条旧动作保真；专项与真实渲染通过，详见docs/v0.1/development/2026-10-16_melee_styles_v041.md；v042修正斧子握持：绕柄轴-90°，刃面进入下劈平面、银刃领先；14斧动作仅WeaponSocket旋转改变，其余114动作逐值不变；docs/v0.1/development/2026-10-17_axe_edge_v042.md
A14: CHR-PLY-CAPSULE01-3D-BUNNY01-BODY | B14: 兔子主角3D身体 | C14: 角色 | D14: player_component | E14: player_capsule01 | F14: body_3d_bunny01 | G14: CHR-PLY-CAPSULE01-3D-BUNNY01 | H14: 俯视3D | I14: default | J14: 3D玩家场景 | K14: 原型已接入 | L14: P0 | M14: v021 | N14: GLB / 1,958 verts / pivot-local / 1.5m总高比例 | O14: assets/art/characters/player/chr_player_capsule01_3d/variants/bunny01/production/v021/exports/chr_bunny01_body_v021.glb | P14: art_source/characters/player/chr_player_capsule01_3d/variants/bunny01/production/v021/source/model/chr_bunny01_model_v021.blend; ../ShellStorm2-backup/2026-10-11_slimming/original_tree/art_source/characters/player/chr_player_capsule01_3d/variants/bunny01/production/v021/source/animation/chr_bunny01_animation_v021.blend; assets/art/characters/player/chr_player_capsule01_3d/variants/bunny01/production/v021/character_transfer_ledger_v021.json | Q14: 兔子;身体;服装;body;bunny01 | R14: =LOWER(TRIM(C14)&"|"&TRIM(D14)&"|"&TRIM(E14)&"|"&TRIM(F14)&"|"&TRIM(H14)&"|"&TRIM(I14)) | S14: =IF(COUNTIF($R$6:$R$30,R14)>1,"重复","唯一") | T14: 120a25fd63abc29f5e9e04f13b207b86c77207abca6cb8a82c120177535dd45b | U14: Codex | V14: 46264 | W14: 用户提供 Blender 源文件 | X14: — | Y14: v0.1 v006：身体网格与底部中心原点保持不变；BodyJoint新增LowerBodySocket local=(0,0.14,0)，用于裙摆/腰甲/下摆并继承全部身体程序动画。 2026-08-30 AST-04：Bunny v008 包装层实际消费 v007 组件；登记路径 assets/art/characters/player/chr_player_capsule01_3d/variants/bunny01/components/chr_player_capsule01_bunny01_body_top3d_v006.glb → assets/art/characters/player/chr_player_capsule01_3d/variants/bunny01/components/chr_player_capsule01_bunny01_body_top3d_v007.glb；稳定组件 AssetID 不变；源母版为 art_source/characters/player/chr_player_capsule01_3d/variants/bunny01/source/chr_player_capsule01_bunny01_top3d_v008.blend；验收角色节点/尺寸/姿势/换装契约。 2026-09-09：双Blend共享骨架 v009；新导出分件骨局部原点，八态Blender动作库接入；玩法层级/碰撞不变。 2026-09-09：v010 腰胸/上下臂/指链/大小腿新骨架，模型未改；待机、移动、持枪待机、持枪移动重新制作并接入。用户要求跳过验收，未验证；其他状态沿用v009。 2026-09-10：v011 +Y到Godot -Z统一朝向；原位直链绑定、腰胸归位、四基础动作无骨链拉伸。验收结果见中转JSON。 2026-09-10：v021 完整12动作库接入；八个玩法基础状态与慢走/单手持枪变体均来自新版Blender，body读取chest，右手使用掌心握点。仅替换表现层，碰撞与功能层级不变。
A15: CHR-PLY-CAPSULE01-3D-BUNNY01-HEAD | B15: 兔子主角3D头部 | C15: 角色 | D15: player_component | E15: player_capsule01 | F15: head_3d_bunny01 | G15: CHR-PLY-CAPSULE01-3D-BUNNY01 | H15: 俯视3D | I15: default | J15: 3D玩家场景 | K15: 原型已接入 | L15: P0 | M15: v021 | N15: GLB / 5,936 verts / pivot-local / 头顶1.103390m | O15: assets/art/characters/player/chr_player_capsule01_3d/variants/bunny01/production/v021/exports/chr_bunny01_head_v021.glb | P15: art_source/characters/player/chr_player_capsule01_3d/variants/bunny01/production/v021/source/model/chr_bunny01_model_v021.blend; ../ShellStorm2-backup/2026-10-11_slimming/original_tree/art_source/characters/player/chr_player_capsule01_3d/variants/bunny01/production/v021/source/animation/chr_bunny01_animation_v021.blend; assets/art/characters/player/chr_player_capsule01_3d/variants/bunny01/production/v021/character_transfer_ledger_v021.json | Q15: 兔子;头部;head;bunny01 | R15: =LOWER(TRIM(C15)&"|"&TRIM(D15)&"|"&TRIM(E15)&"|"&TRIM(F15)&"|"&TRIM(H15)&"|"&TRIM(I15)) | S15: =IF(COUNTIF($R$6:$R$30,R15)>1,"重复","唯一") | T15: ff6d106a59068101e87692a73818f0cf0bf94319732d9bbda366f2febe5aaca9 | U15: Codex | V15: 46264 | W15: 用户提供 Blender 源文件 | X15: — | Y15: v0.1 v006：头部与下沿中心原点真实1.5倍；不含耳头顶1.103390m，完整双耳顶部1.500m。 2026-08-30 AST-04：Bunny v008 包装层实际消费 v007 组件；登记路径 assets/art/characters/player/chr_player_capsule01_3d/variants/bunny01/components/chr_player_capsule01_bunny01_head_top3d_v006.glb → assets/art/characters/player/chr_player_capsule01_3d/variants/bunny01/components/chr_player_capsule01_bunny01_head_top3d_v007.glb；稳定组件 AssetID 不变；源母版为 art_source/characters/player/chr_player_capsule01_3d/variants/bunny01/source/chr_player_capsule01_bunny01_top3d_v008.blend；验收角色节点/尺寸/姿势/换装契约。 2026-09-09：双Blend共享骨架 v009；新导出分件骨局部原点，八态Blender动作库接入；玩法层级/碰撞不变。 2026-09-09：v010 腰胸/上下臂/指链/大小腿新骨架，模型未改；待机、移动、持枪待机、持枪移动重新制作并接入。用户要求跳过验收，未验证；其他状态沿用v009。 2026-09-10：v011 +Y到Godot -Z统一朝向；原位直链绑定、腰胸归位、四基础动作无骨链拉伸。验收结果见中转JSON。 2026-09-10：v021 完整12动作库接入；八个玩法基础状态与慢走/单手持枪变体均来自新版Blender，body读取chest，右手使用掌心握点。仅替换表现层，碰撞与功能层级不变。
A16: CHR-PLY-CAPSULE01-3D-BUNNY01-EARS | B16: 兔子主角3D双耳配件 | C16: 角色 | D16: player_accessory | E16: player_capsule01 | F16: ears_3d_bunny01 | G16: CHR-PLY-CAPSULE01-3D-BUNNY01-HEAD | H16: 俯视3D | I16: default | J16: 3D玩家场景 | K16: 原型已接入 | L16: P0 | M16: v021 | N16: 左右独立 GLB / 已烘焙镜像 | O16: assets/art/characters/player/chr_player_capsule01_3d/variants/bunny01/production/v021/exports/chr_bunny01_ear_l_v021.glb; assets/art/characters/player/chr_player_capsule01_3d/variants/bunny01/production/v021/exports/chr_bunny01_ear_r_v021.glb | P16: art_source/characters/player/chr_player_capsule01_3d/variants/bunny01/production/v021/source/model/chr_bunny01_model_v021.blend; ../ShellStorm2-backup/2026-10-11_slimming/original_tree/art_source/characters/player/chr_player_capsule01_3d/variants/bunny01/production/v021/source/animation/chr_bunny01_animation_v021.blend; assets/art/characters/player/chr_player_capsule01_3d/variants/bunny01/production/v021/character_transfer_ledger_v021.json | Q16: 兔耳;耳朵;耳部配件;EarSocketL;EarSocketR;bunny01 | R16: =LOWER(TRIM(C16)&"|"&TRIM(D16)&"|"&TRIM(E16)&"|"&TRIM(F16)&"|"&TRIM(H16)&"|"&TRIM(I16)) | S16: =IF(COUNTIF($R$6:$R$30,R16)>1,"重复","唯一") | T16: 0936a7e3212554eddf48af62704649b6a6c98a67b56b180ed2e802bc97a1fc7c / 7719ba73dec977951da3edf997752ba5afcf4a1c9f8b2bc8dd5ad8a78381b208 | U16: Codex | V16: 46264 | W16: 用户提供 Blender 源文件 | X16: — | Y16: v0.1 v006：耳朵网格与耳根原点真实1.5倍；左右挂点复用单资产，装配后最高点严格1.500m。 2026-08-30 AST-04：Bunny v008 包装层实际消费 v007 组件；登记路径 assets/art/characters/player/chr_player_capsule01_3d/variants/bunny01/components/chr_player_capsule01_bunny01_ear_top3d_v006.glb → assets/art/characters/player/chr_player_capsule01_3d/variants/bunny01/components/chr_player_capsule01_bunny01_ear_top3d_v007.glb；稳定组件 AssetID 不变；源母版为 art_source/characters/player/chr_player_capsule01_3d/variants/bunny01/source/chr_player_capsule01_bunny01_top3d_v008.blend；验收角色节点/尺寸/姿势/换装契约。 2026-09-09：双Blend共享骨架 v009；新导出分件骨局部原点，八态Blender动作库接入；玩法层级/碰撞不变。 2026-09-09：v010 腰胸/上下臂/指链/大小腿新骨架，模型未改；待机、移动、持枪待机、持枪移动重新制作并接入。用户要求跳过验收，未验证；其他状态沿用v009。 2026-09-10：v011 +Y到Godot -Z统一朝向；原位直链绑定、腰胸归位、四基础动作无骨链拉伸。验收结果见中转JSON。 2026-09-10：v021 完整12动作库接入；八个玩法基础状态与慢走/单手持枪变体均来自新版Blender，body读取chest，右手使用掌心握点。仅替换表现层，碰撞与功能层级不变。
A17: CHR-PLY-CAPSULE01-3D-BUNNY01-HAND | B17: 兔子主角3D双爪表现组件 | C17: 角色 | D17: player_component | E17: player_capsule01 | F17: hand_3d_bunny01 | G17: CHR-PLY-CAPSULE01-3D-BUNNY01 | H17: 俯视3D | I17: default | J17: 3D玩家场景 | K17: 原型已接入 | L17: P0 | M17: v021 | N17: 双 GLB / 左右各1,058 verts / pivot-local / 1.5m角色比例 | O17: assets/art/characters/player/chr_player_capsule01_3d/variants/bunny01/production/v021/exports/chr_bunny01_hand_l_v021.glb; assets/art/characters/player/chr_player_capsule01_3d/variants/bunny01/production/v021/exports/chr_bunny01_hand_r_v021.glb | P17: art_source/characters/player/chr_player_capsule01_3d/variants/bunny01/production/v021/source/model/chr_bunny01_model_v021.blend; ../ShellStorm2-backup/2026-10-11_slimming/original_tree/art_source/characters/player/chr_player_capsule01_3d/variants/bunny01/production/v021/source/animation/chr_bunny01_animation_v021.blend; assets/art/characters/player/chr_player_capsule01_3d/variants/bunny01/production/v021/character_transfer_ledger_v021.json | Q17: 兔爪;手;握持;weapon_socket;bunny01 | R17: =LOWER(TRIM(C17)&"|"&TRIM(D17)&"|"&TRIM(E17)&"|"&TRIM(F17)&"|"&TRIM(H17)&"|"&TRIM(I17)) | S17: =IF(COUNTIF($R$6:$R$30,R17)>1,"重复","唯一") | T17: eb021c9f0858a3b6bc5012551db2424cbc44baa0f769d6365fde780df4b8058c / ceaf3366cd4fa1887c3e897608052419120f2e4887003f48871b1fdea71f5cfb | U17: Codex | V17: 46264 | W17: 用户提供 Blender 源文件 | X17: — | Y17: v0.1 v006：左右手、手腕原点、单/双手握持目标和动作平移统一改用0.606060606米制比例；持枪外观与确认预览一致。 2026-08-21：右手收紧到GripSocket；手枪待机自由左手前伸胸前，枪口下俯并向角色外侧偏转，正面与三分之四近景保持面部净空。 2026-08-21：HandJointR/Model使用局部枢轴校正(-0.135996,0.038999,0.018441)，持枪状态每帧按真实GripSocket换算到HandRoot局部空间，三点偏差0mm。 2026-08-21：右手掌球仍与HandJointR/GripSocket保持0mm；吹风机Prefab另将可见握把中心校正到该同一坐标，未改角色GLB。 2026-08-30 AST-04：Bunny v008 包装层实际消费 v007 组件；登记路径 assets/art/characters/player/chr_player_capsule01_3d/variants/bunny01/components/chr_player_capsule01_bunny01_hand_l_top3d_v006.glb; assets/art/characters/player/chr_player_capsule01_3d/variants/bunny01/components/chr_player_capsule01_bunny01_hand_r_top3d_v006.glb → assets/art/characters/player/chr_player_capsule01_3d/variants/bunny01/components/chr_player_capsule01_bunny01_hand_l_top3d_v007.glb; assets/art/characters/player/chr_player_capsule01_3d/variants/bunny01/components/chr_player_capsule01_bunny01_hand_r_top3d_v007.glb；稳定组件 AssetID 不变；源母版为 art_source/characters/player/chr_player_capsule01_3d/variants/bunny01/source/chr_player_capsule01_bunny01_top3d_v008.blend；验收角色节点/尺寸/姿势/换装契约。 2026-09-09：双Blend共享骨架 v009；新导出分件骨局部原点，八态Blender动作库接入；玩法层级/碰撞不变。 2026-09-09：v010 腰胸/上下臂/指链/大小腿新骨架，模型未改；待机、移动、持枪待机、持枪移动重新制作并接入。用户要求跳过验收，未验证；其他状态沿用v009。 2026-09-10：v011 +Y到Godot -Z统一朝向；原位直链绑定、腰胸归位、四基础动作无骨链拉伸。验收结果见中转JSON。 2026-09-10：v021 完整12动作库接入；八个玩法基础状态与慢走/单手持枪变体均来自新版Blender，body读取chest，右手使用掌心握点。仅替换表现层，碰撞与功能层级不变。
A18: CHR-PLY-CAPSULE01-3D-BUNNY01-FOOT-L | B18: 兔子主角3D左脚 | C18: 角色 | D18: player_component | E18: player_capsule01 | F18: foot_l_3d_bunny01 | G18: CHR-PLY-CAPSULE01-3D-BUNNY01 | H18: 俯视3D | I18: moving | J18: 3D玩家场景 | K18: 原型已接入 | L18: P0 | M18: v021 | N18: GLB / 5,396 verts / pivot-local / 1.5m角色比例 | O18: assets/art/characters/player/chr_player_capsule01_3d/variants/bunny01/production/v021/exports/chr_bunny01_foot_l_v021.glb | P18: art_source/characters/player/chr_player_capsule01_3d/variants/bunny01/production/v021/source/model/chr_bunny01_model_v021.blend; ../ShellStorm2-backup/2026-10-11_slimming/original_tree/art_source/characters/player/chr_player_capsule01_3d/variants/bunny01/production/v021/source/animation/chr_bunny01_animation_v021.blend; assets/art/characters/player/chr_player_capsule01_3d/variants/bunny01/production/v021/character_transfer_ledger_v021.json | Q18: 兔脚;左脚;步态;FootL;bunny01 | R18: =LOWER(TRIM(C18)&"|"&TRIM(D18)&"|"&TRIM(E18)&"|"&TRIM(F18)&"|"&TRIM(H18)&"|"&TRIM(I18)) | S18: =IF(COUNTIF($R$6:$R$30,R18)>1,"重复","唯一") | T18: 055de14fc0840b5e218b0db8f26b496bc080cede6a43bf131a9bed9cf163ac9e | U18: Codex | V18: 46264 | W18: 用户提供 Blender 源文件 | X18: — | Y18: v0.1：v006网格与AssetID不变；FootJointL除moving步态外新增falling收腿与landing压缩恢复职责，动作由PlayerAvatar3D程序变换驱动。 2026-08-30 AST-04：Bunny v008 包装层实际消费 v007 组件；登记路径 assets/art/characters/player/chr_player_capsule01_3d/variants/bunny01/components/chr_player_capsule01_bunny01_foot_l_top3d_v006.glb → assets/art/characters/player/chr_player_capsule01_3d/variants/bunny01/components/chr_player_capsule01_bunny01_foot_l_top3d_v007.glb；稳定组件 AssetID 不变；源母版为 art_source/characters/player/chr_player_capsule01_3d/variants/bunny01/source/chr_player_capsule01_bunny01_top3d_v008.blend；验收角色节点/尺寸/姿势/换装契约。 2026-09-09：双Blend共享骨架 v009；新导出分件骨局部原点，八态Blender动作库接入；玩法层级/碰撞不变。 2026-09-09：v010 腰胸/上下臂/指链/大小腿新骨架，模型未改；待机、移动、持枪待机、持枪移动重新制作并接入。用户要求跳过验收，未验证；其他状态沿用v009。 2026-09-10：v011 +Y到Godot -Z统一朝向；原位直链绑定、腰胸归位、四基础动作无骨链拉伸。验收结果见中转JSON。 2026-09-10：v021 完整12动作库接入；八个玩法基础状态与慢走/单手持枪变体均来自新版Blender，body读取chest，右手使用掌心握点。仅替换表现层，碰撞与功能层级不变。
A19: CHR-PLY-CAPSULE01-3D-BUNNY01-FOOT-R | B19: 兔子主角3D右脚 | C19: 角色 | D19: player_component | E19: player_capsule01 | F19: foot_r_3d_bunny01 | G19: CHR-PLY-CAPSULE01-3D-BUNNY01 | H19: 俯视3D | I19: moving | J19: 3D玩家场景 | K19: 原型已接入 | L19: P0 | M19: v021 | N19: GLB / 5,396 verts / pivot-local / 1.5m角色比例 | O19: assets/art/characters/player/chr_player_capsule01_3d/variants/bunny01/production/v021/exports/chr_bunny01_foot_r_v021.glb | P19: art_source/characters/player/chr_player_capsule01_3d/variants/bunny01/production/v021/source/model/chr_bunny01_model_v021.blend; ../ShellStorm2-backup/2026-10-11_slimming/original_tree/art_source/characters/player/chr_player_capsule01_3d/variants/bunny01/production/v021/source/animation/chr_bunny01_animation_v021.blend; assets/art/characters/player/chr_player_capsule01_3d/variants/bunny01/production/v021/character_transfer_ledger_v021.json | Q19: 兔脚;右脚;步态;FootR;bunny01 | R19: =LOWER(TRIM(C19)&"|"&TRIM(D19)&"|"&TRIM(E19)&"|"&TRIM(F19)&"|"&TRIM(H19)&"|"&TRIM(I19)) | S19: =IF(COUNTIF($R$6:$R$30,R19)>1,"重复","唯一") | T19: bf9ddff69d423f1beb60c84d091bf6c86bfdf01a85a0a517202faaf635338813 | U19: Codex | V19: 46264 | W19: 用户提供 Blender 源文件 | X19: — | Y19: v0.1：v006网格与AssetID不变；FootJointR除moving步态外新增falling收腿与landing压缩恢复职责，动作由PlayerAvatar3D程序变换驱动。 2026-08-30 AST-04：Bunny v008 包装层实际消费 v007 组件；登记路径 assets/art/characters/player/chr_player_capsule01_3d/variants/bunny01/components/chr_player_capsule01_bunny01_foot_r_top3d_v006.glb → assets/art/characters/player/chr_player_capsule01_3d/variants/bunny01/components/chr_player_capsule01_bunny01_foot_r_top3d_v007.glb；稳定组件 AssetID 不变；源母版为 art_source/characters/player/chr_player_capsule01_3d/variants/bunny01/source/chr_player_capsule01_bunny01_top3d_v008.blend；验收角色节点/尺寸/姿势/换装契约。 2026-09-09：双Blend共享骨架 v009；新导出分件骨局部原点，八态Blender动作库接入；玩法层级/碰撞不变。 2026-09-09：v010 腰胸/上下臂/指链/大小腿新骨架，模型未改；待机、移动、持枪待机、持枪移动重新制作并接入。用户要求跳过验收，未验证；其他状态沿用v009。 2026-09-10：v011 +Y到Godot -Z统一朝向；原位直链绑定、腰胸归位、四基础动作无骨链拉伸。验收结果见中转JSON。 2026-09-10：v021 完整12动作库接入；八个玩法基础状态与慢走/单手持枪变体均来自新版Blender，body读取chest，右手使用掌心握点。仅替换表现层，碰撞与功能层级不变。
A20: CHR-PLAYER-AVATAR-TEMPLATE-001 | B20: 玩家角色1.5米制作母版 | C20: 角色 | D20: authoring_template | E20: player_avatar_template | F20: root | G20: CHR-PLY-CAPSULE01 | H20: 全向3D | I20: template | J20: 角色制作 | K20: 已完成 | L20: P0 | M20: v001 | N20: 1.50m；根缩放1 | O20: art_source/characters/player/chr_player_avatar_template_3d/source/chr_player_avatar_template_source_v001.blend | P20: scripts/blender/validate_player_avatar_asset_template.py | Q20: 角色母版; 1.5米; 挂点; 配件 | R20: =LOWER(TRIM(C20)&"|"&TRIM(D20)&"|"&TRIM(E20)&"|"&TRIM(F20)&"|"&TRIM(H20)&"|"&TRIM(I20)) | S20: =IF(COUNTIF($R$6:$R$30,R20)>1,"重复","唯一") | T20: 8bb17309f5dac5a5b8c4d3917193042213c64ff566486abdfff0aeafdc893117 | U20: Codex | V20: 46264 | W20: 用户自制/项目内资产 | X20: — | Y20: 2026-08-20：本轮基地系统、角色母版与资产流程登记。 2026-08-30 AST-01规范化（原制作状态：正式制作母版） 2026-08-30 AST-02：补齐单一生产路径SHA；验收：scripts/blender/validate_player_avatar_asset_template.py；SHA 8bb17309f5da。
A21: CHR-PLY-BUNNY01-HEAD-CHIBI-ANIME-3D | B21: Bunny 二次元女仆头部配件 | C21: 角色 | D21: 头部配件 | E21: chibi_anime | F21: head | G21: CHR-PLY-CAPSULE01-3D-BUNNY01 | H21: 3D | I21: default | J21: 玩家换装 | K21: 原型已接入 | L21: P1 | M21: v021 | N21: 0.777×0.771×0.723m；HeadJoint 原点；root scale 1 | O21: assets/art/characters/player/chr_player_capsule01_3d/variants/bunny01/production/v021/runtime/chr_bunny01_chibi_anime_root_v021.tscn | P21: art_source/characters/player/chr_player_capsule01_3d/variants/bunny01/production/v021/source/model/chr_bunny01_model_v021.blend; ../ShellStorm2-backup/2026-10-11_slimming/original_tree/art_source/characters/player/chr_player_capsule01_3d/variants/bunny01/production/v021/source/animation/chr_bunny01_animation_v021.blend; assets/art/characters/player/chr_player_capsule01_3d/variants/bunny01/production/v021/character_transfer_ledger_v021.json | Q21: chibi anime maid head | R21: =LOWER(TRIM(C21)&"|"&TRIM(D21)&"|"&TRIM(E21)&"|"&TRIM(F21)&"|"&TRIM(H21)&"|"&TRIM(I21)) | S21: =IF(COUNTIF($R$6:$R$30,R21)>1,"重复","唯一") | T21: 7f01db18d3f93d33567589bdf93f3b966930df9221a571dea8cf99d0ca005d9c | U21: 美术 | V21: 46264 | W21: 项目现有；原始模型商业使用许可须由项目方复核 | X21: — | Y21: 2026-08-30 AST-04：当前 Bunny v008 正式消费 v002 头部包装场景；新增稳定子 AssetID；碰撞仍由 Player3D 独占；动画继承 HeadJoint；Blender v008 审计通过；asset_guard PASS。 2026-09-09：双Blend共享骨架 v009；新导出分件骨局部原点，八态Blender动作库接入；玩法层级/碰撞不变。 2026-09-09：v010 腰胸/上下臂/指链/大小腿新骨架，模型未改；待机、移动、持枪待机、持枪移动重新制作并接入。用户要求跳过验收，未验证；其他状态沿用v009。 2026-09-10：v011 +Y到Godot -Z统一朝向；原位直链绑定、腰胸归位、四基础动作无骨链拉伸。验收结果见中转JSON。 2026-09-10：v021 完整12动作库接入；八个玩法基础状态与慢走/单手持枪变体均来自新版Blender，body读取chest，右手使用掌心握点。仅替换表现层，碰撞与功能层级不变。
A22: CHR-PLY-BUNNY01-FACE-ELECTRONIC-MASK | B22: 兔子主角黑色蓝光电子面具 | C22: 角色 | D22: player_accessory | E22: player_capsule01 | F22: glasses | G22: CHR-PLY-CAPSULE01-3D-BUNNY01 | H22: 3D/正面+俯视 | I22: 8种网格表情；mask_idle/blink/flicker；独立系统随机与状态事件调用 | J22: Bunny01面饰槽 | K22: 正式美术已接入 | L22: P1 | M22: v005 | N22: 原黑色面具+8种独立方块网格；自发光1.25（降低75%）；情绪无嘴；眼睛/爱心/符号饱满加粗；11.8mm颗粒/14mm网格；生气红色；单位根/原head契约 | O22: assets/art/characters/player/chr_player_capsule01_3d/variants/bunny01/components/face/electronic_mask/runtime/chr_bunny01_electronic_mask_root.tscn | P22: src/player3d/PlayerAvatar3D.gd；docs/v0.1/16_技术施工_主页面与角色换装.md | Q22: 电子面具;黑色面罩;蓝光;方块眼睛;面饰;electronic_mask | R22: =LOWER(TRIM(C22)&"|"&TRIM(D22)&"|"&TRIM(E22)&"|"&TRIM(F22)&"|"&TRIM(H22)&"|"&TRIM(I22)) | S22: =IF(COUNTIF($R$6:$R$30,R22)>1,"重复","唯一") | T22: 3775f317b0abc0ea1bff93150221ba3d0a26bd851520c230c0773ced52155628 | U22: Codex | V22: 46296 | W22: 用户参考图；项目既有头部曲面派生；代码制作蓝光颗粒 | X22: — | Y22: v005同ID version_increment；独立CharacterExpressionSystem拥有选择/随机/保持，PlayerExpressionStateAdapter消费真实状态事件，面具只显示。8种表情自发光1.25；无嘴部且图案饱满；原11网格/骨架及v001–v004源保留；8种表情分别登记子资产。源、8种Forward+图、独立系统/实际状态调用和眨眼/闪烁/换装专项通过。
A23: CHR-PLY-BUNNY01-EXPR-NEUTRAL | B23: 电子面具表情：平静 | C23: 角色 | D23: player_accessory | E23: player_capsule01_expression_neutral | F23: glasses | G23: CHR-PLY-BUNNY01-FACE-ELECTRONIC-MASK | H23: 3D/正面+俯视 | I23: neutral | J23: 独立角色表情系统 | K23: 正式美术已接入 | L23: P1 | M23: v003 | N23: 180颗11.8mm方块/14mm网格；自发光1.25；情绪无嘴部；图案加粗放大；#21bfff；独立根缩放1 | O23: assets/art/characters/player/chr_player_capsule01_3d/variants/bunny01/components/face/electronic_mask/expressions/chr_bunny01_expression_neutral/runtime/chr_bunny01_expression_neutral_root_top3d.tscn | P23: docs/v0.1/design/character_expression_system.md；src/presentation/expressions/CharacterExpressionSystem.gd | Q23: 网格表情;情绪;符号;平静;neutral | R23: =LOWER(TRIM(C23)&"|"&TRIM(D23)&"|"&TRIM(E23)&"|"&TRIM(F23)&"|"&TRIM(H23)&"|"&TRIM(I23)) | S23: =IF(COUNTIF($R$6:$R$30,R23)>1,"重复","唯一") | T23: 91bf8992535d92214043b1f732fb9ef10f263f1507428fda2cd55282429b9fa2 | U23: Codex | V23: 2026-10-01 | W23: 用户要求；原创方块网格排布 | X23: 01_部件/眼镜/眼镜__electronic_mask/表情__neutral | Y23: version_increment；父CHR-PLY-BUNNY01-FACE-ELECTRONIC-MASK v005；共享v005模型/动作双母版与SKEL-BUNNY01-004签名；独立稳定GLB/Prefab；180颗方块，颜色#21bfff，符号不闭眼；随机可达/命令/实际状态事件/Forward+真实渲染通过。
A24: CHR-PLY-BUNNY01-EXPR-HAPPY | B24: 电子面具表情：开心 | C24: 角色 | D24: player_accessory | E24: player_capsule01_expression_happy | F24: glasses | G24: CHR-PLY-BUNNY01-FACE-ELECTRONIC-MASK | H24: 3D/正面+俯视 | I24: happy | J24: 独立角色表情系统 | K24: 正式美术已接入 | L24: P1 | M24: v003 | N24: 116颗11.8mm方块/14mm网格；自发光1.25；情绪无嘴部；图案加粗放大；#29e9ff；独立根缩放1 | O24: assets/art/characters/player/chr_player_capsule01_3d/variants/bunny01/components/face/electronic_mask/expressions/chr_bunny01_expression_happy/runtime/chr_bunny01_expression_happy_root_top3d.tscn | P24: docs/v0.1/design/character_expression_system.md；src/presentation/expressions/CharacterExpressionSystem.gd | Q24: 网格表情;情绪;符号;开心;happy | R24: =LOWER(TRIM(C24)&"|"&TRIM(D24)&"|"&TRIM(E24)&"|"&TRIM(F24)&"|"&TRIM(H24)&"|"&TRIM(I24)) | S24: =IF(COUNTIF($R$6:$R$30,R24)>1,"重复","唯一") | T24: 6096540f49967a91f361561915c16f586ce6f32bf66548b4178ccf4b16e9cd4f | U24: Codex | V24: 2026-10-01 | W24: 用户要求；原创方块网格排布 | X24: 01_部件/眼镜/眼镜__electronic_mask/表情__happy | Y24: version_increment；父CHR-PLY-BUNNY01-FACE-ELECTRONIC-MASK v005；共享v005模型/动作双母版与SKEL-BUNNY01-004签名；独立稳定GLB/Prefab；116颗方块，颜色#29e9ff，符号不闭眼；随机可达/命令/实际状态事件/Forward+真实渲染通过。
A25: CHR-PLY-BUNNY01-EXPR-SAD | B25: 电子面具表情：难过 | C25: 角色 | D25: player_accessory | E25: player_capsule01_expression_sad | F25: glasses | G25: CHR-PLY-BUNNY01-FACE-ELECTRONIC-MASK | H25: 3D/正面+俯视 | I25: sad | J25: 独立角色表情系统 | K25: 正式美术已接入 | L25: P1 | M25: v003 | N25: 102颗11.8mm方块/14mm网格；自发光1.25；情绪无嘴部；图案加粗放大；#777bff；独立根缩放1 | O25: assets/art/characters/player/chr_player_capsule01_3d/variants/bunny01/components/face/electronic_mask/expressions/chr_bunny01_expression_sad/runtime/chr_bunny01_expression_sad_root_top3d.tscn | P25: docs/v0.1/design/character_expression_system.md；src/presentation/expressions/CharacterExpressionSystem.gd | Q25: 网格表情;情绪;符号;难过;sad | R25: =LOWER(TRIM(C25)&"|"&TRIM(D25)&"|"&TRIM(E25)&"|"&TRIM(F25)&"|"&TRIM(H25)&"|"&TRIM(I25)) | S25: =IF(COUNTIF($R$6:$R$30,R25)>1,"重复","唯一") | T25: 64b0b018248b0f2901755b51caf6af2246372424e246e0e2d2e52daa6c0db05e | U25: Codex | V25: 2026-10-01 | W25: 用户要求；原创方块网格排布 | X25: 01_部件/眼镜/眼镜__electronic_mask/表情__sad | Y25: version_increment；父CHR-PLY-BUNNY01-FACE-ELECTRONIC-MASK v005；共享v005模型/动作双母版与SKEL-BUNNY01-004签名；独立稳定GLB/Prefab；102颗方块，颜色#777bff，符号不闭眼；随机可达/命令/实际状态事件/Forward+真实渲染通过。
A26: CHR-PLY-BUNNY01-EXPR-ANGRY | B26: 电子面具表情：生气 | C26: 角色 | D26: player_accessory | E26: player_capsule01_expression_angry | F26: glasses | G26: CHR-PLY-BUNNY01-FACE-ELECTRONIC-MASK | H26: 3D/正面+俯视 | I26: angry | J26: 独立角色表情系统 | K26: 正式美术已接入 | L26: P1 | M26: v003 | N26: 112颗11.8mm方块/14mm网格；自发光1.25；情绪无嘴部；图案加粗放大；#ff3028；独立根缩放1 | O26: assets/art/characters/player/chr_player_capsule01_3d/variants/bunny01/components/face/electronic_mask/expressions/chr_bunny01_expression_angry/runtime/chr_bunny01_expression_angry_root_top3d.tscn | P26: docs/v0.1/design/character_expression_system.md；src/presentation/expressions/CharacterExpressionSystem.gd | Q26: 网格表情;情绪;符号;生气;angry | R26: =LOWER(TRIM(C26)&"|"&TRIM(D26)&"|"&TRIM(E26)&"|"&TRIM(F26)&"|"&TRIM(H26)&"|"&TRIM(I26)) | S26: =IF(COUNTIF($R$6:$R$30,R26)>1,"重复","唯一") | T26: a7a713e8dfa53e0690b7dfa5957573d0cfd4551a85146b46de67eea1ee837eaa | U26: Codex | V26: 2026-10-01 | W26: 用户要求；原创方块网格排布 | X26: 01_部件/眼镜/眼镜__electronic_mask/表情__angry | Y26: version_increment；父CHR-PLY-BUNNY01-FACE-ELECTRONIC-MASK v005；共享v005模型/动作双母版与SKEL-BUNNY01-004签名；独立稳定GLB/Prefab；112颗方块，颜色#ff3028，符号不闭眼；随机可达/命令/实际状态事件/Forward+真实渲染通过。
A27: CHR-PLY-BUNNY01-EXPR-SURPRISED | B27: 电子面具表情：惊讶 | C27: 角色 | D27: player_accessory | E27: player_capsule01_expression_surprised | F27: glasses | G27: CHR-PLY-BUNNY01-FACE-ELECTRONIC-MASK | H27: 3D/正面+俯视 | I27: surprised | J27: 独立角色表情系统 | K27: 正式美术已接入 | L27: P1 | M27: v003 | N27: 144颗11.8mm方块/14mm网格；自发光1.25；情绪无嘴部；图案加粗放大；#ffe45c；独立根缩放1 | O27: assets/art/characters/player/chr_player_capsule01_3d/variants/bunny01/components/face/electronic_mask/expressions/chr_bunny01_expression_surprised/runtime/chr_bunny01_expression_surprised_root_top3d.tscn | P27: docs/v0.1/design/character_expression_system.md；src/presentation/expressions/CharacterExpressionSystem.gd | Q27: 网格表情;情绪;符号;惊讶;surprised | R27: =LOWER(TRIM(C27)&"|"&TRIM(D27)&"|"&TRIM(E27)&"|"&TRIM(F27)&"|"&TRIM(H27)&"|"&TRIM(I27)) | S27: =IF(COUNTIF($R$6:$R$30,R27)>1,"重复","唯一") | T27: fcf462e945994543ded0497e84dbfe44f33ff4d89d5422641fd93794a9747712 | U27: Codex | V27: 2026-10-01 | W27: 用户要求；原创方块网格排布 | X27: 01_部件/眼镜/眼镜__electronic_mask/表情__surprised | Y27: version_increment；父CHR-PLY-BUNNY01-FACE-ELECTRONIC-MASK v005；共享v005模型/动作双母版与SKEL-BUNNY01-004签名；独立稳定GLB/Prefab；144颗方块，颜色#ffe45c，符号不闭眼；随机可达/命令/实际状态事件/Forward+真实渲染通过。
A28: CHR-PLY-BUNNY01-EXPR-LOVE | B28: 电子面具表情：爱心 | C28: 角色 | D28: player_accessory | E28: player_capsule01_expression_love | F28: glasses | G28: CHR-PLY-BUNNY01-FACE-ELECTRONIC-MASK | H28: 3D/正面+俯视 | I28: love | J28: 独立角色表情系统 | K28: 正式美术已接入 | L28: P1 | M28: v003 | N28: 148颗11.8mm方块/14mm网格；自发光1.25；情绪无嘴部；图案加粗放大；#ff6abb；独立根缩放1 | O28: assets/art/characters/player/chr_player_capsule01_3d/variants/bunny01/components/face/electronic_mask/expressions/chr_bunny01_expression_love/runtime/chr_bunny01_expression_love_root_top3d.tscn | P28: docs/v0.1/design/character_expression_system.md；src/presentation/expressions/CharacterExpressionSystem.gd | Q28: 网格表情;情绪;符号;爱心;love | R28: =LOWER(TRIM(C28)&"|"&TRIM(D28)&"|"&TRIM(E28)&"|"&TRIM(F28)&"|"&TRIM(H28)&"|"&TRIM(I28)) | S28: =IF(COUNTIF($R$6:$R$30,R28)>1,"重复","唯一") | T28: 0c7c63c8bf72ba2dc21be59232dbfdebc982347d05eb13e1384646604229011d | U28: Codex | V28: 2026-10-01 | W28: 用户要求；原创方块网格排布 | X28: 01_部件/眼镜/眼镜__electronic_mask/表情__love | Y28: version_increment；父CHR-PLY-BUNNY01-FACE-ELECTRONIC-MASK v005；共享v005模型/动作双母版与SKEL-BUNNY01-004签名；独立稳定GLB/Prefab；148颗方块，颜色#ff6abb，符号不闭眼；随机可达/命令/实际状态事件/Forward+真实渲染通过。
A29: CHR-PLY-BUNNY01-EXPR-QUESTION | B29: 电子面具表情：疑问 | C29: 角色 | D29: player_accessory | E29: player_capsule01_expression_question | F29: glasses | G29: CHR-PLY-BUNNY01-FACE-ELECTRONIC-MASK | H29: 3D/正面+俯视 | I29: question | J29: 独立角色表情系统 | K29: 正式美术已接入 | L29: P1 | M29: v003 | N29: 112颗11.8mm方块/14mm网格；自发光1.25；情绪无嘴部；图案加粗放大；#ffd24a；独立根缩放1 | O29: assets/art/characters/player/chr_player_capsule01_3d/variants/bunny01/components/face/electronic_mask/expressions/chr_bunny01_expression_question/runtime/chr_bunny01_expression_question_root_top3d.tscn | P29: docs/v0.1/design/character_expression_system.md；src/presentation/expressions/CharacterExpressionSystem.gd | Q29: 网格表情;情绪;符号;疑问;question | R29: =LOWER(TRIM(C29)&"|"&TRIM(D29)&"|"&TRIM(E29)&"|"&TRIM(F29)&"|"&TRIM(H29)&"|"&TRIM(I29)) | S29: =IF(COUNTIF($R$6:$R$30,R29)>1,"重复","唯一") | T29: 9a682f546faf4a778a1db97d6c58e010b9db54814cf40cc91c3d4705603bd3c1 | U29: Codex | V29: 2026-10-01 | W29: 用户要求；原创方块网格排布 | X29: 01_部件/眼镜/眼镜__electronic_mask/表情__question | Y29: version_increment；父CHR-PLY-BUNNY01-FACE-ELECTRONIC-MASK v005；共享v005模型/动作双母版与SKEL-BUNNY01-004签名；独立稳定GLB/Prefab；112颗方块，颜色#ffd24a，符号不闭眼；随机可达/命令/实际状态事件/Forward+真实渲染通过。
A30: CHR-PLY-BUNNY01-EXPR-ALERT | B30: 电子面具表情：警示 | C30: 角色 | D30: player_accessory | E30: player_capsule01_expression_alert | F30: glasses | G30: CHR-PLY-BUNNY01-FACE-ELECTRONIC-MASK | H30: 3D/正面+俯视 | I30: alert | J30: 独立角色表情系统 | K30: 正式美术已接入 | L30: P1 | M30: v003 | N30: 96颗11.8mm方块/14mm网格；自发光1.25；情绪无嘴部；图案加粗放大；#a1fff2；独立根缩放1 | O30: assets/art/characters/player/chr_player_capsule01_3d/variants/bunny01/components/face/electronic_mask/expressions/chr_bunny01_expression_alert/runtime/chr_bunny01_expression_alert_root_top3d.tscn | P30: docs/v0.1/design/character_expression_system.md；src/presentation/expressions/CharacterExpressionSystem.gd | Q30: 网格表情;情绪;符号;警示;alert | R30: =LOWER(TRIM(C30)&"|"&TRIM(D30)&"|"&TRIM(E30)&"|"&TRIM(F30)&"|"&TRIM(H30)&"|"&TRIM(I30)) | S30: =IF(COUNTIF($R$6:$R$30,R30)>1,"重复","唯一") | T30: 5c6f8b8035594d8c68e0159eda199b050f1261d22e648ae30738863ba5bcd3b3 | U30: Codex | V30: 2026-10-01 | W30: 用户要求；原创方块网格排布 | X30: 01_部件/眼镜/眼镜__electronic_mask/表情__alert | Y30: version_increment；父CHR-PLY-BUNNY01-FACE-ELECTRONIC-MASK v005；共享v005模型/动作双母版与SKEL-BUNNY01-004签名；独立稳定GLB/Prefab；96颗方块，颜色#a1fff2，符号不闭眼；随机可达/命令/实际状态事件/Forward+真实渲染通过。

Sheet 角色组件
A1: 角色组件与挂点契约
A3: 每个角色优先复用这些槽；允许缺少某槽，但禁止把手臂烘焙回 body，武器永远挂 weapon_socket
A5: 角色ID | B5: 组件槽 | C5: 节点路径 | D5: 父槽 | E5: 纹理路径 | F5: 运行时尺寸 | G5: 局部位置 | H5: 旋转/翻转 | I5: Z | J5: 动画职责 | K5: 换装边界 | L5: 必需 | M5: 备注
A6: player_capsule01 | B6: body | C6: PixelComponents/Body | D6: root | E6: assets/art/characters/player/chr_player_capsule01/components/chr_player_capsule01_body_side_v001.png | F6: 32×35 | G6: (0, 7) | H6: 随朝向 flip_h | I6: 1 | J6: 呼吸/移动压缩/死亡倾倒 | K6: 防护服主体 | L6: 是 | M6: 已退役（2026-08-09）：旧2D节点/纹理/Marker2D已删除；仅作历史组件记录，禁止运行时引用。
A7: player_capsule01 | B7: scarf | C7: PixelComponents/Scarf | D7: root | E7: assets/art/characters/player/chr_player_capsule01/components/chr_player_capsule01_scarf_side_v001.png | F7: 26×14 | G7: (0, -8) | H7: flip_h + 轻摆 | I7: 2 | J7: 移动滞后/冲刺飘动 | K7: 身份配件 | L7: 否 | M7: 已退役（2026-08-09）：旧2D节点/纹理/Marker2D已删除；仅作历史组件记录，禁止运行时引用。
A8: player_capsule01 | B8: head | C8: PixelComponents/Head | D8: root | E8: assets/art/characters/player/chr_player_capsule01/components/chr_player_capsule01_head_side_v001.png | F8: 28×24 | G8: (0, -19) | H8: 随朝向 flip_h | I8: 3 | J8: 朝向/受击/死亡 | K8: 头壳/传感器 | L8: 是 | M8: 已退役（2026-08-09）：旧2D节点/纹理/Marker2D已删除；仅作历史组件记录，禁止运行时引用。
A9: player_capsule01 | B9: hand_l_source | C9: 不实例化 | D9: root | E9: assets/art/characters/player/chr_player_capsule01/components/chr_player_capsule01_hand_l_side_v001.png | F9: 22×21 | G9: 不适用 | H9: 不适用 | I9: 4 | J9: 停用；仅保留源文件 | K9: 历史副手源 | L9: 否 | M9: 已退役（2026-08-09）：旧2D节点/纹理/Marker2D已删除；仅作历史组件记录，禁止运行时引用。
A10: player_capsule01 | B10: hand | C10: PixelComponents/Hand | D10: root | E10: assets/art/characters/player/chr_player_capsule01/components/chr_player_capsule01_hand_r_side_v001.png | F10: 22×17 | G10: (-19, 0)/(19, 0) | H10: 随身体 flip_h；不连续旋转 | I10: 5 | J10: 随身体左右换边；局部距离固定 | K10: 唯一握持手 | L10: 是 | M10: 已退役（2026-08-09）：旧2D节点/纹理/Marker2D已删除；仅作历史组件记录，禁止运行时引用。
A11: player_capsule01 | B11: weapon_socket | C11: Player/WeaponAnchor | D11: player_root | E11: 无纹理 | F11: Marker2D | G11: (-24, 0)/(24, 0) | H11: 挂点随身体换边；枪械跟随 aim_direction | I11: 6 | J11: 枪械挂载/枪口特效 | K11: 武器系统 | L11: 是 | M11: 已退役（2026-08-09）：旧2D节点/纹理/Marker2D已删除；仅作历史组件记录，禁止运行时引用。
A12: template | B12: accessory_back | C12: PixelComponents/AccessoryBack | D12: root | E12: 按需 | F12: 按需 | G12: 按需 | H12: 随朝向 | I12: 0 | J12: 披风/背包/长围巾尾 | K12: 背部配件 | L12: 否 | M12: 避免与 body 合图
A13: template | B13: accessory_front | C13: PixelComponents/AccessoryFront | D13: root | E13: 按需 | F13: 按需 | G13: 按需 | H13: 随朝向 | I13: 6 | J13: 徽章/护盾/前景饰物 | K13: 前景配件 | L13: 否 | M13: 必要时高于双手
A14: player_capsule01_3d | B14: root | C14: Avatar3D/CapsuleAvatar3D/VisualRoot | D14: player_root | E14: assets/art/characters/player/chr_player_capsule01_3d/chr_player_capsule01_root_top3d_v001.tscn | F14: Node3D | G14: (0,0,0) | H14: 整体随准星绕Y轴 | I14: 0 | J14: 六态整体 + reloading/firing/charging/knockback覆盖 | K14: 3D表现根 | L14: 是 | M14: 正式3D表现根；旧2D胶囊已完成退役，不再属于兼容范围。
A15: player_capsule01_3d | B15: body | C15: VisualRoot/Body | D15: root | E15: assets/art/characters/player/chr_player_capsule01_3d/chr_player_capsule01_root_top3d_v001.tscn | F15: BoxMesh + 子件 | G15: (0,0.76,0.02) | H15: 随root | I15: 1 | J15: 呼吸/移动压缩/射击前探/死亡倾倒 | K15: 方形猫身 | L15: 是 | M15: BodyShell + BellyPatch；方形主轮廓
A16: player_capsule01_3d | B16: head | C16: VisualRoot/Head | D16: root | E16: assets/art/characters/player/chr_player_capsule01_3d/chr_player_capsule01_root_top3d_v001.tscn | F16: BoxMesh + 子件 | G16: (0,1.72,-0.08) | H16: 随root | I16: 3 | J16: 移动反相滞后/后坐/受击/死亡 | K16: 方形猫头 | L16: 是 | M16: 无嘴无鼻；Eyes与Ears固定归Head
A17: player_capsule01_3d | B17: hand | C17: VisualRoot/Hand | D17: root | E17: assets/art/characters/player/chr_player_capsule01_3d/chr_player_capsule01_root_top3d_v001.tscn | F17: BoxMesh | G17: (0.60,1.10,-0.30) | H17: 随root；动作同相 | I17: 4 | J17: 移动/换弹/射击/蓄力/击飞保持握持 | K17: 唯一悬浮手 | L17: 是 | M17: 无手臂、无第二手；与WeaponSocket固定相对向量
... A39: player_capsule01_bunny01_3d | B39: foot_r | C39: VisualRoot/BunnyRig/FeetRoot/FootJointR/Model | D39: FeetRoot | E39: assets/art/characters/player/chr_player_capsule01_3d/variants/bunny01/production/v021/exports/chr_bunny01_foot_r_v021.glb | F39: pivot-local GLB / 1.5m比例 | G39: (0.129002,0,-0.010887) | H39: 独立FootJointR | I39: 1 | J39: moving右脚/翻滚收腿/受击甩脚/falling收腿/landing压缩 | K39: 右脚组件 | L39: 是 | M39: v021：foot_r 兼容部件原点导出；共享模型/动作骨架；状态 active。
A40: player_capsule01_3d | B40: weapon_stow_primary | C40: VisualRoot/BunnyRig/StowedWeaponSocketPrimary | D40: root | E40: 无纹理 | F40: Marker3D | G40: (-0.42,1.12,0.25) | H40: 随root；local -Z枪口轴转向世界下方 | I40: 5 | J40: 主武器未激活时背部左侧收纳 | K40: 武器系统 | L40: 是 | M40: 主武器槽0专属；枪口朝下；回退节点VisualRoot/StowedWeaponSocketPrimary
A41: player_capsule01_3d | B41: weapon_stow_secondary | C41: VisualRoot/BunnyRig/StowedWeaponSocketSecondary | D41: root | E41: 无纹理 | F41: Marker3D | G41: (0.42,1.12,0.25) | H41: 随root；local -Z枪口轴转向世界下方 | I41: 5 | J41: 副武器未激活时背部右侧收纳 | K41: 武器系统 | L41: 是 | M41: 副武器槽1专属；枪口朝下；回退节点VisualRoot/StowedWeaponSocketSecondary
A42: player_capsule01_3d | B42: backpack_socket | C42: VisualRoot/BunnyRig/BackpackSocket（fallback: VisualRoot/BackpackSocket） | D42: root | E42: 无纹理；子模型来自ItemModelFactory3D | F42: Marker3D + 程序Mesh | G42: bunny (0,0.74,0.30)；fallback (0,1.25,0.48) | H42: 继承VisualRoot朝向 | I42: 3 | J42: 装备时生成背包占位Mesh；卸下时移除 | K42: 背包装备系统 | L42: 是 | M42: 与StowedWeaponSocketPrimary/Secondary分离；2/4/8格共用模型工厂；无碰撞；verify_backpack_equipment_flow与Metal/OpenGL实机渲染通过。
A43: player_capsule01_bunny01_3d | B43: lower_body_socket | C43: VisualRoot/BunnyRig/BodyJoint/LowerBodySocket（fallback: VisualRoot/Body/LowerBodySocket） | D43: body | E43: 无纹理 | F43: Marker3D | G43: bunny Body local (0,0.14,0)；fallback Body local (0,-0.36,0) | H43: 继承BodyJoint位置/旋转/缩放 | I43: 2 | J43: 裙摆/腰甲/下摆继承全部身体状态与动作覆盖 | K43: 下身配件挂点 | L43: 是 | M43: presentation_only；无碰撞；不改变玩法；专项验证 verify_player3d_lower_body_socket_flow.tscn。
A44: player_capsule01_bunny01_3d | B44: glasses/electronic_mask | C44: VisualRoot/BunnyRig/HeadJoint/FaceAccessorySocket/ElectronicMask | D44: head | E44: assets/art/characters/player/chr_player_capsule01_3d/variants/bunny01/components/face/electronic_mask/components/chr_bunny01_electronic_mask_visual.glb | F44: 源0.630×0.479×0.257m；运行时继承玩家0.8表现倍率 | G44: HeadJoint局部原点；源曲面+Y前移0.009m | H44: Blender +Y / Godot -Z；独立根缩放1 | I44: 5 | J44: 继承head姿态；局部Blink/闪烁；独立CharacterExpressionSystem选择8种网格，状态事件适配器调用 | K44: 面饰槽，可独立替换/卸下 | L44: 否 | M44: CHR-PLY-BUNNY01-FACE-ELECTRONIC-MASK v005；8种发光强度1.25；8个无嘴部表达子组件；11.8mm颗粒、加粗眼睛/爱心/符号；生气红色，?和!为符号；无玩法/碰撞权威。
A45: player_capsule01_bunny01_3d | B45: glasses/expression/neutral | C45: HeadJoint/FaceAccessorySocket/ElectronicMask/Visual/ExpressionPixels | D45: head | E45: assets/art/characters/player/chr_player_capsule01_3d/variants/bunny01/components/face/electronic_mask/expressions/chr_bunny01_expression_neutral/components/chr_bunny01_expression_neutral_visual_top3d.glb | F45: 14mm网格/11.8mm颗粒；发光1.25；运行时继承角色比例 | G45: HeadJoint原点；原脸曲面前移9mm | H45: Blender +Y / Godot -Z；独立根缩放1 | I45: 5 | J45: 无嘴部；加粗眼睛/爱心/符号；独立系统命令/随机/状态调用；共用Blender局部剪辑 | K45: 只替换面具表情，不更换面饰配置 | L45: 否 | M45: CHR-PLY-BUNNY01-EXPR-NEUTRAL；平静；emotion；#21bfff；180颗；v003；共享父v005双母版
A46: player_capsule01_bunny01_3d | B46: glasses/expression/happy | C46: HeadJoint/FaceAccessorySocket/ElectronicMask/Visual/ExpressionPixels | D46: head | E46: assets/art/characters/player/chr_player_capsule01_3d/variants/bunny01/components/face/electronic_mask/expressions/chr_bunny01_expression_happy/components/chr_bunny01_expression_happy_visual_top3d.glb | F46: 14mm网格/11.8mm颗粒；发光1.25；运行时继承角色比例 | G46: HeadJoint原点；原脸曲面前移9mm | H46: Blender +Y / Godot -Z；独立根缩放1 | I46: 5 | J46: 无嘴部；加粗眼睛/爱心/符号；独立系统命令/随机/状态调用；共用Blender局部剪辑 | K46: 只替换面具表情，不更换面饰配置 | L46: 否 | M46: CHR-PLY-BUNNY01-EXPR-HAPPY；开心；emotion；#29e9ff；116颗；v003；共享父v005双母版
A47: player_capsule01_bunny01_3d | B47: glasses/expression/sad | C47: HeadJoint/FaceAccessorySocket/ElectronicMask/Visual/ExpressionPixels | D47: head | E47: assets/art/characters/player/chr_player_capsule01_3d/variants/bunny01/components/face/electronic_mask/expressions/chr_bunny01_expression_sad/components/chr_bunny01_expression_sad_visual_top3d.glb | F47: 14mm网格/11.8mm颗粒；发光1.25；运行时继承角色比例 | G47: HeadJoint原点；原脸曲面前移9mm | H47: Blender +Y / Godot -Z；独立根缩放1 | I47: 5 | J47: 无嘴部；加粗眼睛/爱心/符号；独立系统命令/随机/状态调用；共用Blender局部剪辑 | K47: 只替换面具表情，不更换面饰配置 | L47: 否 | M47: CHR-PLY-BUNNY01-EXPR-SAD；难过；emotion；#777bff；102颗；v003；共享父v005双母版
A48: player_capsule01_bunny01_3d | B48: glasses/expression/angry | C48: HeadJoint/FaceAccessorySocket/ElectronicMask/Visual/ExpressionPixels | D48: head | E48: assets/art/characters/player/chr_player_capsule01_3d/variants/bunny01/components/face/electronic_mask/expressions/chr_bunny01_expression_angry/components/chr_bunny01_expression_angry_visual_top3d.glb | F48: 14mm网格/11.8mm颗粒；发光1.25；运行时继承角色比例 | G48: HeadJoint原点；原脸曲面前移9mm | H48: Blender +Y / Godot -Z；独立根缩放1 | I48: 5 | J48: 无嘴部；加粗眼睛/爱心/符号；独立系统命令/随机/状态调用；共用Blender局部剪辑 | K48: 只替换面具表情，不更换面饰配置 | L48: 否 | M48: CHR-PLY-BUNNY01-EXPR-ANGRY；生气；emotion；#ff3028；112颗；v003；共享父v005双母版
A49: player_capsule01_bunny01_3d | B49: glasses/expression/surprised | C49: HeadJoint/FaceAccessorySocket/ElectronicMask/Visual/ExpressionPixels | D49: head | E49: assets/art/characters/player/chr_player_capsule01_3d/variants/bunny01/components/face/electronic_mask/expressions/chr_bunny01_expression_surprised/components/chr_bunny01_expression_surprised_visual_top3d.glb | F49: 14mm网格/11.8mm颗粒；发光1.25；运行时继承角色比例 | G49: HeadJoint原点；原脸曲面前移9mm | H49: Blender +Y / Godot -Z；独立根缩放1 | I49: 5 | J49: 无嘴部；加粗眼睛/爱心/符号；独立系统命令/随机/状态调用；共用Blender局部剪辑 | K49: 只替换面具表情，不更换面饰配置 | L49: 否 | M49: CHR-PLY-BUNNY01-EXPR-SURPRISED；惊讶；emotion；#ffe45c；144颗；v003；共享父v005双母版
A50: player_capsule01_bunny01_3d | B50: glasses/expression/love | C50: HeadJoint/FaceAccessorySocket/ElectronicMask/Visual/ExpressionPixels | D50: head | E50: assets/art/characters/player/chr_player_capsule01_3d/variants/bunny01/components/face/electronic_mask/expressions/chr_bunny01_expression_love/components/chr_bunny01_expression_love_visual_top3d.glb | F50: 14mm网格/11.8mm颗粒；发光1.25；运行时继承角色比例 | G50: HeadJoint原点；原脸曲面前移9mm | H50: Blender +Y / Godot -Z；独立根缩放1 | I50: 5 | J50: 无嘴部；加粗眼睛/爱心/符号；独立系统命令/随机/状态调用；共用Blender局部剪辑 | K50: 只替换面具表情，不更换面饰配置 | L50: 否 | M50: CHR-PLY-BUNNY01-EXPR-LOVE；爱心；emotion；#ff6abb；148颗；v003；共享父v005双母版
A51: player_capsule01_bunny01_3d | B51: glasses/expression/question | C51: HeadJoint/FaceAccessorySocket/ElectronicMask/Visual/ExpressionPixels | D51: head | E51: assets/art/characters/player/chr_player_capsule01_3d/variants/bunny01/components/face/electronic_mask/expressions/chr_bunny01_expression_question/components/chr_bunny01_expression_question_visual_top3d.glb | F51: 14mm网格/11.8mm颗粒；发光1.25；运行时继承角色比例 | G51: HeadJoint原点；原脸曲面前移9mm | H51: Blender +Y / Godot -Z；独立根缩放1 | I51: 5 | J51: 无嘴部；加粗眼睛/爱心/符号；独立系统命令/随机/状态调用；共用Blender局部剪辑 | K51: 只替换面具表情，不更换面饰配置 | L51: 否 | M51: CHR-PLY-BUNNY01-EXPR-QUESTION；疑问；symbol；#ffd24a；112颗；v003；共享父v005双母版
A52: player_capsule01_bunny01_3d | B52: glasses/expression/alert | C52: HeadJoint/FaceAccessorySocket/ElectronicMask/Visual/ExpressionPixels | D52: head | E52: assets/art/characters/player/chr_player_capsule01_3d/variants/bunny01/components/face/electronic_mask/expressions/chr_bunny01_expression_alert/components/chr_bunny01_expression_alert_visual_top3d.glb | F52: 14mm网格/11.8mm颗粒；发光1.25；运行时继承角色比例 | G52: HeadJoint原点；原脸曲面前移9mm | H52: Blender +Y / Godot -Z；独立根缩放1 | I52: 5 | J52: 无嘴部；加粗眼睛/爱心/符号；独立系统命令/随机/状态调用；共用Blender局部剪辑 | K52: 只替换面具表情，不更换面饰配置 | L52: 否 | M52: CHR-PLY-BUNNY01-EXPR-ALERT；警示；symbol；#a1fff2；96颗；v003；共享父v005双母版

Sheet 动画与状态
A1: 玩家状态机 × 美术组件映射
A3: Player3D 九态状态机 × 组件表现（falling/landing为真实垂直物理顶层状态）
A5: 层级 | B5: 状态ID | C5: 中文名 | D5: 允许来源 | E5: 允许去向 | F5: Body | G5: Head | H5: Hand L | I5: Hand R / WeaponSocket | J5: Scarf | K5: VFX/UI | L5: 首版实现
A6: 顶层 | B6: idle | C6: 待命 | D6: start/moving/hurt/locked/landing | E6: moving,dashing,hurt,locked,falling,dead,seated | F6: v039：无枪idle源2.4秒；三枪型使用独立sidearm_idle/longgun_idle/machinegun_idle；全局1.25倍率。 | G6: 头部起伏与延迟跟随，耳部错相摆动；不缩放头部。 | H6: 双手随源躯干扭转；单手短枪及双手长枪/机枪分别制作。 | I6: 右掌对齐源WeaponSocket，支撑手同枪体随动；射击使用独立稳枪动作，不启用程序手部覆盖。 | J6: 脚部支撑保持；身体重心转移与竖轴扭转。 | K6: HUD 待命；无新增VFX | L6: v039 active；头部起伏/前进前探/躯干竖轴扭转；移动射击保持枪口朝向。art_source/characters/player/chr_player_capsule01_3d/variants/bunny01/source/animation/chr_bunny01_animation_v039.blend；63循环源检查及运行方向/待机/关联专项通过。
A7: 顶层 | B7: moving | C7: 机动 | D7: idle/dashing/hurt/locked/landing | E7: idle,dashing,hurt,locked,falling,dead,seated | F7: v021：正常速度0.8秒小跑，慢速1秒慢走；按速度选择moving/walking及对应armed变体。 | G7: 较小反相滞后 | H7: 手枪自由左手大幅反摆；长枪左手锁定托举 | I7: 手枪右手与右侧挂点紧凑起伏；长枪双手/挂点收胸跑 | J7: 周期滞后 | K7: 地面划痕 | L7: 位移驱动独立循环；WeaponPoseFSM 进入 sidearm_run 或 longgun_run；双脚交替，单手/双手剪影分离
A8: 顶层 | B8: dashing | C8: 突进 | D8: idle/moving | E8: idle,moving,hurt,locked,falling,dead | F8: v021：0.4秒收身前翻一周后展开；root不驱动玩法位移。 | G8: 随翻滚形成清晰弧线，耳朵延迟跟随。 | H8: 按当前武器握持数收束；自由左手随整体抱团 | I8: 右手握把与 WeaponSocket 同轴完整翻滚 | J8: 随整体收束 | K8: 青色尾迹 | L8: 0.17s 内完成 360° 本地X前滚；用半高轴心补偿避免钻地；夸张压缩与抛物线位移
A9: 顶层 | B9: hurt | C9: 受创 | D9: 任意存活态 | E9: idle,moving,locked,falling,dead | F9: v021：0.55秒后仰失衡、反向回弹并收稳。 | G9: 头部甩动与耳朵拖曳形成受击重点。 | H9: 手枪左手自由外甩；长枪左手回护木 | I9: 右手/WeaponSocket 同相后退，握把不脱离 | J9: 冲击滞后 | K9: 红闪/击退轨迹 | L9: 真实命中方向 + 受击进度关键姿势；头、双脚、双耳使用独立夸张回弹
A10: 顶层 | B10: locked | C10: 交互锁定 | D10: 任意存活态/landing | E10: idle,moving,hurt,falling,dead | F10: v021：1.8秒循环警觉重心交换。 | G10: 小幅警觉转头，保持瞄准可读性。 | H10: 稳定 | I10: 保持握持 | J10: 低摆 | K10: 琥珀锁定环 | L10: 降亮 + 锁定环；保持刚性层级
A11: 顶层 | B11: falling | C11: 下落 | D11: idle/moving/dashing/hurt/locked | E11: landing,hurt,dead | F11: v021：0.65秒张臂失衡，下落末帧保持。 | G11: 头部及耳朵表现向上拖曳。 | H11: 手枪自由手收束；长枪托举手不脱离 | I11: 握持手与WeaponSocket保持同相 | J11: 向上滞后 | K11: 无新增VFX | L11: 真实重力+0.10s离地容错；双脚收起、双耳后压；楼梯接缝不误触发
A12: 顶层 | B12: landing | C12: 落地 | D12: falling | E12: idle,moving,locked,falling,hurt,dead | F12: v021：0.45秒下沉缓冲、回弹并稳定。 | G12: 承接下落末姿后抬头恢复。 | H12: 随整体吸收冲击 | I12: 握持手与WeaponSocket同相稳定 | J12: 短促回摆 | K12: 落地停顿 | L12: 冲击速度映射0.12—0.30s硬直；状态计时结束后恢复地面移动
A13: 顶层 | B13: dead | C13: 生命终止 | D13: 任意存活态 | E13: 无（终态） | F13: v021：1.6秒空中前翻一周，正面朝下趴地，弹一次后保持。 | G13: 头部随整身落地；双臂向头顶两侧伸出。 | H13: 随击飞惯性展开，回弹时收束 | I13: 武器握持层随整体击飞/回弹/侧倒 | J13: 惯性拖尾后停止 | K13: 1.35秒后显示点击返99F确认框 | L13: 真实CharacterBody3D速度+重力；death_animation_finished仅通知表现完成，点击后结算
A14: 叠加 | B14: low_health | C14: 低血 | D14: 任意存活态 | E14: 不改变顶层 | F14: 不变 | G14: 不变 | H14: 保持当前动作 | I14: 保持当前动作 | J14: 不变 | K14: 红色呼吸环 | L14: HP≤30%
