Workbook

Sheet 总览
A1: SHELLSTORM 2 · 特效美术账本 v0.1
A3: 归属域=特效｜覆盖大类=特效｜AssetID 前缀=VFX / FX｜主账本（总目录）=assets/registry/ShellStorm2_美术资产台账_v001.xlsx；本账本可独立并行编辑，跨域契约见主账本
A5: 资产总数 | C5: 已完成/已接入 | E5: 待制作/程序占位 | G5: 重复警报 | I5: 域内专表 / 3D Prefab 分页
A6: =COUNTA('资产主表'!$A$6:$A$53) | C6: =COUNTIF('资产主表'!$K$6:$K$53,"已完成")+COUNTIF('资产主表'!$K$6:$K$53,"原型已接入")+COUNTIF('资产主表'!$K$6:$K$53,"正式美术已接入")+COUNTIF('资产主表'!$K$6:$K$53,"已优化并正式接入")+COUNTIF('资产主表'!$K$6:$K$53,"Blender源已完成")+COUNTIF('资产主表'!$K$6:$K$53,"已导入；优化完成")+COUNTIF('资产主表'!$K$6:$K$53,"白模源已完成；QA PASS") | E6: =COUNTIF('资产主表'!$K$6:$K$53,"待制作")+COUNTIF('资产主表'!$K$6:$K$53,"程序占位") | G6: =COUNTIF('资产主表'!$S$6:$S$53,"重复") | I6: 域内专表：3D-特效 | 3D Prefab 分页：3D-特效
A9: 大类 | B9: 资产数 | C9: 完成/接入 | E9: 本账本只登记上列大类；跨域搬运资产须同步主账本《分类与编码》并重跑门禁
A10: 特效 | B10: =COUNTIF('资产主表'!$C$6:$C$53,A10) | C10: =SUMPRODUCT(('资产主表'!$C$6:$C$53=A10)*(('资产主表'!$K$6:$K$53="已完成")+('资产主表'!$K$6:$K$53="原型已接入")+('资产主表'!$K$6:$K$53="正式美术已接入")+('资产主表'!$K$6:$K$53="已优化并正式接入")+('资产主表'!$K$6:$K$53="Blender源已完成")+('资产主表'!$K$6:$K$53="已导入；优化完成")+('资产主表'!$K$6:$K$53="白模源已完成；QA PASS")))
A11: 子弹特效 | B11: =COUNTIF('资产主表'!$C$6:$C$53,A11) | C11: =SUMPRODUCT(('资产主表'!$C$6:$C$53=A11)*(('资产主表'!$K$6:$K$53="已完成")+('资产主表'!$K$6:$K$53="原型已接入")+('资产主表'!$K$6:$K$53="正式美术已接入")+('资产主表'!$K$6:$K$53="已优化并正式接入")+('资产主表'!$K$6:$K$53="Blender源已完成")+('资产主表'!$K$6:$K$53="已导入；优化完成")+('资产主表'!$K$6:$K$53="白模源已完成；QA PASS")))
A12: 合计 | B12: =SUM(B10:B11) | C12: =SUM(C10:C11)
A14: 域内 3D Prefab 分页统计（快照口径与本账本分页一致；权威清单在各分页表）
A15: 分页 | B15: Prefab 数 | C15: 直接引用 GLB | D15: 有功能脚本 | E15: 碰撞开启 | F15: 说明
A16: 3D-特效 | B16: =COUNTA('3D-特效'!$A$5:$A$204) | C16: =COUNTIF('3D-特效'!$D$5:$D$204,"<>") | D16: =COUNTIF('3D-特效'!$G$5:$G$204,"<>") | E16: =COUNTIF('3D-特效'!$H$5:$H$204,"开") | F16: 一行 = 一个实际存在的 Godot PackedScene
A17: 合计 | B17: =SUM(B16) | C17: =SUM(C16) | D17: =SUM(D16) | E17: =SUM(E16)

Sheet 账本说明
A1: 本账本说明 · 特效
A3: 本表是分账本自描述；机器可读真源为 assets/registry/ledger_index.json，二者不一致时以 JSON 为准
A5: 项 | B5: 值
A6: 账本归属域 | B6: 特效
A7: 分账本文件 | B7: assets/registry/ledgers/ShellStorm2_特效账本_v001.xlsx
A8: 覆盖大类 | B8: 特效 / 子弹特效
A9: AssetID 前缀 | B9: VFX / FX
A10: 域内专表 | B10: 3D-特效
A11: 3D Prefab 分页 | B11: 3D-特效
A12: 动画登记表 | B12: 无
A13: 主账本（总目录） | B13: assets/registry/ShellStorm2_美术资产台账_v001.xlsx
A14: 跨域契约 | B14: 分类与编码 / 命名与查重 / 版本记录 / Skill 清单 / 3D Prefab 总控 —— 全部只在主账本维护
A15: 首选制作 Skill | B15: godot-model-asset-import-standard
A16: 协作 Skill | B16: 无
... A23: 快照日期 | B23: 2026-09-18

Sheet 资产主表
A1: 资产主表 · 唯一登记源
A3: 查重键由公式生成；S 列出现“重复”时禁止制作，先合并或建立变体父子关系
A5: AssetID | B5: 中文名 | C5: 大类 | D5: 子类 | E5: 逻辑ID/源键 | F5: 组件槽 | G5: 变体父ID | H5: 视角 | I5: 状态/动画 | J5: 复用范围 | K5: 制作状态 | L5: 优先级 | M5: 版本 | N5: 规格(px) | O5: 文件路径 | P5: 源码/策划依据 | Q5: 关键词/别名 | R5: 查重键 | S5: 查重结果 | T5: SHA-256 | U5: 负责人 | V5: 更新时间 | W5: 来源/许可 | X5: 源编号（Blender collection） | Y5: 备注
A6: VFX-PLY-DASH-TRAIL | B6: 玩家冲刺尾迹 | C6: 特效 | D6: player_state | E6: player_dash | F6: root | H6: 侧面朝右（可水平翻转） | I6: dashing | J6: 玩家状态 | K6: 弃用 | L6: P1 | M6: v001 | N6: 待定 | R6: =LOWER(TRIM(C6)&"|"&TRIM(D6)&"|"&TRIM(E6)&"|"&TRIM(F6)&"|"&TRIM(H6)&"|"&TRIM(I6)) | S6: =IF(COUNTIF($R$6:$R$53,R6)>1,"重复","唯一") | U6: 待分配 | V6: 46243 | W6: 原创/待确认 | X6: — | Y6: 2026-08-09：旧2D PlayerAvatarRenderer专用表现已删除；当前3D状态表现由 PlayerAvatar3D / WeaponModel3D 持有。
A7: VFX-PLY-HURT-FLASH | B7: 玩家受击闪光 | C7: 特效 | D7: player_state | E7: player_hurt | F7: root | H7: 侧面朝右（可水平翻转） | I7: hurt | J7: 玩家状态 | K7: 弃用 | L7: P1 | M7: v001 | N7: 待定 | R7: =LOWER(TRIM(C7)&"|"&TRIM(D7)&"|"&TRIM(E7)&"|"&TRIM(F7)&"|"&TRIM(H7)&"|"&TRIM(I7)) | S7: =IF(COUNTIF($R$6:$R$53,R7)>1,"重复","唯一") | U7: 待分配 | V7: 46243 | W7: 原创/待确认 | X7: — | Y7: 2026-08-09：旧2D PlayerAvatarRenderer专用表现已删除；当前3D状态表现由 PlayerAvatar3D / WeaponModel3D 持有。
A8: VFX-PLY-LOWHP-RING | B8: 玩家低血环 | C8: 特效 | D8: player_overlay | E8: player_low_hp | F8: root | H8: 侧面朝右（可水平翻转） | I8: low_health | J8: 叠加状态 | K8: 弃用 | L8: P2 | M8: v001 | N8: 待定 | R8: =LOWER(TRIM(C8)&"|"&TRIM(D8)&"|"&TRIM(E8)&"|"&TRIM(F8)&"|"&TRIM(H8)&"|"&TRIM(I8)) | S8: =IF(COUNTIF($R$6:$R$53,R8)>1,"重复","唯一") | U8: 待分配 | V8: 46243 | W8: 原创/待确认 | X8: — | Y8: 2026-08-09：旧2D PlayerAvatarRenderer专用表现已删除；当前3D状态表现由 PlayerAvatar3D / WeaponModel3D 持有。
A9: VFX-PLY-SILENCED-RING | B9: 玩家沉默干扰环 | C9: 特效 | D9: player_overlay | E9: player_silenced | F9: root | H9: 侧面朝右（可水平翻转） | I9: silenced | J9: 叠加状态 | K9: 弃用 | L9: P2 | M9: v001 | N9: 待定 | R9: =LOWER(TRIM(C9)&"|"&TRIM(D9)&"|"&TRIM(E9)&"|"&TRIM(F9)&"|"&TRIM(H9)&"|"&TRIM(I9)) | S9: =IF(COUNTIF($R$6:$R$53,R9)>1,"重复","唯一") | U9: 待分配 | V9: 46243 | W9: 原创/待确认 | X9: — | Y9: 2026-08-09：旧2D PlayerAvatarRenderer专用表现已删除；当前3D状态表现由 PlayerAvatar3D / WeaponModel3D 持有。
A10: VFX-EXPLOSION | B10: 爆炸 | C10: 特效 | D10: gameplay_vfx | E10: explosion | F10: root | H10: 顶视/屏幕空间 | I10: default | J10: 跨武器/跨场景 | K10: 程序占位 | L10: P1 | M10: v001 | N10: 粒子或 8–16 帧序列 | P10: scenes/ExplosionEffect.tscn | R10: =LOWER(TRIM(C10)&"|"&TRIM(D10)&"|"&TRIM(E10)&"|"&TRIM(F10)&"|"&TRIM(H10)&"|"&TRIM(I10)) | S10: =IF(COUNTIF($R$6:$R$53,R10)>1,"重复","唯一") | U10: 待分配 | V10: 46224 | W10: 原创/待确认 | X10: — | Y10: 颜色/尺寸作参数变体，禁止复制整套
A11: VFX-MUZZLE-FLASH | B11: 枪口火焰 | C11: 特效 | D11: gameplay_vfx | E11: muzzle_flash | F11: root | H11: 顶视/屏幕空间 | I11: default | J11: 跨武器/跨场景 | K11: 程序占位 | L11: P1 | M11: v001 | N11: 粒子或 8–16 帧序列 | P11: src/weapon/WeaponDisplay.gd | R11: =LOWER(TRIM(C11)&"|"&TRIM(D11)&"|"&TRIM(E11)&"|"&TRIM(F11)&"|"&TRIM(H11)&"|"&TRIM(I11)) | S11: =IF(COUNTIF($R$6:$R$53,R11)>1,"重复","唯一") | U11: 待分配 | V11: 46224 | W11: 原创/待确认 | X11: — | Y11: 颜色/尺寸作参数变体，禁止复制整套
A12: VFX-DAMAGE-NUMBER | B12: 伤害数字 | C12: 特效 | D12: gameplay_vfx | E12: damage_number | F12: root | H12: 顶视/屏幕空间 | I12: default | J12: 跨武器/跨场景 | K12: 程序占位 | L12: P2 | M12: v001 | N12: 粒子或 8–16 帧序列 | P12: scenes/DamageNumber.tscn | R12: =LOWER(TRIM(C12)&"|"&TRIM(D12)&"|"&TRIM(E12)&"|"&TRIM(F12)&"|"&TRIM(H12)&"|"&TRIM(I12)) | S12: =IF(COUNTIF($R$6:$R$53,R12)>1,"重复","唯一") | U12: 待分配 | V12: 46224 | W12: 原创/待确认 | X12: — | Y12: 颜色/尺寸作参数变体，禁止复制整套
A13: VFX-SPARK | B13: 火花 | C13: 特效 | D13: gameplay_vfx | E13: spark | F13: root | H13: 顶视/屏幕空间 | I13: default | J13: 跨武器/跨场景 | K13: 程序占位 | L13: P2 | M13: v001 | N13: 粒子或 8–16 帧序列 | P13: src/fx/SparkParticles.gd | R13: =LOWER(TRIM(C13)&"|"&TRIM(D13)&"|"&TRIM(E13)&"|"&TRIM(F13)&"|"&TRIM(H13)&"|"&TRIM(I13)) | S13: =IF(COUNTIF($R$6:$R$53,R13)>1,"重复","唯一") | U13: 待分配 | V13: 46224 | W13: 原创/待确认 | X13: — | Y13: 颜色/尺寸作参数变体，禁止复制整套
A14: VFX-ROOM-TRANSITION | B14: 房间转场 | C14: 特效 | D14: gameplay_vfx | E14: room_transition | F14: root | H14: 顶视/屏幕空间 | I14: default | J14: 跨武器/跨场景 | K14: 程序占位 | L14: P2 | M14: v001 | N14: 粒子或 8–16 帧序列 | P14: src/fx/RoomTransitionFX.gd | R14: =LOWER(TRIM(C14)&"|"&TRIM(D14)&"|"&TRIM(E14)&"|"&TRIM(F14)&"|"&TRIM(H14)&"|"&TRIM(I14)) | S14: =IF(COUNTIF($R$6:$R$53,R14)>1,"重复","唯一") | U14: 待分配 | V14: 46224 | W14: 原创/待确认 | X14: — | Y14: 颜色/尺寸作参数变体，禁止复制整套
A15: VFX-VISIBILITY-LIGHT | B15: 视野光锥 | C15: 特效 | D15: gameplay_vfx | E15: visibility_light | F15: root | H15: 顶视/屏幕空间 | I15: default | J15: 跨武器/跨场景 | K15: 程序占位 | L15: P2 | M15: v001 | N15: 粒子或 8–16 帧序列 | P15: src/fx/VisibilityLight2D.gd | R15: =LOWER(TRIM(C15)&"|"&TRIM(D15)&"|"&TRIM(E15)&"|"&TRIM(F15)&"|"&TRIM(H15)&"|"&TRIM(I15)) | S15: =IF(COUNTIF($R$6:$R$53,R15)>1,"重复","唯一") | U15: 待分配 | V15: 46225 | W15: 原创/待确认 | X15: — | Y15: 2D视野表现根；3D真实判定与地面网格登记为 VFX-VISIBILITY-FIELD-3D，禁止用灯光替代
A16: VFX-EXTRACTION-BEACON | B16: 撤离信标效果 | C16: 特效 | D16: gameplay_vfx | E16: extraction_beacon | F16: root | H16: 顶视/屏幕空间 | I16: default | J16: 跨武器/跨场景 | K16: 程序占位 | L16: P2 | M16: v001 | N16: 粒子或 8–16 帧序列 | P16: src/map/ExtractionDirector.gd | R16: =LOWER(TRIM(C16)&"|"&TRIM(D16)&"|"&TRIM(E16)&"|"&TRIM(F16)&"|"&TRIM(H16)&"|"&TRIM(I16)) | S16: =IF(COUNTIF($R$6:$R$53,R16)>1,"重复","唯一") | U16: 待分配 | V16: 46224 | W16: 原创/待确认 | X16: — | Y16: 颜色/尺寸作参数变体，禁止复制整套
A17: VFX-HAZARD-FIELD-3D | B17: 房间危险场3D特效 | C17: 特效 | D17: environment | E17: hazard_field | F17: root_3d | G17: ENV-DUNGEON-RUNTIME-3D | H17: 俯视3D | I17: active | J17: 陷阱房 | K17: 原型已接入 | L17: P0 | M17: v001 | N17: PackedScene/程序环形特效 | O17: assets/art/vfx/environment_3d/vfx_hazard_field_root_top3d.tscn | P17: src/world3d/HazardField3D.gd | Q17: 危险区;陷阱;范围伤害;3D | R17: =LOWER(TRIM(C17)&"|"&TRIM(D17)&"|"&TRIM(E17)&"|"&TRIM(F17)&"|"&TRIM(H17)&"|"&TRIM(I17)) | S17: =IF(COUNTIF($R$6:$R$53,R17)>1,"重复","唯一") | T17: 9457d360dc6529e42502980b94188d13f76da5efb581b261cfb9b8adbd0f5ff6 | U17: Codex | V17: 46224 | W17: 原创程序特效 | X17: — | Y17: 颜色、半径与伤害可按主题配置
A18: VFX-COMBAT-KIT-3D | B18: 战斗反馈3D通用特效套件 | C18: 特效 | D18: combat | E18: combat_feedback | F18: root_3d | H18: 俯视3D | I18: muzzle_impact_damage_explosion_slash_melee_impact | J18: 枪械/近战/敌人/关卡 | K18: 原型已接入 | L18: P0 | M18: v001 | N18: PackedScene/参数化特效 | O18: assets/art/vfx/combat_3d/vfx_combat_kit_root_top3d.tscn | P18: src/combat3d/CombatEffect3D.gd; src/combat3d/CombatEffectPool3D.gd; src/player3d/melee/PlayerMeleeCombat3D.gd | Q18: 枪口;命中;伤害;爆炸;挥砍;近战冲击;slash;melee_impact;3D | R18: =LOWER(TRIM(C18)&"|"&TRIM(D18)&"|"&TRIM(E18)&"|"&TRIM(F18)&"|"&TRIM(H18)&"|"&TRIM(I18)) | S18: =IF(COUNTIF($R$6:$R$53,R18)>1,"重复","唯一") | T18: 59cd5409b33ff9fae9c541b357699249d8f0574bc21add6fec2d1fdfd89a098e | U18: Codex | V18: 46224 | W18: 原创程序特效 | X18: — | Y18: effect kind、颜色、尺寸、方向与连段参数化；新增slash/melee_impact无碰撞池化种类，复用同一战斗VFX根；近战专项验证一段一弧光、逐目标爆点。
A19: VFX-VISIBILITY-FIELD-3D | B19: 柔边真实单位视野场3D | C19: 特效 | D19: gameplay_vfx | E19: visibility_field | F19: field_mesh_3d | G19: VFX-VISIBILITY-LIGHT | H19: 俯视3D | I19: default | J19: 3D行动区/靶场/基地 | K19: 原型已接入 | L19: P0 | M19: v001 | N19: 360°逻辑射线 + ImmediateMesh 49+28表现射线 | O19: src/player3d/PlayerVision3D.gd | P19: scenes/Player3D.tscn | Q19: 360度逻辑视野;96度目光表现;柔边;墙体遮挡;无描边;非灯光判定 | R19: =LOWER(TRIM(C19)&"|"&TRIM(D19)&"|"&TRIM(E19)&"|"&TRIM(F19)&"|"&TRIM(H19)&"|"&TRIM(I19)) | S19: =IF(COUNTIF($R$6:$R$53,R19)>1,"重复","唯一") | T19: 3a5f9e551802a19e6415e15ee32cea76fe74545bf64af0fcb847c54d3972e740 | U19: Codex | V19: 46264 | W19: 原创程序几何 | X19: — | Y19: 目标显隐使用21m内360°逐目标物理遮挡；身后无遮挡目标保持可见，任意方向的墙/关闭门/实体家具均可遮挡。地面表现保留96°/21m + 2.4m、49+28固定射线、柔边无描边和地板深度豁免；真实照明仍拆为 VFX-PLAYER-FLASHLIGHT-3D。 2026-08-30 AST-02：合法内容更新；文件为Git已跟踪且修改时间不早于原台账日期；验收：verify_3d_vision_input_flow；SHA f2b2eaf61798→3405769a7da2。
A20: VFX-PLAYER-FLASHLIGHT-3D | B20: 玩家真实探照灯组件3D | C20: 特效 | D20: gameplay_vfx | E20: player_flashlight | F20: light_rig_3d | G20: VFX-VISIBILITY-FIELD-3D | H20: 俯视3D | I20: default | J20: 3D行动区/靶场/基地 | K20: 原型已接入 | L20: P0 | M20: v001 | N20: PackedScene/2 SpotLight3D+1 OmniLight3D | O20: assets/art/vfx/visibility_3d/vfx_player_flashlight_root_top3d.tscn | P20: src/player3d/PlayerFlashlight3D.gd | Q20: 真实探照灯;玩家灯光;前向聚光;角色补光;可调灯光 | R20: =LOWER(TRIM(C20)&"|"&TRIM(D20)&"|"&TRIM(E20)&"|"&TRIM(F20)&"|"&TRIM(H20)&"|"&TRIM(I20)) | S20: =IF(COUNTIF($R$6:$R$53,R20)>1,"重复","唯一") | T20: 66d910c4fbcfd63176427c8012d3b6dbb11c4e0999587b34a3a66d6202920017 | U20: Codex | V20: 46225 | W20: 原创程序几何 | X20: — | Y20: v0.1：ForwardBeam仅照环境layer1，shadow_caster_mask也仅包含layer1，明确排除玩家、穿戴物与手持枪layer2；AvatarFrontFill无阴影。玩家网格保留cast_shadow=ON，由太阳和室内灯产生外部投影；准星禁用投影。曝光预算固定为主聚光7.2、环境溢光0.7、角色柔光2.8，并通过真实渲染验收。 2026-08-03：主聚光保持能量7.2/范围25m/角度66°与环境层隔离；Compatibility阴影采样固定 bias=0.18、normal_bias=1.6、blur=1.2，消除远处斜角墙面横纹，不改变玩家自身不投影契约；已通过近25m真GPU画面验收。
A21: VFX-SHELL-CASING-3D | B21: 抛壳落地特效 | C21: 特效 | D21: 战斗反馈 | E21: FX01-07 | H21: 俯视3D | I21: 开火抛壳/落地 | J21: 玩家/敌人远程枪械 | K21: 已完成 | L21: P1 | M21: v001 | N21: PackedScene/程序运动 | O21: assets/art/vfx/combat_3d/vfx_shell_casing_root_top3d.tscn | P21: src/vfx/VfxShellCasing3D.gd | Q21: 弹壳,抛壳,落地,枪械反馈 | R21: =LOWER(TRIM(C21)&"|"&TRIM(D21)&"|"&TRIM(E21)&"|"&TRIM(F21)&"|"&TRIM(H21)&"|"&TRIM(I21)) | S21: =IF(COUNTIF($R$6:$R$53,R21)>1,"重复","唯一") | T21: df2cb64e06aa312f19a4c330a13c37b8c36f6884308c900181a7597a051fbf93 | U21: 摩斯拉 | V21: 46287 | W21: 原创程序几何 | X21: — | Y21: 独立纯视觉 Prefab，无碰撞体；每次成功开火生成 1 枚；从枪械右侧抛出，重力 9.8m/s²，命中地板最多 2 次小弹跳后静止，3.2s 回收；验收 verify_combat_vfx_toon_v002。 PBR 定档：金属度 metallic=0.8 / 反光度（roughness）=0.6，壳体/底缘/底火三件统一（2026-09-22 指定）。 【模拟碰撞】落地改为**纯程序化模拟碰撞**（解析式越线，不做任何物理射线/空间查询，Prefab 无碰撞体）：弹壳中心 y 越过「地面高度 + 贴地半径」即视为碰撞；运动为 飞行(弹跳) → 贴地滚动 → 躺平静止 三阶段；触地带挤压包络。视觉尺寸缩到原基准 **80%**（WeaponModel3D.SHELL_CASING_SIZE=0.8）。⚠️ context.floor_y 必须由调用方按真实世界给，禁以 0 兜底 —— 塔楼楼层向下建（98F ≈ -1176m），兜底 0 会让弹壳出生即判触地、瞬移到世界原点而看不见（2026-09-22 实机缺陷）；调用方口径 = 射击者站立面 y，见 WeaponModel3D._resolve_shell_floor_y()。贴地半径取三件最大径向半展 0.058（底缘），非壳体 0.045。
A22: VFX-ENV-CLOUD-SEA-3D | B22: 主塔柔软体积云海与漂浮小云 | C22: 特效 | D22: environment | E22: outdoor_cloud_sea | F22: root_3d | H22: 俯视3D | I22: slow_flow | J22: 主塔与周边塔楼99F以下室外 | K22: 正式美术已接入 | L22: P1 | M22: v002 | N22: 连续世界密度云海476×90×536m，Y=-105～-15，云顶圆润起伏、云内遮光、下层薄雾、楼边透出下方楼层。24块漂浮小云，低档12块；高/中/低96/64/40步体积采样、4/3/2步定向透射。image-2原创1024²灰度密度，128³ RGB周期云结构，256×80×288 R8建筑避让；无碰撞。 | O22: assets/art/vfx/environment_3d/cloud_sea/vfx_env_cloud_sea_root_top3d.tscn | P22: src/vfx/VfxCloudSea3D.gd; docs/v0.1/design/outdoor_cloud_sea.md; source/v002 | Q22: 云海;体积云;光遇风格;柔软;漂浮;薄雾;室外 | R22: =LOWER(TRIM(C22)&"|"&TRIM(D22)&"|"&TRIM(E22)&"|"&TRIM(F22)&"|"&TRIM(H22)&"|"&TRIM(I22)) | S22: =IF(COUNTIF($R$6:$R$53,R22)>1,"重复","唯一") | T22: f7830ac829de78bdbf189b89ab16a2c5d8b8730e2cb0a694809e7472fa60d63c | U22: Codex | V22: 46295 | W22: 项目原创Shader/三维程序密度；gpt-image-2原创灰度云贴图，用户参考图仅作风格参考 | X22: FX03-02 / procedural_cloud_sea | Y22: v002品质优先版，尚未专项优化。主场景OutdoorClouds持有；主塔全高度禁云，700建筑边界随最新布局重烘焙；建筑改变时用最多16个保守解析区域单独避让，不再隐藏整套云。正式西北楼角、天台520m及99F145m视距均验证云可见、亮部有余量；GPU纹理与实际兜底参数、暂停、60秒流动及变动建筑继续避让通过。原AssetID原行更新。
A23: VFX-RADIO-MUSIC-NOTES-3D | B23: 收音机音乐上飘音符 | C23: 特效 | D23: environment | E23: base99_radio_music_notes | F23: root_3d | H23: 俯视3D | I23: continuous_music | J23: 99F收音机/复用radio附件 | K23: 正式美术已接入 | L23: P1 | M23: v001 | N23: 独立radio child纯视觉持续附件；5预制QuadMesh槽位/10三角形；Godot生成四分/八分/双八分音符纹理，无字体依赖；billboard当前相机；淡青绿/暖金unshaded无emission；2.5发/s、寿命1.8s、上飘1.1m、横摆0.09m、尺度0.88~1.06、淡入0.16s、末0.45s淡出；本地挂点Y1.42m；无碰撞/灯光/音频；真实playing驱动，A/B连续，off/离99/exit同步清空；不进任何战斗池。 单符Quad最终0.46×0.52m、出生横向偏移±0.22m。 | O23: assets/art/vfx/environment_3d/radio_music_notes/vfx_radio_music_notes_root_top3d.tscn | P23: src/vfx/VfxRadioMusicNotes3D.gd; src/base3d/Base99Radio3D.gd; tests/verification/verify_base99_radio_music_notes.tscn | Q23: 音符;音乐;收音机;八分;双八分;billboard | R23: =LOWER(TRIM(C23)&"|"&TRIM(D23)&"|"&TRIM(E23)&"|"&TRIM(F23)&"|"&TRIM(H23)&"|"&TRIM(I23)) | S23: =IF(COUNTIF($R$6:$R$53,R23)>1,"重复","唯一") | T23: f4f3382a58135ff5aafd394d7360f5a2f1e084fb5731519f05f2c18648f77a12 | U23: CodeBuddy | V23: 46303 | W23: 原创Godot ImageTexture/QuadMesh；无第三方字体 | X23: FX03-03 | Y23: 宿主唯一生命周期；固定槽位非live节点增殖；off全部槽位隐藏、alpha=0、age=-1；主体599面独立统计。
A24: VFX-ENV-BIRDS-FLYBY-3D | B24: 鸟群空中掠过 | C24: 特效 | D24: environment | E24: env_birds_flyby | F24: flock_root | H24: 3D | I24: flyby | J24: 室外场景环境氛围 | K24: 正式美术已接入 | L24: P1 | M24: v003 | N24: 7只；每鸟296三角面/11骨骼；导入尺度75%（上版150%），每鸟±10%错落；共享场景哑光材质/PaletteUV R10C10冷白；无碰撞；200m/24s，速度8.33m/s为上版50%；错落编队；振翅135%保持 | O24: assets/art/vfx/environment_3d/bird_flocks/runtime/flyby/vfx_env_birds_flyby_root_top3d.tscn | P24: art_source/vfx/environment_3d/bird_flocks/source/flyby/v001/asset_manifest.json; GLB; Godot PackedScene | Q24: 鸟群;场景特效;低模;白色;拍翼;落地;啄地 | R24: =LOWER(TRIM(C24)&"|"&TRIM(D24)&"|"&TRIM(E24)&"|"&TRIM(F24)&"|"&TRIM(H24)&"|"&TRIM(I24)) | S24: =IF(COUNTIF($R$6:$R$53,R24)>1,"重复","唯一") | T24: f2f77648bad2e897294293474faaedf3a0777d8ca662bd9d3aae8a9c5e4c4413 | U24: Codex | V24: 46307 | W24: 原创程序建模与人工动作编排；项目共享材质 | X24: 02_游戏输出_鸟群资产包 | Y24: 运行包装v003，Blender/GLB母版v001；24秒+间隔20秒；桥上(20,1.6,-64.5)，桥下塔2屋顶上方(20,-9,-70)，后一组延迟5秒；独立实例裁剪动画，不改GLB资源。；按吊桥玩家摄像机红框纠正位置，路线移近桥边，穿过左右两侧空域。；本轮各鸟比上版大50%并±10%错落，空中速度减半，航程200m/24s。
A25: VFX-ENV-BIRDS-GROUND-3D | B25: 鸟群落地停留再起飞 | C25: 特效 | D25: environment | E25: env_birds_ground | F25: flock_root | H25: 3D | I25: land_walk_peck_takeoff | J25: 室外场景环境氛围 | K25: 正式美术已接入 | L25: P1 | M25: v003 | N25: 7只；每鸟296三角面/11骨骼；导入尺度75%（上版150%），每鸟±10%错落；共享场景哑光材质/PaletteUV R10C10冷白；无碰撞；24秒落地/啄地/起飞演出；尺寸变化补偿脚底高度 | O25: assets/art/vfx/environment_3d/bird_flocks/runtime/ground/vfx_env_birds_ground_root_top3d.tscn | P25: art_source/vfx/environment_3d/bird_flocks/source/ground/v001/asset_manifest.json; GLB; Godot PackedScene | Q25: 鸟群;场景特效;低模;白色;拍翼;落地;啄地 | R25: =LOWER(TRIM(C25)&"|"&TRIM(D25)&"|"&TRIM(E25)&"|"&TRIM(F25)&"|"&TRIM(H25)&"|"&TRIM(I25)) | S25: =IF(COUNTIF($R$6:$R$53,R25)>1,"重复","唯一") | T25: 0c2584b52972808854c94e9885a1550538eba47cc52b2ea076afb00fa7edd666 | U25: Codex | V25: 46307 | W25: 原创程序建模与人工动作编排；项目共享材质 | X25: 02_游戏输出_鸟群资产包 | Y25: 运行包装v003，Blender/GLB母版v001；24秒+间隔30秒；100F天台局部(25,0,-31)；尺寸75%±10%，路径保持，补偿脚底高度。；本轮各鸟比上版大50%并±10%错落，空中速度减半，航程200m/24s。
A26: VFX-BULLET-VISUAL-3D | B26: 飞行子弹通用弹体视觉（共用父体） | C26: 子弹特效 | D26: bullet_shared | E26: FX01-06 | F26: root_3d | H26: 俯视3D | I26: flight | J26: 玩家/敌人飞行子弹 | K26: 已完成 | L26: P0 | M26: v001 | N26: PackedScene/程序几何（铂金亮芯胶囊 + 弹色半透明外壳 + 沿弹道拖尾锥 + 跟随灯） | O26: assets/art/vfx/combat_3d/vfx_bullet_visual_root_top3d.tscn | P26: src/vfx/VfxBulletVisual3D.gd; src/combat3d/Projectile3D.gd | Q26: 子弹;弹体;尾迹;飞行;投射物;projectile;bullet;3D;共用弹体 | R26: =LOWER(TRIM(C26)&"|"&TRIM(D26)&"|"&TRIM(E26)&"|"&TRIM(F26)&"|"&TRIM(H26)&"|"&TRIM(I26)) | S26: =IF(COUNTIF($R$6:$R$53,R26)>1,"重复","唯一") | T26: 2293c574f80d5d6103c0088c5fc385c1b9bd72600cc71c61bf2e4748d9f6b2d2 | U26: 摩斯拉 | V26: 2026-10-13 00:00:00 | W26: 原创程序几何 | X26: FX01-06 | Y26: 由《3D-特效》分页 FX01-06 补登进《资产主表》——该 Prefab 此前只登记在分页，主表缺行，与「《资产主表》＝唯一登记源」的口径不符。宿主唯一生命周期：由 Projectile3D 作为子节点持有，随 ProjectilePool3D 回收；刻意不进 VfxPool3D 注册表，避免弹体池与特效池双重所有权（见 14.6 §1.3/§3.5 与 skill vfx-combat-effect-authoring）。本行同时是 8 个弹种专属弹体特效的变体父体（G 列指向本 AssetID），弹种专属 Prefab 落地后仍复用本行的弹芯/外壳/拖尾几何分层，仅按弹种替换外观与行为段。 【枪族弹体尺寸档 2026-10-14】业主「每把枪的子弹大小要做出区分」+「散射喷壶的子弹太小了，出生和结束都增加 2 倍」+「减面，减到 100 个面以下先」：① **尺寸两层**：弹体视觉尺寸 = 弹种 profile × 枪身族档位（档位真源 WeaponModel3D.BULLET_GEOMETRY_BY_GUN_TAG，键 = 枪身 tags 族标识，不是 gun_id —— 按族声明，新增同族枪自动继承）。三档：散射喷壶 shotgun 各向同性 ×2.00 + 由小变大（出生 0.84、0.30s 线性长到 2.00；grow_from = 0.42 是**比例**，保持不变即出生与长满两端同步 ×2）；反胃榴弹筒 launcher ×1.55；弹弓狙击 sniper 横向 ×0.95 + 沿飞行轴 ×2.0（净长 1.90 倍）；其余枪中性档。轴向拉伸只落各件自己的局部长轴与尾迹段距，不写父级 scale/rotation（父级非均匀缩放 × 子级旋转 = 剪切变形）。② **链路**：WeaponModel3D 解析 → projectile_config.gun_bullet_geometry → Projectile3D._gun_bullet_geometry → activate 的 context（axial_scale / grow_from / grow_duration）→ VfxBulletBody3D；子投射物继承，池化复借在 configure 与 deactivate 双处复位。③ **纯视觉边界**：枪身档位不进碰撞半径 —— Projectile3D 的 _visual_scale_factor()（弹种 × 命运 × 枪身族，供视觉）与 _collision_scale_factor()（只含弹种 × 命运，供 0.12 基准球）已拆开，验收有正面断言钉住。④ **低面数档**：弹芯/外壳由 CapsuleMesh 改为 4 边棱柱（CylinderMesh，16 面/件）—— CapsuleMesh 的圆头来自 rings，rings=0 的「胶囊」等价平盖圆柱且贵 8 面，rings=1 要 48 面/件、两件即吃掉 100 面全部预算；尾迹锥 4 段（12 面）、滴珠改 BoxMesh（16→12 面，滴珠世界尺寸仅 0.011~0.018m 不可分辨）、黑洞/气球球核 SphereMesh 4×1（16 面）。单弹总面数 **44~80**（改前 468~1020，降 92%~94%）；均值 819 → **61.3**；霰弹枪一次 5 发 3660 → **220** 面。**件数与尾迹构图未动**（件数属账本与验收契约）。缩放不改变面数。分段常量集中在 VfxBulletBody3D 顶部与 VfxBulletVisual3D._SEGMENTS。⑤ **验收**：verify_bullet_vfx_profiles（samples=69）—— 9 枪档位 + 生长包络步进 + 中性档不启用 + 复借复位 + 碰撞半径守卫 + 面数预算（上限 100 与逐弹种实测值双层钉住，期望硬编码在验收侧）；反向对照 RC1~RC8 全部精准变红后还原复绿（文件 md5 与改前一致）。
A27: VFX-BULLET-STANDARD-3D | B27: 标准子弹弹体与尾迹特效 | C27: 子弹特效 | D27: bullet_standard | E27: mod_bullet_standard | F27: root_3d | G27: VFX-BULLET-VISUAL-3D | H27: 俯视3D | I27: flight_neutral | J27: 标准子弹模块（mod_bullet_standard） | K27: 已完成 | L27: P1 | M27: v001 | N27: 弹芯胶囊 r=0.045/h=0.20；外壳 r=0.075/h=0.18；单锥尾迹 底0.055/长0.46；灯 energy1.15/range1.75m | O27: assets/art/vfx/combat_3d/vfx_bullet_standard_root_top3d.tscn | P27: docs/v0.1/04_技术施工_战斗与局内成长.md §6.2（子弹模块必填 visual_id）; docs/v0.1/data/ShellStorm2_游戏内容数据库_v010.xlsx#武器 S17/T17; src/base/BlueprintRegistry.gd（mod_bullet_standard） | Q27: 子弹特效;标准子弹;标准弹;中性弹体;尾迹;kinetic;standard;3D | R27: =LOWER(TRIM(C27)&"|"&TRIM(D27)&"|"&TRIM(E27)&"|"&TRIM(F27)&"|"&TRIM(H27)&"|"&TRIM(I27)) | S27: =IF(COUNTIF($R$6:$R$53,R27)>1,"重复","唯一") | T27: 4568edb503262d863cb17629936935e4b1f02678de623f67776667c41df8f455 | U27: 摩斯拉 | V27: 2026-10-13 00:00:00 | W27: 原创程序几何 | Y27: 已制成并实装：Prefab=assets/art/vfx/combat_3d/vfx_bullet_standard_root_top3d.tscn + 脚本=src/vfx/VfxBulletStandard3D.gd；根节点=VfxBulletStandard3D(Node3D)；《3D-特效》分页编号见该页（FX01-06 系列）。变体父体 VFX-BULLET-VISUAL-3D（复用其弹芯/外壳/拖尾几何分层，仅按弹种换外观与行为段）。调用方 Projectile3D._build_visual() 经 BULLET_VISUAL_REGISTRY 按 visual_id 路由，作为子节点持有、生命周期随 ProjectilePool3D，刻意不进 VfxPool3D；纯视觉无碰撞体。验收：verify_bullet_vfx_profiles（8 profile 可区分 + AssetID 路由 + 尺寸线性 + 端到端开火 + 无碰撞 + 反向对照）。设计依据：内容库《武器》S17「使用清晰中性弹体、尾迹和命中；不附加误导性的元素效果」。 【枪族弹体尺寸档 2026-10-14】业主「每把枪的子弹大小要做出区分」+「散射喷壶的子弹太小了，出生和结束都增加 2 倍」+「减面，减到 100 个面以下先」：① **尺寸两层**：弹体视觉尺寸 = 弹种 profile × 枪身族档位（档位真源 WeaponModel3D.BULLET_GEOMETRY_BY_GUN_TAG，键 = 枪身 tags 族标识，不是 gun_id —— 按族声明，新增同族枪自动继承）。三档：散射喷壶 shotgun 各向同性 ×2.00 + 由小变大（出生 0.84、0.30s 线性长到 2.00；grow_from = 0.42 是**比例**，保持不变即出生与长满两端同步 ×2）；反胃榴弹筒 launcher ×1.55；弹弓狙击 sniper 横向 ×0.95 + 沿飞行轴 ×2.0（净长 1.90 倍）；其余枪中性档。轴向拉伸只落各件自己的局部长轴与尾迹段距，不写父级 scale/rotation（父级非均匀缩放 × 子级旋转 = 剪切变形）。② **链路**：WeaponModel3D 解析 → projectile_config.gun_bullet_geometry → Projectile3D._gun_bullet_geometry → activate 的 context（axial_scale / grow_from / grow_duration）→ VfxBulletBody3D；子投射物继承，池化复借在 configure 与 deactivate 双处复位。③ **纯视觉边界**：枪身档位不进碰撞半径 —— Projectile3D 的 _visual_scale_factor()（弹种 × 命运 × 枪身族，供视觉）与 _collision_scale_factor()（只含弹种 × 命运，供 0.12 基准球）已拆开，验收有正面断言钉住。④ **低面数档**：弹芯/外壳由 CapsuleMesh 改为 4 边棱柱（CylinderMesh，16 面/件）—— CapsuleMesh 的圆头来自 rings，rings=0 的「胶囊」等价平盖圆柱且贵 8 面，rings=1 要 48 面/件、两件即吃掉 100 面全部预算；尾迹锥 4 段（12 面）、滴珠改 BoxMesh（16→12 面，滴珠世界尺寸仅 0.011~0.018m 不可分辨）、黑洞/气球球核 SphereMesh 4×1（16 面）。单弹总面数 **44~80**（改前 468~1020，降 92%~94%）；均值 819 → **61.3**；霰弹枪一次 5 发 3660 → **220** 面。**件数与尾迹构图未动**（件数属账本与验收契约）。缩放不改变面数。分段常量集中在 VfxBulletBody3D 顶部与 VfxBulletVisual3D._SEGMENTS。⑤ **验收**：verify_bullet_vfx_profiles（samples=69）—— 9 枪档位 + 生长包络步进 + 中性档不启用 + 复借复位 + 碰撞半径守卫 + 面数预算（上限 100 与逐弹种实测值双层钉住，期望硬编码在验收侧）；反向对照 RC1~RC8 全部精准变红后还原复绿（文件 md5 与改前一致）。
A28: VFX-BULLET-STICKY-3D | B28: 黏黏弹附着与倒计时特效 | C28: 子弹特效 | D28: bullet_sticky | E28: mod_bullet_sticky | F28: root_3d | G28: VFX-BULLET-VISUAL-3D | H28: 俯视3D | I28: attach_countdown | J28: 黏黏弹模块（mod_bullet_sticky） | K28: 已完成 | L28: P1 | M28: v001 | N28: 弹芯胶囊 r=0.050/h=0.16；外壳 r=0.086/h=0.16；锥尾迹 底0.062/长0.34 + 3 滴落珠；灯 energy1.20/range1.80m | O28: assets/art/vfx/combat_3d/vfx_bullet_sticky_root_top3d.tscn | P28: docs/v0.1/04_技术施工_战斗与局内成长.md §6.2（子弹模块必填 visual_id）; docs/v0.1/data/ShellStorm2_游戏内容数据库_v010.xlsx#武器 S18/T18; src/base/BlueprintRegistry.gd（mod_bullet_sticky） | Q28: 子弹特效;黏黏弹;附着;倒计时;持续伤害;sticky;dot;3D | R28: =LOWER(TRIM(C28)&"|"&TRIM(D28)&"|"&TRIM(E28)&"|"&TRIM(F28)&"|"&TRIM(H28)&"|"&TRIM(I28)) | S28: =IF(COUNTIF($R$6:$R$53,R28)>1,"重复","唯一") | T28: 778be3a1a693e11c1bed08c51c511df742e8502c74c60fc6c3d9919f00141c8b | U28: 摩斯拉 | V28: 2026-10-13 00:00:00 | W28: 原创程序几何 | Y28: 已制成并实装：Prefab=assets/art/vfx/combat_3d/vfx_bullet_sticky_root_top3d.tscn + 脚本=src/vfx/VfxBulletSticky3D.gd；根节点=VfxBulletSticky3D(Node3D)；《3D-特效》分页编号见该页（FX01-06 系列）。变体父体 VFX-BULLET-VISUAL-3D（复用其弹芯/外壳/拖尾几何分层，仅按弹种换外观与行为段）。调用方 Projectile3D._build_visual() 经 BULLET_VISUAL_REGISTRY 按 visual_id 路由，作为子节点持有、生命周期随 ProjectilePool3D，刻意不进 VfxPool3D；纯视觉无碰撞体。验收：verify_bullet_vfx_profiles（8 profile 可区分 + AssetID 路由 + 尺寸线性 + 端到端开火 + 无碰撞 + 反向对照）。设计依据：内容库《武器》S18「命中后弹体留在表面并显示倒计时/状态，结束时反馈与结算同步」。 【枪族弹体尺寸档 2026-10-14】业主「每把枪的子弹大小要做出区分」+「散射喷壶的子弹太小了，出生和结束都增加 2 倍」+「减面，减到 100 个面以下先」：① **尺寸两层**：弹体视觉尺寸 = 弹种 profile × 枪身族档位（档位真源 WeaponModel3D.BULLET_GEOMETRY_BY_GUN_TAG，键 = 枪身 tags 族标识，不是 gun_id —— 按族声明，新增同族枪自动继承）。三档：散射喷壶 shotgun 各向同性 ×2.00 + 由小变大（出生 0.84、0.30s 线性长到 2.00；grow_from = 0.42 是**比例**，保持不变即出生与长满两端同步 ×2）；反胃榴弹筒 launcher ×1.55；弹弓狙击 sniper 横向 ×0.95 + 沿飞行轴 ×2.0（净长 1.90 倍）；其余枪中性档。轴向拉伸只落各件自己的局部长轴与尾迹段距，不写父级 scale/rotation（父级非均匀缩放 × 子级旋转 = 剪切变形）。② **链路**：WeaponModel3D 解析 → projectile_config.gun_bullet_geometry → Projectile3D._gun_bullet_geometry → activate 的 context（axial_scale / grow_from / grow_duration）→ VfxBulletBody3D；子投射物继承，池化复借在 configure 与 deactivate 双处复位。③ **纯视觉边界**：枪身档位不进碰撞半径 —— Projectile3D 的 _visual_scale_factor()（弹种 × 命运 × 枪身族，供视觉）与 _collision_scale_factor()（只含弹种 × 命运，供 0.12 基准球）已拆开，验收有正面断言钉住。④ **低面数档**：弹芯/外壳由 CapsuleMesh 改为 4 边棱柱（CylinderMesh，16 面/件）—— CapsuleMesh 的圆头来自 rings，rings=0 的「胶囊」等价平盖圆柱且贵 8 面，rings=1 要 48 面/件、两件即吃掉 100 面全部预算；尾迹锥 4 段（12 面）、滴珠改 BoxMesh（16→12 面，滴珠世界尺寸仅 0.011~0.018m 不可分辨）、黑洞/气球球核 SphereMesh 4×1（16 面）。单弹总面数 **44~80**（改前 468~1020，降 92%~94%）；均值 819 → **61.3**；霰弹枪一次 5 发 3660 → **220** 面。**件数与尾迹构图未动**（件数属账本与验收契约）。缩放不改变面数。分段常量集中在 VfxBulletBody3D 顶部与 VfxBulletVisual3D._SEGMENTS。⑤ **验收**：verify_bullet_vfx_profiles（samples=69）—— 9 枪档位 + 生长包络步进 + 中性档不启用 + 复借复位 + 碰撞半径守卫 + 面数预算（上限 100 与逐弹种实测值双层钉住，期望硬编码在验收侧）；反向对照 RC1~RC8 全部精准变红后还原复绿（文件 md5 与改前一致）。
A29: VFX-BULLET-BOUNCE-3D | B29: 回旋镖弹反弹折线与计数特效 | C29: 子弹特效 | D29: bullet_bounce | E29: mod_bullet_bounce | F29: root_3d | G29: VFX-BULLET-VISUAL-3D | H29: 俯视3D | I29: bounce_ricochet | J29: 回旋镖弹模块（mod_bullet_bounce） | K29: 已完成 | L29: P1 | M29: v001 | N29: 弹芯胶囊 r=0.048/h=0.14；外壳 r=0.072/h=0.13；三段折线锥 底0.052/0.040/0.030；灯 energy1.20/range1.80m | O29: assets/art/vfx/combat_3d/vfx_bullet_bounce_root_top3d.tscn | P29: docs/v0.1/04_技术施工_战斗与局内成长.md §6.2（子弹模块必填 visual_id）; docs/v0.1/data/ShellStorm2_游戏内容数据库_v010.xlsx#武器 S13/T13; src/base/BlueprintRegistry.gd（mod_bullet_bounce） | Q29: 子弹特效;回旋镖弹;反弹;弹跳;折线闪光;计数递减;ricochet;3D | R29: =LOWER(TRIM(C29)&"|"&TRIM(D29)&"|"&TRIM(E29)&"|"&TRIM(F29)&"|"&TRIM(H29)&"|"&TRIM(I29)) | S29: =IF(COUNTIF($R$6:$R$53,R29)>1,"重复","唯一") | T29: c31373aa7b45d6539702f03f12f5536ee5a5766e694e2612f82b9887c1280517 | U29: 摩斯拉 | V29: 2026-10-13 00:00:00 | W29: 原创程序几何 | Y29: 已制成并实装：Prefab=assets/art/vfx/combat_3d/vfx_bullet_bounce_root_top3d.tscn + 脚本=src/vfx/VfxBulletBounce3D.gd；根节点=VfxBulletBounce3D(Node3D)；《3D-特效》分页编号见该页（FX01-06 系列）。变体父体 VFX-BULLET-VISUAL-3D（复用其弹芯/外壳/拖尾几何分层，仅按弹种换外观与行为段）。调用方 Projectile3D._build_visual() 经 BULLET_VISUAL_REGISTRY 按 visual_id 路由，作为子节点持有、生命周期随 ProjectilePool3D，刻意不进 VfxPool3D；纯视觉无碰撞体。验收：verify_bullet_vfx_profiles（8 profile 可区分 + AssetID 路由 + 尺寸线性 + 端到端开火 + 无碰撞 + 反向对照）。设计依据：内容库《武器》S13「反弹点有折线闪光与计数递减，飞行方向变化清楚可读」。 【枪族弹体尺寸档 2026-10-14】业主「每把枪的子弹大小要做出区分」+「散射喷壶的子弹太小了，出生和结束都增加 2 倍」+「减面，减到 100 个面以下先」：① **尺寸两层**：弹体视觉尺寸 = 弹种 profile × 枪身族档位（档位真源 WeaponModel3D.BULLET_GEOMETRY_BY_GUN_TAG，键 = 枪身 tags 族标识，不是 gun_id —— 按族声明，新增同族枪自动继承）。三档：散射喷壶 shotgun 各向同性 ×2.00 + 由小变大（出生 0.84、0.30s 线性长到 2.00；grow_from = 0.42 是**比例**，保持不变即出生与长满两端同步 ×2）；反胃榴弹筒 launcher ×1.55；弹弓狙击 sniper 横向 ×0.95 + 沿飞行轴 ×2.0（净长 1.90 倍）；其余枪中性档。轴向拉伸只落各件自己的局部长轴与尾迹段距，不写父级 scale/rotation（父级非均匀缩放 × 子级旋转 = 剪切变形）。② **链路**：WeaponModel3D 解析 → projectile_config.gun_bullet_geometry → Projectile3D._gun_bullet_geometry → activate 的 context（axial_scale / grow_from / grow_duration）→ VfxBulletBody3D；子投射物继承，池化复借在 configure 与 deactivate 双处复位。③ **纯视觉边界**：枪身档位不进碰撞半径 —— Projectile3D 的 _visual_scale_factor()（弹种 × 命运 × 枪身族，供视觉）与 _collision_scale_factor()（只含弹种 × 命运，供 0.12 基准球）已拆开，验收有正面断言钉住。④ **低面数档**：弹芯/外壳由 CapsuleMesh 改为 4 边棱柱（CylinderMesh，16 面/件）—— CapsuleMesh 的圆头来自 rings，rings=0 的「胶囊」等价平盖圆柱且贵 8 面，rings=1 要 48 面/件、两件即吃掉 100 面全部预算；尾迹锥 4 段（12 面）、滴珠改 BoxMesh（16→12 面，滴珠世界尺寸仅 0.011~0.018m 不可分辨）、黑洞/气球球核 SphereMesh 4×1（16 面）。单弹总面数 **44~80**（改前 468~1020，降 92%~94%）；均值 819 → **61.3**；霰弹枪一次 5 发 3660 → **220** 面。**件数与尾迹构图未动**（件数属账本与验收契约）。缩放不改变面数。分段常量集中在 VfxBulletBody3D 顶部与 VfxBulletVisual3D._SEGMENTS。⑤ **验收**：verify_bullet_vfx_profiles（samples=69）—— 9 枪档位 + 生长包络步进 + 中性档不启用 + 复借复位 + 碰撞半径守卫 + 面数预算（上限 100 与逐弹种实测值双层钉住，期望硬编码在验收侧）；反向对照 RC1~RC8 全部精准变红后还原复绿（文件 md5 与改前一致）。
A30: VFX-BULLET-PIERCING-3D | B30: 穿甲弹贯穿线与层数特效 | C30: 子弹特效 | D30: bullet_piercing | E30: mod_bullet_piercing | F30: root_3d | G30: VFX-BULLET-VISUAL-3D | H30: 俯视3D | I30: pierce_through | J30: 穿甲弹模块（mod_bullet_piercing） | K30: 已完成 | L30: P1 | M30: v001 | N30: 弹芯胶囊 r=0.028/h=0.30；外壳 r=0.044/h=0.28；两段针形尾迹 底0.036/0.022；灯 energy1.35/range1.95m | O30: assets/art/vfx/combat_3d/vfx_bullet_piercing_root_top3d.tscn | P30: docs/v0.1/04_技术施工_战斗与局内成长.md §6.2（子弹模块必填 visual_id）; docs/v0.1/data/ShellStorm2_游戏内容数据库_v010.xlsx#武器 S16/T16; src/base/BlueprintRegistry.gd（mod_bullet_piercing） | Q30: 子弹特效;穿甲弹;穿透;贯穿线;剩余层数;piercing;armor;3D | R30: =LOWER(TRIM(C30)&"|"&TRIM(D30)&"|"&TRIM(E30)&"|"&TRIM(F30)&"|"&TRIM(H30)&"|"&TRIM(I30)) | S30: =IF(COUNTIF($R$6:$R$53,R30)>1,"重复","唯一") | T30: 7dac07ff53a03e159245a033af9cd01cde83837d57c1cc8d96e0fdd2aa13aed3 | U30: 摩斯拉 | V30: 2026-10-13 00:00:00 | W30: 原创程序几何 | Y30: 已制成并实装：Prefab=assets/art/vfx/combat_3d/vfx_bullet_piercing_root_top3d.tscn + 脚本=src/vfx/VfxBulletPiercing3D.gd；根节点=VfxBulletPiercing3D(Node3D)；《3D-特效》分页编号见该页（FX01-06 系列）。变体父体 VFX-BULLET-VISUAL-3D（复用其弹芯/外壳/拖尾几何分层，仅按弹种换外观与行为段）。调用方 Projectile3D._build_visual() 经 BULLET_VISUAL_REGISTRY 按 visual_id 路由，作为子节点持有、生命周期随 ProjectilePool3D，刻意不进 VfxPool3D；纯视觉无碰撞体。验收：verify_bullet_vfx_profiles（8 profile 可区分 + AssetID 路由 + 尺寸线性 + 端到端开火 + 无碰撞 + 反向对照）。设计依据：内容库《武器》S16「穿透命中显示连续贯穿线与剩余层数，不在首个目标处假性消失」。 【枪族弹体尺寸档 2026-10-14】业主「每把枪的子弹大小要做出区分」+「散射喷壶的子弹太小了，出生和结束都增加 2 倍」+「减面，减到 100 个面以下先」：① **尺寸两层**：弹体视觉尺寸 = 弹种 profile × 枪身族档位（档位真源 WeaponModel3D.BULLET_GEOMETRY_BY_GUN_TAG，键 = 枪身 tags 族标识，不是 gun_id —— 按族声明，新增同族枪自动继承）。三档：散射喷壶 shotgun 各向同性 ×2.00 + 由小变大（出生 0.84、0.30s 线性长到 2.00；grow_from = 0.42 是**比例**，保持不变即出生与长满两端同步 ×2）；反胃榴弹筒 launcher ×1.55；弹弓狙击 sniper 横向 ×0.95 + 沿飞行轴 ×2.0（净长 1.90 倍）；其余枪中性档。轴向拉伸只落各件自己的局部长轴与尾迹段距，不写父级 scale/rotation（父级非均匀缩放 × 子级旋转 = 剪切变形）。② **链路**：WeaponModel3D 解析 → projectile_config.gun_bullet_geometry → Projectile3D._gun_bullet_geometry → activate 的 context（axial_scale / grow_from / grow_duration）→ VfxBulletBody3D；子投射物继承，池化复借在 configure 与 deactivate 双处复位。③ **纯视觉边界**：枪身档位不进碰撞半径 —— Projectile3D 的 _visual_scale_factor()（弹种 × 命运 × 枪身族，供视觉）与 _collision_scale_factor()（只含弹种 × 命运，供 0.12 基准球）已拆开，验收有正面断言钉住。④ **低面数档**：弹芯/外壳由 CapsuleMesh 改为 4 边棱柱（CylinderMesh，16 面/件）—— CapsuleMesh 的圆头来自 rings，rings=0 的「胶囊」等价平盖圆柱且贵 8 面，rings=1 要 48 面/件、两件即吃掉 100 面全部预算；尾迹锥 4 段（12 面）、滴珠改 BoxMesh（16→12 面，滴珠世界尺寸仅 0.011~0.018m 不可分辨）、黑洞/气球球核 SphereMesh 4×1（16 面）。单弹总面数 **44~80**（改前 468~1020，降 92%~94%）；均值 819 → **61.3**；霰弹枪一次 5 发 3660 → **220** 面。**件数与尾迹构图未动**（件数属账本与验收契约）。缩放不改变面数。分段常量集中在 VfxBulletBody3D 顶部与 VfxBulletVisual3D._SEGMENTS。⑤ **验收**：verify_bullet_vfx_profiles（samples=69）—— 9 枪档位 + 生长包络步进 + 中性档不启用 + 复借复位 + 碰撞半径守卫 + 面数预算（上限 100 与逐弹种实测值双层钉住，期望硬编码在验收侧）；反向对照 RC1~RC8 全部精准变红后还原复绿（文件 md5 与改前一致）。
A31: VFX-BULLET-EXPLOSIVE-3D | B31: 爆炸弹弹体与爆炸时点特效 | C31: 子弹特效 | D31: bullet_explosive | E31: mod_bullet_explosive | F31: root_3d | G31: VFX-BULLET-VISUAL-3D | H31: 俯视3D | I31: flight_to_detonate | J31: 爆炸弹模块（mod_bullet_explosive） | K31: 已完成 | L31: P1 | M31: v001 | N31: 弹芯胶囊 r=0.055/h=0.22；外壳 r=0.094/h=0.20；锥尾迹 底0.078/长0.40 + 3 火星条；灯 energy1.65/range2.40m | O31: assets/art/vfx/combat_3d/vfx_bullet_explosive_root_top3d.tscn | P31: docs/v0.1/04_技术施工_战斗与局内成长.md §6.2（子弹模块必填 visual_id）; docs/v0.1/data/ShellStorm2_游戏内容数据库_v010.xlsx#武器 S14/T14; src/base/BlueprintRegistry.gd（mod_bullet_explosive） | Q31: 子弹特效;爆炸弹;范围伤害;爆炸半径;伤害时点;低特效轮廓圈;explosive;area;3D | R31: =LOWER(TRIM(C31)&"|"&TRIM(D31)&"|"&TRIM(E31)&"|"&TRIM(F31)&"|"&TRIM(H31)&"|"&TRIM(I31)) | S31: =IF(COUNTIF($R$6:$R$53,R31)>1,"重复","唯一") | T31: 16668244baa6415476e9f53a7207843de1ec43981cc46b8fba3b77259c43aa66 | U31: 摩斯拉 | V31: 2026-10-13 00:00:00 | W31: 原创程序几何 | Y31: 已制成并实装：Prefab=assets/art/vfx/combat_3d/vfx_bullet_explosive_root_top3d.tscn + 脚本=src/vfx/VfxBulletExplosive3D.gd；根节点=VfxBulletExplosive3D(Node3D)；《3D-特效》分页编号见该页（FX01-06 系列）。变体父体 VFX-BULLET-VISUAL-3D（复用其弹芯/外壳/拖尾几何分层，仅按弹种换外观与行为段）。调用方 Projectile3D._build_visual() 经 BULLET_VISUAL_REGISTRY 按 visual_id 路由，作为子节点持有、生命周期随 ProjectilePool3D，刻意不进 VfxPool3D；纯视觉无碰撞体。验收：verify_bullet_vfx_profiles（8 profile 可区分 + AssetID 路由 + 尺寸线性 + 端到端开火 + 无碰撞 + 反向对照）。设计依据：内容库《武器》S14「弹体、尾迹、爆炸半径与伤害时点同步，低特效下保留轮廓圈」。 【枪族弹体尺寸档 2026-10-14】业主「每把枪的子弹大小要做出区分」+「散射喷壶的子弹太小了，出生和结束都增加 2 倍」+「减面，减到 100 个面以下先」：① **尺寸两层**：弹体视觉尺寸 = 弹种 profile × 枪身族档位（档位真源 WeaponModel3D.BULLET_GEOMETRY_BY_GUN_TAG，键 = 枪身 tags 族标识，不是 gun_id —— 按族声明，新增同族枪自动继承）。三档：散射喷壶 shotgun 各向同性 ×2.00 + 由小变大（出生 0.84、0.30s 线性长到 2.00；grow_from = 0.42 是**比例**，保持不变即出生与长满两端同步 ×2）；反胃榴弹筒 launcher ×1.55；弹弓狙击 sniper 横向 ×0.95 + 沿飞行轴 ×2.0（净长 1.90 倍）；其余枪中性档。轴向拉伸只落各件自己的局部长轴与尾迹段距，不写父级 scale/rotation（父级非均匀缩放 × 子级旋转 = 剪切变形）。② **链路**：WeaponModel3D 解析 → projectile_config.gun_bullet_geometry → Projectile3D._gun_bullet_geometry → activate 的 context（axial_scale / grow_from / grow_duration）→ VfxBulletBody3D；子投射物继承，池化复借在 configure 与 deactivate 双处复位。③ **纯视觉边界**：枪身档位不进碰撞半径 —— Projectile3D 的 _visual_scale_factor()（弹种 × 命运 × 枪身族，供视觉）与 _collision_scale_factor()（只含弹种 × 命运，供 0.12 基准球）已拆开，验收有正面断言钉住。④ **低面数档**：弹芯/外壳由 CapsuleMesh 改为 4 边棱柱（CylinderMesh，16 面/件）—— CapsuleMesh 的圆头来自 rings，rings=0 的「胶囊」等价平盖圆柱且贵 8 面，rings=1 要 48 面/件、两件即吃掉 100 面全部预算；尾迹锥 4 段（12 面）、滴珠改 BoxMesh（16→12 面，滴珠世界尺寸仅 0.011~0.018m 不可分辨）、黑洞/气球球核 SphereMesh 4×1（16 面）。单弹总面数 **44~80**（改前 468~1020，降 92%~94%）；均值 819 → **61.3**；霰弹枪一次 5 发 3660 → **220** 面。**件数与尾迹构图未动**（件数属账本与验收契约）。缩放不改变面数。分段常量集中在 VfxBulletBody3D 顶部与 VfxBulletVisual3D._SEGMENTS。⑤ **验收**：verify_bullet_vfx_profiles（samples=69）—— 9 枪档位 + 生长包络步进 + 中性档不启用 + 复借复位 + 碰撞半径守卫 + 面数预算（上限 100 与逐弹种实测值双层钉住，期望硬编码在验收侧）；反向对照 RC1~RC8 全部精准变红后还原复绿（文件 md5 与改前一致）。
A32: VFX-BULLET-HOMING-3D | B32: 蜂卵弹锁定框与弯曲尾迹特效 | C32: 子弹特效 | D32: bullet_homing | E32: mod_bullet_homing | F32: root_3d | G32: VFX-BULLET-VISUAL-3D | H32: 俯视3D | I32: homing_curve | J32: 蜂卵弹模块（mod_bullet_homing） | K32: 已完成 | L32: P1 | M32: v001 | N32: 弹芯胶囊 r=0.050/h=0.18；外壳 r=0.082/h=0.16；三段摆动尾迹；灯 energy1.25/range1.90m | O32: assets/art/vfx/combat_3d/vfx_bullet_homing_root_top3d.tscn | P32: docs/v0.1/04_技术施工_战斗与局内成长.md §6.2（子弹模块必填 visual_id）; docs/v0.1/data/ShellStorm2_游戏内容数据库_v010.xlsx#武器 S15/T15; src/base/BlueprintRegistry.gd（mod_bullet_homing） | Q32: 子弹特效;蜂卵弹;追踪;锁定框;弯曲尾迹;解除提示;homing;3D | R32: =LOWER(TRIM(C32)&"|"&TRIM(D32)&"|"&TRIM(E32)&"|"&TRIM(F32)&"|"&TRIM(H32)&"|"&TRIM(I32)) | S32: =IF(COUNTIF($R$6:$R$53,R32)>1,"重复","唯一") | T32: 7b674e50097eef28c900780031f808ddc6077efed1194dae6debe74b710fe87e | U32: 摩斯拉 | V32: 2026-10-13 00:00:00 | W32: 原创程序几何 | Y32: 已制成并实装：Prefab=assets/art/vfx/combat_3d/vfx_bullet_homing_root_top3d.tscn + 脚本=src/vfx/VfxBulletHoming3D.gd；根节点=VfxBulletHoming3D(Node3D)；《3D-特效》分页编号见该页（FX01-06 系列）。变体父体 VFX-BULLET-VISUAL-3D（复用其弹芯/外壳/拖尾几何分层，仅按弹种换外观与行为段）。调用方 Projectile3D._build_visual() 经 BULLET_VISUAL_REGISTRY 按 visual_id 路由，作为子节点持有、生命周期随 ProjectilePool3D，刻意不进 VfxPool3D；纯视觉无碰撞体。验收：verify_bullet_vfx_profiles（8 profile 可区分 + AssetID 路由 + 尺寸线性 + 端到端开火 + 无碰撞 + 反向对照）。设计依据：内容库《武器》S15「锁定框、弯曲尾迹和转向动作一致；目标丢失有解除提示」。 【枪族弹体尺寸档 2026-10-14】业主「每把枪的子弹大小要做出区分」+「散射喷壶的子弹太小了，出生和结束都增加 2 倍」+「减面，减到 100 个面以下先」：① **尺寸两层**：弹体视觉尺寸 = 弹种 profile × 枪身族档位（档位真源 WeaponModel3D.BULLET_GEOMETRY_BY_GUN_TAG，键 = 枪身 tags 族标识，不是 gun_id —— 按族声明，新增同族枪自动继承）。三档：散射喷壶 shotgun 各向同性 ×2.00 + 由小变大（出生 0.84、0.30s 线性长到 2.00；grow_from = 0.42 是**比例**，保持不变即出生与长满两端同步 ×2）；反胃榴弹筒 launcher ×1.55；弹弓狙击 sniper 横向 ×0.95 + 沿飞行轴 ×2.0（净长 1.90 倍）；其余枪中性档。轴向拉伸只落各件自己的局部长轴与尾迹段距，不写父级 scale/rotation（父级非均匀缩放 × 子级旋转 = 剪切变形）。② **链路**：WeaponModel3D 解析 → projectile_config.gun_bullet_geometry → Projectile3D._gun_bullet_geometry → activate 的 context（axial_scale / grow_from / grow_duration）→ VfxBulletBody3D；子投射物继承，池化复借在 configure 与 deactivate 双处复位。③ **纯视觉边界**：枪身档位不进碰撞半径 —— Projectile3D 的 _visual_scale_factor()（弹种 × 命运 × 枪身族，供视觉）与 _collision_scale_factor()（只含弹种 × 命运，供 0.12 基准球）已拆开，验收有正面断言钉住。④ **低面数档**：弹芯/外壳由 CapsuleMesh 改为 4 边棱柱（CylinderMesh，16 面/件）—— CapsuleMesh 的圆头来自 rings，rings=0 的「胶囊」等价平盖圆柱且贵 8 面，rings=1 要 48 面/件、两件即吃掉 100 面全部预算；尾迹锥 4 段（12 面）、滴珠改 BoxMesh（16→12 面，滴珠世界尺寸仅 0.011~0.018m 不可分辨）、黑洞/气球球核 SphereMesh 4×1（16 面）。单弹总面数 **44~80**（改前 468~1020，降 92%~94%）；均值 819 → **61.3**；霰弹枪一次 5 发 3660 → **220** 面。**件数与尾迹构图未动**（件数属账本与验收契约）。缩放不改变面数。分段常量集中在 VfxBulletBody3D 顶部与 VfxBulletVisual3D._SEGMENTS。⑤ **验收**：verify_bullet_vfx_profiles（samples=69）—— 9 枪档位 + 生长包络步进 + 中性档不启用 + 复借复位 + 碰撞半径守卫 + 面数预算（上限 100 与逐弹种实测值双层钉住，期望硬编码在验收侧）；反向对照 RC1~RC8 全部精准变红后还原复绿（文件 md5 与改前一致）。
A33: VFX-BULLET-BLACKHOLE-3D | B33: 黑洞弹核心与吸入流线特效 | C33: 子弹特效 | D33: bullet_blackhole | E33: mod_bullet_blackhole | F33: root_3d | G33: VFX-BULLET-VISUAL-3D | H33: 俯视3D | I33: blackhole_pull | J33: 黑洞弹模块（mod_bullet_blackhole） | K33: 已完成 | L33: P1 | M33: v001 | N33: 弹芯球 r=0.058；外壳球 r=0.098；外扩喇叭三段 底0.040/0.068/0.096；灯 energy1.45/range2.20m | O33: assets/art/vfx/combat_3d/vfx_bullet_blackhole_root_top3d.tscn | P33: docs/v0.1/04_技术施工_战斗与局内成长.md §6.2（子弹模块必填 visual_id）; docs/v0.1/data/ShellStorm2_游戏内容数据库_v010.xlsx#武器 S12/T12; src/base/BlueprintRegistry.gd（mod_bullet_blackhole） | Q33: 子弹特效;黑洞弹;黑洞核心;吸入流线;范围边界;收束反馈;pull;3D | R33: =LOWER(TRIM(C33)&"|"&TRIM(D33)&"|"&TRIM(E33)&"|"&TRIM(F33)&"|"&TRIM(H33)&"|"&TRIM(I33)) | S33: =IF(COUNTIF($R$6:$R$53,R33)>1,"重复","唯一") | T33: 3e3b832d8bbd74d0c82fded0ff4e416722a17b2a64af56d8ebee4a4cc03c354a | U33: 摩斯拉 | V33: 2026-10-13 00:00:00 | W33: 原创程序几何 | Y33: 已制成并实装：Prefab=assets/art/vfx/combat_3d/vfx_bullet_blackhole_root_top3d.tscn + 脚本=src/vfx/VfxBulletBlackhole3D.gd；根节点=VfxBulletBlackhole3D(Node3D)；《3D-特效》分页编号见该页（FX01-06 系列）。变体父体 VFX-BULLET-VISUAL-3D（复用其弹芯/外壳/拖尾几何分层，仅按弹种换外观与行为段）。调用方 Projectile3D._build_visual() 经 BULLET_VISUAL_REGISTRY 按 visual_id 路由，作为子节点持有、生命周期随 ProjectilePool3D，刻意不进 VfxPool3D；纯视觉无碰撞体。验收：verify_bullet_vfx_profiles（8 profile 可区分 + AssetID 路由 + 尺寸线性 + 端到端开火 + 无碰撞 + 反向对照）。设计依据：内容库《武器》S12「黑洞核心、吸入流线和范围边界清晰；命中/结束有收束反馈」。 【枪族弹体尺寸档 2026-10-14】业主「每把枪的子弹大小要做出区分」+「散射喷壶的子弹太小了，出生和结束都增加 2 倍」+「减面，减到 100 个面以下先」：① **尺寸两层**：弹体视觉尺寸 = 弹种 profile × 枪身族档位（档位真源 WeaponModel3D.BULLET_GEOMETRY_BY_GUN_TAG，键 = 枪身 tags 族标识，不是 gun_id —— 按族声明，新增同族枪自动继承）。三档：散射喷壶 shotgun 各向同性 ×2.00 + 由小变大（出生 0.84、0.30s 线性长到 2.00；grow_from = 0.42 是**比例**，保持不变即出生与长满两端同步 ×2）；反胃榴弹筒 launcher ×1.55；弹弓狙击 sniper 横向 ×0.95 + 沿飞行轴 ×2.0（净长 1.90 倍）；其余枪中性档。轴向拉伸只落各件自己的局部长轴与尾迹段距，不写父级 scale/rotation（父级非均匀缩放 × 子级旋转 = 剪切变形）。② **链路**：WeaponModel3D 解析 → projectile_config.gun_bullet_geometry → Projectile3D._gun_bullet_geometry → activate 的 context（axial_scale / grow_from / grow_duration）→ VfxBulletBody3D；子投射物继承，池化复借在 configure 与 deactivate 双处复位。③ **纯视觉边界**：枪身档位不进碰撞半径 —— Projectile3D 的 _visual_scale_factor()（弹种 × 命运 × 枪身族，供视觉）与 _collision_scale_factor()（只含弹种 × 命运，供 0.12 基准球）已拆开，验收有正面断言钉住。④ **低面数档**：弹芯/外壳由 CapsuleMesh 改为 4 边棱柱（CylinderMesh，16 面/件）—— CapsuleMesh 的圆头来自 rings，rings=0 的「胶囊」等价平盖圆柱且贵 8 面，rings=1 要 48 面/件、两件即吃掉 100 面全部预算；尾迹锥 4 段（12 面）、滴珠改 BoxMesh（16→12 面，滴珠世界尺寸仅 0.011~0.018m 不可分辨）、黑洞/气球球核 SphereMesh 4×1（16 面）。单弹总面数 **44~80**（改前 468~1020，降 92%~94%）；均值 819 → **61.3**；霰弹枪一次 5 发 3660 → **220** 面。**件数与尾迹构图未动**（件数属账本与验收契约）。缩放不改变面数。分段常量集中在 VfxBulletBody3D 顶部与 VfxBulletVisual3D._SEGMENTS。⑤ **验收**：verify_bullet_vfx_profiles（samples=69）—— 9 枪档位 + 生长包络步进 + 中性档不启用 + 复借复位 + 碰撞半径守卫 + 面数预算（上限 100 与逐弹种实测值双层钉住，期望硬编码在验收侧）；反向对照 RC1~RC8 全部精准变红后还原复绿（文件 md5 与改前一致）。
A34: VFX-BULLET-BALLOON-3D | B34: 气球弹膨胀弹体与命中体积特效 | C34: 子弹特效 | D34: bullet_balloon | E34: mod_bullet_balloon | F34: root_3d | G34: VFX-BULLET-VISUAL-3D | H34: 俯视3D | I34: inflate_flight | J34: 气球弹模块（mod_bullet_balloon） | K34: 已完成 | L34: P1 | M34: v001 | N34: 弹芯球 r=0.070；外壳球 r=0.118；粗短锥尾迹 底0.104/长0.36；灯 energy1.30/range2.05m | O34: assets/art/vfx/combat_3d/vfx_bullet_balloon_root_top3d.tscn | P34: docs/v0.1/04_技术施工_战斗与局内成长.md §6.2（子弹模块必填 visual_id）; docs/v0.1/data/ShellStorm2_游戏内容数据库_v010.xlsx#武器 S11/T11; src/base/BlueprintRegistry.gd（mod_bullet_balloon） | Q34: 子弹特效;气球弹;膨胀弹体;命中体积;低速;balloon;big;3D | R34: =LOWER(TRIM(C34)&"|"&TRIM(D34)&"|"&TRIM(E34)&"|"&TRIM(F34)&"|"&TRIM(H34)&"|"&TRIM(I34)) | S34: =IF(COUNTIF($R$6:$R$53,R34)>1,"重复","唯一") | T34: 4cf2bd23539184d121d209a180475951bd7ae9478b35e8be565ca15515dc36cf | U34: 摩斯拉 | V34: 2026-10-13 00:00:00 | W34: 原创程序几何 | Y34: 已制成并实装：Prefab=assets/art/vfx/combat_3d/vfx_bullet_balloon_root_top3d.tscn + 脚本=src/vfx/VfxBulletBalloon3D.gd；根节点=VfxBulletBalloon3D(Node3D)；《3D-特效》分页编号见该页（FX01-06 系列）。变体父体 VFX-BULLET-VISUAL-3D（复用其弹芯/外壳/拖尾几何分层，仅按弹种换外观与行为段）。调用方 Projectile3D._build_visual() 经 BULLET_VISUAL_REGISTRY 按 visual_id 路由，作为子节点持有、生命周期随 ProjectilePool3D，刻意不进 VfxPool3D；纯视觉无碰撞体。验收：verify_bullet_vfx_profiles（8 profile 可区分 + AssetID 路由 + 尺寸线性 + 端到端开火 + 无碰撞 + 反向对照）。设计依据：内容库《武器》S11「膨胀弹体、较重尾迹与命中体积一致，不能只改伤害数值」。 【枪族弹体尺寸档 2026-10-14】业主「每把枪的子弹大小要做出区分」+「散射喷壶的子弹太小了，出生和结束都增加 2 倍」+「减面，减到 100 个面以下先」：① **尺寸两层**：弹体视觉尺寸 = 弹种 profile × 枪身族档位（档位真源 WeaponModel3D.BULLET_GEOMETRY_BY_GUN_TAG，键 = 枪身 tags 族标识，不是 gun_id —— 按族声明，新增同族枪自动继承）。三档：散射喷壶 shotgun 各向同性 ×2.00 + 由小变大（出生 0.84、0.30s 线性长到 2.00；grow_from = 0.42 是**比例**，保持不变即出生与长满两端同步 ×2）；反胃榴弹筒 launcher ×1.55；弹弓狙击 sniper 横向 ×0.95 + 沿飞行轴 ×2.0（净长 1.90 倍）；其余枪中性档。轴向拉伸只落各件自己的局部长轴与尾迹段距，不写父级 scale/rotation（父级非均匀缩放 × 子级旋转 = 剪切变形）。② **链路**：WeaponModel3D 解析 → projectile_config.gun_bullet_geometry → Projectile3D._gun_bullet_geometry → activate 的 context（axial_scale / grow_from / grow_duration）→ VfxBulletBody3D；子投射物继承，池化复借在 configure 与 deactivate 双处复位。③ **纯视觉边界**：枪身档位不进碰撞半径 —— Projectile3D 的 _visual_scale_factor()（弹种 × 命运 × 枪身族，供视觉）与 _collision_scale_factor()（只含弹种 × 命运，供 0.12 基准球）已拆开，验收有正面断言钉住。④ **低面数档**：弹芯/外壳由 CapsuleMesh 改为 4 边棱柱（CylinderMesh，16 面/件）—— CapsuleMesh 的圆头来自 rings，rings=0 的「胶囊」等价平盖圆柱且贵 8 面，rings=1 要 48 面/件、两件即吃掉 100 面全部预算；尾迹锥 4 段（12 面）、滴珠改 BoxMesh（16→12 面，滴珠世界尺寸仅 0.011~0.018m 不可分辨）、黑洞/气球球核 SphereMesh 4×1（16 面）。单弹总面数 **44~80**（改前 468~1020，降 92%~94%）；均值 819 → **61.3**；霰弹枪一次 5 发 3660 → **220** 面。**件数与尾迹构图未动**（件数属账本与验收契约）。缩放不改变面数。分段常量集中在 VfxBulletBody3D 顶部与 VfxBulletVisual3D._SEGMENTS。⑤ **验收**：verify_bullet_vfx_profiles（samples=69）—— 9 枪档位 + 生长包络步进 + 中性档不启用 + 复借复位 + 碰撞半径守卫 + 面数预算（上限 100 与逐弹种实测值双层钉住，期望硬编码在验收侧）；反向对照 RC1~RC8 全部精准变红后还原复绿（文件 md5 与改前一致）。
A35: VFX-MONSTER-ROAR-ICON-3D | B35: 怪物启动吼叫头顶图标 | C35: 特效 | D35: 战斗反馈 | E35: FX01-16 | F35: root_3d | H35: 俯视3D | I35: startup_roar_icon | J35: 普通怪/精英（Boss 豁免） | K35: 已完成 | L35: P1 | M35: v002 | N35: PackedScene/程序 Sprite3D（256² RGBA 透明底贴图；世界边长 = 头顶血条宽 × 0.42，钳制 0.45–1.20 m） | O35: assets/art/vfx/combat_3d/vfx_monster_roar_icon_root_top3d.tscn | P35: src/vfx/VfxMonsterRoarIcon3D.gd; src/enemy3d/MonsterStartupProfile.gd | Q35: 吼叫;咆哮;启动过程;警觉;头顶图标;体型匹配;roar;startup;3D-icon | R35: =LOWER(TRIM(C35)&"|"&TRIM(D35)&"|"&TRIM(E35)&"|"&TRIM(F35)&"|"&TRIM(H35)&"|"&TRIM(I35)) | S35: =IF(COUNTIF($R$6:$R$53,R35)>1,"重复","唯一") | T35: f89109188bae4361cda58cb8c866e3c4d91b9eff4cd2b5259810e5830f4dc403 | U35: 摩斯拉 | V35: 46309 | W35: 原创程序几何/Sprite3D；卡通贴图为 gpt-image-2 绘制（四版迭代 v004 入选），原图留 art_source/vfx/combat_3d/vfx_monster_roar_icon/source/v001/ | X35: FX01-16 | Y35: 怪物从 idle/patrol 进入攻击前的 0.30–0.60s 启动过程里，转向玩家之后头顶弹出的一次性提示。**2026-10-14 改版 v002（业主指定）**：① 图形由「怪兽大嘴」换成**红色感叹号**（整支统一纯红 #FD0104，粗黑描边保留，青色高光已去掉）；② **增加「弹出后停顿一下」的节奏** —— 四段：① 弹出 0.70→1.15（t=0.10 过冲）② 回稳 →1.00（t=0.18）③ **停顿：0.18→hold 全程严格静止** ④ 淡出。实测三段停顿 scale 逐位相同（0.7031/0.7031/0.7031），由 `verify_monster_startup_roar` 钉住；③ 图标与血条的间隙由「固定 0.12m」改为**按图标边长 0.30 的比例**（`ICON_BAR_GAP_RATIO`）—— 感叹号的圆点落在方框底部，固定米数会直接贴住血条（预览实测 elite/boss 档间隙 −1px 即重叠，改成比例后六档间隙 +4~+10px 等比）。贴图 `assets/art/vfx/textures/vfx_monster_roar_icon_atlas_v001.png`（256² RGBA 透明底，`gpt-image-2` 绘制，SHA-256 `8eaf880e2eb2be1e…`；三版迭代 v003 入选，原图留 `art_source/vfx/combat_3d/vfx_monster_roar_icon/source/v002/`）。尺寸仍**按体型等比**：`icon_edge = clamp(头顶血条宽 × 0.42, 0.45, 1.20)` m，偏移 `icon_offset_y = 血条高/2 + 0.30×icon_edge + icon_edge/2`；体型输入直接复用 `Enemy3D.HEALTH_BAR_SIZE_BY_KIND`（刻意不新建第二份体型表）。摆放与朝向复用头顶血条同族口径：`BILLBOARD_ENABLED` + 关闭深度测试；每怪一个常驻 Sprite3D 由怪物自身持有、随怪物创建销毁，**刻意不进 `VfxPool3D`**。⚠️ 死亡/硬直/房间停用/目标失效必须调 `dismiss()`，否则会出现「已死还在吼」的假信息。Boss 由 `MonsterStartupProfile.plays_startup()` 豁免。纯视觉无碰撞体。验收 `verify_monster_startup_roar`（samples=221，含停顿段「必须真静止」的正面判据与负向对照）。视觉证据：`outputs/monster_roar_icon_size_contact_sheet.png`（六档体型）、`outputs/monster_startup_capture.png`（真引擎三帧）、`outputs/monster_startup_capture_pop_rhythm.png`（弹出→停顿节奏取样条）。
A36: VFX-DEATH-BLAST-3D | B36: 胖子僵尸死亡自爆特效 | C36: 特效 | D36: 战斗反馈 | E36: FX01-17 | F36: root_3d | H36: 俯视3D | I36: death_blast | J36: 远征01 胖子僵尸死亡自爆 | K36: 已完成 | L36: P1 | M36: v002 | N36: PackedScene/程序几何（12 枚绿色方块爆开 + 14 枚抛物线飞溅 + 4 块扁平方形地面液体 + 3 层绿色冲击波 + 1 盏 GooLight；lifetime 1.35s；无碰撞体） | O36: assets/art/vfx/combat_3d/vfx_death_blast_root_top3d.tscn | P36: src/vfx/VfxDeathBlast3D.gd; src/enemy3d/Enemy3D.gd | Q36: 死亡自爆;胖子僵尸;爆炸;冲击环;星芒;BlastLight;death-blast | R36: =LOWER(TRIM(C36)&"|"&TRIM(D36)&"|"&TRIM(E36)&"|"&TRIM(F36)&"|"&TRIM(H36)&"|"&TRIM(I36)) | S36: =IF(COUNTIF($R$6:$R$53,R36)>1,"重复","唯一") | T36: 7a88ecd3f4df05e4224484cd369dfe2a1d6ccca5140e1140ef2114d8ac6a19ab | U36: 摩斯拉 | V36: 2026-10-14 | W36: 原创/待确认 | X36: — | Y36: **v002 整体重做（业主 2026-10-14）**：业主第三轮把口径更正为「**把小僵尸的死亡特效放大两倍给胖子僵尸用**，然后带一个绿色冲击波的效果，同样去掉胖子僵尸的倒地动画播放」——也就是本件 = **FX01-19 那套死亡表现（绿方块爆开 + 抛物线飞溅 + 地面液体）×2 + 3 层绿色冲击波**，不是另做一套橙红自爆。v001 的「亮芯 + 2 层冲击环 + 9 道放射星芒 + 8 块飞散碎屑」整组退役。**结构**：身体完全来自 `src/vfx/VfxGooDeathBase3D.gd`（与小僵尸死亡件是同一段代码），本件只覆盖 `_asset_id()` / `_asset_version()` = v002 / `_shockwave_enabled()` = true 三点 ——两件因此不可能在节奏 / 配色 / 落地数学上漂移。**尺寸**：由调用方固定 `Enemy3D.FAT_DEATH_EFFECT_SIZE = 2.0`（业主「放大两倍」），**替换** v001 的「按伤害半径 ×0.6 反推」口径 ⇒ 冲击波外缘 ≈3.1m 不再等于远征01 的 5.0m 伤害半径，它变成风格元素、不再充当半径指示（要说清楚：观感上「炸得多大」与「掉多少血」现在是两条独立的线）。**表现 ≠ 玩法**：`Enemy3D._detonate_death_explosion()` 里视觉那一行不受 `damage` 影响 ——规格 `damage<=0`（本关不自爆）只是不掉血，不是「连死亡表现都不给」；塔楼里被去掉倒地动画的胖子僵尸因此仍有死亡表现。**地面契约**：`context.floor_y` 唯一真源（未传时按「胸口 = 脚底 + 0.65」反推，绝不写死 0）；冲击波平铺 XZ。纯视觉无碰撞体，走 VfxPool3D（FX01_DEATH_BLAST）。与 FX01-18 `VFX-BLAST-ZONE-3D` 的分工未变（那件仍是自爆后留在地上的持续伤害场视觉层）。验收 `verify_death_blast_vfx`（12 方块 + 14 飞溅 + 4 液体 + 3 冲击波 / GooLight 真源与包络 / 尺寸线性 / 冲击波峰值外缘扫描 / 绕竖直轴全向对称（**只看水平分量** —— 抬高式俯仰让三维模长天然 ~2.7）/ 地面平铺含倾斜对照 / 游戏侧选区与到点收场 / 端到端含 `zone.enabled=false` 对照，`samples=12`）。
A37: VFX-BLAST-ZONE-3D | B37: 自爆地面残留伤害场 | C37: 特效 | D37: 战斗反馈 | E37: FX01-18 | F37: root_3d | H37: 俯视3D | I37: lingering_hazard | J37: 远征01 胖子僵尸自爆地面残留 | K37: 已完成 | L37: P1 | M37: v001 | N37: PackedScene/程序几何（场底面 + 外缘定环 + 3 脉冲环 + 6 上升余烬 + 1 盏 ZoneLight；lifetime = 场地持续时长，默认 3.0s） | O37: assets/art/vfx/combat_3d/vfx_blast_zone_root_top3d.tscn | P37: src/vfx/VfxBlastZone3D.gd; src/enemy3d/DeathBlastZone3D.gd | Q37: 地面伤害场;持续伤害;自爆残留;范围伤害;3秒;blast-zone;ground-hazard | R37: =LOWER(TRIM(C37)&"|"&TRIM(D37)&"|"&TRIM(E37)&"|"&TRIM(F37)&"|"&TRIM(H37)&"|"&TRIM(I37)) | S37: =IF(COUNTIF($R$6:$R$53,R37)>1,"重复","唯一") | T37: 4345764d662753b126383e006b0027d3012be2d6a50cd094da955a9afc6cee6e | U37: 摩斯拉 | V37: 2026-10-14 | W37: 原创/待确认 | X37: — | Y37: **纯视觉**：不含碰撞体、不结算伤害；伤害由玩法节点 src/enemy3d/DeathBlastZone3D.gd 按周期处理。地面朝向契约：整件平铺 XZ，调用方在地面高度 activate 且不旋转。宿主自持、**刻意不进 VfxPool3D**（同 FX01-16 / FX03-03 口径）。专项验收 verify_death_blast_vfx。
A38: VFX-ZOMBIE-GOO-DEATH-3D | B38: 僵尸死亡绿色方块爆开特效 | C38: 特效 | D38: 战斗反馈 | E38: FX01-19 | F38: root_3d | H38: 俯视3D | I38: death_goo_burst | J38: 小僵尸/警察僵尸死亡（远征01 与塔楼通用） | K38: 已完成 | L38: P1 | M38: v001 | N38: PackedScene/程序几何（12 绿色方块爆炸粒子 + 14 抛物线飞溅粒子 + 4 块扁平方形地面液体 + 1 盏 GooLight；lifetime 1.35s；无碰撞体） | O38: assets/art/vfx/combat_3d/vfx_zombie_goo_death_root_top3d.tscn | P38: src/vfx/VfxZombieGooDeath3D.gd; src/enemy3d/Enemy3D.gd | Q38: 僵尸死亡;绿色方块;爆开;飞溅;抛物线;地面液体;停留0.5秒;下沉消失;goo-death;3D | R38: =LOWER(TRIM(C38)&"|"&TRIM(D38)&"|"&TRIM(E38)&"|"&TRIM(F38)&"|"&TRIM(H38)&"|"&TRIM(I38)) | S38: =IF(COUNTIF($R$6:$R$53,R38)>1,"重复","唯一") | T38: c8c05ce1f2d020756ad75a5bbbffa5dd0b758b1834b1d1cc7731c355c32f384d | U38: 摩斯拉 | V38: 2026-10-14 | W38: 原创程序几何 | X38: FX01-19 | Y38: 业主口径（2026-10-14）：「绿色方块爆开的粒子，掉落地面，然后地面上有方形像液体一样的扁平模型，停留 0.5 秒后慢慢下沉消失；由三部分组成 —— 爆炸的粒子 / 飞溅出去的粒子 / 地上的液体；节奏要有打击力度感、粒子不要太小、需要有大小的变化动画」，并「配置在小僵尸和警察僵尸死亡后，状态机上去掉倒地动画」。三部分：A `Burst0..11` 爆炸粒子（尺度 0.25 → 1.15 → 0.35 倍，0.24s 收干净）；B `Splat0..13` 飞溅粒子（g = 30 抛物线，解析式求落点，落地压扁后缩没）；C `Puddle0..3` 地上液体（落在飞溅粒子**真实落点**上，出现 → **严格停留 0.50s** → 下沉 0.30m 并淡出）。颜色恒为僵尸绿（调用方本色只作 25% 偏移，保证「绿色」读法不被小僵尸暗红 / 警察青冲掉）。`context.floor_y` 是地面高度**唯一真源**（未传时按调用方「胸口 = 脚底 + 0.65」口径反推，绝不写死 0）。纯视觉无碰撞体，走 `VfxPool3D`（FX01_ZOMBIE_GOO_DEATH）。调用方 `Enemy3D._die()`：`GOO_DEATH_KINDS = [melee_chaser, ranged_caster]` 走 `_spawn_goo_death_burst()` + `_retire_goo_death_visual()`（模型同帧收起、节点本帧回收、不进死亡显影组）⇒ **去掉 2.4s 倒地动画与尸体**；其余怪（胖子 / Boss 等）行为逐字不变。验收 `verify_zombie_goo_death_vfx`（资产契约 / 灯真源 / 三段节奏含停留窗口行为测量 / 尺度变化倍率 4.6 / 地面平铺含倾斜 90° 对照 / `floor_y` 三向对照 / 尺寸线性 / 无碰撞 / 端到端含「死亡同帧模型已收起」与「2 帧内回收」/ 胖子僵尸反向对照，samples=14；反向对照四组：怪种表改成 exploder、PUDDLE_HOLD_SEC 改 0.30、忽略 `context.floor_y` 均精准变红）；`verify_melee_zombie_death_visibility` 同步改写为新契约（死前追踪照旧 / 死后无尸体 / 组不残留 / 结算恰好一次，`--negative-untracked` 反向对照精准变红）。【第二轮订正：本件未改版】业主 2026-10-14 第三轮明确「**小僵尸的死亡特效不要改变**」⇒ 本件回到上面这版（v001），**无绿色冲击波**；中途那一版「放大 2 倍 + 绿色冲击波」被业主指名是**给胖子僵尸用的**，已落在 FX01-17 `VFX-DEATH-BLAST-3D`（v002）。两件现共用 `src/vfx/VfxGooDeathBase3D.gd` 的身体（本件是 v001 的逐字副本），差别只有「尺寸（调用方 1.0 vs 2.0）」与「有没有冲击波（无 vs 有）」两个旋钮。冲击波开关是**子类覆盖点**，验收对两侧都做了断言（本件冲击波数必须为 0 且 `Shockwave*` 节点不存在；FX01-17 必须 3 层且能扫、能收）。
A39: VFX-GOO-HIT-3D | B39: 僵尸命中爆点特效 | C39: 特效 | D39: 战斗反馈 | E39: FX01-20 | F39: root_3d | H39: 俯视3D | I39: hit_goo_burst | J39: 小僵尸/警察僵尸/胖子僵尸被枪击或近战命中（跨关卡通用） | K39: 已完成 | L39: P1 | M39: v002 | N39: PackedScene/程序几何（12 枚绿色方块爆开，0.26s；无灯、无碰撞体） | O39: assets/art/vfx/combat_3d/vfx_goo_hit_root_top3d.tscn | P39: src/vfx/VfxGooHit3D.gd; src/combat3d/Projectile3D.gd; src/player3d/melee/PlayerMeleeCombat3D.gd | Q39: 僵尸命中;受击;绿方块;爆开;goo-hit;枪击;近战;3D | R39: =LOWER(TRIM(C39)&"|"&TRIM(D39)&"|"&TRIM(E39)&"|"&TRIM(F39)&"|"&TRIM(H39)&"|"&TRIM(I39)) | S39: =IF(COUNTIF($R$6:$R$53,R39)>1,"重复","唯一") | T39: 2d932489f0e382a39305c1dd04a9d26b72ad4458e6b745cfe92ea836746b67a2 | U39: 摩斯拉 | V39: 2026-10-14 | W39: 原创程序几何 | X39: FX01-20 | Y39: 业主口径（2026-10-14）历轮： ① 首版：「使用爆炸粒子 ×12 的这个特效，**作为一个独立特效**，作为打中小僵尸、警察僵尸、胖子僵尸的受到枪击的特效」，追问后明确「**枪击 + 近战都用**」⇒ v001 = 12 枚绿方块从命中点炸开、0.26s。 ② **本版 v002**：「**小僵尸和警察僵尸的受击特效太大了**，**使用击中其它物体的那个特效**，然后**改成绿色**即可，放大大概 **10%**」⇒ 造型语言整体换成 FX01-21 `VFX-METAL-SPARK-HIT-3D` 那一套（5 颗方块 + 2 根长条火星），色板换成僵尸绿（方块亮绿 / 长条深一档绿）。本件与 FX01-21 **共用同一个父类** `VfxMetalSparkHit3D`（父类只暴露「资产身份」与「色板三项」两个钩子）⇒ 形状 / 件数 / 方向 / 尺度包络 / 外推曲线 / 长条拉伸**逐字相同**，两件不可能各自漂移。 ③ 同轮：「受击的盒子**没有贴着模型**，碰撞盒里陷进去坐标大概 **0.2 米**」⇒ 命中点必须先过 `Enemy3D.hit_effect_anchor()` 沿**外法线反向**收进模型 `HIT_EFFECT_INSET_M = 0.20` 米才出生（弹体是在碰撞壳表面判命中的，壳比模型大一圈）。收进去只对**怪**做 —— 墙面 / 掩体收了会钻进墙里。 「大 10%」**不写在本件内部**，由调用方按档位给：枪击走 `Projectile3D.ZOMBIE_HIT_SIZE_RATIO = 1.10`（`GOO_HIT_SIZE_TARGET/ABSORB = METAL_SPARK_SIZE_TARGET/ABSORB × 1.10` ⇒ 0.374 / 0.462）；近战走 `PlayerMeleeCombat3D.ZOMBIE_HIT_BASE_SIZE = 0.42` —— 近战件那套 `size`（0.88~1.6）是按 FX01-05 的内部基准定的，直接喂给火星造型会把方块放大到糊住半个怪，那正是业主说的「太大」。 AssetID 里的 “goo” 是**历史名**（v001 是绿方块爆开）；保留不改名 —— AssetID 是账本与 Prefab meta 的**稳定键**，改名等于让既有登记条目失锚。 **刻意无灯**：每发子弹 / 每次近战都生成的高频件（射速上限 12 发/s）。 **消费 `context.normal`**（v002 起与 FX01-21 同形 ⇒ 贴合被击面）；近战侧由 `PlayerMeleeCombat3D._hit_surface_normal()` 给「从怪体中心指向玩家」的外法线。 【贴肉落点实测（2026-10-15 复查修正）】**初版只做「固定下沉 0.20m」是不够的，真渲染实拍仍然悬空** ——业主第四轮的「大概 0.2 米」只是初估。根因：碰撞壳是**玩法口径的圆柱**（世界半径 melee 0.714 / ranged 0.770 / fat 0.770，各向同性），模型是**各向异性**的： · 小僵尸 壳 0.714 vs 模型半宽 X 0.448 / Z 0.334 ⇒ 正面打，壳面比模型多 0.27~0.38m； · 警察僵尸 壳 0.770 vs 模型半宽 X 0.449 / Z 0.602 ⇒ 同上； · 胖子僵尸 壳 0.770 vs 模型半宽 X **1.839** / Z 0.712 ⇒ 反过来，壳面**已经在模型里面**。 ⇒ 一个常数不可能同时满足三只怪 × 各方向。现改为**按模型实测几何现算**：取「命中高度那一层的横截面 + 全高 Y」的包围盒，沿外法线反向射线求**进入**盒子的距离 `travel`，退让 = `travel + 0.03`（咬进肉里 3cm）；`travel == 0`（命中点已在模型内，胖子僵尸 X 向）时**不推**，否则埋进胖身子读成「从肚子里炸」（实测不加这条守卫会被推深到 0.912）。真渲染复验：小僵尸正面 壳半径 0.714 → 落点 0.302，退 0.412，落点落在模型半宽 0.332 之内、画面里爆点从「圆柱壳外圈」移到**僵尸手臂上**。 踩过的三个坑（都写进代码注释了）：① 用**整只怪**的包围盒 ⇒ 头顶丸子头/脚边件把 Z 半宽从 0.332 撑到 0.622，退让少算 0.29m，解析读数说「距模型 0.000」而画面明显在外圈；必须按**命中高度切片**。② 包围盒**不能缓存** ⇒ 正式模型异步挂载，缓存会锁到「只有占位件」的那一版。③ 「盒心支撑函数」近似不行 ⇒ 支撑平面在角上相切，命中点偏离盒心时会残留 0.32~0.54m 悬空，必须用逐轴 slab 夹逼的射线求交。 【容差】猪队友场景：模型包围盒按**轴对齐**算，而躯干是斜的 ⇒ 背面打会差约 0.25m，下一轮可考虑改用命中高度处的**水平最近顶点**（顶点数很小：小僵尸 1543 / 胖子 1513 / 警察 16468）。 【机位教训】验「某个方向上的一小段位移」时，**机位必须垂直于那段位移** —— 第一版预览用斜前机位，0.2m 正好落在视线方向 ⇒ 两张图肉眼看不出区别（等于没验）；改侧视（沿 +X 看回原点）后才能读出。 【双向判据】验收对「贴肉」是**两侧**都钉的：既要求落点不再悬空（距模型 ≤ 0.05m），也要求**不许比原始壳面命中点更深**（±0.05m）。只判「在盒内」是单向的 —— 实测把包围盒故意算大 2.6 倍，单向判据照样全绿。
A40: VFX-METAL-SPARK-HIT-3D | B40: 金属打击火星命中特效 | C40: 特效 | D40: 战斗反馈 | E40: FX01-21 | F40: root_3d | H40: 俯视3D | I40: hit_metal_spark | J40: 击中非僵尸三兄弟的一切目标（墙面/掩体/地面/其它怪种） | K40: 已完成 | L40: P1 | M40: v001 | N40: PackedScene/程序几何（5 颗白色方块 + 2 根金色长条火星，0.32s；无灯、无碰撞体） | O40: assets/art/vfx/combat_3d/vfx_metal_spark_hit_root_top3d.tscn | P40: src/vfx/VfxMetalSparkHit3D.gd; src/combat3d/Projectile3D.gd | Q40: 命中;受击;金属;火星;白色方块;金色长条;metal-spark;切平面;3D | R40: =LOWER(TRIM(C40)&"|"&TRIM(D40)&"|"&TRIM(E40)&"|"&TRIM(F40)&"|"&TRIM(H40)&"|"&TRIM(I40)) | S40: =IF(COUNTIF($R$6:$R$53,R40)>1,"重复","唯一") | T40: 79571e7eb19be6b4e8dde1d7c3b050142ba246269ea1770f54f631d1068b94ec | U40: 摩斯拉 | V40: 2026-10-14 | W40: 原创程序几何 | X40: FX01-21 | Y40: 业主口径（2026-10-14）：原本是「原来那个特效缩小 60%，作为击中其它物体的特效」，追问缩小读数后业主改为「**重新制作一个**，通过一个打击到金属的粒子反馈的特效，用白色方块粒子和 2 根长条的金色火星一样飞溅去替代，这个不要用太多粒子，**4-5 颗 + 2 根金色火星**即可」⇒ 本件是**新资产**，不是 VFX-IMPACT-3D 的改版；VFX-IMPACT-3D 保持原样，继续服务它剩下的用途（非僵尸怪种死亡爆点、护盾弹开）。造型：5 颗白方块（`ToonVfxGeometry.unit_cube_mesh()`）+ 2 根金色长条火星（`ToonVfxGeometry.streak_mesh()`，**长轴 = 本地 Z** ⇒ `scale.z` 直接就是米数，长度 0.50 → 1.30 × size，从短粗拉成细长）。朝向契约 `context.normal`（**本件是唯一消费法线的战斗命中件**）：局部 +Y 对齐法线 ⇒ 局部 XZ 就是被击表面；**金色火星在切平面内擦出**（沿表面擦出去，|世界方向·法线| ≤ 0.20 有断言）、白方块沿法线向外喷。朝向用 `Basis.looking_at`（把本地 **-Z** 对到切向）—— 不能写 `Quaternion(UP, dir)`，后者是把 +Y 转过去，会让火星指向天上。**刻意无灯**：与 FX01-20 同理（高频件）。尺寸 `Projectile3D.METAL_SPARK_SIZE_TARGET = 0.34`（业主「受击的特效也不要太大」）。纯视觉无碰撞体，走 VfxPool3D（FX01_METAL_SPARK_HIT）。真渲染校准（`outputs/combat_vfx_batch2/combat_vfx_batch2_timeline.png`）：首版张角 0.34 rad、长 0.22→0.78 ⇒ 两根几乎重叠、读成「一根小凸起」；抬到 0.62 rad / 0.50→1.30 才成了「长条」。首版白方块切向占比 0.35~0.8、外推 0.30m ⇒ 5 颗挤成一坨，抬高切向占比并加大外推后才读成一撮碎屑。
A41: VFX-FATE-ROCK-3D | B41: 力量滚石弹 | C41: 子弹特效 | D41: combat | E41: fate_rock | F41: root_3d | H41: 俯视3D | I41: fate_rock | J41: 力量命运卡 | K41: 已完成 | L41: P1 | M41: v001 | N41: 低多边形石头，直径0.36m；随弹体滚动，不进入VfxPool3D | O41: assets/art/vfx/combat_3d/vfx_fate_rock_root_top3d.tscn | P41: src/vfx/VfxFateRock3D.gd; docs/v0.1/14_技术施工_命运塔罗牌组.md | Q41: 命运;力量;滚石;碎裂 | R41: =LOWER(TRIM(C41)&"|"&TRIM(D41)&"|"&TRIM(E41)&"|"&TRIM(F41)&"|"&TRIM(H41)&"|"&TRIM(I41)) | S41: =IF(COUNTIF($R$6:$R$53,R41)>1,"重复","唯一") | T41: e85c77c8f7d178fd9cabe8a806e729bd81c4a9cd9969c3ec468cdbb302930138 | U41: Codex | V41: 2026-10-16 | W41: 原创Prefab几何 | X41: FX01-22 | Y41: 低多边形石头，直径0.36m；随弹体滚动，不进入VfxPool3D；行为由Projectile3D持有；碰撞不在VFX里。；隔离专项及真实渲染已验收，见2026-10-16_star_physical_mounts开发记录。
A42: VFX-FATE-ROCK-SHATTER-3D | B42: 力量碎石爆散 | C42: 特效 | D42: combat | E42: fate_rock_shatter | F42: root_3d | H42: 俯视3D | I42: fate_rock_shatter | J42: 力量命运卡 | K42: 已完成 | L42: P1 | M42: v001 | N42: 8枚石块径向飞散，0.55s；无灯无碰撞；进入VfxPool3D | O42: assets/art/vfx/combat_3d/vfx_fate_rock_shatter_root_top3d.tscn | P42: src/vfx/VfxFateRockShatter3D.gd; docs/v0.1/14_技术施工_命运塔罗牌组.md | Q42: 命运;力量;滚石;碎裂 | R42: =LOWER(TRIM(C42)&"|"&TRIM(D42)&"|"&TRIM(E42)&"|"&TRIM(F42)&"|"&TRIM(H42)&"|"&TRIM(I42)) | S42: =IF(COUNTIF($R$6:$R$53,R42)>1,"重复","唯一") | T42: 8e25fad8d8af63c4f41ea3d8ac6b6ddc44c0a702c7f7fcd546dfac2ebddc4726 | U42: Codex | V42: 2026-10-16 | W42: 原创Prefab几何 | X42: FX01-23 | Y42: 8枚石块径向飞散，0.55s；无灯无碰撞；进入VfxPool3D；行为由Projectile3D持有；碰撞不在VFX里。；隔离专项及真实渲染已验收，见2026-10-16_star_physical_mounts开发记录。
...

Sheet 3D-特效
A1: ShellStorm2 · 特效 3D Prefab
A2: 特效按独立 Prefab 原则：每个特效一个独立 .tscn；Prefab 是特效唯一出口；账本和调用代码读 Prefab。本 sheet 共 25 条，按 5 大类分组，每条 VFX 有内部编号 FX<大类>-<序号>。状态：✅ 完成（Prefab + 脚本 + 接入齐）/ 🟡 待落地（已登记 AssetID，文件未创建）/ 🟠 老形态（迁移完成后删除）。规范见 docs/v0.1/14.6_特效系统与制作规范.md。【2026-09-11 进度】FX01 战斗反馈 5 条 + FX02 受击飘字 2 条 共 7 条完成；FX03/04 已实装但命名待对齐。【2026-09-21 进度】新增 FX01-06 VFX-BULLET-VISUAL-3D（飞行子弹纯视觉，含 ProjectileLight，由 Projectile3D 持有、不进 VfxPool）；FX01-01 / FX01-02 升 v002 卡通重做（枪口新增 MuzzleLight、命中改按命中法线对齐）；三类共同验收 verify_combat_vfx_toon_v002。【2026-09-22 进度】新增 FX01-07 VFX-SHELL-CASING-3D：开火抛壳、重力落地、最多两次小弹跳后静止，接入 WeaponModel3D 与 VfxPool3D。。 【2026-10-13 进度】新增 8 个逐弹种专属弹体 Prefab（FX01-08..FX01-15，VFX-BULLET-{STANDARD,STICKY,BOUNCE,PIERCING,EXPLOSIVE,HOMING,BLACKHOLE,BALLOON}-3D），为 FX01-06 通用弹体的弹种专属变体：共享基类 VfxBulletBody3D（弹芯/外壳/尾迹/跟随灯分层），由 Projectile3D 依 visual_id 路由、随 ProjectilePool3D 回收，不进 VfxPool；专项验收 verify_bullet_vfx_profiles。 【2026-10-14 进度】新增 FX01-16 VFX-MONSTER-ROAR-ICON-3D 怪物启动吼叫头顶图标：怪物从 idle/patrol 进攻击前的 0.30–0.60s 启动过程里，转向玩家后头顶弹出的一次性吼叫提示（业主设计，见 docs/v0.1/06A_怪物AI系统完整设计_评审稿.md §6.1.1）。独立 Prefab + 脚本 VfxMonsterRoarIcon3D + 256² RGBA 透明底贴图（gpt-image-2）。**尺寸按体型等比**：世界边长 = 该怪头顶血条宽 × 0.42，钳制 0.45–1.20m，公式真源 src/enemy3d/MonsterStartupProfile.gd。每怪常驻 Sprite3D 由怪物自身持有，刻意不进 VfxPool3D；Boss 豁免。专项验收 verify_monster_startup_roar。 【2026-10-14 进度】新增 FX01-17 VFX-DEATH-BLAST-3D 与 FX01-18 VFX-BLAST-ZONE-3D：远征01 胖子僵尸死亡自爆的**爆炸 + 地面残留伤害场**一整套（业主指定「自爆没有特效」+「地上留一个持续伤害的范围效果，持续3秒」）。爆炸走 VfxPool3D 路由；地面场由玩法节点 DeathBlastZone3D 宿主自持、刻意不进池。专项验收 verify_death_blast_vfx。【2026-10-14 改版】FX01-16 升 v002（业主指定）：图形改为**红色感叹号**，并新增**「弹出后停顿一下」**的节奏 —— ① 弹出 0.70→1.15（过冲）② 回稳 →1.00 ③ 停顿（严格静止）④ 淡出；图标-血条间隙由固定 0.12m 改为按图标边长 0.30 的比例。
A4: 编号 | B4: AssetID | C4: 中文名 | D4: Prefab路径 | E4: GLB模型路径 | F4: Blender源文件 | G4: 功能说明 | H4: 功能脚本路径 | I4: 碰撞开关 | J4: 碰撞归属 | K4: 碰撞方式 | L4: 标准尺寸 | M4: 原点与朝向 | N4: 使用位置 | O4: 制作状态 | P4: 版本 | Q4: 备注
A5: ▼ 00 特效套件（老形态）
A6: FX00-01 | B6: VFX-COMBAT-KIT-3D | C6: 战斗反馈3D通用特效套件 | D6: assets/art/vfx/combat_3d/vfx_combat_kit_root_top3d.tscn | G6: 一个 Prefab + match effect_kind 7 套代码分支，覆盖 7 种战斗反馈视觉。违反 14.6 独立 Prefab 原则 §1；下方 7 个战斗反馈/受击飘字条目为拆分目标。旧调用方继续运行至 2026-Q4 迁移完成。 | H6: src/combat3d/CombatEffect3D.gd | I6: 无 | J6: 无 | K6: 无 | L6: PackedScene/参数化特效 | M6: 未声明 | N6: 枪械/近战/敌人/关卡 | O6: 老 · 待拆分 | P6: v001 | Q6: 老形态·保留为过渡；待 14.6 §6 迁移完成后删除
A7: ▼ 01 战斗反馈
A8: FX01-01 | B8: VFX-MUZZLE-FLASH-3D | C8: 枪口火光特效 | D8: assets/art/vfx/combat_3d/vfx_muzzle_flash_root_top3d.tscn | G8: 枪械开火时的瞬时枪口花火（卡通 v002）：铂金亮芯 + 橙金/弹药色立体楔形火焰（CylinderMesh top_radius=0，Godot 4.x 无 ConeMesh）+ 交叉面尖瓣 + 5 枚飞散火星 + 短冲击环 + 一盏 OmniLight3D（名 MuzzleLight，shadow_enabled=false）。经 VfxPool3D 按 AssetID 路由。2026-09-21 补丁：支持 context.follow / follow_local_offset 挂点跟随——每帧把世界变换贴到挂点（枪口），角色移动、转向与后坐力位移时不残留；未绑定时退化为世界锚定。 | H8: src/vfx/VfxMuzzleFlash3D.gd | I8: 无 | J8: 无 | K8: 无 | L8: 亮芯约 0.18m；火焰长 0.7~1.8×size；lifetime 0.16s；MuzzleLight range 3.5m×size、峰值 light_energy 5.0、寿命末端归零 | M8: 原点=根节点中心；朝向=Basis.looking_at(context.forward)，local -Z 对齐射击方向 | N8: 枪械开火（远程 7 枪） | O8: 完成 | P8: v002 | Q8: v002 卡通重做；Prefab=assets/art/vfx/combat_3d/vfx_muzzle_flash_root_top3d.tscn（去版本化路径，N1/N2 后不再带 _v001）+ 脚本=src/vfx/VfxMuzzleFlash3D.gd；根节点=VfxMuzzleFlash3D(Node3D)；FX编号 FX01-01；调用方：WeaponModel3D._spawn_muzzle_effect 经 VfxPool3D.acquire(FX01_MUZZLE_FLASH, …, {"forward": -global_basis.z})；验收：verify_combat_vfx_toon_v002。注：旧版备注中的 ..._v001.tscn 路径已废弃。；2026-09-21 补丁：新增挂点跟随契约（follow），调用方 WeaponModel3D 以 muzzle 挂点为跟随目标；调用方尺寸基准定档 0.8（视觉体积 80%）。
A9: FX01-02 | B9: VFX-IMPACT-3D | C9: 通用命中特效 | D9: assets/art/vfx/combat_3d/vfx_impact_root_top3d.tscn | G9: 子弹/投射物命中表面的爆点（卡通 v002）：亮芯 + 冲击环（TorusMesh） + 7 道错峰星芒（BoxMesh，Quaternion(UP,dir) 放射） + 8 块错峰旋转碎屑；UNSHADED 半透明材质、透明重叠受控。 | H9: src/vfx/VfxImpact3D.gd | I9: 无 | J9: 无 | K9: 无 | L9: 亮芯约 0.16m；冲击环 0.2→2.4×size；lifetime 0.32s | M9: 原点=根节点中心；朝向=Basis(Quaternion(UP, context.normal))，local +Y 对齐命中法线 | N9: 子弹/投射物命中通用 | O9: 完成 | P9: v002 | Q9: v002 卡通重做；Prefab=assets/art/vfx/combat_3d/vfx_impact_root_top3d.tscn（去版本化路径）+ 脚本=src/vfx/VfxImpact3D.gd；根节点=VfxImpact3D(Node3D)；FX编号 FX01-02；调用方：Projectile3D._spawn_effect(VfxPool3D.FX01_IMPACT, …) 传 hit_context={"normal":…, "position":…}；Enemy3D / PlayerMeleeCombat3D 亦经 VfxPool3D 路由；验收：verify_combat_vfx_toon_v002。注：旧版备注中的 ..._v001.tscn 路径已废弃。
A10: FX01-03 | B10: VFX-EXPLOSION-3D | C10: 爆炸特效 | D10: assets/art/vfx/combat_3d/vfx_explosion_root_top3d.tscn | G10: 范围爆炸；1 SphereMesh 核心 + 2 TorusMesh 冲击波环（径向波 + 二次环）；参数 effect_color / effect_size。 | H10: src/vfx/VfxExplosion3D.gd | I10: 无 | J10: 无 | K10: 无 | L10: 约 0.42m 核心 → 0.82m 外环；lifetime 0.46s | M10: 原点=根节点中心；朝向=local -Z 正面 | N10: 爆炸弹/范围武器 | O10: 完成 | P10: v001 | Q10: 已实装；Prefab=assets/art/vfx/combat_3d/vfx_explosion_root_top3d_v001.tscn + 脚本=src/vfx/VfxExplosion3D.gd；根节点=VfxExplosion3D(Node3D)；FX编号 FX01-03；调用方：PlayerMeleeCombat3D/Enemy3D 经 VfxPool3D 路由
A11: FX01-04 | B11: VFX-MELEE-SLASH-3D | C11: 近战挥砍弧特效 | D11: assets/art/vfx/combat_3d/vfx_melee_slash_root_top3d.tscn | G11: 近战挥砍时的弧光；SurfaceTool 自定义三角扇形 + 顶点 alpha 渐隐；连段 1/2/3 通过 effect_size 和方向区分。 | H11: src/vfx/VfxMeleeSlash3D.gd | I11: 无 | J11: 无 | K11: 无 | L11: 内径 0.78m / 外径 1.42m；lifetime 0.28s | M11: 原点=根节点中心；朝向=local -Z 正面 | N11: 棒球棍/巨刃/战斧挥砍（近战 3 武器） | O11: 完成 | P11: v001 | Q11: 已实装；Prefab=assets/art/vfx/combat_3d/vfx_melee_slash_root_top3d_v001.tscn + 脚本=src/vfx/VfxMeleeSlash3D.gd；根节点=VfxMeleeSlash3D(Node3D)；FX编号 FX01-04；调用方：PlayerMeleeCombat3D/Enemy3D 经 VfxPool3D 路由
