Workbook

Sheet 总览
A1: SHELLSTORM 2 · 敌人美术账本 v0.1
A3: 归属域=敌人｜覆盖大类=敌人｜AssetID 前缀=ENM｜主账本（总目录）=assets/registry/ShellStorm2_美术资产台账_v001.xlsx；本账本可独立并行编辑，跨域契约见主账本
A5: 资产总数 | C5: 已完成/已接入 | E5: 待制作/程序占位 | G5: 重复警报 | I5: 域内专表 / 3D Prefab 分页
A6: =COUNTA('资产主表'!$A$6:$A$20) | C6: =COUNTIF('资产主表'!$K$6:$K$20,"已完成")+COUNTIF('资产主表'!$K$6:$K$20,"原型已接入")+COUNTIF('资产主表'!$K$6:$K$20,"正式美术已接入")+COUNTIF('资产主表'!$K$6:$K$20,"已优化并正式接入")+COUNTIF('资产主表'!$K$6:$K$20,"Blender源已完成")+COUNTIF('资产主表'!$K$6:$K$20,"已导入；优化完成")+COUNTIF('资产主表'!$K$6:$K$20,"白模源已完成；QA PASS") | E6: =COUNTIF('资产主表'!$K$6:$K$20,"待制作")+COUNTIF('资产主表'!$K$6:$K$20,"程序占位") | G6: =COUNTIF('资产主表'!$S$6:$S$20,"重复") | I6: 域内专表：敌人动画与状态 / 3D-敌人 | 3D Prefab 分页：3D-敌人
A9: 大类 | B9: 资产数 | C9: 完成/接入 | E9: 本账本只登记上列大类；跨域搬运资产须同步主账本《分类与编码》并重跑门禁
A10: 敌人 | B10: =COUNTIF('资产主表'!$C$6:$C$20,A10) | C10: =SUMPRODUCT(('资产主表'!$C$6:$C$20=A10)*(('资产主表'!$K$6:$K$20="已完成")+('资产主表'!$K$6:$K$20="原型已接入")+('资产主表'!$K$6:$K$20="正式美术已接入")+('资产主表'!$K$6:$K$20="已优化并正式接入")+('资产主表'!$K$6:$K$20="Blender源已完成")+('资产主表'!$K$6:$K$20="已导入；优化完成")+('资产主表'!$K$6:$K$20="白模源已完成；QA PASS")))
A11: 合计 | B11: =COUNTIF('资产主表'!$C$6:$C$20,A11) | C11: =SUMPRODUCT(('资产主表'!$C$6:$C$20=A11)*(('资产主表'!$K$6:$K$20="已完成")+('资产主表'!$K$6:$K$20="原型已接入")+('资产主表'!$K$6:$K$20="正式美术已接入")+('资产主表'!$K$6:$K$20="已优化并正式接入")+('资产主表'!$K$6:$K$20="Blender源已完成")+('资产主表'!$K$6:$K$20="已导入；优化完成")+('资产主表'!$K$6:$K$20="白模源已完成；QA PASS")))
A13: 域内 3D Prefab 分页统计（快照口径与本账本分页一致；权威清单在各分页表）
A14: 分页 | B14: Prefab 数 | C14: 直接引用 GLB | D14: 有功能脚本 | E14: 碰撞开启 | F14: 说明
A15: 3D-敌人 | B15: =COUNTA('3D-敌人'!$A$5:$A$204) | C15: =COUNTIF('3D-敌人'!$D$5:$D$204,"<>") | D15: =COUNTIF('3D-敌人'!$G$5:$G$204,"<>") | E15: =COUNTIF('3D-敌人'!$H$5:$H$204,"开") | F15: 一行 = 一个实际存在的 Godot PackedScene
A16: 合计 | B16: =SUM(B15) | C16: =SUM(C15) | D16: =SUM(D15) | E16: =SUM(E15)

Sheet 账本说明
A1: 本账本说明 · 敌人
A3: 本表是分账本自描述；机器可读真源为 assets/registry/ledger_index.json，二者不一致时以 JSON 为准
A5: 项 | B5: 值
A6: 账本归属域 | B6: 敌人
A7: 分账本文件 | B7: assets/registry/ledgers/ShellStorm2_敌人账本_v001.xlsx
A8: 覆盖大类 | B8: 敌人
A9: AssetID 前缀 | B9: ENM
A10: 域内专表 | B10: 敌人动画与状态 / 3D-敌人
A11: 3D Prefab 分页 | B11: 3D-敌人
A12: 动画登记表 | B12: 敌人动画与状态
A13: 主账本（总目录） | B13: assets/registry/ShellStorm2_美术资产台账_v001.xlsx
A14: 跨域契约 | B14: 分类与编码 / 命名与查重 / 版本记录 / Skill 清单 / 3D Prefab 总控 —— 全部只在主账本维护
A15: 首选制作 Skill | B15: game-character-model-pipeline
A16: 协作 Skill | B16: 无
... A23: 快照日期 | B23: 2026-09-18

Sheet 资产主表
A1: 资产主表 · 唯一登记源
A3: 查重键由公式生成；S 列出现“重复”时禁止制作，先合并或建立变体父子关系
A5: AssetID | B5: 中文名 | C5: 大类 | D5: 子类 | E5: 逻辑ID/源键 | F5: 组件槽 | G5: 变体父ID | H5: 视角 | I5: 状态/动画 | J5: 复用范围 | K5: 制作状态 | L5: 优先级 | M5: 版本 | N5: 规格(px) | O5: 文件路径 | P5: 源码/策划依据 | Q5: 关键词/别名 | R5: 查重键 | S5: 查重结果 | T5: SHA-256 | U5: 负责人 | V5: 更新时间 | W5: 来源/许可 | X5: 源编号（Blender collection） | Y5: 备注
A6: ENM-MELEE-FUNGBOAR01 | B6: 小僵尸 | C6: 敌人 | D6: normal_melee | E6: melee_chaser | F6: root_3d | G6: ENM-ECOSYSTEM-KIT-3D | H6: Top3D / local -Z 正面 | I6: default / chase | J6: 全部战斗关卡普通怪池 | K6: 已完成 | L6: P0 | M6: v003 | N6: 1.2819×0.9535×1.8571m；1 Mesh；1 材质；36 骨；6 剪辑 | O6: assets/art/enemies/normal_enemy_3d/melee_chaser/runtime/enm_melee_fungboar01_root_top3d.tscn | P6: assets/art/enemies/normal_enemy_3d/melee_chaser/source/model/enm_melee_fungboar01_model_v002.blend; assets/art/enemies/normal_enemy_3d/melee_chaser/source/animation/enm_melee_fungboar01_animation_v003.blend | Q6: 近战追击; chaser; 小僵尸; 小菌猪（旧登记名）; 普通怪标准样板; ENM-MELEE-FUNGBOAR01 | R6: =LOWER(TRIM(C6)&"|"&TRIM(D6)&"|"&TRIM(E6)&"|"&TRIM(F6)&"|"&TRIM(H6)&"|"&TRIM(I6)) | S6: =IF(COUNTIF($R$6:$R$20,R6)>1,"重复","唯一") | T6: 04167459feffd18fa2dfd581ff8def82f58377e13909093a1b599c75080732f0 | U6: Codex | V6: 46285 | W6: AI 生成（Tripo）+ Blender 重制 | X6: — | Y6: GLB 仅表现；runtime PackedScene 无碰撞，Enemy3D 继续持有 CylinderShape3D、AI、生命、伤害与掉落。EnemyAvatar3D 以 FORMAL_MELEE_KIND 常量分支自动挂载，普通怪没有 configure_*_content() 函数。 2026-09-20 首个标准普通怪转正：Tripo 源 → Blender 重制（模型 v002 / 动作 v003），六段剪辑按 12 态采样，verify_melee_zombie_presentation 通过。 显示名迁移：小菌猪 → 小僵尸（Enemy3D.configure_from_enemy_data 精确迁移旧存档尾名）；AssetID 与逻辑 ID 不变。 未闭合：碰撞 FOOTPRINT_PROFILES(radius 1.02/height 1.30) 仍为旧程序网格口径，按新几何应为 0.641/1.857，属玩法数值待拍板；贴图仅 basecolor，无法线贴图。
A7: ENM-RANGED-SPORESHOOTER01 | B7: 保安僵尸 | C7: 敌人 | D7: normal_ranged | E7: ranged_caster | F7: root_3d | G7: ENM-ECOSYSTEM-KIT-3D | H7: Top3D / local -Z 正面 | I7: default / chase / shoot | J7: 全部战斗关卡远程怪池 | K7: 已完成 | L7: P0 | M7: v002 | N7: 1.2819×0.9535×1.8571m；1 Mesh；1 材质；36 骨；10 剪辑 | O7: assets/art/enemies/normal_enemy_3d/ranged_caster/runtime/enm_ranged_sporeshooter01_root_top3d.tscn | P7: assets/art/enemies/normal_enemy_3d/ranged_caster/source/model/enm_ranged_sporeshooter01_model_v001.blend; assets/art/enemies/normal_enemy_3d/ranged_caster/source/animation/enm_ranged_sporeshooter01_animation_v002.blend | Q7: 远程射击; ranged; 保安僵尸; 孢子射手（旧程序名）; 单手持枪; ENM-RANGED-SPORESHOOTER01 | R7: =LOWER(TRIM(C7)&"|"&TRIM(D7)&"|"&TRIM(E7)&"|"&TRIM(F7)&"|"&TRIM(H7)&"|"&TRIM(I7)) | S7: =IF(COUNTIF($R$6:$R$20,R7)>1,"重复","唯一") | T7: 6ef48eb029670062dde23f413badea4a39cd27635f0365aa8bc1e2c9998173d4 | U7: Codex | V7: 46286 | W7: 桌面 FBX + Blender 共享小僵尸骨架重制 | X7: — | Y7: GLB 仅表现；runtime PackedScene 无碰撞；Enemy3D 继续持有 ranged_caster 的 AI、三弹散布、生命、伤害与掉落。枪为双管炮视觉附件，挂 L_Hand，不接玩家武器逻辑。
A8: ENM-SUMMON-HIVE01 | B8: 蜂巢怪 | C8: 敌人 | D8: normal_summoner | E8: summoner | F8: root | H8: 侧面朝右（可水平翻转） | I8: default | J8: 单资产 | K8: 程序占位 | L8: P0 | M8: v001 | N8: 待定 | P8: src/enemy/EnemyTypes.gd | Q8: 召唤型; hive | R8: =LOWER(TRIM(C8)&"|"&TRIM(D8)&"|"&TRIM(E8)&"|"&TRIM(F8)&"|"&TRIM(H8)&"|"&TRIM(I8)) | S8: =IF(COUNTIF($R$6:$R$20,R8)>1,"重复","唯一") | U8: 待分配 | V8: 46224 | W8: 原创/待确认 | X8: —
A9: ENM-TANK-SHELLGUARD01 | B9: 壳甲卫兵 | C9: 敌人 | D9: normal_tank | E9: shielded | F9: root | H9: 侧面朝右（可水平翻转） | I9: default | J9: 单资产 | K9: 弃用 | L9: P0 | M9: v001 | N9: 待定 | P9: src/enemy/EnemyTypes.gd | Q9: 护盾型; tank | R9: =LOWER(TRIM(C9)&"|"&TRIM(D9)&"|"&TRIM(E9)&"|"&TRIM(F9)&"|"&TRIM(H9)&"|"&TRIM(I9)) | S9: =IF(COUNTIF($R$6:$R$20,R9)>1,"重复","唯一") | U9: 待分配 | V9: 46298 | W9: 原创/待确认 | X9: — | Y9: 2026-10-03用户要求退役；现行盒/随机池/主题池由ENM-NORMAL-FAT-ZOMBIE03接替。旧ID、源与存档兼容保留；不再新投放。
A10: ENM-BOMBER-FRUIT01 | B10: 炸弹果 | C10: 敌人 | D10: normal_bomber | E10: exploder | F10: root | H10: 侧面朝右（可水平翻转） | I10: default | J10: 单资产 | K10: 程序占位 | L10: P0 | M10: v001 | N10: 待定 | P10: src/enemy/EnemyTypes.gd | Q10: 膨胀鼠; 自爆型; bomber | R10: =LOWER(TRIM(C10)&"|"&TRIM(D10)&"|"&TRIM(E10)&"|"&TRIM(F10)&"|"&TRIM(H10)&"|"&TRIM(I10)) | S10: =IF(COUNTIF($R$6:$R$20,R10)>1,"重复","唯一") | U10: 待分配 | V10: 46224 | W10: 原创/待确认 | X10: —
A11: ENM-TRAP-SPIKEWORM01 | B11: 地刺虫 | C11: 敌人 | D11: normal_ambusher | E11: ambusher | F11: root | H11: 侧面朝右（可水平翻转） | I11: default | J11: 单资产 | K11: 程序占位 | L11: P0 | M11: v001 | N11: 待定 | P11: src/enemy/EnemyTypes.gd | Q11: 潜伏型; trapper | R11: =LOWER(TRIM(C11)&"|"&TRIM(D11)&"|"&TRIM(E11)&"|"&TRIM(F11)&"|"&TRIM(H11)&"|"&TRIM(I11)) | S11: =IF(COUNTIF($R$6:$R$20,R11)>1,"重复","唯一") | U11: 待分配 | V11: 46224 | W11: 原创/待确认 | X11: —
A12: ENM-BOSS-ABYSS01 | B12: 深渊 Boss | C12: 敌人 | D12: boss | E12: boss | F12: root | H12: 侧面朝右（可水平翻转） | I12: default | J12: 单资产 | K12: 程序占位 | L12: P1 | M12: v001 | N12: 待定 | P12: src/enemy/BossAvatarRenderer.gd | Q12: BossActor; 三阶段 | R12: =LOWER(TRIM(C12)&"|"&TRIM(D12)&"|"&TRIM(E12)&"|"&TRIM(F12)&"|"&TRIM(H12)&"|"&TRIM(I12)) | S12: =IF(COUNTIF($R$6:$R$20,R12)>1,"重复","唯一") | U12: 待分配 | V12: 46224 | W12: 原创/待确认 | X12: — | Y12: 三阶段由同一主体加部件/发光变化，不重复做整套
A13: ENM-ECOSYSTEM-KIT-3D | B13: 七类怪物3D生态套件 | C13: 敌人 | D13: normal_elite_boss | E13: enemy_ecosystem | F13: root_3d | H13: 俯视3D | I13: default | J13: 四主题战斗房 | K13: 原型已接入 | L13: P0 | M13: v001 | N13: PackedScene/模块敌人 | O13: assets/art/enemies/enemy_3d/enm_ecosystem_kit_root_top3d_v001.tscn | P13: src/enemy3d/Enemy3D.gd | Q13: 怪物;七类;核心;外壳;附肢;状态 | R13: =LOWER(TRIM(C13)&"|"&TRIM(D13)&"|"&TRIM(E13)&"|"&TRIM(F13)&"|"&TRIM(H13)&"|"&TRIM(I13)) | S13: =IF(COUNTIF($R$6:$R$20,R13)>1,"重复","唯一") | T13: d9d8a49bed3fdcb863bad72f60be1f774309c7dda52753f5efb3d4e56159c12d | U13: Codex | V13: 46225 | W13: 原创程序几何 | X13: — | Y13: 九态AI视线允许射线命中玩家本体并保留实体墙遮挡；3D基础HP乘旧楼层/主题/精英倍率，开局手枪普通命中不秒杀基础怪
A14: ENM-BOSS-ARCHIVIST-95 | B14: 深渊档案官 | C14: 敌人 | D14: boss | E14: boss_abyss_archivist_95 | F14: root | H14: Top3D | I14: default / 三阶段 | J14: 95层Boss | K14: 已完成 | L14: P0 | M14: v001 | N14: GLB；主体/发光/附肢语义拆分 | O14: assets/art/enemies/bosses_v01/enm_boss_archivist_95_top3d_v001.glb | P14: source/art/blender/bosses_v01/enm_boss_archivist_95_top3d_v001.blend; src/enemy3d/BossContentCatalog.gd | Q14: 深渊档案官; archive; 95F; 三阶段 | R14: =LOWER(TRIM(C14)&"|"&TRIM(D14)&"|"&TRIM(E14)&"|"&TRIM(F14)&"|"&TRIM(H14)&"|"&TRIM(I14)) | S14: =IF(COUNTIF($R$6:$R$20,R14)>1,"重复","唯一") | T14: d48dbdef27c500895471b8e14e4d07ae8f733b511ea67bf44cf0dffe959d781c | U14: Codex | V14: 46247 | W14: 原创程序建模 | X14: — | Y14: 独立正式模型；阶段技能袋 archive_fan/index_beam/archive_storm；通过Boss专项验收。 2026-08-30 AST-01规范化（原制作状态：正式美术已接入）
A15: ENM-BOSS-FURNACE-WARDEN-90 | B15: 熔炉狱监 | C15: 敌人 | D15: boss | E15: boss_furnace_warden_90 | F15: root | H15: Top3D | I15: default / 三阶段 | J15: 90层Boss | K15: 已完成 | L15: P0 | M15: v001 | N15: GLB；主体/发光/附肢语义拆分 | O15: assets/art/enemies/bosses_v01/enm_boss_furnace_warden_90_top3d_v001.glb | P15: source/art/blender/bosses_v01/enm_boss_furnace_warden_90_top3d_v001.blend; src/enemy3d/BossContentCatalog.gd | Q15: 熔炉狱监; furnace; 90F; 三阶段 | R15: =LOWER(TRIM(C15)&"|"&TRIM(D15)&"|"&TRIM(E15)&"|"&TRIM(F15)&"|"&TRIM(H15)&"|"&TRIM(I15)) | S15: =IF(COUNTIF($R$6:$R$20,R15)>1,"重复","唯一") | T15: 77469ad543d9265ffcc32198c06e25dd3ea8b793b79da4afeb7bd5e56f09d24c | U15: Codex | V15: 46247 | W15: 原创程序建模 | X15: — | Y15: 独立正式模型；阶段技能袋 molten_volley/hammer_drive/furnace_burst；通过Boss专项验收。 2026-08-30 AST-01规范化（原制作状态：正式美术已接入）
A16: ENM-BOSS-HOLLOW-CHOIR-85 | B16: 空洞合唱团 | C16: 敌人 | D16: boss | E16: boss_hollow_choir_85 | F16: root | H16: Top3D | I16: default / 三阶段 | J16: 85层Boss | K16: 已完成 | L16: P0 | M16: v001 | N16: GLB；主体/发光/附肢语义拆分 | O16: assets/art/enemies/bosses_v01/enm_boss_hollow_choir_85_top3d_v001.glb | P16: source/art/blender/bosses_v01/enm_boss_hollow_choir_85_top3d_v001.blend; src/enemy3d/BossContentCatalog.gd | Q16: 空洞合唱团; choir; 85F; 三阶段 | R16: =LOWER(TRIM(C16)&"|"&TRIM(D16)&"|"&TRIM(E16)&"|"&TRIM(F16)&"|"&TRIM(H16)&"|"&TRIM(I16)) | S16: =IF(COUNTIF($R$6:$R$20,R16)>1,"重复","唯一") | T16: c7d1bade328047877d64770b2c534cbd930fc377ce8a00e19873fc108a73a56f | U16: Codex | V16: 46247 | W16: 原创程序建模 | X16: — | Y16: 独立正式模型；阶段技能袋 choir_wave/silence_chord/echo_burst；通过Boss专项验收。 2026-08-30 AST-01规范化（原制作状态：正式美术已接入）
A17: ENM-ELITE-RIFT-BOAR-ARMED-3D | B17: 背枪的裂口爬虫3D精英根 | C17: 敌人 | D17: elite | E17: elite_rift_boar_armed | F17: root_3d | G17: ENM-ECOSYSTEM-KIT-3D | H17: Top3D / local -Z 正面 | I17: default / armed_rush | J17: 每次行动98—96F三选一；目标层随机ELITE房 | K17: 已完成 | L17: P0 | M17: v001 | N17: 1.970×1.843×1.345m；18 Mesh；4材质 | O17: assets/art/enemies/elite_3d/rift_boar_armed/runtime/enm_elite_rift_boar_armed_root_top3d_v001.tscn | P17: assets/art/enemies/elite_3d/rift_boar_armed/source/enm_elite_rift_boar_armed_source_v001.blend; assets/art/enemies/elite_3d/rift_boar_armed/components/enm_elite_rift_boar_armed_visual_top3d_v001.glb; scripts/blender/build_elite_rift_boar_armed_v001.py; src/enemy3d/EliteContentCatalog.gd | Q17: 唯一精英;背枪;裂口爬虫;elite_rift_boar_armed;armed_rush;98F;97F;96F;命名血条 | R17: =LOWER(TRIM(C17)&"|"&TRIM(D17)&"|"&TRIM(E17)&"|"&TRIM(F17)&"|"&TRIM(H17)&"|"&TRIM(I17)) | S17: =IF(COUNTIF($R$6:$R$20,R17)>1,"重复","唯一") | T17: b5b187474a58aebe1f5e7c2522b2e4a4db609f103365dca6e7bd8c082a08b496 | U17: Codex | V17: 46264 | W17: 原创 Blender/Godot 组合 | X17: — | Y17: GLB仅表现；core/shell/appendages/weapon_attachment/state_vfx语义齐全；PackedScene无碰撞；Enemy3D继续持有melee_chaser碰撞、AI、生命、伤害与掉落。Forward+固定机位与专项验收通过。 2026-08-30 AST-01规范化（原制作状态：正式美术已接入） 2026-08-30 AST-02：合法内容更新；文件为Git已跟踪且修改时间不早于原台账日期；验收：verify_unique_elite_roster_flow；SHA c72d42495532→b5b187474a58。
A18: ENM-BEAST-SPIKESHELL01 | B18: 暗影兽 | C18: 敌人 | D18: normal_beast | E18: spike_shell | F18: root | H18: 侧面朝右（可水平翻转） | I18: default | J18: 单资产 | K18: 待制作 | L18: P1 | M18: v001 | N18: 待定 | P18: 待入库（Tripo 生成模型当前仅在 Blender 会话中，尚未保存为 .blend） | Q18: 暗影兽; 暗影; 刺背; spike shell; 四足怪; Tripo生成; ENM-BEAST-SPIKESHELL01 | R18: =LOWER(TRIM(C18)&"|"&TRIM(D18)&"|"&TRIM(E18)&"|"&TRIM(F18)&"|"&TRIM(H18)&"|"&TRIM(I18)) | S18: =IF(COUNTIF($R$6:$R$20,R18)>1,"重复","唯一") | U18: 待分配 | V18: 46288 | W18: AI 生成（Tripo）/待确认 | X18: — | Y18: 2026-09-23 新登记为独立新怪，只登记不接线。造型：低伏四足、背脊一排尖刺、大圆头带尾，头部朝 Blender -Y（契约要求 +Y，后续 S3 需整体转 180°）。源尺寸 0.8286×0.9995×0.7104m（Tripo 原始尺度，未按展示倍率归一）。已完成 Rigify 骨架生成 + 自动权重蒙皮（Rigify Basic Human 29 骨 metarig → 219 骨 rig / 34 DEF 骨 / 34 顶点组，3241 顶点全有权重），但**尚未改名到本项目 36 骨契约骨架**，也**缺契约的 16 根手指骨**（Basic Human 无手指链）。入库前待办：① 源 .blend 落 source/model/ 并内部改名；② 按展示倍率 0.70 归一尺寸（源高 = 目标游戏内高 / (0.70×kind×variant)）；③ 朝向归正到 +Y；④ DEF 改名到契约骨架并补手指链；⑤ 另建动作母版 6 段剪辑；⑥ 导出视觉 GLB + runtime Prefab；⑦ 补《3D-敌人》与《敌人动画与状态》行（那两张表分别有『一行=一个真实 PackedScene』与逐字节摘要约束，故本次刻意未动）。玩法数值（HP/速度/伤害/范围/冷却）未定，未接入 Enemy3D.PROFILES。
A19: ENM-NORMAL-FAT-ZOMBIE03 | B19: 胖子僵尸 | C19: 敌人 | D19: normal | E19: fat_zombie03 | F19: root_3d | H19: Top3D / local -Z 正面 | I19: 12态绑定13段动画；idle/walking/running循环，其他单次；hit_light上半身局部混合 | J19: 独立新怪资产；未投放 | K19: 正式美术已接入 | L19: P1 | M19: v011 | N19: 源高3.142857m；游戏站立高2.2m；2867顶点/5690三角；66骨；512²贴图；13已验收动作/13设计动作 | O19: assets/art/enemies/normal_enemy_3d/fat_zombie03/runtime/enm_normal_fat_zombie03_root_top3d.tscn | P19: assets/art/enemies/normal_enemy_3d/fat_zombie03/source/model/enm_normal_fat_zombie03_model_v003.blend; assets/art/enemies/normal_enemy_3d/fat_zombie03/source/animation/enm_normal_fat_zombie03_animation_v008.blend; docs/v0.1/design/胖子僵尸03运行配置.md | Q19: 胖子僵尸; fat zombie; 03 | R19: =LOWER(TRIM(C19)&"|"&TRIM(D19)&"|"&TRIM(E19)&"|"&TRIM(F19)&"|"&TRIM(H19)&"|"&TRIM(I19)) | S19: =IF(COUNTIF($R$6:$R$20,R19)>1,"重复","唯一") | T19: 946f406f5f9faee0387576fd46888eb314e9c70e294c7eb0bb0111e434edd704 | U19: Codex | V19: 46299 | W19: 用户提供Tripo素材；许可待确认 | X19: 03 | Y19: 编号03；v011正式绑定Enemy3D共用12态与13段动画，独立类型fat_zombie03；标准2.2m/512贴图，生命696伤害19，巡逻0.30/追击0.60m/s；F36拍合单次命中、F30锁朝向、视线/范围/扇区判定；普通命中仅上半身，死亡2.6s保留腹部压扁及回弹。专项152项、负向循环故障检出及真实Forward+四图通过。；已替换壳甲卫兵的远征盒、默认随机池和两个主题怪池；固定种子全关实测10只胖子/0只壳甲。；2026-10-04修复游戏内死亡隐藏：尸体退出AI后独立视野组继续判定距离/遮挡，表现帧计时推进2.6秒倒地/腹部接地/回弹后回收；AI休眠不暂停死亡。真实Player3D视野逻辑与Forward+四帧截图通过，负向原失踪条件检出；胖子152项/小僵尸死亡/玩家视野回归通过。
A20: ENM-BOSS-MONITOR002-3D | B20: Boss002 显示器 MONITOR.EXE | C20: 敌人 | D20: boss | E20: boss_monitor002 | F20: root_3d | H20: Top3D / Blender +Y | I20: 12态；16剪辑：idle move melee_keyboard melee_cable heavy_spin_slam special四段 hurt stun三段 turn_left/right dead | J20: expedition_01 / floor_00 / boss（源房ID f00_boss） | K20: active | L20: P1 | M20: v032 | N20: 18684三角面；64骨；每臂6段；3材质；中心后轴独立屏幕旋转 | O20: assets/art/enemies/bosses/enm_boss_monitor002/runtime/enm_boss_monitor002/enm_boss_monitor002_root_top3d.tscn | P20: assets/art/enemies/bosses/enm_boss_monitor002/source/enm_boss_monitor002_model_v032.blend; assets/art/enemies/bosses/enm_boss_monitor002/source/enm_boss_monitor002_animation_v032.blend；SKEL-MONITOR002-005 | Q20: Boss002;monitor;显示器;平面五官 | R20: =LOWER(TRIM(C20)&"|"&TRIM(D20)&"|"&TRIM(E20)&"|"&TRIM(F20)&"|"&TRIM(H20)&"|"&TRIM(I20)) | S20: =IF(COUNTIF($R$6:$R$20,R20)>1,"重复","唯一") | T20: b34c90ef9a59473a9267ddd1f11f7cfeb83c0eca6f84cc4c6b974c842c20f62d | U20: Codex | V20: 2026-10-08 | W20: 用户设计图；原创程序建模 | X20: BOSS002_MONITOR | Y20: v032：仅move改为底座平放左右挪动0.46m，机身左右扭转约41°，双臂柔性跟随。1.6s/48帧，其他15剪辑与四技能时序保留。源97采样、Godot509项、48帧真实渲染通过；previews/move_v032/monitor_walk.mp4。远征01首波1只/3波清房/钥匙通行/ STANDARD撤离规则保留。

Sheet 敌人动画与状态
A1: 敌人动画与状态 · 状态机 × 表现职责
A3: 状态ID 逐字取自 src/enemy3d/Enemy3D.gd 的 VALID_STATES（12 态）；敌人当前为程序驱动，尚无 Blender 动作母版。动作库接入后必须在「动作来源」列改为 Blender，并登记动作母版路径与 SHA-256。
A5: 序号 | B5: 状态ID | C5: 中文名 | D5: 表现职责 | E5: 动作来源 | F5: 循环 | G5: 挂点/特效挂钩 | H5: 首版实现 | I5: 备注
A6: 1 | B6: dormant | C6: 休眠 | D6: 未激活前不表现；不消耗视觉预算 | E6: 程序驱动；ranged_caster 已接入保安僵尸 Blender 视觉与射击剪辑 | F6: 不播放（采样钉在 0） | G6: — | H6: 无（钉 0） | I6: 状态转移表见 src/enemy3d/Enemy3D.gd transition_to()，尚未逐条登记
A7: 2 | B7: idle | C7: 待机 | D7: 呼吸/轻微起伏；程序驱动 | E7: 程序驱动；ranged_caster 已接入保安僵尸 Blender 视觉与射击剪辑 | F7: 循环 | G7: StateVFX 状态环 | H7: idle 循环剪辑 | I7: 状态转移表见 src/enemy3d/Enemy3D.gd transition_to()，尚未逐条登记
A8: 3 | B8: patrol | C8: 巡逻 | D8: 沿巡逻点位移；朝向跟随路径 | E8: 程序驱动；ranged_caster 已接入保安僵尸 Blender 视觉与射击剪辑 | F8: 循环 | G8: StateVFX 状态环 | H8: walking（唯一用走路的移动状态） | I8: 状态转移表见 src/enemy3d/Enemy3D.gd transition_to()，尚未逐条登记
A9: 4 | B9: alert | C9: 警觉 | D9: 锁定可疑目标；身体抬升/视线上抬 | E9: 程序驱动；ranged_caster 已接入保安僵尸 Blender 视觉与射击剪辑 | F9: 循环（复用 idle） | G9: StateVFX 状态环 | H9: idle 循环剪辑 | I9: 状态转移表见 src/enemy3d/Enemy3D.gd transition_to()，尚未逐条登记
A10: 5 | B10: chase | C10: 追击 | D10: 朝玩家追击；步频随速度切换 | E10: 程序驱动；ranged_caster 已接入保安僵尸 Blender 视觉与射击剪辑 | F10: 循环 | G10: StateVFX 状态环 | H10: running 循环剪辑 | I10: 状态转移表见 src/enemy3d/Enemy3D.gd transition_to()，尚未逐条登记
A11: 6 | B11: search | C11: 搜寻 | D11: 丢失目标后在最后已知位置环视 | E11: 程序驱动；ranged_caster 已接入保安僵尸 Blender 视觉与射击剪辑 | F11: 循环 | G11: StateVFX 状态环 | H11: running 循环剪辑 | I11: 状态转移表见 src/enemy3d/Enemy3D.gd transition_to()，尚未逐条登记
A12: 7 | B12: return | C12: 归位 | D12: 脱离战斗归巡逻点 | E12: 程序驱动；ranged_caster 已接入保安僵尸 Blender 视觉与射击剪辑 | F12: 循环 | G12: StateVFX 状态环 | H12: running 循环剪辑 | I12: 状态转移表见 src/enemy3d/Enemy3D.gd transition_to()，尚未逐条登记
A13: 8 | B13: telegraph | C13: 预警 | D13: 出手前的蓄力前摇，必须可读 | E13: 程序驱动；ranged_caster 已接入保安僵尸 Blender 视觉与射击剪辑 | F13: 单次（采样至 length×0.48） | G13: StateVFX 状态环（前摇必须可读） | H13: shoot（状态机采样；攻击事件仍由 Enemy3D 发射三弹） | I13: 状态转移表见 src/enemy3d/Enemy3D.gd transition_to()，尚未逐条登记
A14: 9 | B14: attack | C14: 攻击 | D14: 判定生效帧与挥击/发射表现对齐 | E14: 程序驱动；ranged_caster 已接入保安僵尸 Blender 视觉与射击剪辑 | F14: 单次（钉 length×0.48） | G14: StateVFX 状态环；VFX-IMPACT-3D | H14: shoot（状态机采样；攻击事件仍由 Enemy3D 发射三弹） | I14: 状态转移表见 src/enemy3d/Enemy3D.gd transition_to()，尚未逐条登记
A15: 10 | B15: recovery | C15: 收招 | D15: 攻击后的硬直表现 | E15: 程序驱动；ranged_caster 已接入保安僵尸 Blender 视觉与射击剪辑 | F15: 单次（0.48 → 1.0 线性） | G15: StateVFX 状态环 | H15: shoot（状态机采样；攻击事件仍由 Enemy3D 发射三弹） | I15: 状态转移表见 src/enemy3d/Enemy3D.gd transition_to()，尚未逐条登记
A16: 11 | B16: stagger | C16: 踉跄 | D16: 受击打断；闪白 + 位移 | E16: 程序驱动；ranged_caster 已接入保安僵尸 Blender 视觉与射击剪辑 | F16: 单次（0.16s 硬直内） | G16: 受击闪白（材质 emission 覆盖） | H16: hurt 按 0.16s 采样 | I16: 状态转移表见 src/enemy3d/Enemy3D.gd transition_to()，尚未逐条登记
A17: 12 | B17: dead | C17: 死亡 | D17: 倒地/瓦解；播放结束即回收 | E17: 程序驱动；ranged_caster 已接入保安僵尸 Blender 视觉与射击剪辑 | F17: 单次（末帧保持） | G17: VFX-IMPACT-3D；表现保留 2.4s | H17: dead 采样至剪辑长 | I17: 状态转移表见 src/enemy3d/Enemy3D.gd transition_to()，尚未逐条登记
A19: 敌人条目 × 状态机对照（本账本《资产主表》的每条敌人资产都走同一套 12 态状态机）
A20: 序号 | B20: 敌人ID(AssetID) | C20: 中文名 | D20: 骨架/动作库 | E20: 状态机 | F20: 表现层级 | G20: 独立动作母版 | H20: 首版实现 | I20: 备注
A21: 1 | B21: ENM-MELEE-FUNGBOAR01 | C21: 小僵尸 | D21: Blender 动作母版 v003（36 骨；6 剪辑 idle/walking/running/attack/hurt/dead） | E21: ENEMY_AI_12_STATES | F21: 骨骼 GLB / runtime Prefab（无碰撞） | G21: 有：assets/art/enemies/normal_enemy_3d/melee_chaser/source/animation/enm_melee_fungboar01_animation_v003.blend | H21: 已完成（verify_melee_zombie_presentation）
A22: 2 | B22: ENM-RANGED-SPORESHOOTER01 | C22: 保安僵尸 | D22: Blender 动作母版 v002（复用36骨；6基础剪辑 + armed_idle/walking_armed/running_armed/shoot） | E22: ENEMY_AI_12_STATES | F22: 骨骼 GLB / runtime Prefab / 双管炮视觉附件（无碰撞） | G22: 有：assets/art/enemies/normal_enemy_3d/ranged_caster/source/animation/enm_ranged_sporeshooter01_animation_v002.blend | H22: 已接入（verify_security_zombie_presentation）
A23: 3 | B23: ENM-SUMMON-HIVE01 | C23: 蜂巢怪 | D23: 无 Blender 动作母版（程序驱动） | E23: ENEMY_AI_12_STATES | F23: 程序 Mesh / Prefab | G23: 无 | H23: 待登记
A24: 4 | B24: ENM-TANK-SHELLGUARD01 | C24: 壳甲卫兵 | D24: 无 Blender 动作母版（程序驱动） | E24: ENEMY_AI_12_STATES | F24: 程序 Mesh / Prefab | G24: 无 | H24: 待登记
A25: 5 | B25: ENM-BOMBER-FRUIT01 | C25: 炸弹果 | D25: 无 Blender 动作母版（程序驱动） | E25: ENEMY_AI_12_STATES | F25: 程序 Mesh / Prefab | G25: 无 | H25: 待登记
A26: 6 | B26: ENM-TRAP-SPIKEWORM01 | C26: 地刺虫 | D26: 无 Blender 动作母版（程序驱动） | E26: ENEMY_AI_12_STATES | F26: 程序 Mesh / Prefab | G26: 无 | H26: 待登记
A27: 7 | B27: ENM-BOSS-ABYSS01 | C27: 深渊 Boss | D27: 无 Blender 动作母版（程序驱动） | E27: ENEMY_AI_12_STATES | F27: 程序 Mesh / Prefab | G27: 无 | H27: 待登记
A28: 8 | B28: ENM-ECOSYSTEM-KIT-3D | C28: 七类怪物3D生态套件 | D28: 无 Blender 动作母版（程序驱动） | E28: ENEMY_AI_12_STATES | F28: 程序 Mesh / Prefab | G28: 无 | H28: 待登记
A29: 9 | B29: ENM-BOSS-ARCHIVIST-95 | C29: 深渊档案官 | D29: 无 Blender 动作母版（程序驱动） | E29: ENEMY_AI_12_STATES | F29: 程序 Mesh / Prefab | G29: 无 | H29: 待登记
A30: 10 | B30: ENM-BOSS-FURNACE-WARDEN-90 | C30: 熔炉狱监 | D30: 无 Blender 动作母版（程序驱动） | E30: ENEMY_AI_12_STATES | F30: 程序 Mesh / Prefab | G30: 无 | H30: 待登记
A31: 11 | B31: ENM-BOSS-HOLLOW-CHOIR-85 | C31: 空洞合唱团 | D31: 无 Blender 动作母版（程序驱动） | E31: ENEMY_AI_12_STATES | F31: 程序 Mesh / Prefab | G31: 无 | H31: 待登记
A32: 12 | B32: ENM-ELITE-RIFT-BOAR-ARMED-3D | C32: 背枪的裂口爬虫3D精英根 | D32: 无 Blender 动作母版（程序驱动） | E32: ENEMY_AI_12_STATES | F32: 程序 Mesh / Prefab | G32: 无 | H32: 待登记
A33: 合计 | B33: =COUNTA(B21:B32)
A34: ENM-NORMAL-FAT-ZOMBIE03 | B34: idle | C34: 胖子僵尸03 压重待机 | D34: 自然张手/压重呼吸/左右移重；30fps F0—96；3.2s | E34: assets/art/enemies/normal_enemy_3d/fat_zombie03/source/animation/enm_normal_fat_zombie03_animation_v008.blend | F34: 循环 | G34: idle循环；dormant保持首帧 | H34: 已制作/导出/12态绑定/运行验收通过 | I34: 编号03；v011正式绑定Enemy3D共用12态与13段动画，独立类型fat_zombie03；标准2.2m/512贴图，生命696伤害19，巡逻0.30/追击0.60m/s；F36拍合单次命中、F30锁朝向、视线/范围/扇区判定；普通命中仅上半身，死亡2.6s保留腹部压扁及回弹。专项152项、负向循环故障检出及真实Forward+四图通过。；已接替壳甲卫兵，现行投放启用。
A35: ENM-NORMAL-FAT-ZOMBIE03 | B35: walking | C35: 胖子僵尸03 沉重巡逻 | D35: 抬臂自然屈肘；短步移重；30fps F0—60；2.0s；参考0.30m/s | E35: assets/art/enemies/normal_enemy_3d/fat_zombie03/source/animation/enm_normal_fat_zombie03_animation_v008.blend | F35: 循环 | G35: 仅patrol；步频按实际速度采样 | H35: 已制作/导出/12态绑定/运行验收通过 | I35: 编号03；v011正式绑定Enemy3D共用12态与13段动画，独立类型fat_zombie03；标准2.2m/512贴图，生命696伤害19，巡逻0.30/追击0.60m/s；F36拍合单次命中、F30锁朝向、视线/范围/扇区判定；普通命中仅上半身，死亡2.6s保留腹部压扁及回弹。专项152项、负向循环故障检出及真实Forward+四图通过。；已接替壳甲卫兵，现行投放启用。
A36: ENM-NORMAL-FAT-ZOMBIE03 | B36: running | C36: 胖子僵尸03 低速压迫追击 | D36: 张臂重踏/胸肩扭摆；30fps F0—36；1.2s；参考0.60m/s | E36: assets/art/enemies/normal_enemy_3d/fat_zombie03/source/animation/enm_normal_fat_zombie03_animation_v008.blend | F36: 循环 | G36: chase/search/return；按实际速度采样 | H36: 已制作/导出/12态绑定/运行验收通过 | I36: 编号03；v011正式绑定Enemy3D共用12态与13段动画，独立类型fat_zombie03；标准2.2m/512贴图，生命696伤害19，巡逻0.30/追击0.60m/s；F36拍合单次命中、F30锁朝向、视线/范围/扇区判定；普通命中仅上半身，死亡2.6s保留腹部压扁及回弹。专项152项、负向循环故障检出及真实Forward+四图通过。；已接替壳甲卫兵，现行投放启用。
A37: ENM-NORMAL-FAT-ZOMBIE03 | B37: attack | C37: 双手张开向内抱扑 | D37: 大幅张臂/6帧双掌拍合/压实收势；30fps F0—75；2.5s | E37: assets/art/enemies/normal_enemy_3d/fat_zombie03/source/animation/enm_normal_fat_zombie03_animation_v008.blend | F37: 单次末帧保持 | G37: Enemy3D：F30锁朝向，F36单次伤害；Root无突进 | H37: 已制作/导出/12态绑定/运行验收通过 | I37: 编号03；v011正式绑定Enemy3D共用12态与13段动画，独立类型fat_zombie03；标准2.2m/512贴图，生命696伤害19，巡逻0.30/追击0.60m/s；F36拍合单次命中、F30锁朝向、视线/范围/扇区判定；普通命中仅上半身，死亡2.6s保留腹部压扁及回弹。专项152项、负向循环故障检出及真实Forward+四图通过。；已接替壳甲卫兵，现行投放启用。
A38: ENM-NORMAL-FAT-ZOMBIE03 | B38: hurt | C38: 胖子僵尸03 重击硬直 | D38: 30fps F0—24；0.8s；独立Action | E38: assets/art/enemies/normal_enemy_3d/fat_zombie03/source/animation/enm_normal_fat_zombie03_animation_v008.blend | F38: 单次末帧保持 | G38: 重击stagger 0.8秒 | H38: 已制作/导出/12态绑定/运行验收通过 | I38: 编号03；v011正式绑定Enemy3D共用12态与13段动画，独立类型fat_zombie03；标准2.2m/512贴图，生命696伤害19，巡逻0.30/追击0.60m/s；F36拍合单次命中、F30锁朝向、视线/范围/扇区判定；普通命中仅上半身，死亡2.6s保留腹部压扁及回弹。专项152项、负向循环故障检出及真实Forward+四图通过。；已接替壳甲卫兵，现行投放启用。
A39: ENM-NORMAL-FAT-ZOMBIE03 | B39: dead | C39: 胖子僵尸03 跪塌前扑 | D39: 30fps F0—78；2.6s；独立Action | E39: assets/art/enemies/normal_enemy_3d/fat_zombie03/source/animation/enm_normal_fat_zombie03_animation_v008.blend | F39: 单次末帧保持 | G39: 死亡2.6秒回收；腹部形变/落地回弹保留 | H39: 已制作/导出/12态绑定/运行验收通过 | I39: 编号03；v011正式绑定Enemy3D共用12态与13段动画，独立类型fat_zombie03；标准2.2m/512贴图，生命696伤害19，巡逻0.30/追击0.60m/s；F36拍合单次命中、F30锁朝向、视线/范围/扇区判定；普通命中仅上半身，死亡2.6s保留腹部压扁及回弹。专项152项、负向循环故障检出及真实Forward+四图通过。；已接替壳甲卫兵，现行投放启用。；2026-10-04修复游戏内死亡隐藏：尸体退出AI后独立视野组继续判定距离/遮挡，表现帧计时推进2.6秒倒地/腹部接地/回弹后回收；AI休眠不暂停死亡。真实Player3D视野逻辑与Forward+四帧截图通过，负向原失踪条件检出；胖子152项/小僵尸死亡/玩家视野回归通过。
A40: ENM-NORMAL-FAT-ZOMBIE03 | B40: awaken | C40: 胖子僵尸03 唤醒 | D40: 30fps F0—36；1.2s；独立Action | E40: assets/art/enemies/normal_enemy_3d/fat_zombie03/source/animation/enm_normal_fat_zombie03_animation_v008.blend | F40: 单次末帧保持 | G40: dormant→idle | H40: 已制作/导出/12态绑定/运行验收通过 | I40: 编号03；v011正式绑定Enemy3D共用12态与13段动画，独立类型fat_zombie03；标准2.2m/512贴图，生命696伤害19，巡逻0.30/追击0.60m/s；F36拍合单次命中、F30锁朝向、视线/范围/扇区判定；普通命中仅上半身，死亡2.6s保留腹部压扁及回弹。专项152项、负向循环故障检出及真实Forward+四图通过。；已接替壳甲卫兵，现行投放启用。
A41: ENM-NORMAL-FAT-ZOMBIE03 | B41: alert | C41: 胖子僵尸03 察觉定身 | D41: 30fps F0—18；0.6s；独立Action | E41: assets/art/enemies/normal_enemy_3d/fat_zombie03/source/animation/enm_normal_fat_zombie03_animation_v008.blend | F41: 单次末帧保持 | G41: alert 0.6秒 | H41: 已制作/导出/12态绑定/运行验收通过 | I41: 编号03；v011正式绑定Enemy3D共用12态与13段动画，独立类型fat_zombie03；标准2.2m/512贴图，生命696伤害19，巡逻0.30/追击0.60m/s；F36拍合单次命中、F30锁朝向、视线/范围/扇区判定；普通命中仅上半身，死亡2.6s保留腹部压扁及回弹。专项152项、负向循环故障检出及真实Forward+四图通过。；已接替壳甲卫兵，现行投放启用。
A42: ENM-NORMAL-FAT-ZOMBIE03 | B42: turn_l | C42: 胖子僵尸03 左转 | D42: 30fps F0—24；0.8s；独立Action | E42: assets/art/enemies/normal_enemy_3d/fat_zombie03/source/animation/enm_normal_fat_zombie03_animation_v008.blend | F42: 单次末帧保持 | G42: idle实际左转触发 | H42: 已制作/导出/12态绑定/运行验收通过 | I42: 编号03；v011正式绑定Enemy3D共用12态与13段动画，独立类型fat_zombie03；标准2.2m/512贴图，生命696伤害19，巡逻0.30/追击0.60m/s；F36拍合单次命中、F30锁朝向、视线/范围/扇区判定；普通命中仅上半身，死亡2.6s保留腹部压扁及回弹。专项152项、负向循环故障检出及真实Forward+四图通过。；已接替壳甲卫兵，现行投放启用。
A43: ENM-NORMAL-FAT-ZOMBIE03 | B43: turn_r | C43: 胖子僵尸03 右转 | D43: 30fps F0—24；0.8s；独立Action | E43: assets/art/enemies/normal_enemy_3d/fat_zombie03/source/animation/enm_normal_fat_zombie03_animation_v008.blend | F43: 单次末帧保持 | G43: idle实际右转触发 | H43: 已制作/导出/12态绑定/运行验收通过 | I43: 编号03；v011正式绑定Enemy3D共用12态与13段动画，独立类型fat_zombie03；标准2.2m/512贴图，生命696伤害19，巡逻0.30/追击0.60m/s；F36拍合单次命中、F30锁朝向、视线/范围/扇区判定；普通命中仅上半身，死亡2.6s保留腹部压扁及回弹。专项152项、负向循环故障检出及真实Forward+四图通过。；已接替壳甲卫兵，现行投放启用。
...

Sheet 3D-敌人
A1: ShellStorm2 · 敌人 3D Prefab
A2: 普通敌人、精英、Boss与敌人共用根；当前2个独立Prefab，其中首只正式精英资产1/12。
A4: AssetID | B4: 中文名 | C4: Prefab路径 | D4: GLB模型路径 | E4: Blender源文件 | F4: 功能说明 | G4: 功能脚本路径 | H4: 碰撞开关 | I4: 碰撞归属 | J4: 碰撞方式 | K4: 标准尺寸 | L4: 原点与朝向 | M4: 使用位置 | N4: 制作状态 | O4: 版本 | P4: 备注
A5: ENM-ECOSYSTEM-KIT-3D | B5: 七类怪物3D生态套件 | C5: assets/art/enemies/enemy_3d/enm_ecosystem_kit_root_top3d_v001.tscn | F5: 敌人3D共用根与表现系统 | G5: src/enemy3d/Enemy3D.gd; src/enemy3d/EnemyAvatar3D.gd | H5: 开 | I5: Prefab自身 | J5: CapsuleShape3D | K5: PackedScene/模块敌人 | L5: 未声明 | M5: 四主题战斗房 | N5: 原型已接入 | O5: v001 | P5: 根节点=Enemy3D(CharacterBody3D)
A6: ENM-ELITE-RIFT-BOAR-ARMED-3D | B6: 背枪的裂口爬虫 | C6: assets/art/enemies/elite_3d/rift_boar_armed/runtime/enm_elite_rift_boar_armed_root_top3d_v001.tscn | D6: assets/art/enemies/elite_3d/rift_boar_armed/components/enm_elite_rift_boar_armed_visual_top3d_v001.glb | E6: assets/art/enemies/elite_3d/rift_boar_armed/source/enm_elite_rift_boar_armed_source_v001.blend | F6: 首只唯一精英独立表现、背负副枪与命名专属血条 | G6: src/enemy3d/EliteContentCatalog.gd; src/enemy3d/EliteRosterService.gd; src/enemy3d/EnemyAvatar3D.gd; src/enemy3d/Enemy3D.gd | H6: 关（表现资产） | I6: Enemy3D | J6: 复用melee_chaser CylinderShape3D | K6: 1.970×1.843×1.345m；18 Mesh；4材质 | L6: 底部可预测；Blender -Y / Godot -Z 正面；根Scale=1 | M6: 每次行动按run_seed在98F/97F/96F三选一；目标层随机ELITE房 | N6: 正式美术已接入 | O6: v001 | P6: AssetID与elite_id稳定；其余11只仍为design_only，完成专项前不投放。
A7: ENM-MELEE-FUNGBOAR01 | B7: 小僵尸 | C7: assets/art/enemies/normal_enemy_3d/melee_chaser/runtime/enm_melee_fungboar01_root_top3d.tscn | D7: assets/art/enemies/normal_enemy_3d/melee_chaser/components/enm_melee_fungboar01_visual_top3d.glb | E7: assets/art/enemies/normal_enemy_3d/melee_chaser/source/model/enm_melee_fungboar01_model_v002.blend; assets/art/enemies/normal_enemy_3d/melee_chaser/source/animation/enm_melee_fungboar01_animation_v003.blend | F7: 首个标准普通怪表现；六段 Blender 剪辑按 12 态 AI 采样；36 骨 | G7: src/enemy3d/EnemyAvatar3D.gd; assets/art/enemies/normal_enemy_3d/melee_chaser/runtime/melee_chaser_formal_visual.gd | H7: 关（表现资产） | I7: Enemy3D | J7: CylinderShape3D（FOOTPRINT_PROFILES） | K7: 1.2819×0.9535×1.8571m；1 Mesh；1 材质 | L7: 底部可预测；Blender +Y / Godot -Z 正面；根 Scale=1 | M7: 全部战斗关卡普通怪池（melee_chaser） | N7: 正式美术已接入 | O7: v003 | P7: 无碰撞；Enemy3D 持有碰撞/AI/伤害/掉落。碰撞体尺寸沿用旧程序网格口径（1.02/1.30），与模型几何（0.641/1.857）不一致，待拍板后再收紧。显示名 小菌猪 → 小僵尸。
A8: ENM-RANGED-SPORESHOOTER01 | B8: 保安僵尸 | C8: assets/art/enemies/normal_enemy_3d/ranged_caster/runtime/enm_ranged_sporeshooter01_root_top3d.tscn | D8: assets/art/enemies/normal_enemy_3d/ranged_caster/components/enm_ranged_sporeshooter01_visual_top3d.glb | E8: assets/art/enemies/normal_enemy_3d/ranged_caster/source/model/enm_ranged_sporeshooter01_model_v001.blend; assets/art/enemies/normal_enemy_3d/ranged_caster/source/animation/enm_ranged_sporeshooter01_animation_v002.blend | F8: 远程普通怪正式表现；复用小僵尸36骨与基础动作；单手持枪shoot；双管炮视觉挂 L_Hand | G8: src/enemy3d/EnemyAvatar3D.gd; assets/art/enemies/normal_enemy_3d/ranged_caster/runtime/ranged_caster_formal_visual.gd | H8: 关（表现资产） | I8: Enemy3D | J8: CylinderShape3D（既有 ranged_caster FOOTPRINT_PROFILES） | K8: 1.2819×0.9535×1.8571m；1 Mesh；1 材质；36 骨；10 剪辑 | L8: 底部可预测；Blender +Y / Godot -Z 正面；根 Scale=1 | M8: 全部战斗关卡远程怪池（ranged_caster） | N8: 正式美术已接入 | O8: v002 | P8: 无碰撞；Enemy3D 保留三弹齐射和所有玩法规则；双管炮仅视觉附件。
A9: ENM-NORMAL-FAT-ZOMBIE03 | B9: 胖子僵尸 | C9: assets/art/enemies/normal_enemy_3d/fat_zombie03/runtime/enm_normal_fat_zombie03_root_top3d.tscn | D9: assets/art/enemies/normal_enemy_3d/fat_zombie03/components/enm_normal_fat_zombie03_visual_top3d.glb | E9: assets/art/enemies/normal_enemy_3d/fat_zombie03/source/model/enm_normal_fat_zombie03_model_v003.blend; assets/art/enemies/normal_enemy_3d/fat_zombie03/source/animation/enm_normal_fat_zombie03_animation_v008.blend | F9: 正式厚血慢速近战；12态输出单向驱动13段动画 | G9: src/enemy3d/Enemy3D.gd; src/enemy3d/EnemyAvatar3D.gd; assets/art/enemies/normal_enemy_3d/fat_zombie03/runtime/fat_zombie03_formal_visual.gd | H9: 视觉包关闭；实体开启 | I9: Enemy3D | J9: 玩法CylinderShape3D；视觉包无碰撞 | K9: 站立2.2m；世界圆柱半径0.77m/高2.2m；66骨；512贴图 | L9: 脚底0；Blender+Y/Godot-Z；Scale=1；游戏高2.2m | M9: 远征01纵列/桥心盒；默认随机池、锈炉/深渊主题池；独立实体 | N9: 正式美术已接入 | O9: v011 | P9: 编号03；v011正式绑定Enemy3D共用12态与13段动画，独立类型fat_zombie03；标准2.2m/512贴图，生命696伤害19，巡逻0.30/追击0.60m/s；F36拍合单次命中、F30锁朝向、视线/范围/扇区判定；普通命中仅上半身，死亡2.6s保留腹部压扁及回弹。专项152项、负向循环故障检出及真实Forward+四图通过。；已接替壳甲卫兵，现行投放启用。；2026-10-04修复游戏内死亡隐藏：尸体退出AI后独立视野组继续判定距离/遮挡，表现帧计时推进2.6秒倒地/腹部接地/回弹后回收；AI休眠不暂停死亡。真实Player3D视野逻辑与Forward+四帧截图通过，负向原失踪条件检出；胖子152项/小僵尸死亡/玩家视野回归通过。
A10: ENM-BOSS-MONITOR002-3D | B10: MONITOR.EXE 显示器 | C10: assets/art/enemies/bosses/enm_boss_monitor002/runtime/enm_boss_monitor002/enm_boss_monitor002_root_top3d.tscn | D10: assets/art/enemies/bosses/enm_boss_monitor002/components/enm_boss_monitor002/enm_boss_monitor002_visual_top3d.glb | E10: assets/art/enemies/bosses/enm_boss_monitor002/source/enm_boss_monitor002_model_v032.blend; assets/art/enemies/bosses/enm_boss_monitor002/source/enm_boss_monitor002_animation_v032.blend | F10: 16剪辑；四技能；三阶段；双母版同64骨架 | G10: src/enemy3d/Enemy3D.gd; src/enemy3d/MonitorBossCombat.gd; src/enemy3d/MonitorBossPresentation.gd | H10: 视觉关闭；玩法开启 | I10: 外部脚本Enemy3D | J10: CylinderShape3D，沿用Boss基线1.92/2.30m | K10: 18684三角形；64骨；站立约4m；根倍率1.05 | L10: 底座接地；Blender+Y / Godot-Z；Prefab根1 | M10: expedition_01 / floor_00 / boss（源房ID f00_boss）；box_boss_arena首波1只 | N10: active | O10: v032 | P10: v032：仅move改为底座平放左右挪动0.46m，机身左右扭转约41°，双臂柔性跟随。1.6s/48帧，其他15剪辑与四技能时序保留。源97采样、Godot509项、48帧真实渲染通过；previews/move_v032/monitor_walk.mp4。远征01首波1只/3波清房/钥匙通行/ STANDARD撤离规则保留。

Sheet 域变更日志
A1: 敌人账本变更日志
A3: 只记录本账本的域内变更；跨域与全局变更记录在主账本《版本记录》
A5: 台账版本 | B5: 日期 | C5: 变更类型 | D5: 范围 | E5: 说明 | F5: 兼容性 | G5: 负责人
A6: v0.1.0 | B6: 2026-09-18 | C6: 分账本建立 | D6: 敌人 | E6: 由单体账本《ShellStorm2_美术资产台账_v001.xlsx》按大类拆分而来；本账本接管大类=敌人，条目内容逐格不变，仅登记位置变化。 | F6: 资产条目、AssetID、路径与哈希全部不变；只换文件。旧引用可用 scripts/ledger_registry.py 解析。 | G6: 摩斯拉
A7: v0.1.1 | B7: 2026-09-20 | C7: 资产转正 | D7: 敌人 | E7: ENM-MELEE-FUNGBOAR01（小僵尸，旧登记名小菌猪）由「程序占位」转正为「已完成」：AssetID 与逻辑 ID(melee_chaser) 不变；《资产主表》r6 迁 3D 口径（组件槽 root_3d、变体父 ID ENM-ECOSYSTEM-KIT-3D、视角 Top3D/local -Z、规格真实包围盒、文件路径 -> runtime tscn、SHA-256、模型/动作双 blend）；《敌人动画与状态》12 态补 动作来源/循环/挂点/首版实现 四列，条目行补骨架与动作母版；《3D-敌人》新增该 Prefab 行。 | F7: 只升级既有行，未新增 AssetID；其余 6 类普通怪仍为程序占位。碰撞体积未动（玩法数值待拍板）。 | G7: Codex
A8: v0.1.2 | B8: 2026-09-21 | C8: 资产转正 | D8: 敌人 | E8: ENM-RANGED-SPORESHOOTER01（保安僵尸）由程序占位转正为正式3D表现：复用小僵尸36骨与基础动作，新增armed_idle/持枪移动/shoot，双管炮仅作为L_Hand视觉附件；ranged_caster逻辑与三弹发射规则不变。 | F8: 只升级既有 AssetID 与 ranged_caster 行，未新增逻辑敌人；Prefab无碰撞，Enemy3D继续持有AI、碰撞、生命、伤害、掉落和弹丸。 | G8: Codex
A9: v0.1.3 | B9: 2026-09-23 | C9: 新增登记 | D9: 敌人 | E9: 新增 ENM-BEAST-SPIKESHELL01（暗影兽）作为独立新怪，制作状态=待制作。AssetID 与既有 7 类预登记不冲突（新原型 normal_beast / 逻辑ID spike_shell）。《资产主表》新增 r18，规格、文件路径、SHA-256 留空（无产物），来源记为 Tripo 生成模型待入库。《总览》公式区间由 $6:$17 扩到 $6:$18 以满足门禁「区间 == 本账本行数」。本次只登记、不接线：游戏侧 Enemy3D.PROFILES / FOOTPRINT_PROFILES / EnemyAvatar3D 挂载分支 与《怪物与Boss》数值均未定义。未触碰《敌人动画与状态》与《3D-敌人》——前者受逐字节摘要约束，后者要求「一行=一个真实 PackedScene」。 | F9: 新增资产行 ⇒ 其余 11 行内容未变，仅《总览》区间随之扩到 $18（属预期）。无损基线 verify_ledger_split 原会 fail(asset_not_in_baseline) —— 已按既有「从当前分账本重建」口径做最小补录（只加本行指纹，其余 409 条逐位不变，列摘要与分类计数重算），补录前基线备份见 ledger_split_baseline.json.bak_before_spikeshell。 | G9: 摩斯拉
A10: v0.1.4 | B10: 2026-10-03 | C10: 新增素材入库 | D10: 敌人 | E10: ENM-NORMAL-FAT-ZOMBIE03 胖子僵尸源编号03；源编号03；模型入库及Godot独立加载通过，非完整怪物验收。65骨Mixamo骨名未对齐项目，缺Root；无动画，待idle/walking/running/attack/hurt/dead六段与动作母版、状态绑定。未配置AI/伤害/掉落/碰撞或投放。T姿势宽度不作为碰撞尺寸。来源许可待确认。 | F10: 既有资产内容不变；未接入运行池 | G10: Codex
A11: v0.1.5 | B11: 2026-10-03 | C11: 骨架修正与动作设计 | D11: 敌人 | E11: ENM-NORMAL-FAT-ZOMBIE03；编号03；v002从原始FBX重建，修正v001连接骨重复变换。36核心骨名齐全+30原有附加骨=66；Root无父级、Hip→Root；保留全部权重。512²贴图；游戏高2.2m（源3.142857m×0.70，kind/variant=1）。动作设计r1为13段，动画尚未制作或绑定，未投放。独立骨架签名，不声称共享静止姿态。 | F11: 模型与稳定GLB更新；AI/碰撞/伤害未变 | G11: Codex
A12: v0.1.6 | B12: 2026-10-03 | C12: 待机动画制作 | D12: 敌人 | E12: 编号03；v003待机idle已制作并验收，30fps/F0—96/3.2s循环；压重呼吸、左右2cm移重、低垂握拳，双脚锁地。模型v002/动作v001共享66骨签名，512贴图、站立游戏高2.2m。独立Prefab默认循环idle；其余12段仍设计待制作，未绑定完整AI状态或投放。 | F12: 骨架/网格/权重/碰撞不变；仅新增idle | G12: Codex
A13: v0.1.7 | B13: 2026-10-03 | C13: 张手修正与行走制作 | D13: 敌人 | E13: 编号03；v004修正右手指姿态，双手自然张开；idle 3.2s与walking 2.0s均30fps循环并验收。walking短步承重、抬脚6cm、参考速度0.30m/s，Root固定。模型v002/动作v002共享66骨签名、512贴图、站立高2.2m；其余11段待制作，未绑定完整AI或投放。 | F13: 骨架/网格/权重/碰撞不变；修正idle并新增walking | G13: Codex
A14: v0.1.8 | B14: 2026-10-03 | C14: 行走屈肘与夸张跑步制作 | D14: 敌人 | E14: 编号03；v005行走上臂略抬自然屈肘，脚步逐帧保留；新增running 1.2s/30fps，张臂屈肘、胸肩扭摆、髋横摆8cm/起伏6cm、抬脚9cm，顶视剪影清晰。参考跑速0.60m/s。idle/walking/running共3段已验收，余10段待制作；模型v002/动作v003共享66骨签名；未绑定完整AI或投放。 | F14: 骨架/网格/权重/碰撞不变；保留idle与行走脚步，修正行走双臂并新增running | G14: Codex
A15: v0.1.9 | B15: 2026-10-03 | C15: 双手张开向内抱扑攻击制作 | D15: 敌人 | E15: 编号03；v006新增双手张开向内抱扑attack，30fps/F0—75/2.5s单次，F26—30大幅张臂蓄力、F30—36快速收拢、F36—38压实、F75回待机；双脚承重，Root固定。已有3段逐骨逐帧保留。4段已验收，余9段待制作；模型v002/动作v004共享66骨签名；未绑定完整AI/伤害/投放。 | F15: 骨架/网格/权重/碰撞不变；保留idle/walking/running，新增attack | G15: Codex
A16: v0.1.10 | B16: 2026-10-03 | C16: 攻击终点双掌拍合修正 | D16: 敌人 | E16: 编号03；v007攻击命中终点改为双掌相向拍合，手掌立起、手指朝前、肘向外撑；F36—38压实停顿，F75回待机。2.5s单次，其他三段保留。模型v002/动作v005；4段已验收，余9段待制作，未绑定伤害逻辑。 | F16: 骨架/网格/权重/碰撞不变；保留idle/walking/running，新增attack | G16: Codex
A17: v0.1.新增Boss002 | B17: 46298 | C17: Codex | D17: ENM-BOSS-MONITOR002-3D | E17: 新增002显示器Boss，仅T Pose无骨骼模型，独立制作明细账；尚无运行时映射
A18: v0.1.11 | B18: 2026-10-03 | C18: 补齐九段基础补充动作 | D18: 敌人 | E18: 编号03；v008补齐hurt/dead/awaken/alert/turn_l/turn_r/move_start/move_stop/hit_light九段，13段源与导入专项完成。原四段曲线保留，hit_light仅上半身。模型v002/动作v006共享66骨签名；完整AI状态适配、加法受击及伤害/事件仍待绑定，不标记在役。 | F18: 骨架/网格/权重/碰撞不变；保留idle/walking/running，新增attack | G18: Codex
A19: v0.1.12 | B19: 2026-10-03 | C19: 死亡脱离脚锁与弹性回落修正 | D19: 敌人 | E19: 编号03；v009重做dead：解除脚底锁定、整条腿随身体前倒，F34落地、F40约10cm主回弹、F52约2cm余震，F60—78停稳。其余12段曲线原样保留。13段导入专项验证，玩法适配待接入。模型v002/动作v007。 | F19: 骨架/网格/权重/碰撞不变；保留idle/walking/running，新增attack | G19: Codex
A20: v002 | B20: 2026-10-03 | C20: Codex | D20: ENM-BOSS-MONITOR002-3D | E20: 四指手套改为平展姿势；保留v001源
A21: v0.1.13 | B21: 2026-10-03 | C21: 死亡脱离脚锁与弹性回落修正 | D21: 敌人 | E21: 编号03；v010死亡增加腹部地面压扁形态键及横向展开，降低躯干、手掌和腿部悬空；回弹时部分恢复。模型v003/动作v008，静止骨架与权重保留，其他12段骨曲线保留，非死亡全身动作形态键归零。13段导入验证，玩法适配待接入。 | F21: 骨架/网格/权重/碰撞不变；保留idle/walking/running，新增attack | G21: Codex
A22: v003 | B22: 2026-10-03 | C22: Codex | D22: ENM-BOSS-MONITOR002-3D | E22: 圆头手指；整套低于20000三角面；image-2代码与表情贴图；键盘减面无字
A23: v0.1.14 | B23: 2026-10-03 | C23: 胖子僵尸03正式运行配置 | D23: 敌人 | E23: 编号03；v011正式绑定Enemy3D共用12态与13段动画，独立类型fat_zombie03；标准2.2m/512贴图，生命696伤害19，巡逻0.30/追击0.60m/s；F36拍合单次命中、F30锁朝向、视线/范围/扇区判定；普通命中仅上半身，死亡2.6s保留腹部压扁及回弹。专项150项、负向循环故障检出及真实Forward+四图通过。 | F23: 新增kind复用FSM；既有七类玩法默认值保留 | G23: Codex
A24: v004 | B24: 2026-10-03 | C24: Codex | D24: ENM-BOSS-MONITOR002-3D | E24: 六表情图集与可切换预览，保持18144面
A25: v0.1.15 | B25: 2026-10-03 | C25: 壳甲卫兵退役，由03胖子僵尸接替 | D25: 敌人 | E25: 远征纵列1只/桥心4只，数量延迟保留；所有现行shielded池改fat_zombie03 | F25: 旧存档兼容与未实装精英设计保留 | G25: Codex
A26: v005 | B26: 2026-10-03 | C26: Codex | D26: ENM-BOSS-MONITOR002-3D | E26: 41骨蒙皮与双母版；六表情状态；21项源级验收通过
A27: v006 | B27: 2026-10-04 | C27: Codex | D27: ENM-BOSS-MONITOR002-3D | E27: 中心后轴、每臂6骨、3材质、向上代码滚动；32项检查通过
A28: v007 | B28: 2026-10-04 | C28: Codex | D28: ENM-BOSS-MONITOR002-3D | E28: 五官按红框下移，10类/15剪辑动画设计，正式动作未制作；33项检查通过
A29: v008 | B29: 2026-10-04 | C29: Codex | D29: ENM-BOSS-MONITOR002-3D | E29: 五官恢复；正式idle循环，弧线下垂双臂和滞后回摆；9项检查通过
A30: v009 | B30: 2026-10-04 | C30: Codex | D30: ENM-BOSS-MONITOR002-3D | E30: 待机重做握持：四指夹键盘、握线；16节垂线及朝下插头；16项检查通过
A31: v010 | B31: 2026-10-04 | C31: Codex | D31: ENM-BOSS-MONITOR002-3D | E31: 橡皮管风格idle：强弧臂、键盘中段握持、呼吸浮动和代码UV上升；21项检查通过
A32: v011 | B32: 2026-10-04 | C32: Codex | D32: ENM-BOSS-MONITOR002-3D | E32: 新增move：底座左右23度压重与46厘米横移、弹性滞后；保留idle；26项检查通过
A33: v012 | B33: 2026-10-04 | C33: Codex | D33: ENM-BOSS-MONITOR002-3D | E33: 新增键盘普通攻击：举高蓄力、停顿、六帧砸下、低位回收，表情切换；20项检查通过
A34: v0.1.16 | B34: 2026-10-04 | C34: 死亡表现视野与回收修复 | D34: 敌人 | E34: 2026-10-04修复游戏内死亡隐藏：尸体退出AI后独立视野组继续判定距离/遮挡，表现帧计时推进2.6秒倒地/腹部接地/回弹后回收；AI休眠不暂停死亡。真实Player3D视野逻辑与Forward+四帧截图通过，负向原失踪条件检出；胖子152项/小僵尸死亡/玩家视野回归通过。 | F34: 美术源/导出不变；Owner Enemy3D/PlayerVision3D | G34: Codex
A35: v031/S2 | B35: 2026-10-06 | C35: Codex | D35: ENM-BOSS-MONITOR002-3D | E35: 双母版签名比对、纯视觉GLB与骨姿态采样导出；中转character_transfer_ledger.json
A36: v031/S3 | B36: 2026-10-06 | C36: Codex | D36: ENM-BOSS-MONITOR002-3D | E36: 独立PackedScene加载，根1，无碰撞，64骨；骨与变形网格边界比对通过
A37: v031/S4-S5 | B37: 2026-10-06 | C37: Codex | D37: ENM-BOSS-MONITOR002-3D | E37: v031正式接入：16源剪辑/64骨/十二态/四技能/三阶段；根驱动弹簧甩臂、双螺旋坐地、黄色单帧闪形及接地电流；507项专项及真实渲染10关键帧通过；Enemy3D拥有碰撞/AI/伤害；远征01 Boss房调用boss_monitor002。；asset_guard分类：version_increment。
A38: v017 | B38: 2026-10-05 | C38: Codex | D38: ENM-BOSS-MONITOR002-3D | E38: v017 源级制作：深化heavy_spin_slam：双手惯性滞后与腕部跟随；专用旋转弧带；19度后仰、停顿、6帧加速砸地、回弹压稳。原三个动作保持。保留idle/move。特效为独立预览集合；未导出/未接入Godot。
A39: v018 | B39: 2026-10-05 | C39: Codex | D39: ENM-BOSS-MONITOR002-3D | E39: v018 源级制作：重击特效改为高饱和正红/亮蓝，降低发光避免冲淡；四个角色动作曲线与v017完全相同。保留idle/move。特效为独立预览集合；未导出/未接入Godot。
A40: v019 | B40: 2026-10-05 | C40: Codex | D40: ENM-BOSS-MONITOR002-3D | E40: v019 源级制作：重击特效改为纯色块加清晰勾线，去掉涂鸦纹理；高饱和红蓝；四个角色动作曲线与v017完全相同。保留idle/move。特效为独立预览集合；未导出/未接入Godot。
A41: v020 | B41: 2026-10-05 | C41: Codex | D41: ENM-BOSS-MONITOR002-3D | E41: v020 源级制作：重击特效重新设计为无勾线冷蓝色块、分段脉冲环、惯性旋转光带及少量玫红数据碎片，降低整体饱和度；四个角色动作曲线与v017完全相同。保留idle/move。特效为独立预览集合；未导出/未接入Godot。
A42: v021 | B42: 2026-10-05 | C42: Codex | D42: ENM-BOSS-MONITOR002-3D | E42: v021 源级制作：砸地第65帧增加冰白高亮锯齿爆裂色块及瞬时地面补光，仅持续1帧；保留v020无勾线赛博脉冲；四个角色动作曲线与v017完全相同。保留idle/move。特效为独立预览集合；未导出/未接入Godot。
...
