Workbook

Sheet 总览
A1: SHELLSTORM 2 · 关卡场景美术账本 v0.1
A3: 归属域=关卡场景｜覆盖大类=场景 / 场景道具 / 基地资产包｜AssetID 前缀=ART / ENV / BPK / PRP｜主账本（总目录）=assets/registry/ShellStorm2_美术资产台账_v001.xlsx；本账本可独立并行编辑，跨域契约见主账本
A5: 资产总数 | C5: 已完成/已接入 | E5: 待制作/程序占位 | G5: 重复警报 | I5: 域内专表 / 3D Prefab 分页
A6: =COUNTA(资产主表!$A$6:$A$928) | C6: =COUNTIF(资产主表!$K$6:$K$928,"已完成")+COUNTIF(资产主表!$K$6:$K$928,"原型已接入")+COUNTIF(资产主表!$K$6:$K$928,"正式美术已接入")+COUNTIF(资产主表!$K$6:$K$928,"已优化并正式接入")+COUNTIF(资产主表!$K$6:$K$928,"Blender源已完成")+COUNTIF(资产主表!$K$6:$K$928,"已导入；优化完成")+COUNTIF(资产主表!$K$6:$K$928,"白模源已完成；QA PASS") | E6: =COUNTIF(资产主表!$K$6:$K$928,"待制作")+COUNTIF(资产主表!$K$6:$K$928,"程序占位") | G6: =COUNTIF(资产主表!$S$6:$S$928,"重复") | I6: 域内专表：3D-场景通用 / 3D-设施 / 3D-其他 | 3D Prefab 分页：3D-场景通用 / 3D-设施 / 3D-其他
A9: 大类 | B9: 资产数 | C9: 完成/接入 | E9: 本账本只登记上列大类；跨域搬运资产须同步主账本《分类与编码》并重跑门禁
A10: 场景 | B10: =COUNTIF(资产主表!$C$6:$C$928,A10) | C10: =SUMPRODUCT((资产主表!$C$6:$C$928=A10)*((资产主表!$K$6:$K$928="已完成")+(资产主表!$K$6:$K$928="原型已接入")+(资产主表!$K$6:$K$928="正式美术已接入")+(资产主表!$K$6:$K$928="已优化并正式接入")+(资产主表!$K$6:$K$928="Blender源已完成")+(资产主表!$K$6:$K$928="已导入；优化完成")+(资产主表!$K$6:$K$928="白模源已完成；QA PASS")))
A11: 场景道具 | B11: =COUNTIF(资产主表!$C$6:$C$928,A11) | C11: =SUMPRODUCT((资产主表!$C$6:$C$928=A11)*((资产主表!$K$6:$K$928="已完成")+(资产主表!$K$6:$K$928="原型已接入")+(资产主表!$K$6:$K$928="正式美术已接入")+(资产主表!$K$6:$K$928="已优化并正式接入")+(资产主表!$K$6:$K$928="Blender源已完成")+(资产主表!$K$6:$K$928="已导入；优化完成")+(资产主表!$K$6:$K$928="白模源已完成；QA PASS")))
A12: 基地资产包 | B12: =COUNTIF(资产主表!$C$6:$C$928,A12) | C12: =SUMPRODUCT((资产主表!$C$6:$C$928=A12)*((资产主表!$K$6:$K$928="已完成")+(资产主表!$K$6:$K$928="原型已接入")+(资产主表!$K$6:$K$928="正式美术已接入")+(资产主表!$K$6:$K$928="已优化并正式接入")+(资产主表!$K$6:$K$928="Blender源已完成")+(资产主表!$K$6:$K$928="已导入；优化完成")+(资产主表!$K$6:$K$928="白模源已完成；QA PASS")))
A13: 合计 | B13: ==COUNTIF(资产主表!$C$6:$C$928,A13) | C13: ==SUMPRODUCT((资产主表!$C$6:$C$928=A13)*((资产主表!$K$6:$K$928="已完成")+(资产主表!$K$6:$K$928="原型已接入")+(资产主表!$K$6:$K$928="正式美术已接入")+(资产主表!$K$6:$K$928="已优化并正式接入")+(资产主表!$K$6:$K$928="Blender源已完成")+(资产主表!$K$6:$K$928="已导入；优化完成")+(资产主表!$K$6:$K$928="白模源已完成；QA PASS")))
A15: 域内 3D Prefab 分页统计（快照口径与本账本分页一致；权威清单在各分页表）
A16: 分页 | B16: Prefab 数 | C16: 直接引用 GLB | D16: 有功能脚本 | E16: 碰撞开启 | F16: 说明
A17: 3D-场景通用 | B17: =COUNTA('3D-场景通用'!$A$5:$A$726) | C17: =COUNTIF('3D-场景通用'!$D$5:$D$726,"<>") | D17: =COUNTIF('3D-场景通用'!$G$5:$G$726,"<>") | E17: =COUNTIF('3D-场景通用'!$H$5:$H$726,"开") | F17: 一行 = 一个实际存在的 Godot PackedScene
A18: 3D-设施 | B18: ==COUNTA('3D-设施'!$A$5:$A$204) | C18: ==COUNTIF('3D-设施'!$D$5:$D$204,"<>") | D18: ==COUNTIF('3D-设施'!$G$5:$G$204,"<>") | E18: ==COUNTIF('3D-设施'!$H$5:$H$204,"开") | F18: 一行 = 一个实际存在的 Godot PackedScene
A19: 3D-其他 | B19: ==COUNTA('3D-其他'!$A$5:$A$204) | C19: ==COUNTIF('3D-其他'!$D$5:$D$204,"<>") | D19: ==COUNTIF('3D-其他'!$G$5:$G$204,"<>") | E19: ==COUNTIF('3D-其他'!$H$5:$H$204,"开") | F19: 一行 = 一个实际存在的 Godot PackedScene
A20: 合计 | B20: ==SUM(B17:B19) | C20: ==SUM(C17:C19) | D20: ==SUM(D17:D19) | E20: ==SUM(E17:E19)

Sheet 账本说明
A1: 本账本说明 · 关卡场景
A3: 本表是分账本自描述；机器可读真源为 assets/registry/ledger_index.json，二者不一致时以 JSON 为准
A5: 项 | B5: 值
A6: 账本归属域 | B6: 关卡场景
A7: 分账本文件 | B7: assets/registry/ledgers/ShellStorm2_场景账本_v001.xlsx
A8: 覆盖大类 | B8: 场景 / 场景道具 / 基地资产包
A9: AssetID 前缀 | B9: ART / ENV / BPK / PRP
A10: 域内专表 | B10: 3D-场景通用 / 3D-设施 / 3D-其他
A11: 3D Prefab 分页 | B11: 3D-场景通用 / 3D-设施 / 3D-其他
A12: 动画登记表 | B12: 无
A13: 主账本（总目录） | B13: assets/registry/ShellStorm2_美术资产台账_v001.xlsx
A14: 跨域契约 | B14: 分类与编码 / 命名与查重 / 版本记录 / Skill 清单 / 3D Prefab 总控 —— 全部只在主账本维护
A15: 首选制作 Skill | B15: scene-full-pipeline
A16: 协作 Skill | B16: godot-model-asset-import-standard / blender-game-prop-standard / scene-art-merge-into-shared-component
... A23: 快照日期 | B23: 2026-09-18

Sheet 资产主表
A1: 资产主表 · 唯一登记源
A3: 查重键由公式生成；S 列出现“重复”时禁止制作，先合并或建立变体父子关系
A5: AssetID | B5: 中文名 | C5: 大类 | D5: 子类 | E5: 逻辑ID/源键 | F5: 组件槽 | G5: 变体父ID | H5: 视角 | I5: 状态/动画 | J5: 复用范围 | K5: 制作状态 | L5: 优先级 | M5: 版本 | N5: 规格(px) | O5: 文件路径 | P5: 源码/策划依据 | Q5: 关键词/别名 | R5: 查重键 | S5: 查重结果 | T5: SHA-256 | U5: 负责人 | V5: 更新时间 | W5: 来源/许可 | X5: 源编号（Blender collection） | Y5: 备注
A6: ENV-BASE-WORLD-KIT | B6: 末日基地与荒野 | C6: 场景 | D6: biome_kit | E6: base_world | F6: root | H6: 顶视 | I6: default | J6: 同主题房间共享 | K6: 程序占位 | L6: P0 | M6: v001 | N6: 64 px 网格；模块化 Tile/Prop | P6: scenes/BaseWorld.tscn | R6: =LOWER(TRIM(C6)&"|"&TRIM(D6)&"|"&TRIM(E6)&"|"&TRIM(F6)&"|"&TRIM(H6)&"|"&TRIM(I6)) | S6: =IF(COUNTIF($R$6:$R$928,R6)>1,"重复","唯一") | U6: 待分配 | V6: 46224 | W6: 原创/待确认 | X6: — | Y6: 先拆地面/墙/门/大中小道具，禁止整张场景烘焙
A7: ENV-IRON-FRONTIER-KIT | B7: 冷钢边境 | C7: 场景 | D7: biome_kit | E7: iron_frontier | F7: root | H7: 顶视 | I7: default | J7: 同主题房间共享 | K7: 程序占位 | L7: P0 | M7: v001 | N7: 64 px 网格；模块化 Tile/Prop | P7: scenes/levels/IronFrontier.tscn | R7: =LOWER(TRIM(C7)&"|"&TRIM(D7)&"|"&TRIM(E7)&"|"&TRIM(F7)&"|"&TRIM(H7)&"|"&TRIM(I7)) | S7: =IF(COUNTIF($R$6:$R$928,R7)>1,"重复","唯一") | U7: 待分配 | V7: 46224 | W7: 原创/待确认 | X7: — | Y7: 先拆地面/墙/门/大中小道具，禁止整张场景烘焙
A8: ENV-RUST-FOUNDRY-KIT | B8: 锈蚀铸造厂 | C8: 场景 | D8: biome_kit | E8: rust_foundry | F8: root | H8: 顶视 | I8: default | J8: 同主题房间共享 | K8: 程序占位 | L8: P1 | M8: v001 | N8: 64 px 网格；模块化 Tile/Prop | P8: scenes/levels/RustFoundry.tscn | R8: =LOWER(TRIM(C8)&"|"&TRIM(D8)&"|"&TRIM(E8)&"|"&TRIM(F8)&"|"&TRIM(H8)&"|"&TRIM(I8)) | S8: =IF(COUNTIF($R$6:$R$928,R8)>1,"重复","唯一") | U8: 待分配 | V8: 46224 | W8: 原创/待确认 | X8: — | Y8: 先拆地面/墙/门/大中小道具，禁止整张场景烘焙
A9: ENV-SPORE-DEPTHS-KIT | B9: 孢子深层 | C9: 场景 | D9: biome_kit | E9: spore_depths | F9: root | H9: 顶视 | I9: default | J9: 同主题房间共享 | K9: 程序占位 | L9: P1 | M9: v001 | N9: 64 px 网格；模块化 Tile/Prop | P9: scenes/levels/SporeDepths.tscn | R9: =LOWER(TRIM(C9)&"|"&TRIM(D9)&"|"&TRIM(E9)&"|"&TRIM(F9)&"|"&TRIM(H9)&"|"&TRIM(I9)) | S9: =IF(COUNTIF($R$6:$R$928,R9)>1,"重复","唯一") | U9: 待分配 | V9: 46224 | W9: 原创/待确认 | X9: — | Y9: 先拆地面/墙/门/大中小道具，禁止整张场景烘焙
A10: ENV-ABYSS-ARCHIVE-KIT | B10: 深渊档案库 | C10: 场景 | D10: biome_kit | E10: abyss_archive | F10: root | H10: 顶视 | I10: default | J10: 同主题房间共享 | K10: 程序占位 | L10: P1 | M10: v001 | N10: 64 px 网格；模块化 Tile/Prop | P10: scenes/levels/AbyssArchive.tscn | R10: =LOWER(TRIM(C10)&"|"&TRIM(D10)&"|"&TRIM(E10)&"|"&TRIM(F10)&"|"&TRIM(H10)&"|"&TRIM(I10)) | S10: =IF(COUNTIF($R$6:$R$928,R10)>1,"重复","唯一") | U10: 待分配 | V10: 46224 | W10: 原创/待确认 | X10: — | Y10: 先拆地面/墙/门/大中小道具，禁止整张场景烘焙
A11: ENV-TRAINING-RANGE-KIT | B11: 地下训练靶场 | C11: 场景 | D11: biome_kit | E11: training_range | F11: root | H11: 顶视 | I11: default | J11: 同主题房间共享 | K11: 程序占位 | L11: P0 | M11: v001 | N11: 64 px 网格；模块化 Tile/Prop | P11: scenes/TrainingRange.tscn | R11: =LOWER(TRIM(C11)&"|"&TRIM(D11)&"|"&TRIM(E11)&"|"&TRIM(F11)&"|"&TRIM(H11)&"|"&TRIM(I11)) | S11: =IF(COUNTIF($R$6:$R$928,R11)>1,"重复","唯一") | U11: 待分配 | V11: 46224 | W11: 原创/待确认 | X11: — | Y11: 先拆地面/墙/门/大中小道具，禁止整张场景烘焙
A12: ENV-ROOM-COMBAT-DRESSING | B12: combat 房间陈设包 | C12: 场景 | D12: room_dressing | E12: room_combat | F12: root | H12: 顶视 | I12: default | J12: 跨楼层配色变体 | K12: 程序占位 | L12: P1 | M12: v001 | N12: 64 px 网格 | P12: scenes/RoomCombat.tscn | R12: =LOWER(TRIM(C12)&"|"&TRIM(D12)&"|"&TRIM(E12)&"|"&TRIM(F12)&"|"&TRIM(H12)&"|"&TRIM(I12)) | S12: =IF(COUNTIF($R$6:$R$928,R12)>1,"重复","唯一") | U12: 待分配 | V12: 46224 | W12: 原创/待确认 | X12: — | Y12: 只登记房间独有件；地板墙体引用 biome kit
A13: ENV-ROOM-ELITE-DRESSING | B13: elite 房间陈设包 | C13: 场景 | D13: room_dressing | E13: room_elite | F13: root | H13: 顶视 | I13: default | J13: 跨楼层配色变体 | K13: 程序占位 | L13: P2 | M13: v001 | N13: 64 px 网格 | P13: scenes/RoomElite.tscn | R13: =LOWER(TRIM(C13)&"|"&TRIM(D13)&"|"&TRIM(E13)&"|"&TRIM(F13)&"|"&TRIM(H13)&"|"&TRIM(I13)) | S13: =IF(COUNTIF($R$6:$R$928,R13)>1,"重复","唯一") | U13: 待分配 | V13: 46224 | W13: 原创/待确认 | X13: — | Y13: 只登记房间独有件；地板墙体引用 biome kit
A14: ENV-ROOM-BOSS-DRESSING | B14: boss 房间陈设包 | C14: 场景 | D14: room_dressing | E14: room_boss | F14: root | H14: 顶视 | I14: default | J14: 跨楼层配色变体 | K14: 程序占位 | L14: P1 | M14: v001 | N14: 64 px 网格 | P14: scenes/RoomBoss.tscn | R14: =LOWER(TRIM(C14)&"|"&TRIM(D14)&"|"&TRIM(E14)&"|"&TRIM(F14)&"|"&TRIM(H14)&"|"&TRIM(I14)) | S14: =IF(COUNTIF($R$6:$R$928,R14)>1,"重复","唯一") | U14: 待分配 | V14: 46224 | W14: 原创/待确认 | X14: — | Y14: 只登记房间独有件；地板墙体引用 biome kit
A15: ENV-ROOM-EVENT-DRESSING | B15: event 房间陈设包 | C15: 场景 | D15: room_dressing | E15: room_event | F15: root | H15: 顶视 | I15: default | J15: 跨楼层配色变体 | K15: 程序占位 | L15: P2 | M15: v001 | N15: 64 px 网格 | P15: scenes/RoomEvent.tscn | R15: =LOWER(TRIM(C15)&"|"&TRIM(D15)&"|"&TRIM(E15)&"|"&TRIM(F15)&"|"&TRIM(H15)&"|"&TRIM(I15)) | S15: =IF(COUNTIF($R$6:$R$928,R15)>1,"重复","唯一") | U15: 待分配 | V15: 46224 | W15: 原创/待确认 | X15: — | Y15: 只登记房间独有件；地板墙体引用 biome kit
A16: ENV-ROOM-EXTRACTION-DRESSING | B16: extraction 房间陈设包 | C16: 场景 | D16: room_dressing | E16: room_extraction | F16: root | H16: 顶视 | I16: default | J16: 跨楼层配色变体 | K16: 程序占位 | L16: P1 | M16: v001 | N16: 64 px 网格 | P16: scenes/RoomExtraction.tscn | R16: =LOWER(TRIM(C16)&"|"&TRIM(D16)&"|"&TRIM(E16)&"|"&TRIM(F16)&"|"&TRIM(H16)&"|"&TRIM(I16)) | S16: =IF(COUNTIF($R$6:$R$928,R16)>1,"重复","唯一") | U16: 待分配 | V16: 46224 | W16: 原创/待确认 | X16: — | Y16: 只登记房间独有件；地板墙体引用 biome kit
A17: ENV-ROOM-MERCHANT-DRESSING | B17: merchant 房间陈设包 | C17: 场景 | D17: room_dressing | E17: room_merchant | F17: root | H17: 顶视 | I17: default | J17: 跨楼层配色变体 | K17: 程序占位 | L17: P2 | M17: v001 | N17: 64 px 网格 | P17: scenes/RoomMerchant.tscn | R17: =LOWER(TRIM(C17)&"|"&TRIM(D17)&"|"&TRIM(E17)&"|"&TRIM(F17)&"|"&TRIM(H17)&"|"&TRIM(I17)) | S17: =IF(COUNTIF($R$6:$R$928,R17)>1,"重复","唯一") | U17: 待分配 | V17: 46224 | W17: 原创/待确认 | X17: — | Y17: 只登记房间独有件；地板墙体引用 biome kit
... A31: PRP-DOOR | B31: 房门 | C31: 场景道具 | D31: facility | E31: door | F31: root | H31: 顶视 | I31: default | J31: 基地/房间 | K31: 程序占位 | L31: P1 | M31: v001 | N31: 64 px 网格对齐 | P31: scenes/BaseWorld.tscn | R31: =LOWER(TRIM(C31)&"|"&TRIM(D31)&"|"&TRIM(E31)&"|"&TRIM(F31)&"|"&TRIM(H31)&"|"&TRIM(I31)) | S31: =IF(COUNTIF($R$6:$R$928,R31)>1,"重复","唯一") | U31: 待分配 | V31: 46224 | W31: 原创/待确认 | X31: — | Y31: 状态变体使用同一 AssetID + state，不复制新命名根
A32: ENV-BASE99-FLOOR-DETAILS-V017 | B32: 基地99层完整地板替换 V021 | C32: 场景 | D32: environment_module_3d | E32: base99_floor_full_replacement_v021 | F32: full_floor_visual_replacement | G32: ENV-BASE99-ART-LAYOUT-3D | H32: Top3D / local -Z 正面 | I32: default / visual_only | J32: 99层基地地面表现 | K32: 已完成 | L32: P0 | M32: v003 | N32: 30×30m；6×6×5m；2网格；4材质表面；498,920三角面；无内置碰撞 | O32: assets/art/environments/base_facility_3d/runtime/env_base99_floor_full_replacement/env_base99_floor_full_replacement_root_top3d.tscn | P32: art_source/design/blender/base_facility_layout/base_facility_runtime_layout_hq_v020.blend（Blender v020）；assets/art/environments/base_facility_3d/components/env_base99_floor_full_replacement_v021/env_base99_floor_full_replacement_v021_visual_top3d_v003.glb；assets/art/environments/base_facility_3d/components/env_base99_floor_full_replacement_v021/env_base99_floor_full_replacement_v021_runtime_manifest_v003.json；scripts/blender/export_base_facility_v021_floor_replacement.py；tests/verification/verify_base99_floor_visuals_v021.tscn | Q32: 基地99层;完整地板替换;V021;PaletteUV;visual_only;旧MultiMesh已移除;无重叠 | R32: =LOWER(TRIM(C32)&"|"&TRIM(D32)&"|"&TRIM(E32)&"|"&TRIM(F32)&"|"&TRIM(H32)&"|"&TRIM(I32)) | S32: =IF(COUNTIF($R$6:$R$928,R32)>1,"重复","唯一") | T32: e0c6ff0eae3b248affa941ed793ac8cfe7c681995e3eb514ebd686f5a91d6944 | U32: Codex | V32: 46269 | W32: 用户自制Blender资产 | X32: — | Y32: GLB SHA256=6655e4322cd654e533e53670fb1e6611ce65818068de016faaea1b59ffb6835a；基础18普通板+18铆钉板保持复用；V017独占细节聚合为2网格，承重碰撞不变。
A33: ENV-BASE99-LOFT-FLOOR-FINISH-V017 | B33: 基地99层二层地板面层 V020 | C33: 场景 | D33: environment_module_3d | E33: base99_loft_floor_finish_v020 | F33: loft_floor_finish_overlay | G33: ENV-BASE99-ART-LAYOUT-3D | H33: Top3D / local -Z 正面 | I33: default / visual_only | J33: 99层基地楼中楼地面表现 | K33: 已完成 | L33: P0 | M33: v002 | N33: 19.6×9.6×0.108m；1网格；2材质表面；206三角面；无内置碰撞 | O33: assets/art/environments/base_facility_3d/runtime/env_base99_loft_floor_finish/env_base99_loft_floor_finish_root_top3d.tscn | P33: art_source/design/blender/base_facility_layout/base_facility_runtime_layout_hq_v020.blend（Blender v020）；assets/art/environments/base_facility_3d/components/env_base99_loft_floor_finish_v020/env_base99_loft_floor_finish_v020_visual_top3d_v002.glb；scripts/blender/export_base_facility_v020_floor_visuals.py；tests/verification/verify_base99_floor_visuals_v020.tscn | Q33: 基地99层;二层地板;V020;PaletteUV;visual_only;无重叠 | R33: =LOWER(TRIM(C33)&"|"&TRIM(D33)&"|"&TRIM(E33)&"|"&TRIM(F33)&"|"&TRIM(H33)&"|"&TRIM(I33)) | S33: =IF(COUNTIF($R$6:$R$928,R33)>1,"重复","唯一") | T33: 6fa73686f671683d08dfdbaadc315b996874404341318cbab806bbcfa7631a65 | U33: Codex | V33: 46269 | W33: 用户自制Blender资产 | X33: — | Y33: GLB SHA256=bf66319f75f5cac1c301dbfc09e4e7fe4ec0f518b7ee7dadb8e7068b94a2939c；运行时Y=-1m偏移；V020新增二楼地板面层保留，并作为V004阁楼结构唯一可见甲板。
A34: ENV-BASE99-FLOOR-VISUAL-LAYOUT-V017 | B34: 基地99层完整地板表现装配 V021 | C34: 场景 | D34: environment_module_3d | E34: base99_floor_visual_layout_v021 | F34: floor_visual_assembly | G34: ENV-BASE99-ART-LAYOUT-3D | H34: Top3D / local -Z 正面 | I34: default / visual_only | J34: 99层基地美术布局 | K34: 已完成 | L34: P0 | M34: v003 | N34: 一层30×30m + 二层20×10m；无内置碰撞 | O34: assets/art/environments/base_facility_3d/runtime/env_base99_floor_visuals/env_base99_floor_visuals_root_top3d.tscn | P34: art_source/design/blender/base_facility_layout/base_facility_runtime_layout_hq_v020.blend（Blender v020）；assets/art/environments/base_facility_3d/runtime/env_base99_floor_visuals_v021/env_base99_floor_visuals_root_top3d_v003.tscn；assets/art/environments/base_facility_3d/runtime/env_base99_loft_floor_finish_v020/env_base99_loft_floor_finish_v020_root_top3d_v002.tscn；assets/art/environments/base_facility_3d/runtime/env_base99_mezzanine_20x10_z5/env_base99_mezzanine_20x10_z5_root_top3d_v004.tscn；assets/art/environments/base_facility_3d/runtime/env_base99_wall_contents_v021/env_base99_wall_contents_root_top3d_v001.tscn；tests/verification/verify_base99_structural_asset_integration.tscn；tests/verification/verify_base99_wall_content_v021.tscn | Q34: 基地99层;完整地板表现装配;V021;visual_only;旧MultiMesh已移除 | R34: =LOWER(TRIM(C34)&"|"&TRIM(D34)&"|"&TRIM(E34)&"|"&TRIM(F34)&"|"&TRIM(H34)&"|"&TRIM(I34)) | S34: =IF(COUNTIF($R$6:$R$928,R34)>1,"重复","唯一") | T34: 0627bed9c921913e241bedcbd0265cffa173f32f3bd1e9a716045fb7441a9719 | U34: Codex | V34: 46269 | W34: 项目现有Godot资产 | X34: — | Y34: 运行时布局接入点；一层保持Blender V021完整地板替换与既有FloorSupport碰撞；二层保留Blender V020新增地板面层。2026-09-05：阁楼结构V004与L型楼梯V004恢复正式实例化；阁楼移除9个重复地板网格，二层甲板继续复用V020。下方工业铁门保持未实例化。新增V021非门墙面内容仅表现导入。
A35: ENV-BASE-WORLD-KIT-3D | B35: 入口基地3D环境套件 | C35: 场景 | D35: base | E35: base_world | F35: root_3d | G35: ENV-BASE-WORLD-KIT | H35: 俯视3D | I35: default | J35: 入口基地地图 | K35: 原型已接入 | L35: P0 | M35: v001 | N35: 约1:100迁移/程序几何 | O35: assets/art/environments/base_world_3d/env_base_world_kit_top3d.tscn | P35: scenes/BaseWorld3D.tscn | Q35: 基地;道路;废墟;3D;入口地图 | R35: =LOWER(TRIM(C35)&"|"&TRIM(D35)&"|"&TRIM(E35)&"|"&TRIM(F35)&"|"&TRIM(H35)&"|"&TRIM(I35)) | S35: =IF(COUNTIF($R$6:$R$928,R35)>1,"重复","唯一") | T35: 63c840d59bcecefab946690136474c9ca7b70408fb7b6bcc264819f9b66f14a5 | U35: Codex | V35: 46224 | W35: 原创程序几何 | X35: — | Y35: 保留原2D布局语义；首张3D迁移地图
A36: PRP-BASE-FACILITY-3D | B36: 基地设施3D通用模块 | C36: 场景道具 | D36: facility | E36: base_facility_module | F36: root_3d | G36: ENV-BASE-WORLD-KIT-3D | H36: 俯视3D | I36: default | J36: 8类基地设施/统一状态牌 | K36: 原型已接入 | L36: P0 | M36: v001 | N36: PackedScene/材质变体/名称与实时摘要共用Label3D | O36: assets/art/props/base_world_3d/prp_base_facility_root_top3d.tscn | P36: src/base3d/BaseFacility3D.gd; src/base/BaseFacilityCatalog.gd; src/base/BaseFacilityService.gd; src/world3d/TowerDescent3D.gd; tests/verification/verify_base_facility_framework.tscn; tests/verification/verify_base_world_3d_visual.tscn | Q36: 设施;交互;信标;3D;facility_id;实时摘要;状态牌;共享目录 | R36: =LOWER(TRIM(C36)&"|"&TRIM(D36)&"|"&TRIM(E36)&"|"&TRIM(F36)&"|"&TRIM(H36)&"|"&TRIM(I36)) | S36: =IF(COUNTIF($R$6:$R$928,R36)>1,"重复","唯一") | T36: 391cad1c83f33586ba70d208dca713c52c05e62c6c8100801a615c84d2d7c719 | U36: Codex | V36: 46264 | W36: 原创程序几何 | X36: — | Y36: 2026-08-06：确认该根资产服务正式基地8项设施；颜色材质、名称、交互提示与实时摘要均由稳定facility_id驱动，基地大世界与塔内99层同类设施共用。复用原NameLabel显示名称+状态，不增加节点和碰撞；注意态为金色、正常态为青绿色、不可用态为红色。管理终端与3D设施读取同一快照；Metal/OpenGL 1280×720基地和终端画面验收通过。塔楼电梯只复用外壳，保持独立交通身份。 2026-08-30 AST-02：合法内容更新；文件为Git已跟踪且修改时间不早于原台账日期；验收：verify_base_facility_framework；verify_base_facility_interaction_zones；SHA 18921dbda4e5→391cad1c83f3。
A37: PRP-DUNGEON-GATE-3D | B37: 地下城入口3D模块 | C37: 场景道具 | D37: door | E37: dungeon_gate | F37: root_3d | G37: PRP-DUNGEON-GATE | H37: 俯视3D | I37: default | J37: 4个地下城入口 | K37: 原型已接入 | L37: P0 | M37: v001 | N37: PackedScene/材质变体 | O37: assets/art/props/base_world_3d/prp_dungeon_gate_root_top3d.tscn | P37: src/base3d/DungeonEntrance3D.gd | Q37: 地下城;门;交互;3D | R37: =LOWER(TRIM(C37)&"|"&TRIM(D37)&"|"&TRIM(E37)&"|"&TRIM(F37)&"|"&TRIM(H37)&"|"&TRIM(I37)) | S37: =IF(COUNTIF($R$6:$R$928,R37)>1,"重复","唯一") | T37: 1fc802ceb8caef1ce77a54958a8b5e82a0fcae37459106fee970c8941146ba8f | U37: Codex | V37: 46224 | W37: 原创程序几何 | X37: — | Y37: 保持旧入口ID与目标场景；地下城内部暂保留2D
A38: ENV-BASE-WORLD-3D-PREVIEW | B38: 入口基地3D验收预览 | C38: 场景 | D38: review_board | E38: base_world | F38: preview_3d | G38: ENV-BASE-WORLD-KIT-3D | H38: 俯视3D | I38: default | J38: 评审与资产QA | K38: 已完成 | L38: P1 | M38: v001 | N38: 1280×720 PNG | O38: assets/art/environments/base_world_3d/env_base_world_preview_top3d_v001.png | P38: tests/verification/verify_base_world_3d_visual.tscn | Q38: 3D预览;评审;入口地图 | R38: =LOWER(TRIM(C38)&"|"&TRIM(D38)&"|"&TRIM(E38)&"|"&TRIM(F38)&"|"&TRIM(H38)&"|"&TRIM(I38)) | S38: =IF(COUNTIF($R$6:$R$928,R38)>1,"重复","唯一") | T38: 6ad569cd014b50df23e17e694063da49f49740413da4351eb4ff9de22ed230b9 | U38: Codex | V38: 46224 | W38: 项目运行截图 | X38: — | Y38: 用于检查3D布局、镜头、组件比例与交互可读性
A39: ENV-DUNGEON-RUNTIME-3D | B39: 3D随机关卡通用房间套件 | C39: 场景 | D39: room | E39: dungeon_runtime | F39: root_3d | H39: 俯视3D | I39: default | J39: 四主题副本/随机房间 | K39: 原型已接入 | L39: P0 | M39: v001 | N39: PackedScene/三档程序几何 | O39: assets/art/environments/dungeon_3d/env_dungeon_runtime_kit_top3d.tscn | P39: src/world3d/DungeonRoom3D.gd | Q39: 房间;门洞;走廊;随机地图;3D | R39: =LOWER(TRIM(C39)&"|"&TRIM(D39)&"|"&TRIM(E39)&"|"&TRIM(F39)&"|"&TRIM(H39)&"|"&TRIM(I39)) | S39: =IF(COUNTIF($R$6:$R$928,R39)>1,"重复","唯一") | T39: fc33ac084150c3e3cbba89505b3e04f35712abbceaa5cec297c94fe4d7dcc2f3 | U39: Codex | V39: 46233 | W39: 原创程序几何 | X39: — | Y39: v0.1：塔楼98—95层形成可闭环的搜打撤流程；普通层每层同时含战斗房和搜刮房，容器按种子掉落。Boss房清理后现在按房间类型正确解锁撤离，不再依赖固定room_id。生成快照增加门连通与全息小地图实时状态，测试覆盖100→99→98实机楼梯路径、95层Boss和撤离完成。
A40: ENV-DUNGEON-IRON-FRONTIER-3D | B40: 冷钢边境3D主题资源 | C40: 场景 | D40: biome | E40: iron_frontier | F40: theme_3d | G40: ENV-DUNGEON-RUNTIME-3D | H40: 俯视3D | I40: default | J40: 冷钢边境 | K40: 原型已接入 | L40: P0 | M40: v001 | N40: DungeonTheme3D Resource | O40: assets/art/environments/dungeon_3d/env_iron_frontier_kit_top3d_v001.tres | P40: scenes/levels3d/IronFrontier3D.tscn | Q40: 冷钢;冷蓝;边境;雾;灯光 | R40: =LOWER(TRIM(C40)&"|"&TRIM(D40)&"|"&TRIM(E40)&"|"&TRIM(F40)&"|"&TRIM(H40)&"|"&TRIM(I40)) | S40: =IF(COUNTIF($R$6:$R$928,R40)>1,"重复","唯一") | T40: a3c6e7e5433928b790e1fa0fe5124beaeb5ab579f2d376aa35a1be25b6736b58 | U40: Codex | V40: 46224 | W40: 原创程序配置 | X40: — | Y40: 只保存3D色彩/雾/灯光/家具倾向；玩法读取MapThemeProfile
A41: ENV-DUNGEON-RUST-FOUNDRY-3D | B41: 锈蚀铸造厂3D主题资源 | C41: 场景 | D41: biome | E41: rust_foundry | F41: theme_3d | G41: ENV-DUNGEON-RUNTIME-3D | H41: 俯视3D | I41: default | J41: 锈蚀铸造厂 | K41: 原型已接入 | L41: P0 | M41: v001 | N41: DungeonTheme3D Resource | O41: assets/art/environments/dungeon_3d/env_rust_foundry_kit_top3d_v001.tres | P41: scenes/levels3d/RustFoundry3D.tscn | Q41: 锈蚀;铸造;橙光;工业 | R41: =LOWER(TRIM(C41)&"|"&TRIM(D41)&"|"&TRIM(E41)&"|"&TRIM(F41)&"|"&TRIM(H41)&"|"&TRIM(I41)) | S41: =IF(COUNTIF($R$6:$R$928,R41)>1,"重复","唯一") | T41: 0c14c1dd5a5b8edcb51fa5bb024666d845611bfd87c3c4ee0ded56c4614010a8 | U41: Codex | V41: 46224 | W41: 原创程序配置 | X41: — | Y41: 复用通用房间根；主题资源不复制玩法规则
A42: ENV-DUNGEON-SPORE-DEPTHS-3D | B42: 孢子深层3D主题资源 | C42: 场景 | D42: biome | E42: spore_depths | F42: theme_3d | G42: ENV-DUNGEON-RUNTIME-3D | H42: 俯视3D | I42: default | J42: 孢子深层 | K42: 原型已接入 | L42: P0 | M42: v001 | N42: DungeonTheme3D Resource | O42: assets/art/environments/dungeon_3d/env_spore_depths_kit_top3d_v001.tres | P42: scenes/levels3d/SporeDepths3D.tscn | Q42: 孢子;病绿;地下;异化 | R42: =LOWER(TRIM(C42)&"|"&TRIM(D42)&"|"&TRIM(E42)&"|"&TRIM(F42)&"|"&TRIM(H42)&"|"&TRIM(I42)) | S42: =IF(COUNTIF($R$6:$R$928,R42)>1,"重复","唯一") | T42: bbd5cc04028e3962ce9eb8ea04c1c06157d128b5dbad1cea64bed7b4a02e7689 | U42: Codex | V42: 46224 | W42: 原创程序配置 | X42: — | Y42: 复用通用房间根；主题资源不复制玩法规则
A43: ENV-DUNGEON-ABYSS-ARCHIVE-3D | B43: 深渊档案库3D主题资源 | C43: 场景 | D43: biome | E43: abyss_archive | F43: theme_3d | G43: ENV-DUNGEON-RUNTIME-3D | H43: 俯视3D | I43: default | J43: 深渊档案库 | K43: 原型已接入 | L43: P0 | M43: v001 | N43: DungeonTheme3D Resource | O43: assets/art/environments/dungeon_3d/env_abyss_archive_kit_top3d_v001.tres | P43: scenes/levels3d/AbyssArchive3D.tscn | Q43: 深渊;档案;紫光;禁区 | R43: =LOWER(TRIM(C43)&"|"&TRIM(D43)&"|"&TRIM(E43)&"|"&TRIM(F43)&"|"&TRIM(H43)&"|"&TRIM(I43)) | S43: =IF(COUNTIF($R$6:$R$928,R43)>1,"重复","唯一") | T43: fb276fb1586de1b69d306ff894800f51da600b8dfb2780cf8bc8d22695ad3a52 | U43: Codex | V43: 46224 | W43: 原创程序配置 | X43: — | Y43: 复用通用房间根；主题资源不复制玩法规则
A44: PRP-WASTELAND-LIGHT-3D | B44: 废土灯具3D通用模块（街灯/顶灯） | C44: 场景道具 | D44: light | E44: wasteland_light | F44: root_3d | G44: ENV-DUNGEON-RUNTIME-3D | H44: 俯视3D | I44: default | J44: 关卡/靶场/房间中央照明 | K44: 原型已接入 | L44: P0 | M44: v001 | N44: PackedScene/OmniLight3D | O44: assets/art/props/dungeon_3d/prp_wasteland_light_root_top3d.tscn | P44: src/world3d/WastelandLight3D.gd | Q44: 灯具;街灯;中央顶灯;故障灯;废土 | R44: =LOWER(TRIM(C44)&"|"&TRIM(D44)&"|"&TRIM(E44)&"|"&TRIM(F44)&"|"&TRIM(H44)&"|"&TRIM(I44)) | S44: =IF(COUNTIF($R$6:$R$928,R44)>1,"重复","唯一") | T44: 0a6ec0add8b6e01b83f4dbaae421ff0dc69ed08648d304bac061f540af27d99b | U44: Codex | V44: 46237 | W44: 原创程序几何 | X44: — | Y44: v0.1：房间灯统一覆盖环境layer1与角色layer2；普通房中央灯与基地四灯组各只保留一盏投影主灯，其余灯无阴影以控制预算。流送状态改为递归同步嵌套灯具，玩家与怪物均可在开灯房间产生投影。 2026-08-03：failing=false 稳定灯不进入慢波/微波亮度调制；房灯开关仅切换 0/配置能量并保留 Compatibility 渲染实例，固定机位初始开灯与复明后的地面采样一致。
A45: PRP-ROOM-FURNITURE-3D | B45: 房间家具3D通用模块 | C45: 场景道具 | D45: furniture | E45: room_furniture | F45: root_3d | G45: ENV-DUNGEON-RUNTIME-3D | H45: 俯视3D | I45: default | J45: 全部3D房间 | K45: 原型已接入 | L45: P0 | M45: v001 | N45: PackedScene/类型与尺寸配置 | O45: assets/art/props/dungeon_3d/prp_room_furniture_root_top3d.tscn | P45: src/world3d/RoomFurniture3D.gd | Q45: 家具;小中大;箱柜;工作台 | R45: =LOWER(TRIM(C45)&"|"&TRIM(D45)&"|"&TRIM(E45)&"|"&TRIM(F45)&"|"&TRIM(H45)&"|"&TRIM(I45)) | S45: =IF(COUNTIF($R$6:$R$928,R45)>1,"重复","唯一") | T45: a78a7eaac02ce39add97d8a57754cc86ea34e740e24e0e901f4e037198a086e9 | U45: Codex | V45: 46224 | W45: 原创程序几何 | X45: — | Y45: 11类轮廓；small/medium/large影响占地与碰撞
A46: PRP-SEARCH-CONTAINER-3D | B46: 可搜索容器3D通用模块 | C46: 场景道具 | D46: container | E46: search_container | F46: root_3d | G46: PRP-ROOM-FURNITURE-3D | H46: 俯视3D | I46: closed_opened | J46: 搜索房/仓储/事件 | K46: 原型已接入 | L46: P0 | M46: v001 | N46: PackedScene/搜索状态 | O46: assets/art/props/dungeon_3d/prp_search_container_root_top3d.tscn | P46: src/world3d/RoomFurniture3D.gd | Q46: 搜索;容器;战利品;小中大 | R46: =LOWER(TRIM(C46)&"|"&TRIM(D46)&"|"&TRIM(E46)&"|"&TRIM(F46)&"|"&TRIM(H46)&"|"&TRIM(I46)) | S46: =IF(COUNTIF($R$6:$R$928,R46)>1,"重复","唯一") | T46: 2c0852d86e7c0e635e76197ff8d2f6a030daa186f760dfb339d3fdeddf3c192d | U46: Codex | V46: 46224 | W46: 原创程序几何 | X46: — | Y46: 搜索为家具状态与配置，不建立关卡局部重复模型
A47: PRP-SERVICE-STATION-3D | B47: 废土服务终端3D模块 | C47: 场景道具 | D47: facility | E47: service_station | F47: root_3d | G47: ENV-DUNGEON-RUNTIME-3D | H47: 俯视3D | I47: default | J47: 商店/升级/事件/重置 | K47: 原型已接入 | L47: P0 | M47: v001 | N47: PackedScene/程序组件 | O47: assets/art/props/dungeon_3d/prp_service_station_root_top3d.tscn | P47: src/world3d/ServiceStation3D.gd | Q47: 终端;商店;升级;事件;重置 | R47: =LOWER(TRIM(C47)&"|"&TRIM(D47)&"|"&TRIM(E47)&"|"&TRIM(F47)&"|"&TRIM(H47)&"|"&TRIM(I47)) | S47: =IF(COUNTIF($R$6:$R$928,R47)>1,"重复","唯一") | T47: da288e4a8ffc005053741d2eda3bbcbf2f6ad34c32c6657e35d0ddf62b837be4 | U47: Codex | V47: 46224 | W47: 原创程序几何 | X47: — | Y47: 四种服务行为复用同一视觉与交互组件
A48: PRP-EXTRACTION-BEACON-3D | B48: 撤离信标3D模块 | C48: 场景道具 | D48: facility | E48: extraction_beacon | F48: root_3d | G48: ENV-DUNGEON-RUNTIME-3D | H48: 俯视3D | I48: locked_active_done | J48: 四主题撤离房 | K48: 原型已接入 | L48: P0 | M48: v001 | N48: PackedScene/程序组件 | O48: assets/art/props/dungeon_3d/prp_extraction_beacon_root_top3d.tscn | P48: src/world3d/ExtractionBeacon3D.gd | Q48: 撤离;信标;倒计时;Boss解锁 | R48: =LOWER(TRIM(C48)&"|"&TRIM(D48)&"|"&TRIM(E48)&"|"&TRIM(F48)&"|"&TRIM(H48)&"|"&TRIM(I48)) | S48: =IF(COUNTIF($R$6:$R$928,R48)>1,"重复","唯一") | T48: f2638fdaca3f9542e918a56750bda04a5828b18a763569eb16a36619e9e336b4 | U48: Codex | V48: 46237 | W48: 原创程序几何 | X48: — | Y48: 锁定/同步/取消/完成四段生命周期 2026-08-03：待机/锁定 STANDARD 信标局部光固定为 2.2；仅正式撤离倒计时允许能量脉冲，避免干扰基地房灯的地面反馈。
A49: ENV-TRAINING-RANGE-KIT-3D | B49: 独立3D训练靶场套件 | C49: 场景 | D49: training_range | E49: training_range | F49: root_3d | H49: 俯视3D | I49: default | J49: 独立训练地图 | K49: 原型已接入 | L49: P0 | M49: v001 | N49: PackedScene/程序环境 | O49: assets/art/environments/training_range_3d/env_training_range_kit_top3d.tscn | P49: scenes/TrainingRange3D.tscn | Q49: 靶场;射击道;货架;59组合;三类靶 | R49: =LOWER(TRIM(C49)&"|"&TRIM(D49)&"|"&TRIM(E49)&"|"&TRIM(F49)&"|"&TRIM(H49)&"|"&TRIM(I49)) | S49: =IF(COUNTIF($R$6:$R$928,R49)>1,"重复","唯一") | T49: 4d1153bc736fab0790300f171beef8435002670f3789d6434e966bca0a79d28e | U49: Codex | V49: 46224 | W49: 原创程序几何 | X49: — | Y49: 18货架（7远程+3近战+8子弹）、三射击道、三靶标、重置与返回；BaseData隔离
A50: ENV-DUNGEON-RUNTIME-3D-PREVIEW | B50: 3D关卡运行时验收预览 | C50: 场景 | D50: review_board | E50: dungeon_runtime | F50: preview_3d | G50: ENV-DUNGEON-RUNTIME-3D | H50: 俯视3D | I50: default | J50: 评审与资产QA | K50: 已完成 | L50: P1 | M50: v001 | N50: 1280×720 PNG | O50: ../ShellStorm2-backup/2026-10-11_art_source_split/original_tree/assets/art/environments/dungeon_3d/previews/env_dungeon_runtime_preview_top3d_v001.png | P50: tests/verification/verify_full_3d_visual.tscn | Q50: 3D关卡;预览;灯光;战斗;QA | R50: =LOWER(TRIM(C50)&"|"&TRIM(D50)&"|"&TRIM(E50)&"|"&TRIM(F50)&"|"&TRIM(H50)&"|"&TRIM(I50)) | S50: =IF(COUNTIF($R$6:$R$928,R50)>1,"重复","唯一") | T50: 3b2c2212f1283ed366a31dc3a101b3555c78768c3906600eb0b18c74423fb247 | U50: Codex | V50: 46264 | W50: 项目运行截图 | X50: — | Y50: 实际GPU窗口确认360°遮挡逻辑与96°定向表现；v0.1三层玩家灯去除头顶溢光，角色正面柔光、增强中央灯与战斗轮廓通过验收 2026-08-30 AST-04：验证预览图从生产运行目录迁移到 previews/ 隔离目录；稳定 AssetID 与版本不变；路径 assets/art/environments/dungeon_3d/env_dungeon_runtime_preview_top3d_v001.png → ../ShellStorm2-backup/2026-10-11_art_source_split/original_tree/assets/art/environments/dungeon_3d/previews/env_dungeon_runtime_preview_top3d_v001.png；SHA-256 已重算。该图仅用于美术/关卡验证，不作为 Godot 运行时资源。
A51: ENV-TRAINING-RANGE-3D-PREVIEW | B51: 3D训练靶场验收预览 | C51: 场景 | D51: review_board | E51: training_range | F51: preview_3d | G51: ENV-TRAINING-RANGE-KIT-3D | H51: 俯视3D | I51: default | J51: 评审与资产QA | K51: 已完成 | L51: P1 | M51: v001 | N51: 1280×720 PNG | O51: assets/art/environments/training_range_3d/env_training_range_preview_top3d_v001.png | P51: tests/verification/verify_training_range_3d_visual.tscn | Q51: 3D靶场;预览;射击道;目标;QA | R51: =LOWER(TRIM(C51)&"|"&TRIM(D51)&"|"&TRIM(E51)&"|"&TRIM(F51)&"|"&TRIM(H51)&"|"&TRIM(I51)) | S51: =IF(COUNTIF($R$6:$R$928,R51)>1,"重复","唯一") | T51: 2597d0d8bc0cdb95e04a38f444bdde37316c373b230fe3024621a4d1dbcf52d8 | U51: Codex | V51: 46224 | W51: 项目运行截图 | X51: — | Y51: 真实GPU窗口检查三条射击道、三类靶、枪弹组合区与灯光
A52: PRP-ROOM-LIGHT-SWITCH-3D | B52: 房间中央灯墙面开关3D | C52: 场景道具 | D52: facility | E52: room_light_switch | F52: root_3d | G52: ENV-DUNGEON-RUNTIME-3D | H52: 俯视3D | I52: default | J52: 随机关卡房间/四主题复用 | K52: 原型已接入 | L52: P0 | M52: v001 | N52: PackedScene/Area3D | O52: assets/art/props/dungeon_3d/prp_room_light_switch_root_top3d.tscn | P52: src/world3d/RoomLightSwitch3D.gd | Q52: 房灯开关;墙面交互;中央顶灯;E键 | R52: =LOWER(TRIM(C52)&"|"&TRIM(D52)&"|"&TRIM(E52)&"|"&TRIM(F52)&"|"&TRIM(H52)&"|"&TRIM(I52)) | S52: =IF(COUNTIF($R$6:$R$928,R52)>1,"重复","唯一") | T52: 7802bc3a71d892072e43962875e26b60443d19de35bcc77fe0cbedcfa6dd5d94 | U52: Codex | V52: 46237 | W52: 原创程序几何 | X52: — | Y52: v0.1：开关新增灯组控制，同一开关可统一切换多盏房间灯；基地四灯共用一个墙边开关并在快照中报告控制灯数量。单灯房继续兼容原接口。 2026-08-03：基地四灯总开关不再移除 OmniLight3D 渲染实例；关灯能量归零，复明恢复配置能量、范围与阴影，真实 GPU 双区域像素差验收通过。
A53: ENV-TOWER-DESCENT-KIT-3D | B53: 局内关卡01-顶部数据库 | C53: 场景 | D53: room_kit | E53: tower_descent | F53: root_3d | G53: ENV-DUNGEON-RUNTIME-3D | H53: 俯视3D | I53: godot_runtime | J53: 程序占位 | K53: 程序占位 | L53: P0 | M53: v002 | N53: 98–95F白盒区块；稳定编号=局内关卡01；可变设定名=顶部数据库 | O53: scenes/TowerDescent3D.tscn | P53: art_source/design/whitebox/tower_zones/battle_level01/v002/QA_REPORT.md; art_source/design/whitebox/tower_zones/battle_level01/v002/data/unit_plan.json; art_source/design/whitebox/tower_zones/battle_level01/v002/blender/; docs/v0.1/05.1_关卡区块设计.md | Q53: 局内关卡01;顶部数据库;98到95;Battle;首个Boss区段;白盒 | R53: =LOWER(TRIM(C53)&"|"&TRIM(D53)&"|"&TRIM(E53)&"|"&TRIM(F53)&"|"&TRIM(H53)&"|"&TRIM(I53)) | S53: =IF(COUNTIF($R$6:$R$928,R53)>1,"重复","唯一") | T53: e9bf6b5353fe1caa548053d6e7e8aa18ae1eefa40c64307f3cbe13204b6c9097 | U53: Codex | V53: 46295 | W53: 程序生成 Blender 源集合 | X53: 命名合同：level_number=1，level_code=局内关卡01，setting_name=顶部数据库，display_name=局内关卡01-顶部数据库。设定名可改，编号、block_id、AssetID与路径保持稳定。当前白盒为battle_level01/v002的19个可维护Blender源；楼梯白盒另归stairs。 | Y53: 命名合同：level_number=1，level_code=局内关卡01，setting_name=顶部数据库，display_name=局内关卡01-顶部数据库。设定名可改，编号、block_id、AssetID与路径保持稳定。
A54: ENV-TOWER-FLOOR-TILE-5M | B54: 塔楼5米地砖模块 | C54: 场景 | D54: room_kit | E54: tower_descent | F54: floor_tile_5m | G54: ENV-TOWER-DESCENT-KIT-3D | H54: 俯视3D | I54: godot_runtime | J54: 100F天台与98F楼板；旧v001保留其他楼层与交通模块 | K54: 已完成 | L54: P0 | M54: v003 | N54: 5×5×0.304m；740三角面；2材质；共享MultiMesh；行走面锚点+0.1500不变；装饰件反共面阶梯+0.1520/+0.1540（XY重叠可见面高度差≥2mm） | O54: assets/art/environments/tower_descent_3d/runtime/floor_tile_5m/env_tower_floor_tile_5m_root_top3d.tscn | P54: art_source/environments/tower_descent_3d/source/floor_tile_5m/env_tower_floor_tile_5m_source_v003.blend; assets/art/environments/tower_descent_3d/components/floor_tile_5m/env_tower_floor_tile_5m_top3d.glb; scripts/blender/build_tower_floor_tile_5m_v003.py; assets/art/props/dungeon_3d/prp_tower_floor_tile_5m.tscn; tests/verification/verify_tower_journey_polish.tscn | Q54: 塔楼;地砖;楼板;5米;模块化;平铺;四向接口 | R54: =LOWER(TRIM(C54)&"|"&TRIM(D54)&"|"&TRIM(E54)&"|"&TRIM(F54)&"|"&TRIM(H54)&"|"&TRIM(I54)) | S54: =IF(COUNTIF($R$6:$R$928,R54)>1,"重复","唯一") | T54: 97e44015f71bd2c180aa5b51a937f57a543e14d40138ac8c44e0d9b34c025cea | U54: Codex | V54: 2026-09-22 00:00:00 | W54: 程序生成Blender源集合 | X54: — | Y54: 2026-08-02：复用于99层楼梯间—基地房间的15m/20m接驳走廊地面，继续遵守5m网格与不透明材质规范。 2026-08-03：水平通道按每5m一块动态生成地砖实例；使用MultiMesh批量提交但保留逐格坐标，禁止拉伸单块Mesh代替模块拼接。 2026-08-18：保留通用塔楼地板稳定ID；基地地板另登记ENV-BASE99-FLOOR-PLAIN-5M / RIVET-5M。本轮地板运行时不切换，允许临时复用。 2026-09-06：纠正旧台账GLB与实际BoxMesh引用差异。v002工业面板、金属压边、紧固槽与检修盖正式接入100F/98F；单包410面逐面PaletteUV验收通过。 2026-09-22：修复细节级闪面（z-fighting）升 v003。v002 顶面四家族（哑光面板/角部紧固座/紧固槽/检修盖板）同落 +0.1500 且 XY 互叠（跨零件共面 13 对、0.3745㎡，最严重一处为检修盖板整片 0.324㎡），相机贴地观察时逐像素闪烁；另一并存缺陷是检修盖框顶面 +0.1480，比面板低 2mm 被永久埋没不可见。v003 采用反共面阶梯：行走面锚点 +0.1500 不动（TowerFloorStage3D 固定 -FLOOR_THICKNESS*0.5=-0.15 偏移契约不受影响），盖框/紧固座/警示短标抬到 +0.1520，紧固槽/盖板格栅条抬到 +0.1540，并将检修盖缝改为 2mm 真实凹槽（通透负空间）。本件与 prp_tower_floor_tile_5m.tscn 共用同一个已去版本化的 GLB，故 98F 标准砖与远征/98F 抛光砖同时受益；99F 自持地砖不受影响。
A55: ENV-TOWER-WALL-SOLID-5M | B55: 塔楼5米满高实墙模块 | C55: 场景 | D55: room_kit | E55: tower_descent | F55: wall_solid_5m | G55: ENV-TOWER-DESCENT-KIT-3D | H55: 俯视3D | I55: godot_runtime | J55: 整层外墙/65m核心/探索房内墙/5m正交走廊 | K55: 原型已接入 | L55: P0 | M55: v004 | N55: GLB / 可视包络 5×11.9×0.4675m（结构阻挡 0.30m）/ 12m逻辑碰撞 / 共享Mesh / 可旋转 | O55: assets/art/environments/tower_descent_3d/components/env_tower_wall_solid_5m_top3d.glb | P55: art_source/environments/tower_descent_3d/source/wall_height12/env_tower_wall_solid_5m_source_v004.blend; art_source/environments/tower_descent_3d/source/wall_height12/export_env_tower_wall_solid_5m_v004.py; art_source/environments/tower_zones/battle/source/common_components/v007/env_battle_common_components_source_v007.blend; assets/art/props/dungeon_3d/prp_tower_wall_solid_5m.tscn; src/world3d/TowerGeometry3D.gd | Q55: 塔楼;实墙;满高墙;5米;12米逻辑墙;11.9米可见墙;模块化 | R55: =LOWER(TRIM(C55)&"|"&TRIM(D55)&"|"&TRIM(E55)&"|"&TRIM(F55)&"|"&TRIM(H55)&"|"&TRIM(I55)) | S55: =IF(COUNTIF($R$6:$R$928,R55)>1,"重复","唯一") | T55: 0bca134eef74148f0df444d72afff769974863cab6fec4ca885b773186649fb9 | U55: Codex | V55: 46284 | W55: Blender 派生（自 v007 通用实墙组件） | X55: — | Y55: 2026-08-02：南北向水平共享墙统一注册相机抬升判定，楼梯南侧墙纳入同一规则；墙体始终不透明，取消运行时墙体透明度改写。 2026-08-03：东西向5m房间连接通道的无门南侧实墙增加独立camera_lower_wall碰撞标记；南北向通道的东/西墙保持不触发。真实98层侧门通道相机回归通过。 2026-08-03：水平通道按每5m左右各一块动态生成9m实墙实例；墙体可视覆盖与连续碰撞严格等长，东西向通道南墙继续承担相机抬升判定。 2026-08-03：动态水平通道按实墙Mesh包围盒底面自动贴合楼面；GLB几何保持Y=0..9m，可视原点不再误用碰撞盒4.5m中心。新增墙底高度与9m墙高自动回归。 2026-09-19：可视网格换为 v004（自 battle/common_components v007「wall_standard_5m_通用包」派生，派生脚本 art_source/environments/tower_descent_3d/source/wall_height12/export_env_tower_wall_solid_5m_v004.py）。Blender 内对根节点烘焙 180° 偏航后 transform_apply，使装饰面落在 Godot +Z（与 prp_tower_* A 套 forward_axis="+Z" 对齐）；先三角化再删朝下面（去 1095 面）、join 成单 Mesh，丢掉无几何的 03_清漆反光_紫粉点缀 槽，只留 01/02/04 三个共享色盘角色。稳定路径 GLB 原地覆盖（文件名去版本号），节点名统一 ENV_TOWER_WALL_SOLID_5M，根变换为单位矩阵（该 GLB 被 TowerDescent3D 直接 preload，根变换会直接决定走廊墙位置）。阻挡不动：结构碰撞仍 0.30m 代理，可视包络 5×11.9×0.4675m（正面装甲凸到 +Z 0.3175）。 2026-10-12：可视本体被复用 —— 远征关卡01 的通用实墙组件 ENV-BATTLE-COMMON-WALL-STANDARD-5M（wall_standard_5m_root_top3d.tscn）把可视 GLB 换成本件，使该关 7 个房间（room_02/05/06/07/10/extraction/start）的实墙统一为本件重装甲外观；结构阻挡仍由该战局组件自持的 BoxShape3D 提供，本件在此纯作视觉来源。
...

Sheet 3D-场景通用
A1: ShellStorm2 · 场景通用组件 3D Prefab
A2: 关卡结构、地板、墙体、走廊、楼梯与楼板；场景模型统一引用 assets/art/shared/palette/设施低亮多巴胺色盘_10x10_512.png。
A4: AssetID | B4: 中文名 | C4: Prefab路径 | D4: GLB模型路径 | E4: Blender源文件 | F4: 功能说明 | G4: 功能脚本路径 | H4: 碰撞开关 | I4: 碰撞归属 | J4: 碰撞方式 | K4: 标准尺寸 | L4: 原点与朝向 | M4: 使用位置 | N4: 制作状态 | O4: 版本 | P4: 备注
A5: ENV-BASE99-ART-LAYOUT-3D | B5: 基地区美术 | C5: assets/art/environments/tower_zones/base/runtime/zone_base.tscn | E5: art_source/design/blender/base_facility_layout/source/base_facility_runtime_layout_hq_v026.blend; art_source/design/blender/base_facility_layout/source/base_facility_runtime_layout_hq_v026.godot.json | F5: Blocks/Base/Art区块入口；运行时桥接基地设施与美术布局 | G5: src/world3d/DungeonRoom3D.gd | H5: 无 | I5: 无 | J5: 无 | K5: 未声明 | L5: 未声明 | M5: Blocks/Base；99F | N5: 原型已接入 | O5: v002 | P5: 根节点=Art(Node3D)；Godot短名和Blender v026源通过账本映射；未重新导入GLB。
A6: ENV-BASE99-WALL-PLAIN-5X12 | B6: 基地99层普通墙体5×12米 | C6: assets/art/environments/base_facility_3d/runtime/env_base99_wall_plain_5x12/env_base99_wall_plain_5x12_root_top3d.tscn | D6: assets/art/environments/base_facility_3d/components/env_base99_wall_plain_5x12/env_base99_wall_plain_5x12_visual_top3d.glb | E6: art_source/environments/base_facility_3d/source/wall_height12/env_base99_wall_plain_5x12_source_v002.blend | F6: 5米网格墙视觉；逻辑高12米，可见高11.9米；共享色盘由Godot导入后处理绑定 | G6: src/world3d/DungeonRoom3D.gd | H6: 开 | I6: 外部脚本 | J6: BoxShape3D | K6: 5×12×0.36m逻辑外廓；11.9m可见墙；无自带碰撞 | L6: bottom_center；-Z | M6: 99/100层基地普通直墙 | N6: 正式美术已接入 | O6: v002 | P6: 根节点=基地99层普通墙体5x12米(Node3D)；PaletteUV共享色盘；碰撞归DungeonRoom3D
A7: ENV-BASE-WORLD-KIT-3D | B7: 入口基地3D环境套件 | C7: assets/art/environments/base_world_3d/env_base_world_kit_top3d.tscn | F7: Godot原生场景结构Prefab；由关卡脚本按模块实例化 | G7: src/base3d/BaseWorld3DEnvironment.gd | H7: 开 | I7: Prefab自身 | J7: 脚本生成 | K7: 约1:100迁移/程序几何 | L7: 未声明 | M7: 入口基地地图 | N7: 原型已接入 | O7: v001 | P7: 根节点=BaseWorld3DEnvironment(Node3D)
A8: ENV-DUNGEON-RUNTIME-3D | B8: 3D随机关卡通用房间套件 | C8: assets/art/environments/dungeon_3d/env_dungeon_runtime_kit_top3d.tscn | F8: Godot原生场景结构Prefab；由关卡脚本按模块实例化 | G8: src/world3d/DungeonRoom3D.gd | H8: 开 | I8: Prefab自身 | J8: 脚本生成 | K8: PackedScene/三档程序几何 | L8: 未声明 | M8: 四主题副本/随机房间 | N8: 原型已接入 | O8: v001 | P8: 根节点=DungeonRoom3D(Node3D)
A9: ENV-TRAINING-RANGE-KIT-3D | B9: 独立3D训练靶场套件 | C9: assets/art/environments/training_range_3d/env_training_range_kit_top3d.tscn | F9: Godot原生场景结构Prefab；由关卡脚本按模块实例化 | G9: src/training3d/TrainingRangeEnvironment3D.gd | H9: 开 | I9: Prefab自身 | J9: 脚本生成 | K9: PackedScene/程序环境 | L9: 未声明 | M9: 独立训练地图 | N9: 原型已接入 | O9: v001 | P9: 根节点=TrainingRangeEnvironment3D(Node3D)
A10: ENV-TOWER-CORNER-L-5M | B10: 塔楼L型转角5米 | C10: assets/art/environments/base_facility_3d/runtime/env_base99_corner_l_5m/env_base99_corner_l_5m_collision_top3d.tscn | D10: assets/art/environments/base_facility_3d/components/env_base99_corner_l_5m/env_base99_corner_l_5m_visual_top3d.glb | E10: art_source/environments/base_facility_3d/source/wall_height12/env_base99_corner_l_5m_source_v002.blend | F10: 基地转角视觉包；逻辑高12米，可见高11.9米；共享色盘由Godot导入后处理绑定 | G10: src/world3d/DungeonRoom3D.gd | H10: 开 | I10: 外部脚本 | J10: BoxShape3D双墙臂 | K10: 5×5×12m逻辑体；11.9m可见墙 | L10: inside_corner_floor；-Z | M10: 99层基地内外围转角 | N10: 正式美术已接入 | O10: v004 | P10: 稳定AssetID；视觉包无重复碰撞；12m双臂碰撞归DungeonRoom3D；PaletteUV共享色盘
A11: ENV-TOWER-CORNER-L-PARAPET-5M | B11: 塔楼L型女儿墙转角5米 | C11: assets/art/props/dungeon_3d/prp_corner_L_parapet_5m.tscn | F11: Godot原生场景结构Prefab；由关卡脚本按模块实例化 | G11: src/world3d/TowerFloorStage3D.gd | H11: 开 | I11: Prefab自身 | J11: BoxShape3D | K11: 未声明 | L11: 未声明 | M11: 场景通用组件 | N11: 程序占位 | O11: v001 | P11: 根节点=PrpCornerLParapet5m(Node3D)；2026-08-18扫描补登记资产主表
A12: ENV-TOWER-CORNER-T-5M | B12: 塔楼T型转角5米 | C12: assets/art/props/dungeon_3d/prp_corner_T_5m.tscn | F12: Godot原生场景结构Prefab；由关卡脚本按模块实例化 | G12: src/world3d/DungeonRoom3D.gd | H12: 开 | I12: Prefab自身 | J12: BoxShape3D | K12: 未声明 | L12: 未声明 | M12: 场景通用组件 | N12: 程序占位 | O12: v001 | P12: 根节点=PrpCornerT5m(Node3D)；2026-08-18扫描补登记资产主表
A13: ENV-TOWER-CORNER-X-5M | B13: 塔楼十字转角5米 | C13: assets/art/props/dungeon_3d/prp_corner_X_5m.tscn | F13: Godot原生场景结构Prefab；由关卡脚本按模块实例化 | G13: src/world3d/DungeonRoom3D.gd | H13: 开 | I13: Prefab自身 | J13: BoxShape3D | K13: 未声明 | L13: 未声明 | M13: 场景通用组件 | N13: 程序占位 | O13: v001 | P13: 根节点=PrpCornerX5m(Node3D)；2026-08-18扫描补登记资产主表
A14: ENV-DUNGEON-CORRIDOR-CEILING-SEGMENT | B14: 地牢走廊天花段 | C14: assets/art/props/dungeon_3d/prp_corridor_ceiling_segment.tscn | F14: Godot原生场景结构Prefab；由关卡脚本按模块实例化 | G14: src/world3d/DungeonRoom3D.gd | H14: 开 | I14: Prefab自身 | J14: BoxShape3D | K14: 未声明 | L14: 未声明 | M14: 场景通用组件 | N14: 程序占位 | O14: v001 | P14: 根节点=PrpCorridorCeilingSegment(Node3D)；2026-08-18扫描补登记资产主表
A15: ENV-DUNGEON-CORRIDOR-FLOOR-SEGMENT | B15: 地牢走廊地板段 | C15: assets/art/props/dungeon_3d/prp_corridor_floor_segment.tscn | F15: Godot原生场景结构Prefab；由关卡脚本按模块实例化 | G15: src/world3d/DungeonRoom3D.gd | H15: 开 | I15: Prefab自身 | J15: BoxShape3D | K15: 未声明 | L15: 未声明 | M15: 场景通用组件 | N15: 程序占位 | O15: v001 | P15: 根节点=PrpCorridorFloorSegment(Node3D)；2026-08-18扫描补登记资产主表
A16: ENV-DUNGEON-CORRIDOR-STAIR-TREAD | B16: 地牢走廊楼梯踏步 | C16: assets/art/props/dungeon_3d/prp_corridor_stair_tread.tscn | F16: Godot原生场景结构Prefab；由关卡脚本按模块实例化 | G16: src/world3d/DungeonRoom3D.gd | H16: 无 | I16: 无 | J16: 无 | K16: 未声明 | L16: 未声明 | M16: 场景通用组件 | N16: 程序占位 | O16: v001 | P16: 根节点=PrpCorridorStairTread(Node3D)；2026-08-18扫描补登记资产主表
A17: ENV-DUNGEON-CORRIDOR-WALL-SEGMENT | B17: 地牢走廊墙段 | C17: assets/art/props/dungeon_3d/prp_corridor_wall_segment.tscn | F17: Godot原生场景结构Prefab；由关卡脚本按模块实例化 | G17: src/world3d/DungeonRoom3D.gd | H17: 开 | I17: Prefab自身 | J17: BoxShape3D | K17: 未声明 | L17: 未声明 | M17: 场景通用组件 | N17: 程序占位 | O17: v001 | P17: 根节点=PrpCorridorWallSegment(Node3D)；2026-08-18扫描补登记资产主表
A18: ENV-DUNGEON-ROOM-ACCESS-STEP | B18: 房间接入台阶 | C18: assets/art/props/dungeon_3d/prp_room_access_step.tscn | F18: Godot原生场景结构Prefab；由关卡脚本按模块实例化 | G18: src/world3d/DungeonRoom3D.gd | H18: 无 | I18: 无 | J18: 无 | K18: 未声明 | L18: 未声明 | M18: 场景通用组件 | N18: 程序占位 | O18: v001 | P18: 根节点=PrpRoomAccessStep(Node3D)；2026-08-18扫描补登记资产主表
A19: ENV-DUNGEON-ROOM-CORNER-POST | B19: 房间转角立柱 | C19: assets/art/props/dungeon_3d/prp_room_corner_post.tscn | F19: Godot原生场景结构Prefab；由关卡脚本按模块实例化 | G19: src/world3d/DungeonRoom3D.gd | H19: 开 | I19: Prefab自身 | J19: BoxShape3D | K19: 未声明 | L19: 未声明 | M19: 场景通用组件 | N19: 程序占位 | O19: v001 | P19: 根节点=PrpRoomCornerPost(Node3D)；2026-08-18扫描补登记资产主表
A20: ENV-DUNGEON-ROOM-DOOR-LINTEL | B20: 房间门楣 | C20: assets/art/props/dungeon_3d/prp_room_door_lintel.tscn | F20: Godot原生场景结构Prefab；由关卡脚本按模块实例化 | G20: src/world3d/DungeonRoom3D.gd | H20: 无 | I20: 无 | J20: 无 | K20: 未声明 | L20: 未声明 | M20: 场景通用组件 | N20: 程序占位 | O20: v001 | P20: 根节点=PrpRoomDoorLintel(Node3D)；2026-08-18扫描补登记资产主表
A21: ENV-DUNGEON-FACILITY-WALL-DOOR-SIDE | B21: 基地设施门墙侧柱 | C21: assets/art/props/dungeon_3d/prp_room_facility_base_wall_door_side.tscn | F21: Godot原生场景结构Prefab；由关卡脚本按模块实例化 | G21: src/world3d/DungeonRoom3D.gd | H21: 开 | I21: Prefab自身 | J21: BoxShape3D | K21: 未声明 | L21: 未声明 | M21: 场景通用组件 | N21: 程序占位 | O21: v001 | P21: 根节点=PrpRoomFacilityBaseWallDoorSide(Node3D)；2026-08-18扫描补登记资产主表
A22: ENV-DUNGEON-FACILITY-WALL-LINTEL | B22: 基地设施墙门楣 | C22: assets/art/props/dungeon_3d/prp_room_facility_base_wall_lintel.tscn | F22: Godot原生场景结构Prefab；由关卡脚本按模块实例化 | G22: src/world3d/DungeonRoom3D.gd | H22: 开 | I22: Prefab自身 | J22: BoxShape3D | K22: 未声明 | L22: 未声明 | M22: 场景通用组件 | N22: 程序占位 | O22: v001 | P22: 根节点=PrpRoomFacilityBaseWallLintel(Node3D)；2026-08-18扫描补登记资产主表
... A41: ENV-DUNGEON-ROOM-WALL-SEGMENT | B41: 房间普通墙段 | C41: assets/art/props/dungeon_3d/prp_room_wall_segment.tscn | F41: Godot原生场景结构Prefab；由关卡脚本按模块实例化 | G41: src/world3d/DungeonRoom3D.gd | H41: 开 | I41: Prefab自身 | J41: BoxShape3D | K41: 未声明 | L41: 未声明 | M41: 场景通用组件 | N41: 程序占位 | O41: v001 | P41: 根节点=PrpRoomWallSegment(Node3D)；2026-08-18扫描补登记资产主表
A42: ENV-TOWER-FLOOR-TILE-5M | B42: 塔楼5米地砖模块 | C42: assets/art/props/dungeon_3d/prp_tower_floor_tile_5m.tscn | D42: assets/art/environments/tower_descent_3d/components/floor_tile_5m/env_tower_floor_tile_5m_top3d.glb | E42: ../ShellStorm2-backup/2026-10-11_slimming/original_tree/art_source/environments/tower_descent_3d/source/floor_tile_5m/env_tower_floor_tile_5m_source_v002.blend | F42: Godot原生场景结构Prefab；由关卡脚本按模块实例化 | G42: src/world3d/TowerFloorStage3D.gd | H42: 开 | I42: TowerFloorStage3D.FloorSupport | J42: BoxShape3D 5×0.30×5m，由 FloorSupport 按槽位生成（Prefab 不再自带碰撞） | K42: GLB / 5×5×0.3005m / 共享Mesh / MultiMesh平铺 | L42: centered_slab（板厚居中；可视顶面与承重面 Y=0 对齐） | M42: 塔楼六个物理层楼板/335m MultiMesh网格/动态水平通道 | N42: 正式美术已接入 | O42: v002 | P42: 2026-09-17：占位 BoxMesh 替换为正式美术 env_tower_floor_tile_5m_top3d_v002.glb（与 100F/98F 同源同版）。根节点=PrpTowerFloorTile5m(Node3D)，下挂 ImportedModel 引用该 GLB；Prefab 原 FloorTileCollision 已移除，承重碰撞由 TowerFloorStage3D.FloorSupport 生成。资产声明 preserve_authored_palette=true，运行时不再用暖色 A/B 主题地砖材质覆盖，保留美术自带双表面 PaletteUV。原点契约 centered_slab，运行时按 -FLOOR_THICKNESS*0.5 偏移对齐承重面 Y=0。
A43: ENV-TOWER-STAIRWELL-GENERIC-12M | B43: 楼梯B（99→98通用） | C43: assets/art/environments/tower_descent_3d/runtime/env_tower_stairwell_generic_12m/env_tower_stairwell_generic_12m_root_top3d.tscn | D43: assets/art/environments/tower_descent_3d/components/env_tower_stairwell_generic_12m_top3d.glb | E43: art_source/environments/tower_descent_3d/source/stairs_12m/stairwell_art_v021/env_tower_stairwell_dual_art_source_v021.blend | F43: Blocks/Stairs/Stair_B；PackedScene v002实例化3个优化网格，保持v021完整视觉与楼层接口 | G43: src/world3d/TowerDescent3D.gd | H43: 开 | I43: TowerDescent3D运行时包装 | J43: ConcavePolygonShape3D（1个Walkable + 1个EnclosureWall） | K43: 15×30m占地 / 12m层差 / v021完整墙地楼梯与装饰 | L43: v002；Z-up；米制；楼层合同原点 | M43: 塔楼跨层楼梯间 | N43: 正式美术已接入 | O43: v002 | P43: 2026-09-15：v021正式美术已导出、共享色盘导入并替换临时资产；3网格运行优化，结构/流程/真实渲染验收通过；v001保留回滚。
A44: ENV-TOWER-STAIRWELL-ROOFTOP-12M | B44: 楼梯A（100→99天台） | C44: assets/art/environments/tower_descent_3d/runtime/env_tower_stairwell_rooftop_12m/env_tower_stairwell_rooftop_12m_root_top3d.tscn | D44: assets/art/environments/tower_descent_3d/components/env_tower_stairwell_rooftop_12m_top3d.glb | E44: art_source/environments/tower_descent_3d/source/stairs_12m/stairwell_art_v021/env_tower_stairwell_dual_art_source_v021.blend | F44: Blocks/Stairs/Stair_A；PackedScene v002实例化3个优化网格，保持v021完整视觉与楼层接口 | G44: src/world3d/TowerDescent3D.gd | H44: 开 | I44: TowerDescent3D运行时包装 | J44: ConcavePolygonShape3D（1个Walkable + 1个EnclosureWall） | K44: 15×30m占地 / 12m层差 / v021完整墙地楼梯与装饰 | L44: v002；Z-up；米制；楼层合同原点 | M44: 塔楼跨层楼梯间 | N44: 正式美术已接入 | O44: v002 | P44: 2026-09-15：v021正式美术已导出、共享色盘导入并替换临时资产；3网格运行优化，结构/流程/真实渲染验收通过；v001保留回滚。
A45: ENV-TOWER-WALL-DOOR-5M | B45: 塔楼5米带门墙模块 | C45: assets/art/props/dungeon_3d/prp_tower_wall_door_5m.tscn | D45: assets/art/environments/tower_descent_3d/components/env_tower_wall_door_5m_top3d.glb | E45: ../ShellStorm2-backup/2026-10-11_slimming/original_tree/art_source/environments/tower_descent_3d/source/wall_height12/env_tower_wall_door_5m_source_v003.blend | F45: Godot原生场景结构Prefab；由关卡脚本按模块实例化 | G45: src/world3d/DungeonRoom3D.gd | H45: 开 | I45: Prefab自身（3×BoxShape3D 代理）+ DungeonRoom3D | J45: 3×BoxShape3D：左/右门柱 1.4×12×0.30（x=∓1.8）+ 门楣 2.2×9.5×0.30（y 底=2.5），门洞镂空可通行 | K45: 5×0.30×11.9m可见墙；12m逻辑碰撞；2.2×2.5m净开口 | L45: bottom_center（几何 Y=0..11.9）；朝 +Z | M45: 5m墙位/2.2m净宽/2.5m净高/独立门扇 | N45: 正式美术已接入 | O45: v003 | P45: 2026-09-17：占位 BoxMesh 替换为正式美术 env_tower_wall_door_5m_top3d_v003.glb。根节点=PrpTowerWallDoor5m(Node3D)，下挂 ImportedModel；美术自带静态门扇 DoorLeaf_OPEN 置 visible=false，门扇改由运行时 RoomDoor3D.DoorPanel 提供（与基地99层带门墙同规范，GLB 只作墙体/门框）。保留原 3×BoxShape3D 碰撞代理（门柱 2 + 门楣 1，门洞镂空可通行）。资产声明 preserve_authored_palette=true，保留美术自带材质，不再用塔楼暖色 A/B 主题覆盖。
A46: ENV-TOWER-WALL-PARAPET-5M | B46: 塔楼5米楼顶女儿墙模块 | C46: assets/art/props/dungeon_3d/prp_tower_wall_parapet_5m.tscn | D46: assets/art/environments/tower_descent_3d/components/env_tower_wall_parapet_5m_top3d.glb | E46: 10C_MOD_WALL_PARAPET_5M_U01（Blender 集合）；export_env_tower_5m_modules_v001.py | F46: Godot原生场景结构Prefab；由关卡脚本按模块实例化 | G46: src/world3d/TowerFloorStage3D.gd | H46: 开 | I46: TowerFloorStage3D | J46: BoxShape3D 5×1.5×0.30，由 OuterBoundaryCollision 按槽位生成（Prefab 不再自带碰撞） | K46: GLB / 5×0.30×1.50m / 共享Mesh | L46: bottom_center（几何 Y=0..1.50）；朝 +Z | M46: 335m楼顶四周边界/268段MultiMesh围栏 | N46: 正式美术已接入 | O46: v001 | P46: 2026-09-17：占位 BoxMesh 替换为正式美术 env_tower_wall_parapet_5m_top3d_v001.glb。根节点=PrpTowerWallParapet5m(Node3D)，下挂 ImportedModel；Prefab 视觉专用（visual_only），楼顶四周边界碰撞由 TowerFloorStage3D.OuterBoundaryCollision 按 0.30m 代理生成。资产声明 preserve_authored_palette=true，保留美术自带 PaletteUV，不再用塔楼暖色 A/B 主题覆盖。原点契约 bottom_center（几何 Y=0..1.50）。
A47: ENV-TOWER-WALL-PARAPET-DOOR-5M | B47: 塔楼带门女儿墙5米 | C47: assets/art/props/dungeon_3d/prp_tower_wall_parapet_door_5m.tscn | F47: Godot原生场景结构Prefab；由关卡脚本按模块实例化 | G47: src/world3d/TowerFloorStage3D.gd | H47: 开 | I47: Prefab自身 | J47: BoxShape3D | K47: 未声明 | L47: 未声明 | M47: 场景通用组件 | N47: 程序占位 | O47: v001 | P47: 根节点=PrpTowerWallParapetDoor5m(Node3D)；2026-08-18扫描补登记资产主表
A48: ENV-TOWER-WALL-SOLID-5M | B48: 塔楼5米满高实墙模块 | C48: assets/art/props/dungeon_3d/prp_tower_wall_solid_5m.tscn | D48: assets/art/environments/tower_descent_3d/components/env_tower_wall_solid_5m_top3d.glb | E48: art_source/environments/tower_descent_3d/source/wall_height12/env_tower_wall_solid_5m_source_v004.blend（派生自 art_source/environments/tower_zones/battle/source/common_components/v007/env_battle_common_components_source_v007.blend） | F48: Godot原生场景结构Prefab；由关卡脚本按模块实例化 | G48: src/world3d/DungeonRoom3D.gd | H48: 开 | I48: DungeonRoom3D + TowerFloorStage3D | J48: DungeonRoom3D TowerWallCollision_*_Run 0.30m 代理；视觉走 MultiMesh，Prefab 不再自带碰撞 | K48: GLB / 可视包络 5×11.9×0.4675m（结构阻挡 0.30m）/ 12m逻辑碰撞 / 共享Mesh | L48: bottom_center（几何 Y=0..11.9）；朝 +Z | M48: 整层外墙/65m核心/探索房内墙/5m正交走廊 | N48: 正式美术已接入 | O48: v004 | P48: 2026-09-17：占位 BoxMesh 替换为正式美术（与 100F/98F 同源同版）。根节点=PrpTowerWallSolid5m(Node3D)，下挂 ImportedModel；Prefab 视觉专用（visual_only），结构碰撞由 DungeonRoom3D.TowerWallCollision_*_Run 与 TowerFloorStage3D.OuterBoundaryCollision_* 按 0.30m 代理生成。资产声明 preserve_authored_palette=true——塔楼 MultiMesh 不再套 WALL_SOLID_MATERIAL_A/B 单色主题，保留美术自带 PaletteUV（共享色盘角色 01_精工金属_紫色骨架 / 02_细腻哑光_青绿大面 / 04_柔和自发光_UI灯光）。原点契约 bottom_center（几何 Y=0..11.9），运行时按 -mesh.get_aabb().position.y 反算贴合楼面。 2026-09-19：升 v004。GLB 原地覆盖稳定路径（文件名去版本号，节点名统一 ENV_TOWER_WALL_SOLID_5M，根变换为单位矩阵）。结构包络与可视包络分离：bounds_size_m 仍 5×11.9×0.30（结构阻挡），visual_bounds_size_m=5×11.9×0.4675（正面装甲凸到 +Z 0.3175，背面 -0.15）。跨套朝向：Blender 侧 +Y 为厚度轴，B 套（battle/common_components，含 v007）装饰面在 -Y，导出前烘焙 180° 使装饰面落 Godot +Z，与 A 套 prp_tower_* 的 forward_axis="+Z" 对齐。该 GLB 除本 Prefab 外还被 TowerDescent3D 直接 preload（_get_corridor_wall_module_mesh / _build_stair_approach_corridor），故根节点变换必须为单位矩阵。
A49: ENV-BASE99-WALL-DOOR-5X12 | B49: 基地99层带门墙体5×12米 | C49: assets/art/environments/base_facility_3d/runtime/env_base99_wall_door_5x12/env_base99_wall_door_5x12_root_top3d.tscn | D49: assets/art/environments/base_facility_3d/components/env_base99_wall_door_5x12/env_base99_wall_door_5x12_visual_top3d.glb | E49: art_source/environments/base_facility_3d/source/wall_height12/env_base99_wall_door_5x12_source_v004.blend | F49: 仅表现；墙体由DungeonRoom3D按5米槽位组合 | G49: src/world3d/DungeonRoom3D.gd | H49: 开 | I49: 外部脚本 | J49: DungeonRoom3D BoxShape3D | K49: 5×12m逻辑外廓；11.9m可见墙；2.2×2.5m门洞 | L49: bottom_center；-Z | M49: 99层基地 | N49: 正式美术已接入 | O49: v004；GLB无玩法碰撞；DungeonRoom3D持有12m阻挡 | P49: GLB无玩法碰撞；cast_and_receive；替换同路径GLB不改变功能。
A50: ENV-BASE99-FLOOR-PLAIN-5M | B50: 基地99层普通地板5×5米 | C50: assets/art/environments/base_facility_3d/runtime/env_base99_floor_plain_5m/env_base99_floor_plain_5m_root_top3d.tscn | D50: assets/art/environments/base_facility_3d/components/env_base99_floor_plain_5m/env_base99_floor_plain_5m_visual_top3d.glb | E50: ../ShellStorm2-backup/2026-10-11_slimming/original_tree/art_source/environments/base_facility_3d/source/env_base99_modular_room/env_base99_modular_room_assets_clean_v001.blend | F50: 仅表现；5米网格由DungeonRoom3D组合 | G50: src/world3d/DungeonRoom3D.gd | H50: 开 | I50: 外部脚本 | J50: TowerFloorStage BoxShape3D | K50: 5×5×0.30m；平面中心/结构底面原点 | L50: bottom_center；-Z | M50: 99层基地 | N50: 正式美术已接入 | O50: v001 | P50: GLB无玩法碰撞；cast_and_receive；替换同路径GLB不改变功能。
A51: ENV-BASE99-FLOOR-RIVET-5M | B51: 基地99层铆钉铁皮带地板5×5米 | C51: assets/art/environments/base_facility_3d/runtime/env_base99_floor_rivet_5m/env_base99_floor_rivet_5m_root_top3d.tscn | D51: assets/art/environments/base_facility_3d/components/env_base99_floor_rivet_5m/env_base99_floor_rivet_5m_visual_top3d.glb | E51: ../ShellStorm2-backup/2026-10-11_slimming/original_tree/art_source/environments/base_facility_3d/source/env_base99_modular_room/env_base99_modular_room_assets_clean_v001.blend | F51: 仅表现；5米网格由DungeonRoom3D组合 | G51: src/world3d/DungeonRoom3D.gd | H51: 开 | I51: 外部脚本 | J51: TowerFloorStage BoxShape3D | K51: 5×5×0.395m视觉外廓；0.30m结构板+0.095m装饰凸起 | L51: bottom_center；-Z | M51: 99层基地 | N51: 正式美术已接入 | O51: v001 | P51: GLB无玩法碰撞；cast_and_receive；替换同路径GLB不改变功能。
A52: ENV-BASE99-WALL-WINDOW-5X12 | B52: 基地99层带窗墙体5×12米 | C52: assets/art/environments/base_facility_3d/runtime/env_base99_wall_window_5x12/env_base99_wall_window_5x12_root_top3d.tscn | D52: assets/art/environments/base_facility_3d/components/env_base99_wall_window_5x12/env_base99_wall_window_5x12_visual_top3d.glb | E52: art_source/environments/base_facility_3d/source/wall_height12/env_base99_wall_window_5x12_source_v002.blend | F52: 100层上层围护表现；99层禁止实例化 | H52: 开 | I52: 外部脚本 | J52: 上层围护独立结构碰撞 | K52: 5×12m逻辑外廓；11.9m可见墙；底边中心原点 | L52: bottom_center；-Z | M52: 100层基地 | N52: 正式美术已接入 | O52: v002；GLB仅表现；上层围护持有12m阻挡 | P52: GLB仅表现；cast_and_receive；99层使用数量必须为0。
A53: ENV-BASE99-MEZZANINE-20X10-Z7 | B53: 基地99层7米楼中楼楼板 | C53: assets/art/environments/base_facility_3d/runtime/env_base99_mezzanine_20x10_z7/env_base99_mezzanine_20x10_z7_root_top3d.tscn | D53: assets/art/environments/base_facility_3d/components/env_base99_mezzanine_20x10_z7/env_base99_mezzanine_20x10_z7_visual_top3d.glb | E53: ../ShellStorm2-backup/2026-10-11_slimming/original_tree/art_source/environments/base_facility_3d/source/env_base99_modular_room/env_base99_modular_room_assets_clean_v001.blend | F53: 可编辑可行走结构；含底部摄像机净空语义 | G53: src/world3d/Base99WalkableModule3D.gd | H53: 开 | I53: Prefab脚本 | J53: 简化Box楼板面 + camera_stair_slab | K53: 约20.25×10.25m外廓；完成面7m；底部中心原点 | L53: bottom_center；-Z | M53: 99层基地 | N53: 正式美术已接入 | O53: v001 | P53: 在基地布局tscn直接移动；模型、碰撞和摄像机语义随实例同步。
A54: ENV-BASE99-STAIR-L-Z7 | B54: 基地99层7米L型楼梯 | C54: assets/art/environments/base_facility_3d/runtime/env_base99_stair_l_z7/env_base99_stair_l_z7_root_top3d.tscn | D54: assets/art/environments/base_facility_3d/components/env_base99_stair_l_z7/env_base99_stair_l_z7_visual_top3d.glb | E54: ../ShellStorm2-backup/2026-10-11_slimming/original_tree/art_source/environments/base_facility_3d/source/env_base99_modular_room/env_base99_modular_room_assets_clean_v001.blend | F54: 可编辑可行走结构；含底部摄像机净空语义 | G54: src/world3d/Base99WalkableModule3D.gd | H54: 开 | I54: Prefab脚本 | J54: 两段Box斜坡+转角平台 + camera_stair_slab | K54: 约9.22×10.54×7.94m外廓；一楼至7m楼板 | L54: bottom_center；-Z | M54: 99层基地 | N54: 正式美术已接入 | O54: v001 | P54: 不使用踏步Trimesh；坡面低于角色44度上限；位置由布局tscn管理。
A55: ENV-BASE99-STAIR-EXTERIOR-H2 | B55: 基地99层二楼外门2米小楼梯 | C55: assets/art/environments/base_facility_3d/runtime/env_base99_stair_exterior_h2/env_base99_stair_exterior_h2_root_top3d.tscn | D55: assets/art/environments/base_facility_3d/components/env_base99_stair_exterior_h2/env_base99_stair_exterior_h2_visual_top3d.glb | E55: ../ShellStorm2-backup/2026-10-11_slimming/original_tree/art_source/environments/base_facility_3d/source/env_base99_modular_room/env_base99_modular_room_assets_clean_v001.blend | F55: 可编辑可行走结构；含底部摄像机净空语义 | G55: src/world3d/Base99WalkableModule3D.gd | H55: 开 | I55: Prefab脚本 | J55: 简化Box斜坡 + camera_stair_slab | K55: 4.515×2.80×2.00m；7m楼板至9m外门门槛 | L55: bottom_center；-Z | M55: 99层基地 | N55: 正式美术已接入 | O55: v001 | P55: 不使用踏步Trimesh；位置和旋转由布局tscn管理。
A56: ENV-BASE100-UPPER-SHELL-30X30-H9 | B56: 基地100层上层围护与18米封顶 | C56: assets/art/environments/base_facility_3d/runtime/env_base100_upper_shell_30x30_h9/env_base100_upper_shell_30x30_h9_root_top3d.tscn | E56: art_source/environments/base_facility_3d/source/env_base99_modular_room/env_base99_modular_room_source_v001.blend | F56: 可编辑组合Prefab；24块围护墙与36块封顶模块；统一挡光并投影 | G56: src/world3d/Base100UpperShell3D.gd | H56: 开 | I56: Prefab脚本 | J56: 9个BoxShape3D（连续墙/东侧门洞框/屋顶） | K56: 30×30×9m上层围护；墙底9m；屋顶底18m；东门洞2.2×2.5m | L56: room_center；local -Z为北；根缩放1 | M56: 基地100层及18米屋顶 | N56: 正式美术已接入 | O56: v001 | P56: 子Prefab=60；北墙两端普通+中间4窗；其余19普通墙，东侧1门墙；复用现有墙/地板资产，cast_and_receive；18米屋顶阻挡室外光；不恢复99/100层中间36块。
A57: ENV-BASE99-MEZZANINE-20X10-Z5 | B57: 基地99层5米楼中楼结构与护栏（复用V020二层地板） | C57: assets/art/environments/base_facility_3d/runtime/env_base99_mezzanine_20x10_z5/env_base99_mezzanine_20x10_z5_root_top3d.tscn | D57: assets/art/environments/base_facility_3d/components/env_base99_mezzanine_20x10_z5/env_base99_mezzanine_20x10_z5_visual_top3d.glb | E57: art_source/environments/base_facility_3d/source/env_base99_modular_room/env_base99_modular_room_assets_clean_v006.blend（v006；资产v004） | F57: 5米承重平台与连续栏杆；移除9个旧地砖/甲板网格，二层表现复用V020地板；真实投影 | G57: src/world3d/Base99WalkableModule3D.gd | H57: 开 | I57: Prefab自身 | J57: 连续Box楼板+独立栏杆Box；西侧入口为L梯留空 | K57: 20.2475×10.2475×5.93m；台面5m；552三角面 | L57: 底面中心；Blender -Y / Godot -Z | M57: 99层基地楼中楼 | N57: 正式美术已接入；优化完成 | O57: 已完成，未接入 | P57: Blender母版v005；660/660面PaletteUV有效；边缘共面数0；视觉/碰撞/功能分离。2026-09-04：旧阁楼架实例从基地布局撤下，资产文件保留回滚。
A58: ENV-BASE99-STAIR-L-Z5 | B58: 基地99层5米L型楼梯 | C58: assets/art/environments/base_facility_3d/runtime/env_base99_stair_l_z5/env_base99_stair_l_z5_root_top3d.tscn | D58: assets/art/environments/base_facility_3d/components/env_base99_stair_l_z5/env_base99_stair_l_z5_visual_top3d.glb | E58: ../ShellStorm2-backup/2026-10-11_slimming/original_tree/art_source/environments/base_facility_3d/source/env_base99_modular_room/env_base99_modular_room_assets_clean_v004.blend | F58: 0→2.5→5米完整双跑L梯；转角扶手收口；真实投影与阻挡 | G58: src/world3d/Base99WalkableModule3D.gd | H58: 开 | I58: Prefab自身 | J58: 单一StaticBody：斜坡+平台+斜坡；独立连续扶手Box | K58: 9.2176×10.538×5.91015m；终点5m | L58: 底面中心；Blender -Y / Godot -Z | M58: 99层基地一楼至楼中楼 | N58: 正式美术已接入；沿用已验收V004 | O58: 已完成，未接入 | P58: 由91个可编辑源组件重建；踏步/斜梁/平台/导光条齐全；转角扶手不穿插；三段行走形状接缝齐平并重叠0.04m。2026-09-04：旧L型楼梯实例从基地布局撤下，资产文件保留回滚。
A59: ENV-BASE99-STAIR-EXTERIOR-H4 | B59: 基地99至100层4米外门楼梯 | C59: assets/art/environments/base_facility_3d/runtime/env_base99_stair_exterior_h4/env_base99_stair_exterior_h4_root_top3d.tscn | D59: assets/art/environments/base_facility_3d/components/env_base99_stair_exterior_h4/env_base99_stair_exterior_h4_visual_top3d.glb | E59: ../ShellStorm2-backup/2026-10-11_slimming/original_tree/art_source/environments/base_facility_3d/source/env_base99_modular_room/env_base99_modular_room_assets_clean_v002.blend | F59: 平台5米至100层9米；两段原生楼梯组合；真实投影 | G59: src/world3d/Base99WalkableModule3D.gd | H59: 开 | I59: Prefab自身 | J59: 覆盖8.515米包络的连续斜坡+双侧护栏 | K59: 8.515×2.8×4m；高差4m | L59: 底面中心；Blender -Y / Godot -Z | M59: 基地楼中楼至100层出口 | N59: 正式美术已接入 | O59: v002 | P59: 不做纵向拉伸；替代H2版本
...

Sheet 3D-设施
A1: ShellStorm2 · 设施组件 3D Prefab
A2: 门扇、终端、工作台、储物与服务设施；设施模型统一引用 assets/art/shared/palette/设施低亮多巴胺色盘_10x10_512.png。
A4: AssetID | B4: 中文名 | C4: Prefab路径 | D4: GLB模型路径 | E4: Blender源文件 | F4: 功能说明 | G4: 功能脚本路径 | H4: 碰撞开关 | I4: 碰撞归属 | J4: 碰撞方式 | K4: 标准尺寸 | L4: 原点与朝向 | M4: 使用位置 | N4: 制作状态 | O4: 版本 | P4: 备注
A5: PRP-BASE-FACILITY-3D | B5: 基地设施3D通用模块 | C5: assets/art/props/base_world_3d/prp_base_facility_root_top3d_v001.tscn | F5: 设施或交互Prefab；保留自身脚本、碰撞和状态接口 | G5: src/base3d/BaseFacility3D.gd | H5: 开 | I5: Prefab自身 | J5: BoxShape3D | K5: PackedScene/材质变体/名称与实时摘要共用Label3D | L5: 未声明 | M5: 8类基地设施/统一状态牌 | N5: 原型已接入 | O5: v001 | P5: 根节点=BaseFacility3D(Area3D)
A6: PRP-BASE-VENDING-MACHINE-3D | B6: 基地科幻自动贩卖机 | C6: assets/art/props/base_world_3d/prp_base_vending_machine_root_top3d_v001.tscn | E6: ../ShellStorm2-backup/2026-10-11_slimming/original_tree/art_source/props/base_world_3d/source/vending_machine/prp_base_vending_machine_source_v001.blend | F6: 设施或交互Prefab；保留自身脚本、碰撞和状态接口 | G6: src/base3d/BaseFacility3D.gd | H6: 开 | I6: Prefab自身 | J6: BoxShape3D | K6: 4材质；主体/自发光分离；独立GLB/PackedScene | L6: 未声明 | M6: BaseWorld3D/TowerDescent99F | N6: 正式美术已接入 | O6: v002 | P6: 根节点=BaseVendingMachine3D(Area3D)；资产主表当前Prefab=assets/art/props/base_world_3d/runtime/vending_machine/prp_base_vending_machine_root_top3d_v002.tscn；旧版Prefab保留用于回滚；正式版本为v002
A7: PRP-DUNGEON-GATE-3D | B7: 地下城入口3D模块 | C7: assets/art/props/base_world_3d/prp_dungeon_gate_root_top3d_v001.tscn | F7: 设施或交互Prefab；保留自身脚本、碰撞和状态接口 | G7: src/base3d/DungeonEntrance3D.gd | H7: 开 | I7: Prefab自身 | J7: BoxShape3D | K7: PackedScene/材质变体 | L7: 未声明 | M7: 4个地下城入口 | N7: 原型已接入 | O7: v001 | P7: 根节点=DungeonEntrance3D(Area3D)
A8: PRP-BASE-LOCKER-STATION-3D | B8: 赛博储物站 | C8: assets/art/props/base_world_3d/runtime/locker_station/prp_base_locker_station_root_top3d_v001.tscn | D8: assets/art/props/base_world_3d/components/locker_station/prp_base_locker_station_visual_top3d_v004.glb | E8: art_source/props/base_world_3d/source/locker_station/prp_base_locker_station_source_v004.blend | F8: 设施或交互Prefab；保留自身脚本、碰撞和状态接口 | G8: src/base3d/BaseFacility3D.gd | H8: 开 | I8: Prefab自身 | J8: BoxShape3D | K8: 4材质；主体/自发光分离；独立GLB/PackedScene | L8: -Z | M8: 基地99层/保险柜设施 | N8: 正式美术已接入 | O8: v004 | P8: 根节点=赛博储物站(Area3D)
A9: PRP-BASE-BRIEFING | B9: 远征情报终端 / 战术情报指挥桌 | C9: assets/art/props/base_world_3d/runtime/mission_operations/prp_base_mission_operations_root_top3d_v001.tscn | D9: assets/art/props/base_world_3d/components/mission_operations/prp_base_mission_operations_visual_top3d_v005.glb | E9: ../ShellStorm2-backup/2026-10-11_slimming/original_tree/art_source/props/base_world_3d/source/mission_operations/prp_base_mission_operations_source_v003.blend | F9: 设施或交互Prefab；保留自身脚本、碰撞和状态接口 | G9: src/base3d/BaseFacility3D.gd | H9: 开 | I9: Prefab自身 | J9: BoxShape3D | K9: 4材质；主体/自发光分离；独立GLB/PackedScene | L9: -Z | M9: BaseWorld3D/TowerDescent99F | N9: 正式美术已接入 | O9: v003 | P9: 根节点=远征情报终端(Area3D)
A10: PRP-BASE-RETRO-TV-STATION-3D | B10: 复古游戏电视站 | C10: assets/art/props/base_world_3d/runtime/retro_tv_station/prp_base_retro_tv_station_root_top3d_v001.tscn | D10: assets/art/props/base_world_3d/components/retro_tv_station/prp_base_retro_tv_station_visual_top3d_v004.glb | E10: art_source/props/base_world_3d/source/retro_tv_station/prp_base_retro_tv_station_source_v004.blend | F10: 设施或交互Prefab；保留自身脚本、碰撞和状态接口 | G10: src/base3d/BaseFacility3D.gd | H10: 开 | I10: Prefab自身 | J10: BoxShape3D | K10: 4材质；主体/自发光分离；独立GLB/PackedScene | L10: -Z | M10: 基地99层/命运卡收藏室 | N10: 正式美术已接入 | O10: v004 | P10: 根节点=复古游戏电视站(Area3D)
